File: SiC 1/Hyst at 30K/First measurement/SiC1_hyst_30K.rso.dat.csv
[Header]
TITLE,MPMS RSO Measurement
BYAPP,MPMS Measurement,1.1,Summary
FILEOPENTIME, 1615586907.470000 3/12/2021, 11:08:27 PM

INFO, APPNAME, MPMS MultiVu Application, Revision 1.61,  Build 082

INFO, NAME,
INFO, WEIGHT, 1.000
INFO, AREA, 1.000
INFO, LENGTH, 1.000
INFO, SHAPE, 0
INFO, COMMENT,
INFO, SEQUENCE FILE: H5T_Lin_NoO.seq


INFO, BACKGROUND DATA FILE:, None


STARTUPAXIS,X,4,LINEAR,AUTO,0.000000,0.000000
STARTUPAXIS,Y1,5,LINEAR,AUTO,0.000000,0.000000


STARTUPGROUP,Longitudinal
FIELDGROUP,Longitudinal,1,2,3,4,5,6,7,8,9,10,11,19,20,21,22,23,35
FIELDGROUP,Transverse,1,2,3,4,12,13,14,15,16,17,18,24,25,26,27,28,35

PLOT_APPEARANCE,ALL,HORZ_GRID_ON,VERT_GRID_ON,MARKERS_AND_LINES

[Data]
Time,Comment,Field (Oe),Temperature (K),Long Moment (emu),Long Scan Std Dev,Long Offset (cm),Long Offset Std Dev,Long Algorithm,Long Reg Fit,Long Reg Factor,Trans Moment (emu),Trans Scan Std Dev,Trans Offset (cm),Trans Offset Std Dev,Trans Algorithm,Trans Reg Fit,Trans Reg Factor,Long Moment [w/o ABS] (emu),Long Scan Std Dev [w/o ABS],Long Offset [w/o ABS] (cm),Long Offset Std Dev [w/o ABS],Long Reg Fit [w/o ABS],Trans Moment [w/o ABS] (emu),Trans Scan Std Dev [w/o ABS],Trans Offset [w/o ABS] (cm),Trans Offset Std Dev [w/o ABS],Trans Reg Fit [w/o ABS],RSO Position (deg),Amplitude (cm),Frequency,Cycles to Average,Scans per Measurement,Delta Temp (K),Error,EC Comp. Running,Using ABS,
1615586907.470,,0.000000e+000,2.999998e+001,-5.998654e-009,3.882390e-009,0.000000e+000,0.000000e+000,2,0.000000e+000,1.825000e+000,,,,,,,,,,,,,,,,,,0,3.000000e+000,1.000000e+000,10,5,2.899170e-003,0,,0,
1615587101.239,,2.000000e+002,3.000012e+001,-7.138351e-007,2.311148e-008,0.000000e+000,0.000000e+000,2,8.834698e-001,1.825000e+000,,,,,,,,,,,,,,,,,,0,3.000000e+000,1.000000e+000,10,5,4.339218e-003,0,,0,
1615587289.038,,4.000000e+002,3.000084e+001,-1.435307e-006,2.475073e-009,0.000000e+000,0.000000e+000,2,9.763544e-001,1.825000e+000,,,,,,,,,,,,,,,,,,0,3.000000e+000,1.000000e+000,10,5,2.889633e-003,0,,0,
1615587477.318,,6.000000e+002,3.000056e+001,-2.200167e-006,1.475674e-008,0.000000e+000,0.000000e+000,2,9.764878e-001,1.825000e+000,,,,,,,,,,,,,,,,,,0,3.000000e+000,1.000000e+000,10,5,1.449585e-003,0,,0,
1615587663.657,,8.000000e+002,3.000056e+001,-3.044321e-006,5.758448e-009,0.000000e+000,0.000000e+000,2,9.809006e-001,1.825000e+000,,,,,,,,,,,,,,,,,,0,3.000000e+000,1.000000e+000,10,5,1.449585e-003,0,,0,
1615587851.057,,1.000000e+003,3.000012e+001,-3.915496e-006,1.181681e-008,0.000000e+000,0.000000e+000,2,9.829515e-001,1.825000e+000,,,,,,,,,,,,,,,,,,0,3.000000e+000,1.000000e+000,10,5,2.889633e-003,0,,0,
1615588070.916,,1.500000e+003,3.000056e+001,-6.264368e-006,8.264862e-009,0.000000e+000,0.000000e+000,2,9.844897e-001,1.825000e+000,,,,,,,,,,,,,,,,,,0,3.000000e+000,1.000000e+000,10,5,1.449585e-003,0,,0,
1615588269.816,,2.000000e+003,3.000055e+001,-8.657270e-006,2.040208e-008,0.000000e+000,0.000000e+000,2,9.822019e-001,1.825000e+000,,,,,,,,,,,,,,,,,,0,3.000000e+000,1.000000e+000,10,5,4.339218e-003,0,,0,
1615588464.945,,2.500000e+003,3.000084e+001,-1.117419e-005,4.703418e-008,0.000000e+000,0.000000e+000,2,9.801698e-001,1.825000e+000,,,,,,,,,,,,,,,,,,0,3.000000e+000,1.000000e+000,10,5,1.449585e-003,0,,0,
1615588683.174,,3.000000e+003,2.999983e+001,-1.363386e-005,7.058355e-008,0.000000e+000,0.000000e+000,2,9.791223e-001,1.825000e+000,,,,,,,,,,,,,,,,,,0,3.000000e+000,1.000000e+000,10,5,1.449585e-003,0,,0,
1615588879.073,,3.500000e+003,3.000084e+001,-1.613517e-005,3.088388e-008,0.000000e+000,0.000000e+000,2,9.804893e-001,1.825000e+000,,,,,,,,,,,,,,,,,,0,3.000000e+000,1.000000e+000,10,5,1.449585e-003,0,,0,
1615589068.442,,4.000000e+003,3.000070e+001,-1.863142e-005,6.475901e-008,0.000000e+000,0.000000e+000,2,9.818914e-001,1.825000e+000,,,,,,,,,,,,,,,,,,0,3.000000e+000,1.000000e+000,10,5,2.889633e-003,0,,0,
1615589275.902,,5.000000e+003,3.000084e+001,-2.361777e-005,6.040164e-008,0.000000e+000,0.000000e+000,2,9.819188e-001,1.825000e+000,,,,,,,,,,,,,,,,,,0,3.000000e+000,1.000000e+000,10,5,2.889633e-003,0,,0,
1615589475.531,,6.000000e+003,3.000113e+001,-2.866431e-005,3.186251e-008,0.000000e+000,0.000000e+000,2,9.800974e-001,1.825000e+000,,,,,,,,,,,,,,,,,,0,3.000000e+000,1.000000e+000,10,5,2.889633e-003,0,,0,
1615589674.010,,7.000000e+003,3.000128e+001,-3.372742e-005,2.584607e-008,0.000000e+000,0.000000e+000,2,9.807833e-001,1.825000e+000,,,,,,,,,,,,,,,,,,0,3.000000e+000,1.000000e+000,10,5,1.440048e-003,0,,0,
1615589861.779,,8.000000e+003,3.000027e+001,-3.879000e-005,5.877823e-008,0.000000e+000,0.000000e+000,2,9.815447e-001,1.825000e+000,,,,,,,,,,,,,,,,,,0,3.000000e+000,1.000000e+000,10,5,1.449585e-003,0,,0,
1615590050.079,,9.000000e+003,3.000128e+001,-4.380697e-005,8.308910e-008,0.000000e+000,0.000000e+000,2,9.812967e-001,1.825000e+000,,,,,,,,,,,,,,,,,,0,3.000000e+000,1.000000e+000,10,5,2.889633e-003,0,,0,
1615590238.138,,1.000000e+004,3.000084e+001,-4.889960e-005,7.886614e-008,0.000000e+000,0.000000e+000,2,9.808381e-001,1.825000e+000,,,,,,,,,,,,,,,,,,0,3.000000e+000,1.000000e+000,10,5,2.889633e-003,0,,0,
1615590428.847,,1.200000e+004,3.000157e+001,-5.898702e-005,4.377011e-008,0.000000e+000,0.000000e+000,2,9.804745e-001,1.825000e+000,,,,,,,,,,,,,,,,,,0,3.000000e+000,1.000000e+000,10,5,2.889633e-003,0,,0,
1615590621.907,,1.400000e+004,3.000084e+001,-6.922063e-005,8.109276e-008,0.000000e+000,0.000000e+000,2,9.804967e-001,1.825000e+000,,,,,,,,,,,,,,,,,,0,3.000000e+000,1.000000e+000,10,5,2.889633e-003,0,,0,
1615590807.496,,1.600000e+004,3.000056e+001,-7.934286e-005,5.840772e-008,0.000000e+000,0.000000e+000,2,9.803370e-001,1.825000e+000,,,,,,,,,,,,,,,,,,0,3.000000e+000,1.000000e+000,10,5,1.449585e-003,0,,0,
1615591000.095,,1.800000e+004,3.000142e+001,-8.959279e-005,5.981658e-008,0.000000e+000,0.000000e+000,2,9.797670e-001,1.825000e+000,,,,,,,,,,,,,,,,,,0,3.000000e+000,1.000000e+000,10,5,2.889633e-003,0,,0,
1615591194.015,,2.000000e+004,3.000128e+001,-9.964675e-005,5.152688e-008,0.000000e+000,0.000000e+000,2,9.800460e-001,1.825000e+000,,,,,,,,,,,,,,,,,,0,3.000000e+000,1.000000e+000,10,5,1.440048e-003,0,,0,
1615591397.874,,2.500000e+004,3.000084e+001,-1.250784e-004,2.220656e-007,0.000000e+000,0.000000e+000,2,9.803630e-001,1.825000e+000,,,,,,,,,,,,,,,,,,0,3.000000e+000,1.000000e+000,10,5,2.889633e-003,0,,0,
1615591602.013,,3.000000e+004,3.000070e+001,-1.504232e-004,7.365404e-008,0.000000e+000,0.000000e+000,2,9.799112e-001,1.825000e+000,,,,,,,,,,,,,,,,,,0,3.000000e+000,1.000000e+000,10,5,2.889633e-003,0,,0,
1615591811.712,,3.500000e+004,3.000186e+001,-1.759877e-004,7.388351e-008,0.000000e+000,0.000000e+000,2,9.805075e-001,1.825000e+000,,,,,,,,,,,,,,,,,,0,3.000000e+000,1.000000e+000,10,5,4.339218e-003,0,,0,
1615592015.992,,4.000000e+004,3.000157e+001,-2.014591e-004,2.012366e-007,0.000000e+000,0.000000e+000,2,9.803914e-001,1.825000e+000,,,,,,,,,,,,,,,,,,0,3.000000e+000,1.000000e+000,10,5,1.440048e-003,0,,0,
1615592224.671,,4.500000e+004,3.000171e+001,-2.270254e-004,2.915075e-007,0.000000e+000,0.000000e+000,2,9.806308e-001,1.825000e+000,,,,,,,,,,,,,,,,,,0,3.000000e+000,1.000000e+000,10,5,1.440048e-003,0,,0,
1615592424.400,,5.000000e+004,3.000055e+001,-2.525576e-004,3.119158e-007,0.000000e+000,0.000000e+000,2,9.799600e-001,1.825000e+000,,,,,,,,,,,,,,,,,,0,3.000000e+000,1.000000e+000,10,5,2.889633e-003,0,,0,
1615592659.019,,4.500000e+004,3.000099e+001,-2.268471e-004,1.984891e-007,0.000000e+000,0.000000e+000,2,9.805983e-001,1.825000e+000,,,,,,,,,,,,,,,,,,0,3.000000e+000,1.000000e+000,10,5,2.889633e-003,0,,0,
1615592873.458,,4.000000e+004,3.000070e+001,-2.013856e-004,1.097665e-007,0.000000e+000,0.000000e+000,2,9.804430e-001,1.825000e+000,,,,,,,,,,,,,,,,,,0,3.000000e+000,1.000000e+000,10,5,4.339218e-003,0,,0,
1615593085.798,,3.500000e+004,3.000142e+001,-1.759647e-004,2.555933e-007,0.000000e+000,0.000000e+000,2,9.797408e-001,1.825000e+000,,,,,,,,,,,,,,,,,,0,3.000000e+000,1.000000e+000,10,5,1.440048e-003,0,,0,
1615593284.967,,3.000000e+004,3.000171e+001,-1.505707e-004,1.503901e-007,0.000000e+000,0.000000e+000,2,9.799194e-001,1.825000e+000,,,,,,,,,,,,,,,,,,0,3.000000e+000,1.000000e+000,10,5,1.440048e-003,0,,0,
1615593495.966,,2.500000e+004,3.000142e+001,-1.249609e-004,1.810300e-007,0.000000e+000,0.000000e+000,2,9.807168e-001,1.825000e+000,,,,,,,,,,,,,,,,,,0,3.000000e+000,1.000000e+000,10,5,2.889633e-003,0,,0,
1615593700.086,,2.000000e+004,3.000084e+001,-9.959003e-005,5.505774e-008,0.000000e+000,0.000000e+000,2,9.801768e-001,1.825000e+000,,,,,,,,,,,,,,,,,,0,3.000000e+000,1.000000e+000,10,5,2.889633e-003,0,,0,
1615593905.815,,1.800000e+004,3.000128e+001,-8.942901e-005,5.175040e-008,0.000000e+000,0.000000e+000,2,9.805301e-001,1.825000e+000,,,,,,,,,,,,,,,,,,0,3.000000e+000,1.000000e+000,10,5,5.788803e-003,0,,0,
1615594098.265,,1.600000e+004,3.000099e+001,-7.915910e-005,6.151842e-008,0.000000e+000,0.000000e+000,2,9.801267e-001,1.825000e+000,,,,,,,,,,,,,,,,,,0,3.000000e+000,1.000000e+000,10,5,2.889633e-003,0,,0,
1615594297.494,,1.400000e+004,3.000099e+001,-6.911720e-005,3.323736e-008,0.000000e+000,0.000000e+000,2,9.807900e-001,1.825000e+000,,,,,,,,,,,,,,,,,,0,3.000000e+000,1.000000e+000,10,5,4.339218e-003,0,,0,
1615594490.363,,1.200000e+004,3.000084e+001,-5.890336e-005,9.517778e-008,0.000000e+000,0.000000e+000,2,9.800777e-001,1.825000e+000,,,,,,,,,,,,,,,,,,0,3.000000e+000,1.000000e+000,10,5,2.889633e-003,0,,0,
1615594680.233,,1.000000e+004,3.000041e+001,-4.879010e-005,2.329148e-008,0.000000e+000,0.000000e+000,2,9.804063e-001,1.825000e+000,,,,,,,,,,,,,,,,,,0,3.000000e+000,1.000000e+000,10,5,4.339218e-003,0,,0,
1615594866.782,,9.000000e+003,3.000142e+001,-4.375027e-005,4.368339e-008,0.000000e+000,0.000000e+000,2,9.805772e-001,1.825000e+000,,,,,,,,,,,,,,,,,,0,3.000000e+000,1.000000e+000,10,5,1.440048e-003,0,,0,
1615595046.792,,8.000000e+003,3.000099e+001,-3.865769e-005,2.388547e-008,0.000000e+000,0.000000e+000,2,9.808581e-001,1.825000e+000,,,,,,,,,,,,,,,,,,0,3.000000e+000,1.000000e+000,10,5,0.000000e+000,0,,0,
1615595260.051,,7.000000e+003,3.000084e+001,-3.361137e-005,2.547101e-008,0.000000e+000,0.000000e+000,2,9.806836e-001,1.825000e+000,,,,,,,,,,,,,,,,,,0,3.000000e+000,1.000000e+000,10,5,2.889633e-003,0,,0,
1615595458.790,,6.000000e+003,3.000070e+001,-2.857338e-005,2.309453e-008,0.000000e+000,0.000000e+000,2,9.820809e-001,1.825000e+000,,,,,,,,,,,,,,,,,,0,3.000000e+000,1.000000e+000,10,5,2.889633e-003,0,,0,
1615595658.080,,5.000000e+003,3.000128e+001,-2.353555e-005,1.398753e-008,0.000000e+000,0.000000e+000,2,9.819930e-001,1.825000e+000,,,,,,,,,,,,,,,,,,0,3.000000e+000,1.000000e+000,10,5,2.889633e-003,0,,0,
1615595851.569,,4.000000e+003,3.000099e+001,-1.849899e-005,2.776933e-008,0.000000e+000,0.000000e+000,2,9.816806e-001,1.825000e+000,,,,,,,,,,,,,,,,,,0,3.000000e+000,1.000000e+000,10,5,2.889633e-003,0,,0,
1615596066.168,,3.500000e+003,3.000070e+001,-1.601038e-005,4.728442e-008,0.000000e+000,0.000000e+000,2,9.820014e-001,1.825000e+000,,,,,,,,,,,,,,,,,,0,3.000000e+000,1.000000e+000,10,5,2.889633e-003,0,,0,
1615596301.117,,3.000000e+003,3.000084e+001,-1.350777e-005,9.540883e-009,0.000000e+000,0.000000e+000,2,9.819788e-001,1.825000e+000,,,,,,,,,,,,,,,,,,0,3.000000e+000,1.000000e+000,10,5,2.889633e-003,0,,0,
1615596535.887,,2.500000e+003,3.000012e+001,-1.101542e-005,3.163390e-008,0.000000e+000,0.000000e+000,2,9.819138e-001,1.825000e+000,,,,,,,,,,,,,,,,,,0,3.000000e+000,1.000000e+000,10,5,1.449585e-003,0,,0,
1615596755.116,,2.000000e+003,3.000056e+001,-8.551841e-006,7.589245e-009,0.000000e+000,0.000000e+000,2,9.791513e-001,1.825000e+000,,,,,,,,,,,,,,,,,,0,3.000000e+000,1.000000e+000,10,5,2.889633e-003,0,,0,
1615596949.705,,1.500000e+003,3.000070e+001,-6.100099e-006,3.830280e-008,0.000000e+000,0.000000e+000,2,9.693912e-001,1.825000e+000,,,,,,,,,,,,,,,,,,0,3.000000e+000,1.000000e+000,10,5,1.449585e-003,0,,0,
1615597143.614,,1.000000e+003,3.000113e+001,-3.765297e-006,4.811580e-008,0.000000e+000,0.000000e+000,2,9.634388e-001,1.825000e+000,,,,,,,,,,,,,,,,,,0,3.000000e+000,1.000000e+000,10,5,2.889633e-003,0,,0,
1615597332.234,,8.000000e+002,3.000070e+001,-2.810803e-006,3.549658e-008,0.000000e+000,0.000000e+000,2,9.296502e-001,1.825000e+000,,,,,,,,,,,,,,,,,,0,3.000000e+000,1.000000e+000,10,5,1.449585e-003,0,,0,
1615597520.833,,6.000000e+002,3.000142e+001,-1.906885e-006,2.891269e-008,0.000000e+000,0.000000e+000,2,9.309251e-001,1.825000e+000,,,,,,,,,,,,,,,,,,0,3.000000e+000,1.000000e+000,10,5,2.889633e-003,0,,0,
1615597709.562,,4.000000e+002,3.000084e+001,-1.070113e-006,7.788555e-008,0.000000e+000,0.000000e+000,2,8.715651e-001,1.825000e+000,,,,,,,,,,,,,,,,,,0,3.000000e+000,1.000000e+000,10,5,2.889633e-003,0,,0,
1615597898.222,,2.000000e+002,3.000113e+001,-2.238666e-007,4.224922e-008,0.000000e+000,0.000000e+000,2,3.783828e-001,1.825000e+000,,,,,,,,,,,,,,,,,,0,3.000000e+000,1.000000e+000,10,5,2.889633e-003,0,,0,
1615598092.782,,0.000000e+000,3.000113e+001,5.007216e-007,6.241805e-008,0.000000e+000,0.000000e+000,2,7.771060e-001,1.825000e+000,,,,,,,,,,,,,,,,,,0,3.000000e+000,1.000000e+000,10,5,2.889633e-003,0,,0,
1615598286.841,,-2.000000e+002,3.000056e+001,1.058931e-006,3.190712e-008,0.000000e+000,0.000000e+000,2,8.852257e-001,1.825000e+000,,,,,,,,,,,,,,,,,,0,3.000000e+000,1.000000e+000,10,5,1.449585e-003,0,,0,
1615598480.700,,-4.000000e+002,3.000128e+001,1.635775e-006,8.958519e-008,0.000000e+000,0.000000e+000,2,9.124948e-001,1.825000e+000,,,,,,,,,,,,,,,,,,0,3.000000e+000,1.000000e+000,10,5,4.339218e-003,0,,0,
1615598669.300,,-6.000000e+002,3.000128e+001,2.332625e-006,4.914522e-008,0.000000e+000,0.000000e+000,2,9.570264e-001,1.825000e+000,,,,,,,,,,,,,,,,,,0,3.000000e+000,1.000000e+000,10,5,1.440048e-003,0,,0,
1615598857.709,,-8.000000e+002,3.000157e+001,3.150024e-006,1.525643e-008,0.000000e+000,0.000000e+000,2,9.489050e-001,1.825000e+000,,,,,,,,,,,,,,,,,,0,3.000000e+000,1.000000e+000,10,5,2.889633e-003,0,,0,
1615599047.218,,-1.000000e+003,3.000113e+001,4.019673e-006,2.351957e-008,0.000000e+000,0.000000e+000,2,9.621076e-001,1.825000e+000,,,,,,,,,,,,,,,,,,0,3.000000e+000,1.000000e+000,10,5,2.889633e-003,0,,0,
1615599243.228,,-1.500000e+003,3.000070e+001,6.341852e-006,1.567234e-008,0.000000e+000,0.000000e+000,2,9.792354e-001,1.825000e+000,,,,,,,,,,,,,,,,,,0,3.000000e+000,1.000000e+000,10,5,2.889633e-003,0,,0,
1615599439.467,,-2.000000e+003,3.000128e+001,8.740183e-006,1.860604e-008,0.000000e+000,0.000000e+000,2,9.818973e-001,1.825000e+000,,,,,,,,,,,,,,,,,,0,3.000000e+000,1.000000e+000,10,5,1.440048e-003,0,,0,
1615599636.836,,-2.500000e+003,3.000128e+001,1.119109e-005,4.188013e-008,0.000000e+000,0.000000e+000,2,9.825844e-001,1.825000e+000,,,,,,,,,,,,,,,,,,0,3.000000e+000,1.000000e+000,10,5,4.339218e-003,0,,0,
1615599832.836,,-3.000000e+003,3.000099e+001,1.360995e-005,1.567159e-007,0.000000e+000,0.000000e+000,2,9.680876e-001,1.825000e+000,,,,,,,,,,,,,,,,,,0,3.000000e+000,1.000000e+000,10,5,0.000000e+000,0,,0,
1615600029.455,,-3.500000e+003,3.000084e+001,1.612347e-005,8.976640e-008,0.000000e+000,0.000000e+000,2,9.771845e-001,1.825000e+000,,,,,,,,,,,,,,,,,,0,3.000000e+000,1.000000e+000,10,5,2.889633e-003,0,,0,
1615600226.295,,-4.000000e+003,3.000128e+001,1.867638e-005,5.164267e-008,0.000000e+000,0.000000e+000,2,9.801698e-001,1.825000e+000,,,,,,,,,,,,,,,,,,0,3.000000e+000,1.000000e+000,10,5,1.440048e-003,0,,0,
1615600432.874,,-5.000000e+003,3.000099e+001,2.366509e-005,7.669929e-008,0.000000e+000,0.000000e+000,2,9.787537e-001,1.825000e+000,,,,,,,,,,,,,,,,,,0,3.000000e+000,1.000000e+000,10,5,4.339218e-003,0,,0,
1615600679.893,,-6.000000e+003,2.999998e+001,2.872148e-005,2.382229e-008,0.000000e+000,0.000000e+000,2,9.813328e-001,1.825000e+000,,,,,,,,,,,,,,,,,,0,3.000000e+000,1.000000e+000,10,5,4.339218e-003,0,,0,
1615600884.782,,-7.000000e+003,3.000084e+001,3.376051e-005,2.521364e-008,0.000000e+000,0.000000e+000,2,9.812082e-001,1.825000e+000,,,,,,,,,,,,,,,,,,0,3.000000e+000,1.000000e+000,10,5,2.889633e-003,0,,0,
1615601078.062,,-8.000000e+003,3.000055e+001,3.879383e-005,4.236753e-008,0.000000e+000,0.000000e+000,2,9.803792e-001,1.825000e+000,,,,,,,,,,,,,,,,,,0,3.000000e+000,1.000000e+000,10,5,4.339218e-003,0,,0,
1615601265.671,,-9.000000e+003,3.000128e+001,4.385486e-005,2.896548e-008,0.000000e+000,0.000000e+000,2,9.810478e-001,1.825000e+000,,,,,,,,,,,,,,,,,,0,3.000000e+000,1.000000e+000,10,5,2.889633e-003,0,,0,
1615601455.401,,-1.000000e+004,3.000185e+001,4.889392e-005,3.692837e-008,0.000000e+000,0.000000e+000,2,9.808951e-001,1.825000e+000,,,,,,,,,,,,,,,,,,0,3.000000e+000,1.000000e+000,10,5,1.440048e-003,0,,0,
1615601640.030,,-1.200000e+004,3.000128e+001,5.906032e-005,1.866225e-008,0.000000e+000,0.000000e+000,2,9.807811e-001,1.825000e+000,,,,,,,,,,,,,,,,,,0,3.000000e+000,1.000000e+000,10,5,1.440048e-003,0,,0,
1615601833.189,,-1.400000e+004,3.000084e+001,6.921285e-005,5.869289e-008,0.000000e+000,0.000000e+000,2,9.806089e-001,1.825000e+000,,,,,,,,,,,,,,,,,,0,3.000000e+000,1.000000e+000,10,5,2.889633e-003,0,,0,
1615602021.799,,-1.600000e+004,3.000084e+001,7.997973e-005,4.791050e-007,0.000000e+000,0.000000e+000,2,9.811759e-001,1.825000e+000,,,,,,,,,,,,,,,,,,0,3.000000e+000,1.000000e+000,10,5,2.889633e-003,0,,0,
1615602207.848,,-1.800000e+004,3.000099e+001,9.267648e-005,7.860583e-008,0.000000e+000,0.000000e+000,2,9.743754e-001,1.825000e+000,,,,,,,,,,,,,,,,,,0,3.000000e+000,1.000000e+000,10,5,0.000000e+000,0,,0,
1615602400.487,,-2.000000e+004,3.000128e+001,1.028295e-004,4.011090e-008,0.000000e+000,0.000000e+000,2,9.765331e-001,1.825000e+000,,,,,,,,,,,,,,,,,,0,3.000000e+000,1.000000e+000,10,5,2.889633e-003,0,,0,
1615602609.197,,-2.500000e+004,3.000113e+001,1.260243e-004,4.352741e-006,0.000000e+000,0.000000e+000,2,9.724496e-001,1.825000e+000,,,,,,,,,,,,,,,,,,0,3.000000e+000,1.000000e+000,10,5,2.889633e-003,0,,0,
1615602818.486,,-3.000000e+004,3.000157e+001,1.576471e-004,1.942385e-006,0.000000e+000,0.000000e+000,2,9.644974e-001,1.825000e+000,,,,,,,,,,,,,,,,,,0,3.000000e+000,1.000000e+000,10,5,4.339218e-003,0,,0,
1615603022.815,,-3.500000e+004,3.000113e+001,1.826182e-004,1.551379e-007,0.000000e+000,0.000000e+000,2,9.706108e-001,1.825000e+000,,,,,,,,,,,,,,,,,,0,3.000000e+000,1.000000e+000,10,5,2.889633e-003,0,,0,
1615603232.485,,-4.000000e+004,3.000157e+001,2.111383e-004,2.424478e-007,0.000000e+000,0.000000e+000,2,9.638578e-001,1.825000e+000,,,,,,,,,,,,,,,,,,0,3.000000e+000,1.000000e+000,10,5,1.440048e-003,0,,0,
1615603441.064,,-4.500000e+004,3.000070e+001,2.366992e-004,1.912730e-007,0.000000e+000,0.000000e+000,2,9.662697e-001,1.825000e+000,,,,,,,,,,,,,,,,,,0,3.000000e+000,1.000000e+000,10,5,4.339218e-003,0,,0,
1615603649.613,,-5.000000e+004,3.000113e+001,2.622990e-004,1.441519e-007,0.000000e+000,0.000000e+000,2,9.683170e-001,1.825000e+000,,,,,,,,,,,,,,,,,,0,3.000000e+000,1.000000e+000,10,5,2.889633e-003,0,,0,
1615603880.243,,-4.500000e+004,3.000084e+001,2.365685e-004,1.232930e-007,0.000000e+000,0.000000e+000,2,9.671514e-001,1.825000e+000,,,,,,,,,,,,,,,,,,0,3.000000e+000,1.000000e+000,10,5,4.339218e-003,0,,0,
1615604088.492,,-4.000000e+004,3.000113e+001,2.109236e-004,1.379834e-007,0.000000e+000,0.000000e+000,2,9.633496e-001,1.825000e+000,,,,,,,,,,,,,,,,,,0,3.000000e+000,1.000000e+000,10,5,2.889633e-003,0,,0,
1615604290.242,,-3.500000e+004,3.000084e+001,1.855422e-004,1.573858e-007,0.000000e+000,0.000000e+000,2,9.600314e-001,1.825000e+000,,,,,,,,,,,,,,,,,,0,3.000000e+000,1.000000e+000,10,5,2.889633e-003,0,,0,
1615604496.461,,-3.000000e+004,3.000142e+001,1.600568e-004,1.529836e-007,0.000000e+000,0.000000e+000,2,9.562631e-001,1.825000e+000,,,,,,,,,,,,,,,,,,0,3.000000e+000,1.000000e+000,10,5,4.339218e-003,0,,0,
1615604702.650,,-2.500000e+004,3.000186e+001,1.346765e-004,8.174953e-008,0.000000e+000,0.000000e+000,2,9.494919e-001,1.825000e+000,,,,,,,,,,,,,,,,,,0,3.000000e+000,1.000000e+000,10,5,4.339218e-003,0,,0,
1615604907.719,,-2.000000e+004,3.000099e+001,1.083375e-004,4.240778e-008,0.000000e+000,0.000000e+000,2,9.444765e-001,1.825000e+000,,,,,,,,,,,,,,,,,,0,3.000000e+000,1.000000e+000,10,5,2.889633e-003,0,,0,
1615605109.209,,-1.800000e+004,3.000056e+001,9.813889e-005,8.202557e-008,0.000000e+000,0.000000e+000,2,9.398272e-001,1.825000e+000,,,,,,,,,,,,,,,,,,0,3.000000e+000,1.000000e+000,10,5,1.449585e-003,0,,0,
1615605303.178,,-1.600000e+004,3.000128e+001,8.791058e-005,4.446572e-008,0.000000e+000,0.000000e+000,2,9.337734e-001,1.825000e+000,,,,,,,,,,,,,,,,,,0,3.000000e+000,1.000000e+000,10,5,2.889633e-003,0,,0,
1615605496.418,,-1.400000e+004,3.000142e+001,7.776320e-005,8.356079e-008,0.000000e+000,0.000000e+000,2,9.255145e-001,1.825000e+000,,,,,,,,,,,,,,,,,,0,3.000000e+000,1.000000e+000,10,5,4.339218e-003,0,,0,
1615605687.787,,-1.200000e+004,3.000084e+001,5.717493e-005,5.657942e-008,0.000000e+000,0.000000e+000,2,9.562805e-001,1.825000e+000,,,,,,,,,,,,,,,,,,0,3.000000e+000,1.000000e+000,10,5,2.889633e-003,0,,0,
1615605884.666,,-1.000000e+004,3.000113e+001,4.701622e-005,3.945772e-008,0.000000e+000,0.000000e+000,2,9.479680e-001,1.825000e+000,,,,,,,,,,,,,,,,,,0,3.000000e+000,1.000000e+000,10,5,2.889633e-003,0,,0,
1615606072.255,,-9.000000e+003,3.000113e+001,4.199729e-005,3.047766e-008,0.000000e+000,0.000000e+000,2,9.417273e-001,1.825000e+000,,,,,,,,,,,,,,,,,,0,3.000000e+000,1.000000e+000,10,5,2.889633e-003,0,,0,
1615606266.463,,-8.000000e+003,3.000041e+001,3.694531e-005,3.663416e-008,0.000000e+000,0.000000e+000,2,9.340380e-001,1.825000e+000,,,,,,,,,,,,,,,,,,0,3.000000e+000,1.000000e+000,10,5,1.449585e-003,0,,0,
1615606465.471,,-7.000000e+003,3.000084e+001,3.334514e-005,2.144738e-007,0.000000e+000,0.000000e+000,2,9.799467e-001,1.825000e+000,,,,,,,,,,,,,,,,,,0,3.000000e+000,1.000000e+000,10,5,2.889633e-003,0,,0,
1615606657.849,,-6.000000e+003,3.000099e+001,2.840919e-005,1.577719e-008,0.000000e+000,0.000000e+000,2,9.819567e-001,1.825000e+000,,,,,,,,,,,,,,,,,,0,3.000000e+000,1.000000e+000,10,5,4.339218e-003,0,,0,
1615606862.748,,-5.000000e+003,3.000157e+001,2.336531e-005,1.105050e-008,0.000000e+000,0.000000e+000,2,9.808845e-001,1.825000e+000,,,,,,,,,,,,,,,,,,0,3.000000e+000,1.000000e+000,10,5,2.889633e-003,0,,0,
1615607061.476,,-4.000000e+003,3.000026e+001,1.832520e-005,4.985768e-008,0.000000e+000,0.000000e+000,2,9.787588e-001,1.825000e+000,,,,,,,,,,,,,,,,,,0,3.000000e+000,1.000000e+000,10,5,4.339218e-003,0,,0,
1615607265.144,,-3.500000e+003,3.000084e+001,1.581837e-005,1.752941e-008,0.000000e+000,0.000000e+000,2,9.759175e-001,1.825000e+000,,,,,,,,,,,,,,,,,,0,3.000000e+000,1.000000e+000,10,5,2.889633e-003,0,,0,
1615607495.842,,-3.000000e+003,3.000084e+001,1.334489e-005,3.671398e-008,0.000000e+000,0.000000e+000,2,9.745712e-001,1.825000e+000,,,,,,,,,,,,,,,,,,0,3.000000e+000,1.000000e+000,10,5,1.449585e-003,0,,0,
1615607757.589,,-2.500000e+003,2.999998e+001,1.085878e-005,3.070678e-008,0.000000e+000,0.000000e+000,2,9.685759e-001,1.825000e+000,,,,,,,,,,,,,,,,,,0,3.000000e+000,1.000000e+000,10,5,2.889633e-003,0,,0,
1615607999.788,,-2.000000e+003,3.000099e+001,8.370220e-006,4.504244e-008,0.000000e+000,0.000000e+000,2,9.610681e-001,1.825000e+000,,,,,,,,,,,,,,,,,,0,3.000000e+000,1.000000e+000,10,5,2.889633e-003,0,,0,
1615608193.556,,-1.500000e+003,3.000099e+001,5.952685e-006,2.705667e-008,0.000000e+000,0.000000e+000,2,9.406394e-001,1.825000e+000,,,,,,,,,,,,,,,,,,0,3.000000e+000,1.000000e+000,10,5,2.889633e-003,0,,0,
1615608388.164,,-1.000000e+003,3.000142e+001,3.606305e-006,6.542902e-008,0.000000e+000,0.000000e+000,2,9.132426e-001,1.825000e+000,,,,,,,,,,,,,,,,,,0,3.000000e+000,1.000000e+000,10,5,2.889633e-003,0,,0,
1615608577.032,,-8.000000e+002,3.000084e+001,2.686172e-006,3.313042e-008,0.000000e+000,0.000000e+000,2,8.714982e-001,1.825000e+000,,,,,,,,,,,,,,,,,,0,3.000000e+000,1.000000e+000,10,5,2.889633e-003,0,,0,
1615608765.551,,-6.000000e+002,3.000157e+001,1.733284e-006,8.047578e-008,0.000000e+000,0.000000e+000,2,8.112798e-001,1.825000e+000,,,,,,,,,,,,,,,,,,0,3.000000e+000,1.000000e+000,10,5,2.889633e-003,0,,0,
1615608954.279,,-4.000000e+002,3.000084e+001,9.420624e-007,1.604493e-008,0.000000e+000,0.000000e+000,2,7.191134e-001,1.825000e+000,,,,,,,,,,,,,,,,,,0,3.000000e+000,1.000000e+000,10,5,2.889633e-003,0,,0,
1615609142.927,,-2.000000e+002,3.000041e+001,1.468372e-007,3.280042e-008,0.000000e+000,0.000000e+000,2,0.000000e+000,1.825000e+000,,,,,,,,,,,,,,,,,,0,3.000000e+000,1.000000e+000,10,5,1.449585e-003,0,,0,
1615609336.975,,0.000000e+000,3.000070e+001,-4.427559e-007,2.761038e-008,0.000000e+000,0.000000e+000,2,7.918419e-001,1.825000e+000,,,,,,,,,,,,,,,,,,0,3.000000e+000,1.000000e+000,10,5,2.889633e-003,0,,0,
1615609530.804,,2.000000e+002,3.000012e+001,-9.355824e-007,6.481422e-008,0.000000e+000,0.000000e+000,2,8.044207e-001,1.825000e+000,,,,,,,,,,,,,,,,,,0,3.000000e+000,1.000000e+000,10,5,2.899170e-003,0,,0,
1615609724.382,,4.000000e+002,3.000142e+001,-1.535637e-006,6.245200e-008,0.000000e+000,0.000000e+000,2,8.498976e-001,1.825000e+000,,,,,,,,,,,,,,,,,,0,3.000000e+000,1.000000e+000,10,5,2.889633e-003,0,,0,
1615609910.661,,6.000000e+002,2.999998e+001,-2.107397e-006,4.393885e-008,0.000000e+000,0.000000e+000,2,8.026652e-001,1.825000e+000,,,,,,,,,,,,,,,,,,0,3.000000e+000,1.000000e+000,10,5,2.899170e-003,0,,0,
1615610097.640,,8.000000e+002,3.000099e+001,-2.960131e-006,7.185392e-008,0.000000e+000,0.000000e+000,2,8.759337e-001,1.825000e+000,,,,,,,,,,,,,,,,,,0,3.000000e+000,1.000000e+000,10,5,2.889633e-003,0,,0,
1615610286.018,,1.000000e+003,3.000142e+001,-3.764114e-006,7.269517e-008,0.000000e+000,0.000000e+000,2,8.808076e-001,1.825000e+000,,,,,,,,,,,,,,,,,,0,3.000000e+000,1.000000e+000,10,5,2.889633e-003,0,,0,
1615610483.537,,1.500000e+003,3.000142e+001,-6.104726e-006,2.752133e-008,0.000000e+000,0.000000e+000,2,9.300244e-001,1.825000e+000,,,,,,,,,,,,,,,,,,0,3.000000e+000,1.000000e+000,10,5,2.889633e-003,0,,0,
1615610678.786,,2.000000e+003,3.000128e+001,-1.369225e-005,8.700876e-009,0.000000e+000,0.000000e+000,2,5.132461e-001,1.825000e+000,,,,,,,,,,,,,,,,,,0,3.000000e+000,1.000000e+000,10,5,4.339218e-003,0,,0,
1615610876.225,,2.500000e+003,3.000084e+001,-1.636811e-005,6.387543e-008,0.000000e+000,0.000000e+000,2,5.742137e-001,1.825000e+000,,,,,,,,,,,,,,,,,,0,3.000000e+000,1.000000e+000,10,5,2.889633e-003,0,,0,
1615611065.434,,3.000000e+003,3.000128e+001,-1.906764e-005,6.921069e-008,0.000000e+000,0.000000e+000,2,6.236337e-001,1.825000e+000,,,,,,,,,,,,,,,,,,0,3.000000e+000,1.000000e+000,10,5,4.339218e-003,0,,0,
1615611264.222,,3.500000e+003,3.000070e+001,-2.173734e-005,3.608555e-008,0.000000e+000,0.000000e+000,2,6.608143e-001,1.825000e+000,,,,,,,,,,,,,,,,,,0,3.000000e+000,1.000000e+000,10,5,1.449585e-003,0,,0,
1615611463.191,,4.000000e+003,3.000128e+001,-2.444290e-005,1.030062e-007,0.000000e+000,0.000000e+000,2,6.881432e-001,1.825000e+000,,,,,,,,,,,,,,,,,,0,3.000000e+000,1.000000e+000,10,5,1.440048e-003,0,,0,
1615611657.370,,5.000000e+003,3.000157e+001,-2.966094e-005,4.711163e-008,0.000000e+000,0.000000e+000,2,7.368610e-001,1.825000e+000,,,,,,,,,,,,,,,,,,0,3.000000e+000,1.000000e+000,10,5,2.889633e-003,0,,0,
1615611856.998,,6.000000e+003,3.000084e+001,-3.488021e-005,3.145250e-008,0.000000e+000,0.000000e+000,2,7.723166e-001,1.825000e+000,,,,,,,,,,,,,,,,,,0,3.000000e+000,1.000000e+000,10,5,1.449585e-003,0,,0,
1615612056.307,,7.000000e+003,3.000070e+001,-4.005080e-005,3.836718e-008,0.000000e+000,0.000000e+000,2,7.988118e-001,1.825000e+000,,,,,,,,,,,,,,,,,,0,3.000000e+000,1.000000e+000,10,5,4.339218e-003,0,,0,
1615612244.506,,8.000000e+003,3.000099e+001,-4.514449e-005,8.449311e-008,0.000000e+000,0.000000e+000,2,8.214045e-001,1.825000e+000,,,,,,,,,,,,,,,,,,0,3.000000e+000,1.000000e+000,10,5,5.790710e-003,0,,0,
1615612432.305,,9.000000e+003,3.000113e+001,-5.026070e-005,4.482295e-008,0.000000e+000,0.000000e+000,2,8.393631e-001,1.825000e+000,,,,,,,,,,,,,,,,,,0,3.000000e+000,1.000000e+000,10,5,2.889633e-003,0,,0,
1615612626.254,,1.000000e+004,3.000157e+001,-5.536856e-005,4.375184e-008,0.000000e+000,0.000000e+000,2,8.557858e-001,1.825000e+000,,,,,,,,,,,,,,,,,,0,3.000000e+000,1.000000e+000,10,5,1.440048e-003,0,,0,
1615612816.853,,1.200000e+004,3.000041e+001,-6.556061e-005,2.430022e-008,0.000000e+000,0.000000e+000,2,8.783969e-001,1.825000e+000,,,,,,,,,,,,,,,,,,0,3.000000e+000,1.000000e+000,10,5,1.449585e-003,0,,0,
1615613009.831,,1.400000e+004,3.000099e+001,-7.579535e-005,7.491516e-008,0.000000e+000,0.000000e+000,2,8.963826e-001,1.825000e+000,,,,,,,,,,,,,,,,,,0,3.000000e+000,1.000000e+000,10,5,0.000000e+000,0,,0,
1615613197.880,,1.600000e+004,3.000084e+001,-8.587573e-005,5.115458e-008,0.000000e+000,0.000000e+000,2,9.102415e-001,1.825000e+000,,,,,,,,,,,,,,,,,,0,3.000000e+000,1.000000e+000,10,5,2.889633e-003,0,,0,
1615613392.029,,1.800000e+004,3.000157e+001,-9.608197e-005,9.861036e-008,0.000000e+000,0.000000e+000,2,9.209027e-001,1.825000e+000,,,,,,,,,,,,,,,,,,0,3.000000e+000,1.000000e+000,10,5,4.339218e-003,0,,0,
1615613586.428,,2.000000e+004,3.000157e+001,-1.062365e-004,2.362867e-008,0.000000e+000,0.000000e+000,2,9.301618e-001,1.825000e+000,,,,,,,,,,,,,,,,,,0,3.000000e+000,1.000000e+000,10,5,2.889633e-003,0,,0,
1615613787.907,,2.500000e+004,3.000099e+001,-1.316581e-004,5.631284e-008,0.000000e+000,0.000000e+000,2,9.457431e-001,1.825000e+000,,,,,,,,,,,,,,,,,,0,3.000000e+000,1.000000e+000,10,5,2.889633e-003,0,,0,
1615613996.527,,3.000000e+004,3.000171e+001,-1.572173e-004,1.472986e-007,0.000000e+000,0.000000e+000,2,9.566428e-001,1.825000e+000,,,,,,,,,,,,,,,,,,0,3.000000e+000,1.000000e+000,10,5,1.440048e-003,0,,0,
1615614211.625,,3.500000e+004,3.000171e+001,-1.826215e-004,4.778687e-008,0.000000e+000,0.000000e+000,2,9.643818e-001,1.825000e+000,,,,,,,,,,,,,,,,,,0,3.000000e+000,1.000000e+000,10,5,4.339218e-003,0,,0,
1615614416.134,,4.000000e+004,3.000229e+001,-2.081519e-004,1.328221e-007,0.000000e+000,0.000000e+000,2,9.705138e-001,1.825000e+000,,,,,,,,,,,,,,,,,,0,3.000000e+000,1.000000e+000,10,5,4.339218e-003,0,,0,
1615614614.814,,4.500000e+004,3.000157e+001,-2.335844e-004,2.562760e-007,0.000000e+000,0.000000e+000,2,9.742453e-001,1.825000e+000,,,,,,,,,,,,,,,,,,0,3.000000e+000,1.000000e+000,10,5,4.339218e-003,0,,0,
1615614821.523,,5.000000e+004,3.000099e+001,-2.591196e-004,1.270629e-007,0.000000e+000,0.000000e+000,2,9.775406e-001,1.825000e+000,,,,,,,,,,,,,,,,,,0,3.000000e+000,1.000000e+000,10,5,4.339218e-003,0,,0,