File: SiC 1/Hyst at 30K/Second measurement/SiC1_hyst_30K_2.rso.dat.csv
[Header]
TITLE,MPMS RSO Measurement
BYAPP,MPMS Measurement,1.1,Summary
FILEOPENTIME, 1615801614.635000 3/15/2021, 10:46:54 AM

INFO, APPNAME, MPMS MultiVu Application, Revision 1.61,  Build 082

INFO, NAME,
INFO, WEIGHT, 1.000
INFO, AREA, 1.000
INFO, LENGTH, 1.000
INFO, SHAPE, 0
INFO, COMMENT,
INFO, SEQUENCE FILE: H5T_Lin_NoO.seq


INFO, BACKGROUND DATA FILE:, None


STARTUPAXIS,X,4,LINEAR,AUTO,0.000000,0.000000
STARTUPAXIS,Y1,5,LINEAR,AUTO,0.000000,0.000000


STARTUPGROUP,Longitudinal
FIELDGROUP,Longitudinal,1,2,3,4,5,6,7,8,9,10,11,19,20,21,22,23,35
FIELDGROUP,Transverse,1,2,3,4,12,13,14,15,16,17,18,24,25,26,27,28,35

PLOT_APPEARANCE,ALL,HORZ_GRID_ON,VERT_GRID_ON,MARKERS_AND_LINES

[Data]
Time,Comment,Field (Oe),Temperature (K),Long Moment (emu),Long Scan Std Dev,Long Offset (cm),Long Offset Std Dev,Long Algorithm,Long Reg Fit,Long Reg Factor,Trans Moment (emu),Trans Scan Std Dev,Trans Offset (cm),Trans Offset Std Dev,Trans Algorithm,Trans Reg Fit,Trans Reg Factor,Long Moment [w/o ABS] (emu),Long Scan Std Dev [w/o ABS],Long Offset [w/o ABS] (cm),Long Offset Std Dev [w/o ABS],Long Reg Fit [w/o ABS],Trans Moment [w/o ABS] (emu),Trans Scan Std Dev [w/o ABS],Trans Offset [w/o ABS] (cm),Trans Offset Std Dev [w/o ABS],Trans Reg Fit [w/o ABS],RSO Position (deg),Amplitude (cm),Frequency,Cycles to Average,Scans per Measurement,Delta Temp (K),Error,EC Comp. Running,Using ABS,
1615801614.625,,0.000000e+000,3.000041e+001,2.533514e-007,6.591580e-009,0.000000e+000,0.000000e+000,2,8.910356e-001,1.825000e+000,,,,,,,,,,,,,,,,,,0,3.000000e+000,1.000000e+000,10,5,1.449585e-003,0,,0,
1615801808.154,,2.000000e+002,3.000055e+001,-4.912463e-007,2.921689e-009,0.000000e+000,0.000000e+000,2,9.252982e-001,1.825000e+000,,,,,,,,,,,,,,,,,,0,3.000000e+000,1.000000e+000,10,5,4.339218e-003,0,,0,
1615801995.594,,4.000000e+002,3.000128e+001,-1.220786e-006,3.073324e-009,0.000000e+000,0.000000e+000,2,9.572723e-001,1.825000e+000,,,,,,,,,,,,,,,,,,0,3.000000e+000,1.000000e+000,10,5,1.440048e-003,0,,0,
1615802223.483,,6.000000e+002,3.000026e+001,-2.042048e-006,1.070569e-008,0.000000e+000,0.000000e+000,2,9.720474e-001,1.825000e+000,,,,,,,,,,,,,,,,,,0,3.000000e+000,1.000000e+000,10,5,4.339218e-003,0,,0,
1615802411.732,,8.000000e+002,3.000113e+001,-2.920282e-006,8.767559e-009,0.000000e+000,0.000000e+000,2,9.777243e-001,1.825000e+000,,,,,,,,,,,,,,,,,,0,3.000000e+000,1.000000e+000,10,5,2.889633e-003,0,,0,
1615802600.491,,1.000000e+003,3.000070e+001,-3.830666e-006,7.674418e-009,0.000000e+000,0.000000e+000,2,9.812845e-001,1.825000e+000,,,,,,,,,,,,,,,,,,0,3.000000e+000,1.000000e+000,10,5,2.889633e-003,0,,0,
1615802796.301,,1.500000e+003,3.000041e+001,-5.699571e-006,7.528362e-009,0.000000e+000,0.000000e+000,2,8.598957e-001,1.825000e+000,,,,,,,,,,,,,,,,,,0,3.000000e+000,1.000000e+000,10,5,1.449585e-003,0,,0,
1615803034.940,,2.000000e+003,3.000056e+001,-7.976068e-006,9.724489e-009,0.000000e+000,0.000000e+000,2,8.694842e-001,1.825000e+000,,,,,,,,,,,,,,,,,,0,3.000000e+000,1.000000e+000,10,5,1.449585e-003,0,,0,
1615803259.929,,2.500000e+003,3.000171e+001,-1.029533e-005,7.299088e-009,0.000000e+000,0.000000e+000,2,8.778457e-001,1.825000e+000,,,,,,,,,,,,,,,,,,0,3.000000e+000,1.000000e+000,10,5,2.889633e-003,0,,0,
1615803497.668,,3.000000e+003,3.000084e+001,-1.323875e-005,1.337864e-006,0.000000e+000,0.000000e+000,2,7.075913e-001,1.825000e+000,,,,,,,,,,,,,,,,,,0,3.000000e+000,1.000000e+000,10,5,2.889633e-003,0,,0,
1615803688.598,,3.500000e+003,3.000056e+001,-1.503599e-005,3.219021e-008,0.000000e+000,0.000000e+000,2,8.891328e-001,1.825000e+000,,,,,,,,,,,,,,,,,,0,3.000000e+000,1.000000e+000,10,5,2.889633e-003,0,,0,
1615803892.668,,4.000000e+003,3.000099e+001,-1.743388e-005,4.281272e-008,0.000000e+000,0.000000e+000,2,8.963257e-001,1.825000e+000,,,,,,,,,,,,,,,,,,0,3.000000e+000,1.000000e+000,10,5,2.889633e-003,0,,0,
1615804086.247,,5.000000e+003,3.000027e+001,-2.325712e-005,5.637528e-007,0.000000e+000,0.000000e+000,2,9.300409e-001,1.825000e+000,,,,,,,,,,,,,,,,,,0,3.000000e+000,1.000000e+000,10,5,1.449585e-003,0,,0,
1615804316.346,,6.000000e+003,3.000113e+001,-2.863997e-005,4.416886e-008,0.000000e+000,0.000000e+000,2,9.447886e-001,1.825000e+000,,,,,,,,,,,,,,,,,,0,3.000000e+000,1.000000e+000,10,5,2.889633e-003,0,,0,
1615804517.055,,7.000000e+003,3.000041e+001,-3.367112e-005,5.976332e-008,0.000000e+000,0.000000e+000,2,9.516795e-001,1.825000e+000,,,,,,,,,,,,,,,,,,0,3.000000e+000,1.000000e+000,10,5,1.449585e-003,0,,0,
1615804705.905,,8.000000e+003,3.000084e+001,-3.868861e-005,2.068897e-008,0.000000e+000,0.000000e+000,2,9.576437e-001,1.825000e+000,,,,,,,,,,,,,,,,,,0,3.000000e+000,1.000000e+000,10,5,2.889633e-003,0,,0,
1615804885.554,,9.000000e+003,3.000128e+001,-4.374018e-005,7.416543e-008,0.000000e+000,0.000000e+000,2,9.623101e-001,1.825000e+000,,,,,,,,,,,,,,,,,,0,3.000000e+000,1.000000e+000,10,5,2.889633e-003,0,,0,
1615805065.854,,1.000000e+004,3.000142e+001,-4.885576e-005,5.949429e-008,0.000000e+000,0.000000e+000,2,9.666384e-001,1.825000e+000,,,,,,,,,,,,,,,,,,0,3.000000e+000,1.000000e+000,10,5,2.889633e-003,0,,0,
1615805259.234,,1.200000e+004,3.000070e+001,-5.902264e-005,5.496424e-008,0.000000e+000,0.000000e+000,2,9.735778e-001,1.825000e+000,,,,,,,,,,,,,,,,,,0,3.000000e+000,1.000000e+000,10,5,1.449585e-003,0,,0,
1615805451.843,,1.400000e+004,3.000027e+001,-6.917910e-005,4.277254e-008,0.000000e+000,0.000000e+000,2,9.775986e-001,1.825000e+000,,,,,,,,,,,,,,,,,,0,3.000000e+000,1.000000e+000,10,5,1.449585e-003,0,,0,
1615805637.262,,1.600000e+004,3.000027e+001,-7.934268e-005,5.351846e-008,0.000000e+000,0.000000e+000,2,9.799328e-001,1.825000e+000,,,,,,,,,,,,,,,,,,0,3.000000e+000,1.000000e+000,10,5,1.449585e-003,0,,0,
1615805829.792,,1.800000e+004,3.000099e+001,-9.026772e-005,1.591732e-006,0.000000e+000,0.000000e+000,2,9.665490e-001,1.825000e+000,,,,,,,,,,,,,,,,,,0,3.000000e+000,1.000000e+000,10,5,2.889633e-003,0,,0,
1615806023.761,,2.000000e+004,3.000128e+001,-9.969001e-005,1.037494e-007,0.000000e+000,0.000000e+000,2,9.847969e-001,1.825000e+000,,,,,,,,,,,,,,,,,,0,3.000000e+000,1.000000e+000,10,5,2.889633e-003,0,,0,
1615806256.691,,2.500000e+004,3.000056e+001,-1.249296e-004,2.014904e-006,0.000000e+000,0.000000e+000,2,9.712710e-001,1.825000e+000,,,,,,,,,,,,,,,,,,0,3.000000e+000,1.000000e+000,10,5,2.889633e-003,0,,0,
1615806458.460,,3.000000e+004,3.000099e+001,-1.507026e-004,1.677331e-007,0.000000e+000,0.000000e+000,2,9.893004e-001,1.825000e+000,,,,,,,,,,,,,,,,,,0,3.000000e+000,1.000000e+000,10,5,2.889633e-003,0,,0,
1615806666.809,,3.500000e+004,3.000070e+001,-1.763526e-004,1.085093e-007,0.000000e+000,0.000000e+000,2,9.904103e-001,1.825000e+000,,,,,,,,,,,,,,,,,,0,3.000000e+000,1.000000e+000,10,5,1.449585e-003,0,,0,
1615806871.148,,4.000000e+004,2.999998e+001,-2.011403e-004,1.255028e-006,0.000000e+000,0.000000e+000,2,9.829057e-001,1.825000e+000,,,,,,,,,,,,,,,,,,0,3.000000e+000,1.000000e+000,10,5,1.449585e-003,0,,0,
1615807079.178,,4.500000e+004,3.000142e+001,-2.263710e-004,2.123875e-006,0.000000e+000,0.000000e+000,2,9.858841e-001,1.825000e+000,,,,,,,,,,,,,,,,,,0,3.000000e+000,1.000000e+000,10,5,2.889633e-003,0,,0,
1615807287.207,,5.000000e+004,3.000142e+001,-2.529840e-004,1.521671e-007,0.000000e+000,0.000000e+000,2,9.912874e-001,1.825000e+000,,,,,,,,,,,,,,,,,,0,3.000000e+000,1.000000e+000,10,5,4.339218e-003,0,,0,
1615807497.217,,4.500000e+004,3.000113e+001,-2.272539e-004,1.749347e-007,0.000000e+000,0.000000e+000,2,9.912224e-001,1.825000e+000,,,,,,,,,,,,,,,,,,0,3.000000e+000,1.000000e+000,10,5,4.339218e-003,0,,0,
1615807706.176,,4.000000e+004,3.000113e+001,-2.016904e-004,1.654491e-007,0.000000e+000,0.000000e+000,2,9.911616e-001,1.825000e+000,,,,,,,,,,,,,,,,,,0,3.000000e+000,1.000000e+000,10,5,4.339218e-003,0,,0,
1615807914.245,,3.500000e+004,3.000070e+001,-1.761436e-004,1.259196e-007,0.000000e+000,0.000000e+000,2,9.904429e-001,1.825000e+000,,,,,,,,,,,,,,,,,,0,3.000000e+000,1.000000e+000,10,5,2.889633e-003,0,,0,
1615808118.304,,3.000000e+004,3.000128e+001,-1.494827e-004,2.422251e-006,0.000000e+000,0.000000e+000,2,9.799801e-001,1.825000e+000,,,,,,,,,,,,,,,,,,0,3.000000e+000,1.000000e+000,10,5,2.889633e-003,0,,0,
1615808332.454,,2.500000e+004,3.000099e+001,-1.254378e-004,6.129906e-007,0.000000e+000,0.000000e+000,2,9.742580e-001,1.825000e+000,,,,,,,,,,,,,,,,,,0,3.000000e+000,1.000000e+000,10,5,2.889633e-003,0,,0,
1615808538.193,,2.000000e+004,3.000157e+001,-9.963693e-005,1.180880e-007,0.000000e+000,0.000000e+000,2,9.845162e-001,1.825000e+000,,,,,,,,,,,,,,,,,,0,3.000000e+000,1.000000e+000,10,5,2.889633e-003,0,,0,
1615808725.972,,1.800000e+004,3.000128e+001,-8.942831e-005,8.803856e-008,0.000000e+000,0.000000e+000,2,9.829213e-001,1.825000e+000,,,,,,,,,,,,,,,,,,0,3.000000e+000,1.000000e+000,10,5,2.889633e-003,0,,0,
1615808920.132,,1.600000e+004,3.000113e+001,-7.936394e-005,8.028876e-008,0.000000e+000,0.000000e+000,2,9.803032e-001,1.825000e+000,,,,,,,,,,,,,,,,,,0,3.000000e+000,1.000000e+000,10,5,2.889633e-003,0,,0,
1615809113.301,,1.400000e+004,3.000099e+001,-6.912430e-005,6.649532e-008,0.000000e+000,0.000000e+000,2,9.775145e-001,1.825000e+000,,,,,,,,,,,,,,,,,,0,3.000000e+000,1.000000e+000,10,5,5.788803e-003,0,,0,
1615809307.670,,1.200000e+004,3.000142e+001,-5.807158e-005,1.815162e-006,0.000000e+000,0.000000e+000,2,9.420596e-001,1.825000e+000,,,,,,,,,,,,,,,,,,0,3.000000e+000,1.000000e+000,10,5,4.339218e-003,0,,0,
1615809497.320,,1.000000e+004,3.000113e+001,-4.875827e-005,3.848254e-008,0.000000e+000,0.000000e+000,2,9.672700e-001,1.825000e+000,,,,,,,,,,,,,,,,,,0,3.000000e+000,1.000000e+000,10,5,2.889633e-003,0,,0,
1615809701.119,,9.000000e+003,3.000099e+001,-4.368227e-005,6.316453e-008,0.000000e+000,0.000000e+000,2,9.628474e-001,1.825000e+000,,,,,,,,,,,,,,,,,,0,3.000000e+000,1.000000e+000,10,5,0.000000e+000,0,,0,
1615809884.828,,8.000000e+003,3.000084e+001,-3.860394e-005,2.142272e-008,0.000000e+000,0.000000e+000,2,9.570040e-001,1.825000e+000,,,,,,,,,,,,,,,,,,0,3.000000e+000,1.000000e+000,10,5,1.449585e-003,0,,0,
1615810084.298,,7.000000e+003,3.000012e+001,-3.357313e-005,5.661260e-008,0.000000e+000,0.000000e+000,2,9.499168e-001,1.825000e+000,,,,,,,,,,,,,,,,,,0,3.000000e+000,1.000000e+000,10,5,2.889633e-003,0,,0,
1615810305.407,,6.000000e+003,3.000113e+001,-2.851632e-005,2.422375e-008,0.000000e+000,0.000000e+000,2,9.411367e-001,1.825000e+000,,,,,,,,,,,,,,,,,,0,3.000000e+000,1.000000e+000,10,5,4.339218e-003,0,,0,
1615810509.347,,5.000000e+003,3.000070e+001,-2.345680e-005,1.530413e-008,0.000000e+000,0.000000e+000,2,9.262483e-001,1.825000e+000,,,,,,,,,,,,,,,,,,0,3.000000e+000,1.000000e+000,10,5,2.889633e-003,0,,0,
1615810753.626,,4.000000e+003,3.000027e+001,-1.844972e-005,2.479439e-008,0.000000e+000,0.000000e+000,2,9.075194e-001,1.825000e+000,,,,,,,,,,,,,,,,,,0,3.000000e+000,1.000000e+000,10,5,1.449585e-003,0,,0,
1615810993.915,,3.500000e+003,3.000056e+001,-1.595617e-005,2.411931e-008,0.000000e+000,0.000000e+000,2,8.933661e-001,1.825000e+000,,,,,,,,,,,,,,,,,,0,3.000000e+000,1.000000e+000,10,5,2.889633e-003,0,,0,
1615811206.794,,3.000000e+003,3.000128e+001,-1.343346e-005,4.023218e-008,0.000000e+000,0.000000e+000,2,8.736099e-001,1.825000e+000,,,,,,,,,,,,,,,,,,0,3.000000e+000,1.000000e+000,10,5,4.339218e-003,0,,0,
1615811499.454,,2.500000e+003,3.000113e+001,-1.097062e-005,1.320696e-008,0.000000e+000,0.000000e+000,2,8.489708e-001,1.825000e+000,,,,,,,,,,,,,,,,,,0,3.000000e+000,1.000000e+000,10,5,1.440048e-003,0,,0,
1615811733.944,,2.000000e+003,3.000027e+001,-9.350960e-006,1.840734e-006,0.000000e+000,0.000000e+000,2,6.953112e-001,1.825000e+000,,,,,,,,,,,,,,,,,,0,3.000000e+000,1.000000e+000,10,5,2.889633e-003,0,,0,
1615811976.633,,1.500000e+003,3.000084e+001,-5.715730e-006,8.222869e-007,0.000000e+000,0.000000e+000,2,5.763240e-001,1.825000e+000,,,,,,,,,,,,,,,,,,0,3.000000e+000,1.000000e+000,10,5,2.889633e-003,0,,0,
1615812170.742,,1.000000e+003,3.000099e+001,-3.652965e-006,4.860543e-008,0.000000e+000,0.000000e+000,2,5.396090e-001,1.825000e+000,,,,,,,,,,,,,,,,,,0,3.000000e+000,1.000000e+000,10,5,2.889633e-003,0,,0,
1615812359.111,,8.000000e+002,3.000070e+001,-2.763685e-006,4.536138e-008,0.000000e+000,0.000000e+000,2,4.001053e-001,1.825000e+000,,,,,,,,,,,,,,,,,,0,3.000000e+000,1.000000e+000,10,5,2.889633e-003,0,,0,
1615812547.761,,6.000000e+002,3.000113e+001,-2.072312e-006,9.394419e-009,0.000000e+000,0.000000e+000,2,3.559025e-001,1.825000e+000,,,,,,,,,,,,,,,,,,0,3.000000e+000,1.000000e+000,10,5,1.440048e-003,0,,0,
1615812757.330,,4.000000e+002,3.000056e+001,-1.214961e-006,2.898222e-008,0.000000e+000,0.000000e+000,2,0.000000e+000,1.825000e+000,,,,,,,,,,,,,,,,,,0,3.000000e+000,1.000000e+000,10,5,1.449585e-003,0,,0,
1615812946.019,,2.000000e+002,3.000099e+001,-1.074520e-006,1.559079e-006,0.000000e+000,0.000000e+000,2,0.000000e+000,1.825000e+000,,,,,,,,,,,,,,,,,,0,3.000000e+000,1.000000e+000,10,5,2.889633e-003,0,,0,
1615813139.999,,0.000000e+000,3.000084e+001,-9.751639e-007,2.220339e-007,0.000000e+000,0.000000e+000,2,0.000000e+000,1.825000e+000,,,,,,,,,,,,,,,,,,0,3.000000e+000,1.000000e+000,10,5,2.889633e-003,0,,0,
1615813334.078,,-2.000000e+002,2.999998e+001,-3.130767e-007,5.171641e-008,0.000000e+000,0.000000e+000,2,0.000000e+000,1.825000e+000,,,,,,,,,,,,,,,,,,0,3.000000e+000,1.000000e+000,10,5,2.899170e-003,0,,0,
1615813527.997,,-4.000000e+002,3.000113e+001,1.206476e-006,2.057622e-006,0.000000e+000,0.000000e+000,2,0.000000e+000,1.825000e+000,,,,,,,,,,,,,,,,,,0,3.000000e+000,1.000000e+000,10,5,1.440048e-003,0,,0,
1615813878.676,,-6.000000e+002,3.000002e+001,1.013408e-006,4.001230e-008,0.000000e+000,0.000000e+000,2,0.000000e+000,1.825000e+000,,,,,,,,,,,,,,,,,,0,3.000000e+000,1.000000e+000,10,3,1.449585e-003,1,,0,
1615814241.385,,-8.000000e+002,3.000056e+001,2.110180e-006,8.736674e-007,0.000000e+000,0.000000e+000,2,0.000000e+000,1.825000e+000,,,,,,,,,,,,,,,,,,0,3.000000e+000,1.000000e+000,10,5,4.339218e-003,0,,0,
1615814427.165,,-1.000000e+003,2.999983e+001,2.747614e-006,2.134866e-007,0.000000e+000,0.000000e+000,2,1.388567e-001,1.825000e+000,,,,,,,,,,,,,,,,,,0,3.000000e+000,1.000000e+000,10,5,1.449585e-003,0,,0,
1615814624.634,,-1.500000e+003,3.000084e+001,4.945204e-006,3.723223e-008,0.000000e+000,0.000000e+000,2,5.388930e-001,1.825000e+000,,,,,,,,,,,,,,,,,,0,3.000000e+000,1.000000e+000,10,5,2.889633e-003,0,,0,
1615814820.163,,-2.000000e+003,3.000128e+001,7.283965e-006,2.077164e-008,0.000000e+000,0.000000e+000,2,6.782003e-001,1.825000e+000,,,,,,,,,,,,,,,,,,0,3.000000e+000,1.000000e+000,10,5,1.440048e-003,0,,0,
1615815018.322,,-2.500000e+003,3.000156e+001,9.711576e-006,4.210294e-008,0.000000e+000,0.000000e+000,2,7.554083e-001,1.825000e+000,,,,,,,,,,,,,,,,,,0,3.000000e+000,1.000000e+000,10,5,5.788803e-003,0,,0,
1615815207.902,,-3.000000e+003,3.000157e+001,1.223241e-005,2.032259e-007,0.000000e+000,0.000000e+000,2,8.112229e-001,1.825000e+000,,,,,,,,,,,,,,,,,,0,3.000000e+000,1.000000e+000,10,5,1.440048e-003,0,,0,
1615815432.051,,-3.500000e+003,3.000056e+001,1.463323e-005,7.771254e-008,0.000000e+000,0.000000e+000,2,8.301995e-001,1.825000e+000,,,,,,,,,,,,,,,,,,0,3.000000e+000,1.000000e+000,10,5,1.449585e-003,0,,0,
1615815622.710,,-4.000000e+003,3.000070e+001,1.696387e-005,4.608034e-007,0.000000e+000,0.000000e+000,2,7.396731e-001,1.825000e+000,,,,,,,,,,,,,,,,,,0,3.000000e+000,1.000000e+000,10,5,1.449585e-003,0,,0,
1615815815.050,,-5.000000e+003,3.000113e+001,2.208248e-005,2.339213e-008,0.000000e+000,0.000000e+000,2,8.829248e-001,1.825000e+000,,,,,,,,,,,,,,,,,,0,3.000000e+000,1.000000e+000,10,5,2.889633e-003,0,,0,
1615816013.989,,-6.000000e+003,3.000012e+001,2.707267e-005,4.857466e-008,0.000000e+000,0.000000e+000,2,9.019329e-001,1.825000e+000,,,,,,,,,,,,,,,,,,0,3.000000e+000,1.000000e+000,10,5,4.339218e-003,0,,0,
1615816213.478,,-7.000000e+003,3.000041e+001,3.208748e-005,2.413872e-008,0.000000e+000,0.000000e+000,2,9.161591e-001,1.825000e+000,,,,,,,,,,,,,,,,,,0,3.000000e+000,1.000000e+000,10,5,2.889633e-003,0,,0,
1615816406.927,,-8.000000e+003,3.000099e+001,3.752134e-005,8.384910e-007,0.000000e+000,0.000000e+000,2,8.860363e-001,1.825000e+000,,,,,,,,,,,,,,,,,,0,3.000000e+000,1.000000e+000,10,5,2.889633e-003,0,,0,
1615816594.907,,-9.000000e+003,3.000070e+001,4.216418e-005,3.030812e-008,0.000000e+000,0.000000e+000,2,9.351977e-001,1.825000e+000,,,,,,,,,,,,,,,,,,0,3.000000e+000,1.000000e+000,10,5,2.899170e-003,0,,0,
1615816781.516,,-1.000000e+004,3.000084e+001,4.725330e-005,3.456200e-008,0.000000e+000,0.000000e+000,2,9.429941e-001,1.825000e+000,,,,,,,,,,,,,,,,,,0,3.000000e+000,1.000000e+000,10,5,4.339218e-003,0,,0,
1615816974.315,,-1.200000e+004,3.000113e+001,5.737231e-005,4.774944e-008,0.000000e+000,0.000000e+000,2,9.526504e-001,1.825000e+000,,,,,,,,,,,,,,,,,,0,3.000000e+000,1.000000e+000,10,5,2.889633e-003,0,,0,
1615817168.415,,-1.400000e+004,3.000084e+001,6.755807e-005,7.893036e-008,0.000000e+000,0.000000e+000,2,9.602683e-001,1.825000e+000,,,,,,,,,,,,,,,,,,0,3.000000e+000,1.000000e+000,10,5,4.339218e-003,0,,0,
1615817357.154,,-1.600000e+004,2.999983e+001,7.769417e-005,4.334527e-008,0.000000e+000,0.000000e+000,2,9.658357e-001,1.825000e+000,,,,,,,,,,,,,,,,,,0,3.000000e+000,1.000000e+000,10,5,2.899170e-003,0,,0,
1615817542.794,,-1.800000e+004,3.000084e+001,8.789817e-005,1.579954e-007,0.000000e+000,0.000000e+000,2,9.701320e-001,1.825000e+000,,,,,,,,,,,,,,,,,,0,3.000000e+000,1.000000e+000,10,5,2.889633e-003,0,,0,
1615817735.893,,-2.000000e+004,3.000055e+001,9.809227e-005,6.103368e-008,0.000000e+000,0.000000e+000,2,9.735138e-001,1.825000e+000,,,,,,,,,,,,,,,,,,0,3.000000e+000,1.000000e+000,10,5,2.889633e-003,0,,0,
1615817944.292,,-2.500000e+004,3.000084e+001,1.236530e-004,1.051973e-007,0.000000e+000,0.000000e+000,2,9.786459e-001,1.825000e+000,,,,,,,,,,,,,,,,,,0,3.000000e+000,1.000000e+000,10,5,2.889633e-003,0,,0,
1615818153.802,,-3.000000e+004,3.000084e+001,1.490283e-004,8.171340e-008,0.000000e+000,0.000000e+000,2,9.818434e-001,1.825000e+000,,,,,,,,,,,,,,,,,,0,3.000000e+000,1.000000e+000,10,5,2.889633e-003,0,,0,
1615818365.981,,-3.500000e+004,3.000084e+001,1.746674e-004,1.253479e-007,0.000000e+000,0.000000e+000,2,9.845109e-001,1.825000e+000,,,,,,,,,,,,,,,,,,0,3.000000e+000,1.000000e+000,10,5,2.889633e-003,0,,0,
1615818570.740,,-4.000000e+004,3.000113e+001,2.002309e-004,8.873781e-008,0.000000e+000,0.000000e+000,2,9.866033e-001,1.825000e+000,,,,,,,,,,,,,,,,,,0,3.000000e+000,1.000000e+000,10,5,2.889633e-003,0,,0,
1615818777.040,,-4.500000e+004,3.000128e+001,2.272200e-004,1.516367e-006,0.000000e+000,0.000000e+000,2,9.880932e-001,1.825000e+000,,,,,,,,,,,,,,,,,,0,3.000000e+000,1.000000e+000,10,5,2.889633e-003,0,,0,
1615819009.489,,-5.000000e+004,3.000099e+001,2.538605e-004,2.681278e-007,0.000000e+000,0.000000e+000,2,9.893265e-001,1.825000e+000,,,,,,,,,,,,,,,,,,0,3.000000e+000,1.000000e+000,10,5,2.889633e-003,0,,0,
1615819218.248,,-4.500000e+004,3.000128e+001,2.282609e-004,1.864288e-007,0.000000e+000,0.000000e+000,2,9.891962e-001,1.825000e+000,,,,,,,,,,,,,,,,,,0,3.000000e+000,1.000000e+000,10,5,2.889633e-003,0,,0,
1615819426.398,,-4.000000e+004,3.000113e+001,2.025413e-004,1.664664e-007,0.000000e+000,0.000000e+000,2,9.879264e-001,1.825000e+000,,,,,,,,,,,,,,,,,,0,3.000000e+000,1.000000e+000,10,5,4.339218e-003,0,,0,
1615819627.217,,-3.500000e+004,3.000113e+001,1.770594e-004,1.247544e-007,0.000000e+000,0.000000e+000,2,9.871510e-001,1.825000e+000,,,,,,,,,,,,,,,,,,0,3.000000e+000,1.000000e+000,10,5,2.889633e-003,0,,0,
1615819833.276,,-3.000000e+004,3.000084e+001,1.514329e-004,9.011985e-008,0.000000e+000,0.000000e+000,2,9.848735e-001,1.825000e+000,,,,,,,,,,,,,,,,,,0,3.000000e+000,1.000000e+000,10,5,2.889633e-003,0,,0,
1615820038.626,,-2.500000e+004,3.000041e+001,1.260134e-004,1.082404e-007,0.000000e+000,0.000000e+000,2,9.816751e-001,1.825000e+000,,,,,,,,,,,,,,,,,,0,3.000000e+000,1.000000e+000,10,5,4.339218e-003,0,,0,
1615820249.345,,-2.000000e+004,3.000084e+001,1.004804e-004,4.485075e-008,0.000000e+000,0.000000e+000,2,9.768279e-001,1.825000e+000,,,,,,,,,,,,,,,,,,0,3.000000e+000,1.000000e+000,10,5,1.449585e-003,0,,0,
1615820456.134,,-1.800000e+004,3.000099e+001,9.033167e-005,5.285236e-008,0.000000e+000,0.000000e+000,2,9.750088e-001,1.825000e+000,,,,,,,,,,,,,,,,,,0,3.000000e+000,1.000000e+000,10,5,4.339218e-003,0,,0,
1615820648.955,,-1.600000e+004,3.000142e+001,8.012683e-005,9.171921e-008,0.000000e+000,0.000000e+000,2,9.708264e-001,1.825000e+000,,,,,,,,,,,,,,,,,,0,3.000000e+000,1.000000e+000,10,5,4.339218e-003,0,,0,
1615820839.584,,-1.400000e+004,3.000113e+001,6.998119e-005,4.710911e-008,0.000000e+000,0.000000e+000,2,9.667588e-001,1.825000e+000,,,,,,,,,,,,,,,,,,0,3.000000e+000,1.000000e+000,10,5,4.339218e-003,0,,0,
1615821025.614,,-1.200000e+004,3.000099e+001,5.957971e-005,4.794751e-008,0.000000e+000,0.000000e+000,2,9.605706e-001,1.825000e+000,,,,,,,,,,,,,,,,,,0,3.000000e+000,1.000000e+000,10,5,2.889633e-003,0,,0,
1615821223.313,,-1.000000e+004,3.000084e+001,5.043298e-005,2.357178e-006,0.000000e+000,0.000000e+000,2,9.290925e-001,1.825000e+000,,,,,,,,,,,,,,,,,,0,3.000000e+000,1.000000e+000,10,5,2.889633e-003,0,,0,
1615821410.813,,-9.000000e+003,3.000099e+001,4.435583e-005,5.843937e-008,0.000000e+000,0.000000e+000,2,9.466655e-001,1.825000e+000,,,,,,,,,,,,,,,,,,0,3.000000e+000,1.000000e+000,10,5,4.339218e-003,0,,0,
1615821630.582,,-8.000000e+003,3.000070e+001,3.927697e-005,2.272970e-008,0.000000e+000,0.000000e+000,2,9.397852e-001,1.825000e+000,,,,,,,,,,,,,,,,,,0,3.000000e+000,1.000000e+000,10,5,2.889633e-003,0,,0,
1615821859.911,,-7.000000e+003,3.000128e+001,3.383717e-005,6.845307e-007,0.000000e+000,0.000000e+000,2,9.367520e-001,1.825000e+000,,,,,,,,,,,,,,,,,,0,3.000000e+000,1.000000e+000,10,5,2.889633e-003,0,,0,
1615822054.190,,-6.000000e+003,3.000041e+001,2.713289e-005,3.283743e-008,0.000000e+000,0.000000e+000,2,9.205005e-001,1.825000e+000,,,,,,,,,,,,,,,,,,0,3.000000e+000,1.000000e+000,10,5,1.449585e-003,0,,0,
1615822253.400,,-5.000000e+003,3.000113e+001,2.208543e-005,2.601884e-008,0.000000e+000,0.000000e+000,2,9.007239e-001,1.825000e+000,,,,,,,,,,,,,,,,,,0,3.000000e+000,1.000000e+000,10,5,4.339218e-003,0,,0,
1615822452.809,,-4.000000e+003,3.000113e+001,1.704554e-005,2.456319e-008,0.000000e+000,0.000000e+000,2,8.709389e-001,1.825000e+000,,,,,,,,,,,,,,,,,,0,3.000000e+000,1.000000e+000,10,5,2.889633e-003,0,,0,
1615822682.868,,-3.500000e+003,3.000027e+001,1.454938e-005,2.456285e-008,0.000000e+000,0.000000e+000,2,8.534107e-001,1.825000e+000,,,,,,,,,,,,,,,,,,0,3.000000e+000,1.000000e+000,10,5,2.899170e-003,0,,0,
1615822932.107,,-3.000000e+003,3.000056e+001,1.195271e-005,2.388440e-008,0.000000e+000,0.000000e+000,2,8.103461e-001,1.825000e+000,,,,,,,,,,,,,,,,,,0,3.000000e+000,1.000000e+000,10,5,1.449585e-003,0,,0,
1615823169.016,,-2.500000e+003,2.999998e+001,9.493997e-006,1.939689e-008,0.000000e+000,0.000000e+000,2,7.634360e-001,1.825000e+000,,,,,,,,,,,,,,,,,,0,3.000000e+000,1.000000e+000,10,5,2.899170e-003,0,,0,
1615823402.885,,-2.000000e+003,2.999998e+001,7.038761e-006,1.492644e-008,0.000000e+000,0.000000e+000,2,6.863623e-001,1.825000e+000,,,,,,,,,,,,,,,,,,0,3.000000e+000,1.000000e+000,10,5,1.449585e-003,0,,0,
1615823598.324,,-1.500000e+003,3.000084e+001,4.611212e-006,1.021660e-008,0.000000e+000,0.000000e+000,2,5.277253e-001,1.825000e+000,,,,,,,,,,,,,,,,,,0,3.000000e+000,1.000000e+000,10,5,2.889633e-003,0,,0,
1615823792.454,,-1.000000e+003,3.000099e+001,2.221868e-006,6.435162e-008,0.000000e+000,0.000000e+000,2,1.322110e-002,1.825000e+000,,,,,,,,,,,,,,,,,,0,3.000000e+000,1.000000e+000,10,5,0.000000e+000,0,,0,
1615823980.953,,-8.000000e+002,3.000142e+001,1.352821e-006,2.283815e-008,0.000000e+000,0.000000e+000,2,0.000000e+000,1.825000e+000,,,,,,,,,,,,,,,,,,0,3.000000e+000,1.000000e+000,10,5,2.889633e-003,0,,0,
1615824170.063,,-6.000000e+002,3.000070e+001,-6.352169e-006,5.168536e-007,0.000000e+000,0.000000e+000,2,7.304472e-001,1.825000e+000,,,,,,,,,,,,,,,,,,0,3.000000e+000,1.000000e+000,10,5,4.339218e-003,0,,0,
1615824358.195,,-4.000000e+002,3.000056e+001,-6.607665e-006,1.913348e-006,0.000000e+000,0.000000e+000,2,6.223645e-001,1.825000e+000,,,,,,,,,,,,,,,,,,0,3.000000e+000,1.000000e+000,10,5,2.899170e-003,0,,0,
1615824552.004,,-2.000000e+002,3.000128e+001,-7.898644e-006,3.800704e-008,0.000000e+000,0.000000e+000,2,8.004950e-001,1.825000e+000,,,,,,,,,,,,,,,,,,0,3.000000e+000,1.000000e+000,10,5,2.889633e-003,0,,0,
1615824746.224,,0.000000e+000,3.000084e+001,6.490222e-007,4.609601e-008,0.000000e+000,0.000000e+000,2,0.000000e+000,1.825000e+000,,,,,,,,,,,,,,,,,,0,3.000000e+000,1.000000e+000,10,5,2.889633e-003,0,,0,
1615824938.844,,2.000000e+002,3.000084e+001,1.277884e-007,3.661622e-008,0.000000e+000,0.000000e+000,2,0.000000e+000,1.825000e+000,,,,,,,,,,,,,,,,,,0,3.000000e+000,1.000000e+000,10,5,2.889633e-003,0,,0,
1615825133.783,,4.000000e+002,3.000171e+001,-5.477560e-007,1.574561e-008,0.000000e+000,0.000000e+000,2,0.000000e+000,1.825000e+000,,,,,,,,,,,,,,,,,,0,3.000000e+000,1.000000e+000,10,5,1.440048e-003,0,,0,
1615825322.852,,6.000000e+002,2.999954e+001,-1.186355e-006,9.276648e-008,0.000000e+000,0.000000e+000,2,0.000000e+000,1.825000e+000,,,,,,,,,,,,,,,,,,0,3.000000e+000,1.000000e+000,10,5,0.000000e+000,0,,0,
1615825607.631,,8.000000e+002,3.000099e+001,-2.017223e-006,3.679118e-008,0.000000e+000,0.000000e+000,2,7.728811e-002,1.825000e+000,,,,,,,,,,,,,,,,,,0,3.000000e+000,1.000000e+000,10,5,2.889633e-003,0,,0,
1615825818.211,,1.000000e+003,3.000113e+001,-2.875233e-006,5.024792e-008,0.000000e+000,0.000000e+000,2,3.499925e-001,1.825000e+000,,,,,,,,,,,,,,,,,,0,3.000000e+000,1.000000e+000,10,5,2.889633e-003,0,,0,
1615826032.500,,1.500000e+003,3.000084e+001,-5.076150e-006,2.786715e-008,0.000000e+000,0.000000e+000,2,6.116034e-001,1.825000e+000,,,,,,,,,,,,,,,,,,0,3.000000e+000,1.000000e+000,10,5,1.449585e-003,0,,0,
1615826297.739,,2.000000e+003,3.000113e+001,-7.409743e-006,6.444057e-009,0.000000e+000,0.000000e+000,2,7.167047e-001,1.825000e+000,,,,,,,,,,,,,,,,,,0,3.000000e+000,1.000000e+000,10,5,2.889633e-003,0,,0,
1615826493.389,,2.500000e+003,3.000113e+001,-9.718985e-006,1.548995e-007,0.000000e+000,0.000000e+000,2,7.577996e-001,1.825000e+000,,,,,,,,,,,,,,,,,,0,3.000000e+000,1.000000e+000,10,5,2.889633e-003,0,,0,
1615826682.388,,3.000000e+003,3.000099e+001,-1.217965e-005,4.371016e-008,0.000000e+000,0.000000e+000,2,8.108963e-001,1.825000e+000,,,,,,,,,,,,,,,,,,0,3.000000e+000,1.000000e+000,10,5,2.889633e-003,0,,0,
1615826874.687,,3.500000e+003,3.000099e+001,-1.460569e-005,5.585529e-008,0.000000e+000,0.000000e+000,2,8.346414e-001,1.825000e+000,,,,,,,,,,,,,,,,,,0,3.000000e+000,1.000000e+000,10,5,2.889633e-003,0,,0,
1615827135.657,,4.000000e+003,3.000056e+001,-1.706087e-005,3.181274e-008,0.000000e+000,0.000000e+000,2,8.586161e-001,1.825000e+000,,,,,,,,,,,,,,,,,,0,3.000000e+000,1.000000e+000,10,5,2.889633e-003,0,,0,
1615827365.536,,5.000000e+003,3.000041e+001,-2.211558e-005,1.998665e-007,0.000000e+000,0.000000e+000,2,8.790556e-001,1.825000e+000,,,,,,,,,,,,,,,,,,0,3.000000e+000,1.000000e+000,10,5,1.449585e-003,0,,0,
1615827564.215,,6.000000e+003,3.000027e+001,-2.706664e-005,3.201142e-008,0.000000e+000,0.000000e+000,2,9.036906e-001,1.825000e+000,,,,,,,,,,,,,,,,,,0,3.000000e+000,1.000000e+000,10,5,2.899170e-003,0,,0,
1615827772.185,,7.000000e+003,3.000070e+001,-3.660636e-005,3.083394e-006,0.000000e+000,0.000000e+000,2,9.331542e-001,1.825000e+000,,,,,,,,,,,,,,,,,,0,3.000000e+000,1.000000e+000,10,5,2.889633e-003,0,,0,
1615827952.205,,8.000000e+003,3.000142e+001,-4.384884e-005,1.587940e-008,0.000000e+000,0.000000e+000,2,9.305381e-001,1.825000e+000,,,,,,,,,,,,,,,,,,0,3.000000e+000,1.000000e+000,10,5,2.889633e-003,0,,0,
1615828134.594,,9.000000e+003,3.000041e+001,-4.895444e-005,2.452129e-008,0.000000e+000,0.000000e+000,2,9.370978e-001,1.825000e+000,,,,,,,,,,,,,,,,,,0,3.000000e+000,1.000000e+000,10,5,1.449585e-003,0,,0,
1615828323.763,,1.000000e+004,3.000157e+001,-5.408260e-005,2.686365e-008,0.000000e+000,0.000000e+000,2,9.424496e-001,1.825000e+000,,,,,,,,,,,,,,,,,,0,3.000000e+000,1.000000e+000,10,5,2.889633e-003,0,,0,
1615828509.193,,1.200000e+004,3.000099e+001,-6.424554e-005,2.911232e-008,0.000000e+000,0.000000e+000,2,9.503981e-001,1.825000e+000,,,,,,,,,,,,,,,,,,0,3.000000e+000,1.000000e+000,10,5,0.000000e+000,0,,0,
1615828701.033,,1.400000e+004,3.000084e+001,-7.435848e-005,4.216793e-008,0.000000e+000,0.000000e+000,2,9.569902e-001,1.825000e+000,,,,,,,,,,,,,,,,,,0,3.000000e+000,1.000000e+000,10,5,2.889633e-003,0,,0,
1615828894.543,,1.600000e+004,3.000156e+001,-8.452663e-005,7.048083e-008,0.000000e+000,0.000000e+000,2,9.619108e-001,1.825000e+000,,,,,,,,,,,,,,,,,,0,3.000000e+000,1.000000e+000,10,5,4.339218e-003,0,,0,
1615829087.962,,1.800000e+004,3.000113e+001,-9.464057e-005,6.428859e-008,0.000000e+000,0.000000e+000,2,9.654353e-001,1.825000e+000,,,,,,,,,,,,,,,,,,0,3.000000e+000,1.000000e+000,10,5,2.889633e-003,0,,0,
1615829274.371,,2.000000e+004,3.000084e+001,-1.048548e-004,1.094609e-007,0.000000e+000,0.000000e+000,2,9.686235e-001,1.825000e+000,,,,,,,,,,,,,,,,,,0,3.000000e+000,1.000000e+000,10,5,2.889633e-003,0,,0,
1615829475.650,,2.500000e+004,3.000128e+001,-1.304157e-004,5.991606e-008,0.000000e+000,0.000000e+000,2,9.741842e-001,1.825000e+000,,,,,,,,,,,,,,,,,,0,3.000000e+000,1.000000e+000,10,5,2.889633e-003,0,,0,
1615829686.430,,3.000000e+004,3.000157e+001,-1.559277e-004,9.989731e-008,0.000000e+000,0.000000e+000,2,9.766045e-001,1.825000e+000,,,,,,,,,,,,,,,,,,0,3.000000e+000,1.000000e+000,10,5,1.440048e-003,0,,0,
1615829890.810,,3.500000e+004,3.000070e+001,-1.816091e-004,3.622356e-008,0.000000e+000,0.000000e+000,2,9.797895e-001,1.825000e+000,,,,,,,,,,,,,,,,,,0,3.000000e+000,1.000000e+000,10,5,2.899170e-003,0,,0,
1615830094.969,,4.000000e+004,3.000113e+001,-2.070410e-004,2.247975e-007,0.000000e+000,0.000000e+000,2,9.816856e-001,1.825000e+000,,,,,,,,,,,,,,,,,,0,3.000000e+000,1.000000e+000,10,5,2.889633e-003,0,,0,
1615830300.429,,4.500000e+004,3.000171e+001,-2.326292e-004,1.094136e-007,0.000000e+000,0.000000e+000,2,9.828389e-001,1.825000e+000,,,,,,,,,,,,,,,,,,0,3.000000e+000,1.000000e+000,10,5,4.339218e-003,0,,0,
1615830507.859,,5.000000e+004,3.000099e+001,-2.580718e-004,1.962679e-007,0.000000e+000,0.000000e+000,2,9.833763e-001,1.825000e+000,,,,,,,,,,,,,,,,,,0,3.000000e+000,1.000000e+000,10,5,2.889633e-003,0,,0,