File: SiC 1/Temperature Dependence/SiC1_temp_dep.rso.dat.csv
[Header]
TITLE,MPMS RSO Measurement
BYAPP,MPMS Measurement,1.1,Summary
FILEOPENTIME, 1615615555.990000 3/13/2021, 7:05:55 AM

INFO, APPNAME, MPMS MultiVu Application, Revision 1.61,  Build 082

INFO, NAME,
INFO, WEIGHT, 1.000
INFO, AREA, 1.000
INFO, LENGTH, 1.000
INFO, SHAPE, 0
INFO, COMMENT,
INFO, SEQUENCE FILE: SiC1_Hyst_30K.seq


INFO, BACKGROUND DATA FILE:, None


STARTUPAXIS,X,4,LINEAR,AUTO,0.000000,0.000000
STARTUPAXIS,Y1,5,LINEAR,AUTO,0.000000,0.000000


STARTUPGROUP,Longitudinal
FIELDGROUP,Longitudinal,1,2,3,4,5,6,7,8,9,10,11,19,20,21,22,23,35
FIELDGROUP,Transverse,1,2,3,4,12,13,14,15,16,17,18,24,25,26,27,28,35

PLOT_APPEARANCE,ALL,HORZ_GRID_ON,VERT_GRID_ON,MARKERS_AND_LINES

[Data]
Time,Comment,Field (Oe),Temperature (K),Long Moment (emu),Long Scan Std Dev,Long Offset (cm),Long Offset Std Dev,Long Algorithm,Long Reg Fit,Long Reg Factor,Trans Moment (emu),Trans Scan Std Dev,Trans Offset (cm),Trans Offset Std Dev,Trans Algorithm,Trans Reg Fit,Trans Reg Factor,Long Moment [w/o ABS] (emu),Long Scan Std Dev [w/o ABS],Long Offset [w/o ABS] (cm),Long Offset Std Dev [w/o ABS],Long Reg Fit [w/o ABS],Trans Moment [w/o ABS] (emu),Trans Scan Std Dev [w/o ABS],Trans Offset [w/o ABS] (cm),Trans Offset Std Dev [w/o ABS],Trans Reg Fit [w/o ABS],RSO Position (deg),Amplitude (cm),Frequency,Cycles to Average,Scans per Measurement,Delta Temp (K),Error,EC Comp. Running,Using ABS,
1615615555.990,,1.000000e+003,5.003948e+000,-1.611512e-005,3.476184e-008,5.708995e-001,1.076665e-003,3,7.366385e-001,1.825000e+000,,,,,,,,,,,,,,,,,,0,3.000000e+000,1.000000e+000,10,5,7.228851e-003,0,,0,
1615615823.348,,1.000000e+003,1.000622e+001,-1.621486e-005,1.461247e-008,5.616935e-001,5.955574e-004,3,7.375125e-001,1.825000e+000,,,,,,,,,,,,,,,,,,0,3.000000e+000,1.000000e+000,10,5,6.179810e-003,0,,0,
1615616090.857,,1.000000e+003,1.500287e+001,-1.624239e-005,2.060593e-008,5.576744e-001,6.834690e-004,3,7.379691e-001,1.825000e+000,,,,,,,,,,,,,,,,,,0,3.000000e+000,1.000000e+000,10,5,5.479813e-003,0,,0,
1615616373.296,,1.000000e+003,2.000117e+001,-3.572440e-006,6.246177e-009,1.341118e-002,1.564756e-003,3,9.249659e-001,1.825000e+000,,,,,,,,,,,,,,,,,,0,3.000000e+000,1.000000e+000,10,5,6.811142e-003,0,,0,
1615616641.915,,1.000000e+003,2.500441e+001,-3.605025e-006,7.393971e-009,1.365635e-002,1.125321e-003,3,9.264360e-001,1.825000e+000,,,,,,,,,,,,,,,,,,0,3.000000e+000,1.000000e+000,10,5,8.270264e-003,0,,0,
1615616911.805,,1.000000e+003,3.000186e+001,-3.627888e-006,3.768954e-009,1.294662e-002,1.926689e-003,3,9.285302e-001,1.825000e+000,,,,,,,,,,,,,,,,,,0,3.000000e+000,1.000000e+000,10,5,1.440048e-003,0,,0,
1615617194.943,,1.000000e+003,3.500169e+001,-3.641659e-006,5.017658e-009,1.316606e-002,9.263766e-004,3,9.270914e-001,1.825000e+000,,,,,,,,,,,,,,,,,,0,3.000000e+000,1.000000e+000,10,5,3.078461e-003,0,,0,
1615617491.592,,1.000000e+003,4.000087e+001,-3.658926e-006,2.593691e-009,1.329022e-002,1.402654e-003,3,9.292672e-001,1.825000e+000,,,,,,,,,,,,,,,,,,0,3.000000e+000,1.000000e+000,10,5,4.920959e-003,0,,0,
1615617792.261,,1.000000e+003,4.500193e+001,-3.663763e-006,3.638076e-009,1.318817e-002,1.123352e-003,3,9.291749e-001,1.825000e+000,,,,,,,,,,,,,,,,,,0,3.000000e+000,1.000000e+000,10,5,3.692627e-003,0,,0,
1615618075.950,,1.000000e+003,5.000497e+001,-3.672854e-006,4.099924e-009,1.513189e-002,1.335788e-003,3,9.291075e-001,1.825000e+000,,,,,,,,,,,,,,,,,,0,3.000000e+000,1.000000e+000,10,5,1.044846e-002,0,,0,
1615618352.518,,1.000000e+003,5.501099e+001,-3.703188e-006,4.203920e-009,1.108310e-002,9.047285e-004,3,9.415753e-001,1.825000e+000,,,,,,,,,,,,,,,,,,0,3.000000e+000,1.000000e+000,10,5,2.490997e-002,0,,0,
1615618632.397,,1.000000e+003,6.001490e+001,-3.708821e-006,4.985010e-009,1.273015e-002,1.062468e-003,3,9.418025e-001,1.825000e+000,,,,,,,,,,,,,,,,,,0,3.000000e+000,1.000000e+000,10,5,3.564072e-002,0,,0,
1615618913.206,,1.000000e+003,6.502144e+001,-3.721649e-006,4.545659e-009,1.298544e-002,1.320700e-003,3,9.450876e-001,1.825000e+000,,,,,,,,,,,,,,,,,,0,3.000000e+000,1.000000e+000,10,5,4.141235e-002,0,,0,
1615619198.075,,1.000000e+003,7.002430e+001,-3.732029e-006,5.344555e-009,1.448588e-002,1.003349e-003,3,9.457692e-001,1.825000e+000,,,,,,,,,,,,,,,,,,0,3.000000e+000,1.000000e+000,10,5,4.193878e-002,0,,0,
1615619479.864,,1.000000e+003,7.503243e+001,-3.745451e-006,7.995985e-009,1.459758e-002,1.518075e-003,3,9.519734e-001,1.825000e+000,,,,,,,,,,,,,,,,,,0,3.000000e+000,1.000000e+000,10,5,5.091858e-002,0,,0,
1615619765.623,,1.000000e+003,8.003369e+001,-3.748625e-006,8.720670e-009,1.527287e-002,9.682025e-004,3,9.525012e-001,1.825000e+000,,,,,,,,,,,,,,,,,,0,3.000000e+000,1.000000e+000,10,5,4.662323e-002,0,,0,
1615620051.232,,1.000000e+003,8.503958e+001,-3.756130e-006,4.486181e-009,1.758435e-002,3.488438e-004,3,9.510502e-001,1.825000e+000,,,,,,,,,,,,,,,,,,0,3.000000e+000,1.000000e+000,10,5,6.015015e-002,0,,0,
1615620336.421,,1.000000e+003,9.004195e+001,-3.759313e-006,2.166664e-009,2.000925e-002,1.003055e-003,3,9.513095e-001,1.825000e+000,,,,,,,,,,,,,,,,,,0,3.000000e+000,1.000000e+000,10,5,6.234741e-002,0,,0,
1615620621.199,,1.000000e+003,9.504722e+001,-3.783514e-006,5.859578e-009,1.711118e-002,1.363187e-003,3,9.562237e-001,1.825000e+000,,,,,,,,,,,,,,,,,,0,3.000000e+000,1.000000e+000,10,5,7.868958e-002,0,,0,
1615620903.468,,1.000000e+003,1.000495e+002,-3.779905e-006,3.774207e-009,1.851644e-002,1.001013e-003,3,9.583415e-001,1.825000e+000,,,,,,,,,,,,,,,,,,0,3.000000e+000,1.000000e+000,10,5,8.380127e-002,0,,0,
1615621183.218,,1.000000e+003,1.050611e+002,-3.810246e-006,6.011383e-009,1.971683e-002,9.359776e-004,3,9.684396e-001,1.825000e+000,,,,,,,,,,,,,,,,,,0,3.000000e+000,1.000000e+000,10,5,7.400513e-002,0,,0,
1615621461.457,,1.000000e+003,1.100560e+002,-3.813790e-006,6.970856e-009,1.926293e-002,1.056545e-003,3,9.690587e-001,1.825000e+000,,,,,,,,,,,,,,,,,,0,3.000000e+000,1.000000e+000,10,5,1.002960e-001,0,,0,
1615621741.036,,1.000000e+003,1.150599e+002,-3.820021e-006,4.562455e-009,2.121572e-002,1.613419e-003,3,9.700381e-001,1.825000e+000,,,,,,,,,,,,,,,,,,0,3.000000e+000,1.000000e+000,10,5,9.129333e-002,0,,0,
1615622023.876,,1.000000e+003,1.200517e+002,-3.821390e-006,6.701756e-009,2.330831e-002,1.461744e-003,3,9.711288e-001,1.825000e+000,,,,,,,,,,,,,,,,,,0,3.000000e+000,1.000000e+000,10,5,1.101990e-001,0,,0,
1615622301.925,,1.000000e+003,1.250735e+002,-3.829127e-006,4.520286e-009,2.486132e-002,1.868546e-003,3,9.692508e-001,1.825000e+000,,,,,,,,,,,,,,,,,,0,3.000000e+000,1.000000e+000,10,5,1.352997e-001,0,,0,
1615622585.355,,1.000000e+003,1.300660e+002,-3.827363e-006,6.014730e-009,2.656874e-002,1.557581e-003,3,9.721132e-001,1.825000e+000,,,,,,,,,,,,,,,,,,0,3.000000e+000,1.000000e+000,10,5,1.057892e-001,0,,0,
1615622868.284,,1.000000e+003,1.350584e+002,-3.830367e-006,4.917187e-009,2.860740e-002,1.964493e-003,3,9.712663e-001,1.825000e+000,,,,,,,,,,,,,,,,,,0,3.000000e+000,1.000000e+000,10,5,1.134033e-001,0,,0,
1615623152.543,,1.000000e+003,1.400639e+002,-3.841599e-006,1.103193e-008,2.947344e-002,8.495444e-004,3,9.728087e-001,1.825000e+000,,,,,,,,,,,,,,,,,,0,3.000000e+000,1.000000e+000,10,5,1.163025e-001,0,,0,
1615623441.092,,1.000000e+003,1.450545e+002,-3.842774e-006,7.422365e-009,3.225860e-002,1.056608e-003,3,9.723506e-001,1.825000e+000,,,,,,,,,,,,,,,,,,0,3.000000e+000,1.000000e+000,10,5,1.188049e-001,0,,0,
1615623730.152,,1.000000e+003,1.500567e+002,-3.840319e-006,6.235673e-009,3.316053e-002,1.611377e-003,3,9.731554e-001,1.825000e+000,,,,,,,,,,,,,,,,,,0,3.000000e+000,1.000000e+000,10,5,1.266937e-001,0,,0,
1615624019.841,,1.000000e+003,1.550541e+002,-3.843828e-006,4.262179e-009,3.517165e-002,1.456377e-003,3,9.727423e-001,1.825000e+000,,,,,,,,,,,,,,,,,,0,3.000000e+000,1.000000e+000,10,5,1.165009e-001,0,,0,
1615624309.962,,1.000000e+003,1.600581e+002,-3.847228e-006,5.351064e-009,3.901895e-002,1.790834e-003,3,9.723876e-001,1.825000e+000,,,,,,,,,,,,,,,,,,0,3.000000e+000,1.000000e+000,10,5,1.367035e-001,0,,0,
1615624603.011,,1.000000e+003,1.650528e+002,-3.848346e-006,9.840884e-009,3.914127e-002,1.096546e-003,3,9.721949e-001,1.825000e+000,,,,,,,,,,,,,,,,,,0,3.000000e+000,1.000000e+000,10,5,1.449890e-001,0,,0,
1615624894.991,,1.000000e+003,1.700567e+002,-3.852907e-006,6.117972e-009,4.278550e-002,1.479528e-003,3,9.740071e-001,1.825000e+000,,,,,,,,,,,,,,,,,,0,3.000000e+000,1.000000e+000,10,5,1.390076e-001,0,,0,
1615625186.640,,1.000000e+003,1.750574e+002,-3.855450e-006,7.061718e-009,4.295975e-002,1.413005e-003,3,9.730272e-001,1.825000e+000,,,,,,,,,,,,,,,,,,0,3.000000e+000,1.000000e+000,10,5,1.393127e-001,0,,0,
1615625479.970,,1.000000e+003,1.800541e+002,-3.851665e-006,1.137824e-008,4.520927e-002,2.059062e-003,3,9.727592e-001,1.825000e+000,,,,,,,,,,,,,,,,,,0,3.000000e+000,1.000000e+000,10,5,1.306915e-001,0,,0,
1615625772.668,,1.000000e+003,1.850551e+002,-3.862236e-006,6.283869e-009,4.760082e-002,4.656811e-004,3,9.737638e-001,1.825000e+000,,,,,,,,,,,,,,,,,,0,3.000000e+000,1.000000e+000,10,5,1.378937e-001,0,,0,
1615626067.007,,1.000000e+003,1.900563e+002,-3.858473e-006,6.309449e-009,5.112074e-002,9.727911e-004,3,9.738169e-001,1.825000e+000,,,,,,,,,,,,,,,,,,0,3.000000e+000,1.000000e+000,10,5,1.361084e-001,0,,0,
1615626361.206,,1.000000e+003,1.950529e+002,-3.860946e-006,9.964696e-009,5.269666e-002,6.892944e-004,3,9.729978e-001,1.825000e+000,,,,,,,,,,,,,,,,,,0,3.000000e+000,1.000000e+000,10,5,1.336060e-001,0,,0,
1615626656.705,,1.000000e+003,2.000547e+002,-3.867814e-006,1.141644e-008,5.594470e-002,1.004703e-003,3,9.723047e-001,1.825000e+000,,,,,,,,,,,,,,,,,,0,3.000000e+000,1.000000e+000,10,5,1.402893e-001,0,,0,
1615626954.904,,1.000000e+003,2.050578e+002,-3.872530e-006,8.763857e-009,5.790442e-002,1.120099e-003,3,9.731292e-001,1.825000e+000,,,,,,,,,,,,,,,,,,0,3.000000e+000,1.000000e+000,10,5,1.576996e-001,0,,0,
1615627252.213,,1.000000e+003,2.100529e+002,-3.875730e-006,1.276291e-008,6.055078e-002,1.026815e-003,3,9.735365e-001,1.825000e+000,,,,,,,,,,,,,,,,,,0,3.000000e+000,1.000000e+000,10,5,1.544037e-001,0,,0,
1615627549.992,,1.000000e+003,2.150495e+002,-3.877733e-006,1.251419e-008,6.395961e-002,2.237824e-003,3,9.728497e-001,1.825000e+000,,,,,,,,,,,,,,,,,,0,3.000000e+000,1.000000e+000,10,5,1.445007e-001,0,,0,
1615627846.101,,1.000000e+003,2.200515e+002,-3.877374e-006,6.338426e-009,6.624528e-002,8.609239e-004,3,9.733491e-001,1.825000e+000,,,,,,,,,,,,,,,,,,0,3.000000e+000,1.000000e+000,10,5,1.452026e-001,0,,0,
1615628142.560,,1.000000e+003,2.250534e+002,-3.882228e-006,4.643828e-009,6.699257e-002,9.056234e-004,3,9.752862e-001,1.825000e+000,,,,,,,,,,,,,,,,,,0,3.000000e+000,1.000000e+000,10,5,1.455994e-001,0,,0,
1615628440.809,,1.000000e+003,2.300455e+002,-3.881639e-006,5.003627e-009,7.084405e-002,3.015067e-003,3,9.716470e-001,1.825000e+000,,,,,,,,,,,,,,,,,,0,3.000000e+000,1.000000e+000,10,5,1.454010e-001,0,,0,
1615628734.348,,1.000000e+003,2.350562e+002,-3.888412e-006,6.462500e-009,7.412350e-002,1.934624e-003,3,9.733663e-001,1.825000e+000,,,,,,,,,,,,,,,,,,0,3.000000e+000,1.000000e+000,10,5,1.725922e-001,0,,0,
1615629032.648,,1.000000e+003,2.400501e+002,-3.878860e-006,9.990351e-009,7.761276e-002,1.315801e-003,3,9.733500e-001,1.825000e+000,,,,,,,,,,,,,,,,,,0,3.000000e+000,1.000000e+000,10,5,1.441956e-001,0,,0,
1615629333.866,,1.000000e+003,2.450428e+002,-3.888394e-006,1.092587e-008,8.138791e-002,1.194685e-003,3,9.746918e-001,1.825000e+000,,,,,,,,,,,,,,,,,,0,3.000000e+000,1.000000e+000,10,5,1.502991e-001,0,,0,
1615629635.075,,1.000000e+003,2.500451e+002,-3.894327e-006,1.164476e-008,8.449481e-002,2.207285e-003,3,9.729298e-001,1.825000e+000,,,,,,,,,,,,,,,,,,0,3.000000e+000,1.000000e+000,10,5,1.331024e-001,0,,0,
1615629937.094,,1.000000e+003,2.550437e+002,-3.887442e-006,1.128552e-008,8.685607e-002,3.174672e-003,3,9.731950e-001,1.825000e+000,,,,,,,,,,,,,,,,,,0,3.000000e+000,1.000000e+000,10,5,1.302948e-001,0,,0,
1615630238.543,,1.000000e+003,2.600455e+002,-3.895586e-006,1.529548e-008,9.143292e-002,2.294270e-003,3,9.724138e-001,1.825000e+000,,,,,,,,,,,,,,,,,,0,3.000000e+000,1.000000e+000,10,5,1.441956e-001,0,,0,
1615630539.512,,1.000000e+003,2.650420e+002,-3.899167e-006,1.122149e-008,9.580525e-002,2.032700e-003,3,9.745688e-001,1.825000e+000,,,,,,,,,,,,,,,,,,0,3.000000e+000,1.000000e+000,10,5,1.499939e-001,0,,0,
1615630841.111,,1.000000e+003,2.700395e+002,-3.906166e-006,5.794778e-009,9.994371e-002,1.764032e-003,3,9.725733e-001,1.825000e+000,,,,,,,,,,,,,,,,,,0,3.000000e+000,1.000000e+000,10,5,1.286011e-001,0,,0,
1615631142.280,,1.000000e+003,2.750384e+002,-3.894570e-006,8.098952e-009,1.030409e-001,1.456371e-003,3,9.740325e-001,1.825000e+000,,,,,,,,,,,,,,,,,,0,3.000000e+000,1.000000e+000,10,5,1.431885e-001,0,,0,
1615631444.820,,1.000000e+003,2.800411e+002,-3.904342e-006,8.362811e-009,1.087313e-001,1.214926e-003,3,9.732531e-001,1.825000e+000,,,,,,,,,,,,,,,,,,0,3.000000e+000,1.000000e+000,10,5,1.091003e-001,0,,0,
1615631747.608,,1.000000e+003,2.850370e+002,-3.903961e-006,4.435087e-009,1.147497e-001,1.155711e-003,3,9.736633e-001,1.825000e+000,,,,,,,,,,,,,,,,,,0,3.000000e+000,1.000000e+000,10,5,1.235962e-001,0,,0,
1615632050.498,,1.000000e+003,2.900372e+002,-3.905737e-006,2.466717e-009,1.202620e-001,1.508144e-003,3,9.729915e-001,1.825000e+000,,,,,,,,,,,,,,,,,,0,3.000000e+000,1.000000e+000,10,5,1.174927e-001,0,,0,
1615632354.577,,1.000000e+003,2.950346e+002,-3.904812e-006,4.940836e-009,1.261323e-001,9.877946e-004,3,9.736996e-001,1.825000e+000,,,,,,,,,,,,,,,,,,0,3.000000e+000,1.000000e+000,10,5,1.218262e-001,0,,0,
1615632659.717,,1.000000e+003,3.000308e+002,-3.912356e-006,3.111315e-009,1.314313e-001,8.175183e-004,3,9.734615e-001,1.825000e+000,,,,,,,,,,,,,,,,,,0,3.000000e+000,1.000000e+000,10,5,1.262817e-001,0,,0,