File: SiC 1/Temperature Dependence/SiC1_temp_dep.rso.raw
[Header]
TITLE,MPMS RSO Measurement
BYAPP,MPMS Measurement,2.1,Raw with ABS
FILEOPENTIME, 1615615555.990000 3/13/2021, 7:05:55 AM

INFO, APPNAME, MPMS MultiVu Application, Revision 1.61,  Build 082

INFO, NAME,
INFO, WEIGHT, 1.000
INFO, AREA, 1.000
INFO, LENGTH, 1.000
INFO, SHAPE, 0
INFO, COMMENT,
INFO, SEQUENCE FILE: SiC1_Hyst_30K.seq


INFO, BACKGROUND DATA FILE:, None


STARTUPAXIS,X,8,LINEAR,AUTO,0.000000,0.000000
STARTUPAXIS,Y1,9,LINEAR,AUTO,0.000000,0.000000


STARTUPGROUP,Longitudinal
FIELDGROUP,Longitudinal,1,2,3,4,5,6,7,8,9,10,11,12,13,14,15,16,17,18,19,20,21,22
FIELDGROUP,Transverse,1,2,3,4,5,6,7,8,23,24,25,26,27,28,29,30,31,32,33,34,35,36

PLOT_APPEARANCE,ALL,HORZ_GRID_ON,VERT_GRID_ON,MARKERS_ONLY

[Data]
Time,Comment,Field (Oe),Start Temperature (K),End Temperature (K),Scan,Rejected,Position (cm),Long Voltage,Long Average Voltage,Long Detrended Voltage,Long Demeaned Voltage,Long Reg Fit,Long Detrended Fit,Long Demeaned Fit,Long Scaled Response,Long Avg. Scaled Response,Long Background Response,Long Response [w/ABS],Long Detrended Resp. [w/ABS],Long Fit [w/ABS],Long Detrended Fit [w/ABS],Trans Voltage,Trans Average Voltage,Trans Detrended Voltage,Trans Demeaned Voltage,Trans Reg Fit,Trans Detrended Fit,Trans Demeaned Fit,Trans Scaled Response,Trans Avg. Scaled Response,Trans Background Response,Trans Response [w/ABS],Trans Detrended Resp. [w/ABS],Trans Adjusted Fit,Trans Detrended Fit [w/ABS],
1615615555.990,,1.000000e+003,5.001225e+000,5.008454e+000,1,0,2.066987e+000,9.445479e-001,,,,,,,1.164140e-004,,,,,,,,,,,,,,,,,,,,,
1615615555.990,,1.000000e+003,5.001225e+000,5.008454e+000,1,0,2.790103e+000,1.074252e+000,,,,,,,1.323997e-004,,,,,,,,,,,,,,,,,,,,,
1615615555.990,,1.000000e+003,5.008454e+000,5.005833e+000,2,0,3.337261e+000,1.031526e+000,,,,,,,1.271338e-004,,,,,,,,,,,,,,,,,,,,,
1615615555.990,,1.000000e+003,5.005833e+000,5.002062e+000,3,0,3.461103e+000,1.113926e+000,,,,,,,1.372895e-004,,,,,,,,,,,,,,,,,,,,,
1615615555.990,,1.000000e+003,5.002062e+000,5.001748e+000,4,0,2.969455e+000,1.020844e+000,,,,,,,1.258173e-004,,,,,,,,,,,,,,,,,,,,,
1615615555.990,,1.000000e+003,5.001748e+000,5.002062e+000,5,0,2.204050e+000,8.734397e-001,9.449751e-001,-1.791273e-001,-1.111879e-001,9.575856e-001,-1.665169e-001,-9.857750e-002,1.076500e-004,1.164666e-004,,,,,,,,,,,,,,,,,,,,
1615615823.348,,1.000000e+003,1.000266e+001,1.000884e+001,1,0,1.432604e+000,8.085879e-001,,,,,,,9.965711e-005,,,,,,,,,,,,,,,,,,,,,
1615615823.348,,1.000000e+003,1.000884e+001,1.000651e+001,2,0,8.221972e-001,8.919035e-001,,,,,,,1.099256e-004,,,,,,,,,,,,,,,,,,,,,
1615615823.348,,1.000000e+003,1.000651e+001,1.000557e+001,3,0,5.066744e-001,8.612323e-001,,,,,,,1.061455e-004,,,,,,,,,,,,,,,,,,,,,
1615615823.348,,1.000000e+003,1.000557e+001,1.000703e+001,4,0,8.195643e-001,9.236427e-001,,,,,,,1.138374e-004,,,,,,,,,,,,,,,,,,,,,
1615615823.348,,1.000000e+003,1.000703e+001,1.000368e+001,5,0,1.528826e+000,6.285287e-001,7.173070e-001,-2.182138e-002,-1.740026e-002,7.546171e-001,1.548868e-002,1.990980e-002,7.746511e-005,8.840689e-005,,,,,,,,,,,,,,,,,,,,
1615615823.348,,1.000000e+003,1.000703e+001,1.000368e+001,5,0,2.326824e+000,5.169836e-001,6.241646e-001,-1.790701e-001,-1.105427e-001,6.054231e-001,-1.978115e-001,-1.292842e-001,6.371736e-005,7.692724e-005,,,,,,,,,,,,,,,,,,,,
1615616090.857,,1.000000e+003,1.500067e+001,1.500615e+001,1,0,2.993623e+000,4.824976e-001,,,,,,,5.946703e-005,,,,,,,,,,,,,,,,,,,,,
1615616090.857,,1.000000e+003,1.500615e+001,1.500459e+001,2,0,3.449322e+000,5.027924e-001,,,,,,,6.196833e-005,,,,,,,,,,,,,,,,,,,,,
1615616090.857,,1.000000e+003,1.500459e+001,1.500146e+001,3,0,3.351783e+000,4.872280e-001,,,,,,,6.005004e-005,,,,,,,,,,,,,,,,,,,,,
1615616090.857,,1.000000e+003,1.500146e+001,1.500146e+001,4,0,2.729974e+000,3.732414e-001,,,,,,,4.600138e-005,,,,,,,,,,,,,,,,,,,,,
1615616090.857,,1.000000e+003,1.500146e+001,1.500067e+001,5,0,1.934324e+000,4.055910e-001,4.271370e-001,-1.320687e-001,-1.146504e-001,4.638081e-001,-9.539755e-002,-7.797930e-002,4.998842e-005,5.264393e-005,,,,,,,,,,,,,,,,,,,,
1615616373.296,,1.000000e+003,1.999688e+001,1.999756e+001,1,0,1.211177e+000,1.588946e+000,,,,,,,3.916700e-005,,,,,,,,,,,,,,,,,,,,,
1615616373.296,,1.000000e+003,1.999756e+001,2.000233e+001,2,0,6.639821e-001,1.871090e+000,,,,,,,4.612174e-005,,,,,,,,,,,,,,,,,,,,,
1615616373.296,,1.000000e+003,2.000233e+001,2.000369e+001,3,0,5.401209e-001,1.764122e+000,,,,,,,4.348503e-005,,,,,,,,,,,,,,,,,,,,,
1615616373.296,,1.000000e+003,2.000369e+001,2.000301e+001,4,0,1.031779e+000,1.583453e+000,,,,,,,3.903159e-005,,,,,,,,,,,,,,,,,,,,,
1615616373.296,,1.000000e+003,2.000301e+001,2.000165e+001,5,0,1.797180e+000,1.321604e+000,1.361889e+000,-2.392132e-001,-2.330047e-001,1.379332e+000,-2.217698e-001,-2.155613e-001,3.257710e-005,3.357010e-005,,,,,,,,,,,,,,,,,,,,
1615616373.296,,1.000000e+003,2.000301e+001,2.000165e+001,5,0,2.568596e+000,1.613971e+000,1.668447e+000,-1.127018e-001,7.355368e-002,1.654431e+000,-1.267173e-001,5.953825e-002,3.978386e-005,4.112666e-005,,,,,,,,,,,,,,,,,,,,
1615616641.915,,1.000000e+003,2.499935e+001,2.500658e+001,1,0,3.179075e+000,1.798151e+000,,,,,,,4.432381e-005,,,,,,,,,,,,,,,,,,,,,
1615616641.915,,1.000000e+003,2.500658e+001,2.500762e+001,2,0,3.494562e+000,1.716514e+000,,,,,,,4.231149e-005,,,,,,,,,,,,,,,,,,,,,
1615616641.915,,1.000000e+003,2.500762e+001,2.500452e+001,3,0,3.181689e+000,1.763054e+000,,,,,,,4.345870e-005,,,,,,,,,,,,,,,,,,,,,
1615616641.915,,1.000000e+003,2.500452e+001,2.500348e+001,4,0,2.472423e+000,1.283914e+000,,,,,,,3.164804e-005,,,,,,,,,,,,,,,,,,,,,
1615616641.915,,1.000000e+003,2.500348e+001,2.500039e+001,5,0,1.674419e+000,1.128727e+000,1.339824e+000,-1.996230e-001,-1.196126e-001,1.345428e+000,-1.940185e-001,-1.140081e-001,2.782275e-005,3.302620e-005,,,,,,,,,,,,,,,,,,,,
1615616911.805,,1.000000e+003,3.000099e+001,3.000243e+001,1,0,1.007647e+000,1.452834e+000,,,,,,,3.581187e-005,,,,,,,,,,,,,,,,,,,,,
1615616911.805,,1.000000e+003,3.000243e+001,3.000243e+001,2,0,5.519333e-001,1.596118e+000,,,,,,,3.934378e-005,,,,,,,,,,,,,,,,,,,,,
1615616911.805,,1.000000e+003,3.000099e+001,3.000243e+001,3,0,6.494474e-001,1.477859e+000,,,,,,,3.642873e-005,,,,,,,,,,,,,,,,,,,,,
1615616911.805,,1.000000e+003,3.000099e+001,3.000243e+001,4,0,1.271240e+000,1.381878e+000,,,,,,,3.406284e-005,,,,,,,,,,,,,,,,,,,,,
1615616911.805,,1.000000e+003,3.000243e+001,3.000099e+001,5,0,2.066900e+000,1.040223e+000,1.114597e+000,-2.646974e-001,-2.646974e-001,1.132394e+000,-2.469002e-001,-2.469002e-001,2.564116e-005,2.747445e-005,,,,,,,,,,,,,,,,,,,,
1615616911.805,,1.000000e+003,3.000243e+001,3.000099e+001,5,0,2.790045e+000,1.386456e+000,1.478866e+000,-4.862388e-002,9.957159e-002,1.470009e+000,-5.748113e-002,9.071434e-002,3.417567e-005,3.645355e-005,,,,,,,,,,,,,,,,,,,,
1615617194.943,,1.000000e+003,3.500154e+001,3.500308e+001,1,0,3.337297e+000,1.309091e+000,,,,,,,3.226867e-005,,,,,,,,,,,,,,,,,,,,,
1615617194.943,,1.000000e+003,3.500308e+001,3.500077e+001,2,0,3.461097e+000,1.427045e+000,,,,,,,3.517620e-005,,,,,,,,,,,,,,,,,,,,,
1615617194.943,,1.000000e+003,3.500077e+001,3.500154e+001,3,0,2.969424e+000,1.213721e+000,,,,,,,2.991782e-005,,,,,,,,,,,,,,,,,,,,,
1615617194.943,,1.000000e+003,3.500154e+001,3.500230e+001,4,0,2.204067e+000,9.645375e-001,,,,,,,2.377553e-005,,,,,,,,,,,,,,,,,,,,,
1615617194.943,,1.000000e+003,3.500230e+001,3.500000e+001,5,0,1.432605e+000,1.136204e+000,1.104282e+000,-1.220949e-001,-6.898761e-002,1.105480e+000,-1.208964e-001,-6.778908e-002,2.800705e-005,2.722018e-005,,,,,,,,,,,,,,,,,,,,
1615617491.592,,1.000000e+003,4.000185e+001,4.000185e+001,1,0,8.220967e-001,1.119877e+000,,,,,,,2.760459e-005,,,,,,,,,,,,,,,,,,,,,
1615617491.592,,1.000000e+003,4.000185e+001,4.000185e+001,2,0,5.066909e-001,1.229591e+000,,,,,,,3.030900e-005,,,,,,,,,,,,,,,,,,,,,
1615617491.592,,1.000000e+003,4.000283e+001,4.000087e+001,3,0,8.196448e-001,1.129795e+000,,,,,,,2.784908e-005,,,,,,,,,,,,,,,,,,,,,
1615617491.592,,1.000000e+003,4.000087e+001,3.999791e+001,4,0,1.528939e+000,8.336131e-001,,,,,,,2.054828e-005,,,,,,,,,,,,,,,,,,,,,
1615617491.592,,1.000000e+003,4.000087e+001,3.999791e+001,4,0,2.326946e+000,8.909879e-001,,,,,,,2.196255e-005,,,,,,,,,,,,,,,,,,,,,
1615617491.592,,1.000000e+003,3.999791e+001,4.000087e+001,5,0,2.993642e+000,1.099887e+000,1.125980e+000,6.094390e-003,9.637642e-002,1.122806e+000,2.920204e-003,9.320223e-002,2.711185e-005,2.775504e-005,,,,,,,,,,,,,,,,,,,,
1615617792.261,,1.000000e+003,4.500476e+001,4.500107e+001,1,0,3.449356e+000,1.121708e+000,,,,,,,2.764972e-005,,,,,,,,,,,,,,,,,,,,,
1615617792.261,,1.000000e+003,4.500107e+001,4.500107e+001,2,0,3.351765e+000,1.055330e+000,,,,,,,2.601353e-005,,,,,,,,,,,,,,,,,,,,,
1615617792.261,,1.000000e+003,4.500107e+001,4.500230e+001,3,0,2.729887e+000,9.128086e-001,,,,,,,2.250043e-005,,,,,,,,,,,,,,,,,,,,,
1615617792.261,,1.000000e+003,4.500107e+001,4.500230e+001,4,0,1.934279e+000,7.107761e-001,,,,,,,1.752039e-005,,,,,,,,,,,,,,,,,,,,,
1615617792.261,,1.000000e+003,4.500230e+001,4.500230e+001,5,0,1.211121e+000,8.880886e-001,9.198584e-001,-4.429854e-002,-1.033783e-002,9.139265e-001,-5.023039e-002,-1.626968e-002,2.189109e-005,2.267420e-005,,,,,,,,,,,,,,,,,,,,
1615618075.950,,1.000000e+003,5.001214e+001,5.000915e+001,1,0,6.639356e-001,1.108585e+000,,,,,,,2.732625e-005,,,,,,,,,,,,,,,,,,,,,
1615618075.950,,1.000000e+003,5.000915e+001,5.000169e+001,2,0,5.401524e-001,1.056398e+000,,,,,,,2.603986e-005,,,,,,,,,,,,,,,,,,,,,
1615618075.950,,1.000000e+003,5.000169e+001,5.000318e+001,3,0,1.031930e+000,8.424634e-001,,,,,,,2.076644e-005,,,,,,,,,,,,,,,,,,,,,
1615618075.950,,1.000000e+003,5.000318e+001,5.000318e+001,4,0,1.797300e+000,6.372265e-001,,,,,,,1.570742e-005,,,,,,,,,,,,,,,,,,,,,
1615618075.950,,1.000000e+003,5.000318e+001,5.000318e+001,4,0,2.568716e+000,8.223212e-001,,,,,,,2.026994e-005,,,,,,,,,,,,,,,,,,,,,
1615618075.950,,1.000000e+003,5.000318e+001,5.000318e+001,5,0,3.179148e+000,1.047548e+000,1.019135e+000,4.664771e-002,1.107064e-001,1.023546e+000,5.105905e-002,1.151178e-001,2.582171e-005,2.512134e-005,,,,,,,,,,,,,,,,,,,,
1615618352.518,,1.000000e+003,5.502612e+001,5.501899e+001,1,0,3.494583e+000,9.132664e-001,,,,,,,2.251171e-005,,,,,,,,,,,,,,,,,,,,,
1615618352.518,,1.000000e+003,5.501899e+001,5.501009e+001,2,0,3.181600e+000,1.013062e+000,,,,,,,2.497164e-005,,,,,,,,,,,,,,,,,,,,,
1615618352.518,,1.000000e+003,5.501009e+001,5.501009e+001,3,0,2.472285e+000,7.533494e-001,,,,,,,1.856981e-005,,,,,,,,,,,,,,,,,,,,,
1615618352.518,,1.000000e+003,5.501009e+001,5.500121e+001,4,0,1.674257e+000,7.933286e-001,,,,,,,1.955529e-005,,,,,,,,,,,,,,,,,,,,,
1615618352.518,,1.000000e+003,5.500121e+001,5.500298e+001,5,0,1.007600e+000,9.680471e-001,9.347209e-001,1.822078e-002,4.709601e-002,9.260181e-001,9.517908e-003,3.839314e-002,2.386204e-005,2.304056e-005,,,,,,,,,,,,,,,,,,,,
1615618632.397,,1.000000e+003,6.003398e+001,6.001930e+001,1,0,5.519071e-001,8.386487e-001,,,,,,,2.067241e-005,,,,,,,,,,,,,,,,,,,,,
1615618632.397,,1.000000e+003,6.001930e+001,6.001930e+001,2,0,6.494949e-001,9.201331e-001,,,,,,,2.268097e-005,,,,,,,,,,,,,,,,,,,,,
1615618632.397,,1.000000e+003,6.001930e+001,6.001301e+001,3,0,1.271436e+000,6.601154e-001,,,,,,,1.627162e-005,,,,,,,,,,,,,,,,,,,,,
1615618632.397,,1.000000e+003,6.001301e+001,6.000672e+001,4,0,2.067015e+000,4.789880e-001,,,,,,,1.180689e-005,,,,,,,,,,,,,,,,,,,,,
1615618632.397,,1.000000e+003,6.001301e+001,6.000672e+001,4,0,2.790161e+000,7.493820e-001,,,,,,,1.847202e-005,,,,,,,,,,,,,,,,,,,,,
1615618632.397,,1.000000e+003,6.000672e+001,5.999834e+001,5,0,3.337312e+000,8.720664e-001,8.719443e-001,7.476538e-002,1.229650e-001,8.819917e-001,8.481276e-002,1.330124e-001,2.149615e-005,2.149314e-005,,,,,,,,,,,,,,,,,,,,
1615618913.206,,1.000000e+003,6.504701e+001,6.503239e+001,1,0,3.461058e+000,8.702353e-001,,,,,,,2.145101e-005,,,,,,,,,,,,,,,,,,,,,
1615618913.206,,1.000000e+003,6.503726e+001,6.502509e+001,2,0,2.969317e+000,6.915494e-001,,,,,,,1.704646e-005,,,,,,,,,,,,,,,,,,,,,
1615618913.206,,1.000000e+003,6.502509e+001,6.501535e+001,3,0,2.203867e+000,4.150517e-001,,,,,,,1.023089e-005,,,,,,,,,,,,,,,,,,,,,
1615618913.206,,1.000000e+003,6.501535e+001,6.500560e+001,4,0,1.432533e+000,5.293435e-001,,,,,,,1.304814e-005,,,,,,,,,,,,,,,,,,,,,
1615618913.206,,1.000000e+003,6.500560e+001,6.500560e+001,5,0,8.220853e-001,7.367168e-001,7.458419e-001,6.387932e-002,7.874322e-002,7.400125e-001,5.804992e-002,7.291383e-002,1.815982e-005,1.838475e-005,,,,,,,,,,,,,,,,,,,,
1615619198.075,,1.000000e+003,7.005171e+001,7.003772e+001,1,0,5.067068e-001,8.035523e-001,,,,,,,1.980730e-005,,,,,,,,,,,,,,,,,,,,,
1615619198.075,,1.000000e+003,7.003772e+001,7.002374e+001,2,0,8.193351e-001,7.736442e-001,,,,,,,1.907007e-005,,,,,,,,,,,,,,,,,,,,,
1615619198.075,,1.000000e+003,7.002374e+001,7.001814e+001,3,0,1.528443e+000,4.310739e-001,,,,,,,1.062583e-005,,,,,,,,,,,,,,,,,,,,,
1615619198.075,,1.000000e+003,7.002374e+001,7.001814e+001,3,0,2.326502e+000,4.260384e-001,,,,,,,1.050170e-005,,,,,,,,,,,,,,,,,,,,,
1615619198.075,,1.000000e+003,7.001814e+001,7.000977e+001,4,0,2.993289e+000,7.242042e-001,,,,,,,1.785139e-005,,,,,,,,,,,,,,,,,,,,,
1615619198.075,,1.000000e+003,7.000977e+001,7.001254e+001,5,0,3.449197e+000,7.869197e-001,7.842342e-001,8.915812e-002,1.199652e-001,7.961540e-001,1.010780e-001,1.318851e-001,1.939731e-005,1.933111e-005,,,,,,,,,,,,,,,,,,,,
1615619479.864,,1.000000e+003,7.506363e+001,7.504771e+001,1,0,3.351911e+000,8.830531e-001,,,,,,,2.176696e-005,,,,,,,,,,,,,,,,,,,,,
1615619479.864,,1.000000e+003,7.504771e+001,7.503180e+001,2,0,2.730256e+000,6.190680e-001,,,,,,,1.525982e-005,,,,,,,,,,,,,,,,,,,,,
1615619479.864,,1.000000e+003,7.503180e+001,7.502544e+001,3,0,1.934678e+000,4.074221e-001,,,,,,,1.004282e-005,,,,,,,,,,,,,,,,,,,,,
1615619479.864,,1.000000e+003,7.502544e+001,7.501907e+001,4,0,1.211468e+000,5.858028e-001,,,,,,,1.443984e-005,,,,,,,,,,,,,,,,,,,,,
1615619479.864,,1.000000e+003,7.501907e+001,7.501271e+001,5,0,6.641657e-001,6.656087e-001,7.581408e-001,9.364467e-002,1.058447e-001,7.544467e-001,8.995055e-002,1.021506e-001,1.640703e-005,1.868792e-005,,,,,,,,,,,,,,,,,,,,
1615619765.623,,1.000000e+003,8.006453e+001,8.004660e+001,1,0,5.400681e-001,7.542650e-001,,,,,,,1.859238e-005,,,,,,,,,,,,,,,,,,,,,
1615619765.623,,1.000000e+003,8.004660e+001,8.003584e+001,2,0,1.031567e+000,6.563005e-001,,,,,,,1.617759e-005,,,,,,,,,,,,,,,,,,,,,
1615619765.623,,1.000000e+003,8.003584e+001,8.002866e+001,3,0,1.796887e+000,5.046236e-001,,,,,,,1.243880e-005,,,,,,,,,,,,,,,,,,,,,
1615619765.623,,1.000000e+003,8.003584e+001,8.002866e+001,3,0,2.568363e+000,6.695760e-001,,,,,,,1.650483e-005,,,,,,,,,,,,,,,,,,,,,
1615619765.623,,1.000000e+003,8.002508e+001,8.001791e+001,4,0,3.178893e+000,7.141331e-001,,,,,,,1.760314e-005,,,,,,,,,,,,,,,,,,,,,
1615619765.623,,1.000000e+003,8.001791e+001,8.001791e+001,5,0,3.494551e+000,8.233894e-001,7.954344e-001,9.343391e-002,1.230451e-001,8.079604e-001,1.059599e-001,1.355711e-001,2.029627e-005,1.960719e-005,,,,,,,,,,,,,,,,,,,,
1615620051.232,,1.000000e+003,8.507647e+001,8.506043e+001,1,0,3.181764e+000,5.818354e-001,,,,,,,1.434205e-005,,,,,,,,,,,,,,,,,,,,,
1615620051.232,,1.000000e+003,8.506043e+001,8.503637e+001,2,0,2.472647e+000,4.354991e-001,,,,,,,1.073491e-005,,,,,,,,,,,,,,,,,,,,,
1615620051.232,,1.000000e+003,8.503637e+001,8.503236e+001,3,0,1.674668e+000,4.449599e-001,,,,,,,1.096811e-005,,,,,,,,,,,,,,,,,,,,,
1615620051.232,,1.000000e+003,8.503637e+001,8.502034e+001,4,0,1.007882e+000,6.845302e-001,,,,,,,1.687344e-005,,,,,,,,,,,,,,,,,,,,,
1615620051.232,,1.000000e+003,8.502034e+001,8.501632e+001,5,0,5.520170e-001,7.502975e-001,7.246620e-001,1.125188e-001,1.203712e-001,7.170749e-001,1.049317e-001,1.127841e-001,1.849459e-005,1.786268e-005,,,,,,,,,,,,,,,,,,,,
1615620336.421,,1.000000e+003,9.008069e+001,9.006288e+001,1,0,6.493651e-001,6.468398e-001,,,,,,,1.594439e-005,,,,,,,,,,,,,,,,,,,,,
1615620336.421,,1.000000e+003,9.006288e+001,9.004951e+001,2,0,1.271060e+000,4.908902e-001,,,,,,,1.210028e-005,,,,,,,,,,,,,,,,,,,,,
1615620336.421,,1.000000e+003,9.004951e+001,9.002725e+001,3,0,2.066584e+000,2.920621e-001,,,,,,,7.199234e-006,,,,,,,,,,,,,,,,,,,,,
1615620336.421,,1.000000e+003,9.004951e+001,9.002725e+001,3,0,2.789770e+000,5.336161e-001,,,,,,,1.315346e-005,,,,,,,,,,,,,,,,,,,,,
1615620336.421,,1.000000e+003,9.002725e+001,9.001834e+001,4,0,3.337074e+000,6.563005e-001,,,,,,,1.617759e-005,,,,,,,,,,,,,,,,,,,,,
1615620336.421,,1.000000e+003,9.001834e+001,9.002280e+001,5,0,3.461192e+000,6.320384e-001,6.564226e-001,8.876279e-002,1.046501e-001,6.701950e-001,1.025352e-001,1.184224e-001,1.557954e-005,1.618060e-005,,,,,,,,,,,,,,,,,,,,
1615620621.199,,1.000000e+003,9.510132e+001,9.506687e+001,1,0,2.969552e+000,5.702384e-001,,,,,,,1.405619e-005,,,,,,,,,,,,,,,,,,,,,
1615620621.199,,1.000000e+003,9.506687e+001,9.504722e+001,2,0,2.204345e+000,3.631703e-001,,,,,,,8.952026e-006,,,,,,,,,,,,,,,,,,,,,
1615620621.199,,1.000000e+003,9.504722e+001,9.503737e+001,3,0,1.432907e+000,4.351940e-001,,,,,,,1.072739e-005,,,,,,,,,,,,,,,,,,,,,
1615620621.199,,1.000000e+003,9.503737e+001,9.502263e+001,4,0,8.223850e-001,6.033509e-001,,,,,,,1.487240e-005,,,,,,,,,,,,,,,,,,,,,
1615620621.199,,1.000000e+003,9.502263e+001,9.502263e+001,5,0,5.066875e-001,6.318858e-001,6.675924e-001,1.138377e-001,1.192963e-001,6.631221e-001,1.093674e-001,1.148260e-001,1.557577e-005,1.645593e-005,,,,,,,,,,,,,,,,,,,,
1615620903.468,,1.000000e+003,1.000985e+002,1.000687e+002,1,0,8.195081e-001,5.587939e-001,,,,,,,1.377408e-005,,,,,,,,,,,,,,,,,,,,,
1615620903.468,,1.000000e+003,1.000687e+002,1.000579e+002,2,0,1.528637e+000,2.946562e-001,,,,,,,7.263177e-006,,,,,,,,,,,,,,,,,,,,,
1615620903.468,,1.000000e+003,1.000687e+002,1.000579e+002,2,0,2.326673e+000,2.549821e-001,,,,,,,6.285225e-006,,,,,,,,,,,,,,,,,,,,,
1615620903.468,,1.000000e+003,1.000579e+002,1.000336e+002,3,0,2.993412e+000,5.041658e-001,,,,,,,1.242752e-005,,,,,,,,,,,,,,,,,,,,,
1615620903.468,,1.000000e+003,1.000336e+002,1.000309e+002,4,0,3.449228e+000,5.583361e-001,,,,,,,1.376280e-005,,,,,,,,,,,,,,,,,,,,,
1615620903.468,,1.000000e+003,1.000309e+002,1.000147e+002,5,0,3.351892e+000,5.793939e-001,5.637684e-001,7.987321e-002,8.733737e-002,5.718488e-001,8.795357e-002,9.541774e-002,1.428187e-005,1.389670e-005,,,,,,,,,,,,,,,,,,,,
1615621183.218,,1.000000e+003,1.050996e+002,1.050967e+002,1,0,2.730124e+000,3.660695e-001,,,,,,,9.023492e-006,,,,,,,,,,,,,,,,,,,,,
1615621183.218,,1.000000e+003,1.050967e+002,1.050700e+002,2,0,1.934543e+000,2.299570e-001,,,,,,,5.668363e-006,,,,,,,,,,,,,,,,,,,,,
1615621183.218,,1.000000e+003,1.050700e+002,1.050463e+002,3,0,1.211377e+000,3.968932e-001,,,,,,,9.783285e-006,,,,,,,,,,,,,,,,,,,,,
1615621183.218,,1.000000e+003,1.050463e+002,1.050256e+002,4,0,6.641340e-001,5.401776e-001,,,,,,,1.331520e-005,,,,,,,,,,,,,,,,,,,,,
1615621183.218,,1.000000e+003,1.050256e+002,1.050345e+002,5,0,5.400741e-001,6.344798e-001,5.790887e-001,1.126805e-001,1.159092e-001,5.741424e-001,1.077342e-001,1.109629e-001,1.563972e-005,1.427434e-005,,,,,,,,,,,,,,,,,,,,
1615621461.457,,1.000000e+003,1.101120e+002,1.100861e+002,1,0,1.031707e+000,4.374829e-001,,,,,,,1.078381e-005,,,,,,,,,,,,,,,,,,,,,
1615621461.457,,1.000000e+003,1.100861e+002,1.100635e+002,2,0,1.796944e+000,1.348918e-001,,,,,,,3.325038e-006,,,,,,,,,,,,,,,,,,,,,
1615621461.457,,1.000000e+003,1.100861e+002,1.100635e+002,2,0,2.568427e+000,2.404858e-001,,,,,,,5.927896e-006,,,,,,,,,,,,,,,,,,,,,
1615621461.457,,1.000000e+003,1.100635e+002,1.100570e+002,3,0,3.178897e+000,4.156621e-001,,,,,,,1.024593e-005,,,,,,,,,,,,,,,,,,,,,
1615621461.457,,1.000000e+003,1.100376e+002,1.100214e+002,4,0,3.494557e+000,4.667806e-001,,,,,,,1.150599e-005,,,,,,,,,,,,,,,,,,,,,
1615621461.457,,1.000000e+003,1.100214e+002,1.100117e+002,5,0,3.181812e+000,4.310739e-001,4.341868e-001,4.931778e-002,4.791647e-002,4.375277e-001,5.265859e-002,5.125728e-002,1.062583e-005,1.070256e-005,,,,,,,,,,,,,,,,,,,,
1615621741.036,,1.000000e+003,1.151049e+002,1.150803e+002,1,0,2.472697e+000,2.107303e-001,,,,,,,5.194432e-006,,,,,,,,,,,,,,,,,,,,,
1615621741.036,,1.000000e+003,1.150803e+002,1.150662e+002,2,0,1.674713e+000,2.052370e-001,,,,,,,5.059023e-006,,,,,,,,,,,,,,,,,,,,,
1615621741.036,,1.000000e+003,1.150662e+002,1.150662e+002,3,0,1.007974e+000,4.284799e-001,,,,,,,1.056189e-005,,,,,,,,,,,,,,,,,,,,,
1615621741.036,,1.000000e+003,1.150662e+002,1.150276e+002,4,0,5.520516e-001,4.721214e-001,,,,,,,1.163763e-005,,,,,,,,,,,,,,,,,,,,,
1615621741.036,,1.000000e+003,1.150276e+002,1.150136e+002,5,0,6.492367e-001,4.649495e-001,4.845119e-001,9.896199e-002,9.890226e-002,4.806693e-001,9.511946e-002,9.505972e-002,1.146085e-005,1.194306e-005,,,,,,,,,,,,,,,,,,,,
1615622023.876,,1.000000e+003,1.201304e+002,1.200696e+002,1,0,1.271146e+000,3.642384e-001,,,,,,,8.978355e-006,,,,,,,,,,,,,,,,,,,,,
1615622023.876,,1.000000e+003,1.200696e+002,1.200506e+002,2,0,2.066725e+000,1.446577e-001,,,,,,,3.565765e-006,,,,,,,,,,,,,,,,,,,,,
1615622023.876,,1.000000e+003,1.200696e+002,1.200506e+002,2,0,2.789917e+000,3.608814e-001,,,,,,,8.895606e-006,,,,,,,,,,,,,,,,,,,,,
1615622023.876,,1.000000e+003,1.200506e+002,1.200278e+002,3,0,3.337130e+000,4.872280e-001,,,,,,,1.201001e-005,,,,,,,,,,,,,,,,,,,,,
1615622023.876,,1.000000e+003,1.200278e+002,1.200354e+002,4,0,3.461178e+000,4.831080e-001,,,,,,,1.190845e-005,,,,,,,,,,,,,,,,,,,,,
1615622023.876,,1.000000e+003,1.200354e+002,1.200202e+002,5,0,2.969607e+000,3.729362e-001,3.995483e-001,-7.264669e-003,-5.508780e-003,3.996997e-001,-7.113303e-003,-5.357414e-003,9.192753e-006,9.848733e-006,,,,,,,,,,,,,,,,,,,,
1615622301.925,,1.000000e+003,1.251502e+002,1.251092e+002,1,0,2.204304e+000,8.102664e-002,,,,,,,1.997280e-006,,,,,,,,,,,,,,,,,,,,,
1615622301.925,,1.000000e+003,1.251092e+002,1.250805e+002,2,0,1.432891e+000,2.330088e-001,,,,,,,5.743590e-006,,,,,,,,,,,,,,,,,,,,,
1615622301.925,,1.000000e+003,1.250805e+002,1.250517e+002,3,0,8.223949e-001,3.955199e-001,,,,,,,9.749433e-006,,,,,,,,,,,,,,,,,,,,,
1615622301.925,,1.000000e+003,1.250517e+002,1.250436e+002,4,0,5.066611e-001,4.783776e-001,,,,,,,1.179185e-005,,,,,,,,,,,,,,,,,,,,,
1615622301.925,,1.000000e+003,1.250436e+002,1.250149e+002,5,0,8.193650e-001,4.168828e-001,4.132206e-001,6.712884e-002,6.616554e-002,4.092306e-001,6.313879e-002,6.217548e-002,1.027602e-005,1.018575e-005,,,,,,,,,,,,,,,,,,,,
1615622585.355,,1.000000e+003,1.301352e+002,1.300999e+002,1,0,1.528744e+000,1.612903e-001,,,,,,,3.975753e-006,,,,,,,,,,,,,,,,,,,,,
1615622585.355,,1.000000e+003,1.301352e+002,1.300999e+002,1,0,2.326732e+000,9.323405e-002,,,,,,,2.298188e-006,,,,,,,,,,,,,,,,,,,,,
1615622585.355,,1.000000e+003,1.300999e+002,1.300735e+002,2,0,2.993418e+000,3.698843e-001,,,,,,,9.117526e-006,,,,,,,,,,,,,,,,,,,,,
1615622585.355,,1.000000e+003,1.300691e+002,1.300382e+002,3,0,3.449227e+000,4.289377e-001,,,,,,,1.057317e-005,,,,,,,,,,,,,,,,,,,,,
1615622585.355,,1.000000e+003,1.300382e+002,1.300382e+002,4,0,3.351921e+000,4.554887e-001,,,,,,,1.122765e-005,,,,,,,,,,,,,,,,,,,,,
1615622585.355,,1.000000e+003,1.300382e+002,1.300294e+002,5,0,2.730135e+000,2.856532e-001,2.676778e-001,-8.326253e-002,-8.904073e-002,2.658126e-001,-8.512777e-002,-9.090596e-002,7.041258e-006,6.598170e-006,,,,,,,,,,,,,,,,,,,,
1615622868.284,,1.000000e+003,1.351345e+002,1.350920e+002,1,0,1.934463e+000,5.355999e-002,,,,,,,1.320236e-006,,,,,,,,,,,,,,,,,,,,,
1615622868.284,,1.000000e+003,1.350920e+002,1.350636e+002,2,0,1.211367e+000,2.259896e-001,,,,,,,5.570567e-006,,,,,,,,,,,,,,,,,,,,,
1615622868.284,,1.000000e+003,1.350636e+002,1.350352e+002,3,0,6.641049e-001,4.474014e-001,,,,,,,1.102829e-005,,,,,,,,,,,,,,,,,,,,,
1615622868.284,,1.000000e+003,1.350352e+002,1.350211e+002,4,0,5.400633e-001,4.429762e-001,,,,,,,1.091922e-005,,,,,,,,,,,,,,,,,,,,,
1615622868.284,,1.000000e+003,1.350211e+002,1.350258e+002,5,0,1.031676e+000,3.207496e-001,3.278298e-001,1.101960e-002,9.588480e-003,3.247449e-001,7.934705e-003,6.503582e-003,7.906369e-006,8.080896e-006,,,,,,,,,,,,,,,,,,,,
1615623152.543,,1.000000e+003,1.401362e+002,1.400957e+002,1,0,1.797065e+000,8.835109e-002,,,,,,,2.177825e-006,,,,,,,,,,,,,,,,,,,,,
1615623152.543,,1.000000e+003,1.401362e+002,1.400957e+002,1,0,2.568516e+000,1.849422e-001,,,,,,,4.558763e-006,,,,,,,,,,,,,,,,,,,,,
1615623152.543,,1.000000e+003,1.400957e+002,1.400704e+002,2,0,3.178931e+000,3.851436e-001,,,,,,,9.493661e-006,,,,,,,,,,,,,,,,,,,,,
1615623152.543,,1.000000e+003,1.400704e+002,1.400401e+002,3,0,3.494566e+000,4.521317e-001,,,,,,,1.114490e-005,,,,,,,,,,,,,,,,,,,,,
1615623152.543,,1.000000e+003,1.400401e+002,1.400350e+002,4,0,3.181805e+000,4.901273e-001,,,,,,,1.208147e-005,,,,,,,,,,,,,,,,,,,,,
1615623152.543,,1.000000e+003,1.400350e+002,1.400199e+002,5,0,2.472598e+000,1.712088e-001,1.888180e-001,-1.714698e-001,-1.737029e-001,1.861155e-001,-1.741723e-001,-1.764053e-001,4.220241e-006,4.654301e-006,,,,,,,,,,,,,,,,,,,,
1615623441.092,,1.000000e+003,1.451279e+002,1.450793e+002,1,0,1.674456e+000,9.994812e-002,,,,,,,2.463688e-006,,,,,,,,,,,,,,,,,,,,,
1615623441.092,,1.000000e+003,1.450793e+002,1.450685e+002,2,0,1.007780e+000,4.206977e-001,,,,,,,1.037006e-005,,,,,,,,,,,,,,,,,,,,,
1615623441.092,,1.000000e+003,1.450685e+002,1.450361e+002,3,0,5.519736e-001,4.470961e-001,,,,,,,1.102077e-005,,,,,,,,,,,,,,,,,,,,,
1615623441.092,,1.000000e+003,1.450361e+002,1.450199e+002,4,0,6.493587e-001,3.707999e-001,,,,,,,9.140093e-006,,,,,,,,,,,,,,,,,,,,,
1615623441.092,,1.000000e+003,1.450199e+002,1.450091e+002,5,0,1.271154e+000,2.787866e-001,2.683187e-001,-6.584185e-002,-6.726453e-002,2.679821e-001,-6.617852e-002,-6.760120e-002,6.871996e-006,6.613967e-006,,,,,,,,,,,,,,,,,,,,
1615623730.152,,1.000000e+003,1.501339e+002,1.500936e+002,1,0,2.066789e+000,1.983703e-002,,,,,,,4.889762e-007,,,,,,,,,,,,,,,,,,,,,
1615623730.152,,1.000000e+003,1.501339e+002,1.500936e+002,1,0,2.789977e+000,2.162236e-001,,,,,,,5.329841e-006,,,,,,,,,,,,,,,,,,,,,
1615623730.152,,1.000000e+003,1.500936e+002,1.500648e+002,2,0,3.337149e+000,3.868221e-001,,,,,,,9.535036e-006,,,,,,,,,,,,,,,,,,,,,
1615623730.152,,1.000000e+003,1.500648e+002,1.500245e+002,3,0,3.461134e+000,3.889584e-001,,,,,,,9.587695e-006,,,,,,,,,,,,,,,,,,,,,
1615623730.152,,1.000000e+003,1.500245e+002,1.500302e+002,4,0,2.969560e+000,1.899777e-001,,,,,,,4.682888e-006,,,,,,,,,,,,,,,,,,,,,
1615623730.152,,1.000000e+003,1.500302e+002,1.500072e+002,5,0,2.204200e+000,8.545183e-003,2.310251e-002,-2.457917e-001,-2.533466e-001,2.159977e-002,-2.472945e-001,-2.548493e-001,2.106359e-007,5.694692e-007,,,,,,,,,,,,,,,,,,,,
1615624019.841,,1.000000e+003,1.551332e+002,1.551025e+002,1,0,1.432736e+000,1.460311e-001,,,,,,,3.599617e-006,,,,,,,,,,,,,,,,,,,,,
1615624019.841,,1.000000e+003,1.550780e+002,1.550473e+002,2,0,8.223293e-001,3.193762e-001,,,,,,,7.872517e-006,,,,,,,,,,,,,,,,,,,,,
1615624019.841,,1.000000e+003,1.550473e+002,1.550290e+002,3,0,5.066878e-001,4.171880e-001,,,,,,,1.028355e-005,,,,,,,,,,,,,,,,,,,,,
1615624019.841,,1.000000e+003,1.550290e+002,1.550351e+002,4,0,8.194284e-001,3.315836e-001,,,,,,,8.173425e-006,,,,,,,,,,,,,,,,,,,,,
1615624019.841,,1.000000e+003,1.550167e+002,1.550229e+002,5,0,1.528661e+000,1.277200e-001,1.211890e-001,-1.560623e-001,-1.574500e-001,1.242495e-001,-1.530019e-001,-1.543895e-001,3.148255e-006,2.987269e-006,,,,,,,,,,,,,,,,,,,,
1615624019.841,,1.000000e+003,1.550167e+002,1.550229e+002,5,0,2.326673e+000,4.821924e-002,4.083377e-002,-2.162969e-001,-2.378052e-001,3.682055e-002,-2.203101e-001,-2.418184e-001,1.188588e-006,1.006539e-006,,,,,,,,,,,,,,,,,,,,
1615624309.962,,1.000000e+003,1.601577e+002,1.600926e+002,1,0,2.993460e+000,2.308725e-001,,,,,,,5.690931e-006,,,,,,,,,,,,,,,,,,,,,
1615624309.962,,1.000000e+003,1.600926e+002,1.600601e+002,2,0,3.449231e+000,2.847377e-001,,,,,,,7.018689e-006,,,,,,,,,,,,,,,,,,,,,
1615624309.962,,1.000000e+003,1.600601e+002,1.600276e+002,3,0,3.351941e+000,3.448592e-001,,,,,,,8.500663e-006,,,,,,,,,,,,,,,,,,,,,
1615624309.962,,1.000000e+003,1.600276e+002,1.600210e+002,4,0,2.730167e+000,1.004059e-001,,,,,,,2.474972e-006,,,,,,,,,,,,,,,,,,,,,
1615624309.962,,1.000000e+003,1.600210e+002,1.600210e+002,5,0,1.934560e+000,5.737480e-002,-1.660207e-002,-2.587814e-001,-2.698369e-001,-1.527889e-002,-2.574582e-001,-2.685137e-001,1.414270e-006,-4.092355e-007,,,,,,,,,,,,,,,,,,,,
1615624603.011,,1.000000e+003,1.651529e+002,1.650977e+002,1,0,1.211292e+000,1.937925e-001,,,,,,,4.776921e-006,,,,,,,,,,,,,,,,,,,,,
1615624603.011,,1.000000e+003,1.650907e+002,1.650493e+002,2,0,6.640933e-001,2.862636e-001,,,,,,,7.056303e-006,,,,,,,,,,,,,,,,,,,,,
1615624603.011,,1.000000e+003,1.650493e+002,1.650286e+002,3,0,5.400810e-001,3.190710e-001,,,,,,,7.864995e-006,,,,,,,,,,,,,,,,,,,,,
1615624603.011,,1.000000e+003,1.650286e+002,1.650079e+002,4,0,1.031663e+000,3.169347e-001,,,,,,,7.812336e-006,,,,,,,,,,,,,,,,,,,,,
1615624603.011,,1.000000e+003,1.650079e+002,1.650148e+002,5,0,1.797032e+000,-1.005585e-001,-1.886044e-002,-2.393884e-001,-2.402578e-001,-1.252095e-002,-2.330489e-001,-2.339183e-001,-2.478733e-006,-4.649035e-007,,,,,,,,,,,,,,,,,,,,
1615624603.011,,1.000000e+003,1.650079e+002,1.650148e+002,5,0,2.568488e+000,-3.006073e-002,5.398724e-002,-1.413259e-001,-1.674102e-001,4.993287e-002,-1.453803e-001,-1.714645e-001,-7.409870e-007,1.330768e-006,,,,,,,,,,,,,,,,,,,,
1615624894.991,,1.000000e+003,1.701540e+002,1.700954e+002,1,0,3.178990e+000,2.317881e-001,,,,,,,5.713499e-006,,,,,,,,,,,,,,,,,,,,,
1615624894.991,,1.000000e+003,1.700954e+002,1.700588e+002,2,0,3.494542e+000,3.097629e-001,,,,,,,7.635552e-006,,,,,,,,,,,,,,,,,,,,,
1615624894.991,,1.000000e+003,1.700588e+002,1.700223e+002,3,0,3.181798e+000,2.102725e-001,,,,,,,5.183148e-006,,,,,,,,,,,,,,,,,,,,,
1615624894.991,,1.000000e+003,1.700223e+002,1.700223e+002,4,0,2.472571e+000,2.548295e-002,,,,,,,6.281464e-007,,,,,,,,,,,,,,,,,,,,,
1615624894.991,,1.000000e+003,1.700223e+002,1.700150e+002,5,0,1.674511e+000,-1.327555e-002,-3.814814e-003,-2.009843e-001,-2.165147e-001,-1.451466e-003,-1.986210e-001,-2.141513e-001,-3.272379e-007,-9.403389e-008,,,,,,,,,,,,,,,,,,,,
1615625186.640,,1.000000e+003,1.751542e+002,1.750922e+002,1,0,1.007777e+000,2.194281e-001,,,,,,,5.408829e-006,,,,,,,,,,,,,,,,,,,,,
1615625186.640,,1.000000e+003,1.750922e+002,1.750535e+002,2,0,5.519866e-001,2.319407e-001,,,,,,,5.717260e-006,,,,,,,,,,,,,,,,,,,,,
1615625186.640,,1.000000e+003,1.750535e+002,1.750381e+002,3,0,6.493672e-001,3.041170e-001,,,,,,,7.496381e-006,,,,,,,,,,,,,,,,,,,,,
1615625186.640,,1.000000e+003,1.750381e+002,1.750149e+002,4,0,1.271117e+000,1.161229e-001,,,,,,,2.862392e-006,,,,,,,,,,,,,,,,,,,,,
1615625186.640,,1.000000e+003,1.750149e+002,1.750226e+002,5,0,2.066761e+000,-1.043733e-001,-9.537034e-002,-2.753496e-001,-2.753496e-001,-8.370687e-002,-2.636861e-001,-2.636861e-001,-2.572767e-006,-2.350847e-006,,,,,,,,,,,,,,,,,,,,
1615625186.640,,1.000000e+003,1.750149e+002,1.750226e+002,5,0,2.789935e+000,7.202368e-002,7.870723e-002,-6.807244e-002,-1.012720e-001,7.566319e-002,-7.111648e-002,-1.043161e-001,1.775360e-006,1.940107e-006,,,,,,,,,,,,,,,,,,,,
1615625479.970,,1.000000e+003,1.801440e+002,1.800949e+002,1,0,3.337245e+000,3.042696e-001,,,,,,,7.500143e-006,,,,,,,,,,,,,,,,,,,,,
1615625479.970,,1.000000e+003,1.800949e+002,1.800460e+002,2,0,3.461129e+000,1.510666e-001,,,,,,,3.723742e-006,,,,,,,,,,,,,,,,,,,,,
1615625479.970,,1.000000e+003,1.800460e+002,1.800296e+002,3,0,2.969501e+000,1.207007e-001,,,,,,,2.975232e-006,,,,,,,,,,,,,,,,,,,,,
1615625479.970,,1.000000e+003,1.800296e+002,1.800215e+002,4,0,2.204117e+000,-1.026948e-001,,,,,,,-2.531392e-006,,,,,,,,,,,,,,,,,,,,,
1615625479.970,,1.000000e+003,1.800215e+002,1.800133e+002,5,0,1.432642e+000,7.660146e-002,4.361095e-002,-1.150110e-001,-1.316643e-001,4.179610e-002,-1.168258e-001,-1.334791e-001,1.888200e-006,1.074995e-006,,,,,,,,,,,,,,,,,,,,
1615625772.668,,1.000000e+003,1.851500e+002,1.850982e+002,1,0,8.222076e-001,2.212592e-001,,,,,,,5.453966e-006,,,,,,,,,,,,,,,,,,,,,
1615625772.668,,1.000000e+003,1.850982e+002,1.850551e+002,2,0,5.066891e-001,2.362133e-001,,,,,,,5.822578e-006,,,,,,,,,,,,,,,,,,,,,
1615625772.668,,1.000000e+003,1.850551e+002,1.850293e+002,3,0,8.195624e-001,2.101199e-001,,,,,,,5.179386e-006,,,,,,,,,,,,,,,,,,,,,
1615625772.668,,1.000000e+003,1.850293e+002,1.850121e+002,4,0,1.528887e+000,-4.425184e-003,,,,,,,-1.090793e-007,,,,,,,,,,,,,,,,,,,,,
1615625772.668,,1.000000e+003,1.850293e+002,1.850121e+002,4,0,2.326894e+000,-1.124607e-001,,,,,,,-2.772119e-006,,,,,,,,,,,,,,,,,,,,,
1615625772.668,,1.000000e+003,1.850121e+002,1.850121e+002,5,0,2.993555e+000,1.747185e-001,1.193579e-001,-5.972524e-003,-4.194311e-002,1.180359e-001,-7.294540e-003,-4.326513e-002,4.306752e-006,2.942132e-006,,,,,,,,,,,,,,,,,,,,
1615626067.007,,1.000000e+003,1.901497e+002,1.900953e+002,1,0,3.449298e+000,2.136296e-001,,,,,,,5.265897e-006,,,,,,,,,,,,,,,,,,,,,
1615626067.007,,1.000000e+003,1.900953e+002,1.900590e+002,2,0,3.351759e+000,2.040162e-001,,,,,,,5.028932e-006,,,,,,,,,,,,,,,,,,,,,
1615626067.007,,1.000000e+003,1.900590e+002,1.900318e+002,3,0,2.729859e+000,-6.714072e-003,,,,,,,-1.654996e-007,,,,,,,,,,,,,,,,,,,,,
1615626067.007,,1.000000e+003,1.900318e+002,1.900136e+002,4,0,1.934286e+000,-1.399274e-001,,,,,,,-3.449163e-006,,,,,,,,,,,,,,,,,,,,,
1615626067.007,,1.000000e+003,1.900136e+002,1.900136e+002,5,0,1.211157e+000,8.865628e-002,8.886990e-002,-3.410881e-002,-5.213340e-002,8.240838e-002,-4.057033e-002,-5.859491e-002,2.185348e-006,2.190613e-006,,,,,,,,,,,,,,,,,,,,
1615626361.206,,1.000000e+003,1.951502e+002,1.950929e+002,1,0,6.638252e-001,2.233955e-001,,,,,,,5.506624e-006,,,,,,,,,,,,,,,,,,,,,
1615626361.206,,1.000000e+003,1.950929e+002,1.950548e+002,2,0,5.405214e-001,2.563555e-001,,,,,,,6.319077e-006,,,,,,,,,,,,,,,,,,,,,
1615626361.206,,1.000000e+003,1.950548e+002,1.950166e+002,3,0,1.032109e+000,1.185644e-001,,,,,,,2.922573e-006,,,,,,,,,,,,,,,,,,,,,
1615626361.206,,1.000000e+003,1.950166e+002,1.950166e+002,4,0,1.797604e+000,-3.509628e-002,,,,,,,-8.651118e-007,,,,,,,,,,,,,,,,,,,,,
1615626361.206,,1.000000e+003,1.950166e+002,1.950166e+002,4,0,2.568920e+000,2.014222e-002,,,,,,,4.964989e-007,,,,,,,,,,,,,,,,,,,,,
1615626361.206,,1.000000e+003,1.950166e+002,1.950166e+002,5,0,3.179432e+000,1.380963e-001,1.519517e-001,4.340689e-002,6.443575e-003,1.527256e-001,4.418084e-002,7.217526e-003,3.404027e-006,3.745558e-006,,,,,,,,,,,,,,,,,,,,
1615626656.705,,1.000000e+003,2.001509e+002,2.001008e+002,1,0,3.494437e+000,2.139348e-001,,,,,,,5.273420e-006,,,,,,,,,,,,,,,,,,,,,
1615626656.705,,1.000000e+003,2.001008e+002,2.000507e+002,2,0,3.181382e+000,1.141392e-001,,,,,,,2.813494e-006,,,,,,,,,,,,,,,,,,,,,
1615626656.705,,1.000000e+003,2.000507e+002,2.000307e+002,3,0,2.472080e+000,-7.034516e-002,,,,,,,-1.733985e-006,,,,,,,,,,,,,,,,,,,,,
1615626656.705,,1.000000e+003,2.000307e+002,2.000106e+002,4,0,1.674177e+000,-2.929777e-002,,,,,,,-7.221802e-007,,,,,,,,,,,,,,,,,,,,,
1615626656.705,,1.000000e+003,2.000106e+002,2.000106e+002,5,0,1.007447e+000,1.264992e-001,1.505173e-001,2.901004e-002,1.245826e-002,1.444377e-001,2.293046e-002,6.378680e-003,3.118164e-006,3.710201e-006,,,,,,,,,,,,,,,,,,,,
1615626954.904,,1.000000e+003,2.051640e+002,2.051009e+002,1,0,5.519423e-001,2.327036e-001,,,,,,,5.736067e-006,,,,,,,,,,,,,,,,,,,,,
1615626954.904,,1.000000e+003,2.051009e+002,2.050589e+002,2,0,6.496443e-001,2.157659e-001,,,,,,,5.318557e-006,,,,,,,,,,,,,,,,,,,,,
1615626954.904,,1.000000e+003,2.050589e+002,2.050273e+002,3,0,1.271349e+000,8.911405e-002,,,,,,,2.196632e-006,,,,,,,,,,,,,,,,,,,,,
1615626954.904,,1.000000e+003,2.050273e+002,2.050168e+002,4,0,2.066893e+000,-1.159703e-001,,,,,,,-2.858630e-006,,,,,,,,,,,,,,,,,,,,,
1615626954.904,,1.000000e+003,2.050273e+002,2.050168e+002,4,0,2.790041e+000,4.699850e-002,,,,,,,1.158498e-006,,,,,,,,,,,,,,,,,,,,,
1615626954.904,,1.000000e+003,2.050168e+002,2.050063e+002,5,0,3.337317e+000,1.860103e-001,1.820429e-001,7.609974e-002,3.948666e-002,1.859080e-001,7.996479e-002,4.335171e-002,4.585092e-006,4.487297e-006,,,,,,,,,,,,,,,,,,,,
1615627252.213,,1.000000e+003,2.101643e+002,2.100981e+002,1,0,3.461068e+000,1.458785e-001,,,,,,,3.595856e-006,,,,,,,,,,,,,,,,,,,,,
1615627252.213,,1.000000e+003,2.100981e+002,2.100540e+002,2,0,2.969501e+000,2.914518e-002,,,,,,,7.184189e-007,,,,,,,,,,,,,,,,,,,,,
1615627252.213,,1.000000e+003,2.100429e+002,2.100209e+002,3,0,2.204133e+000,-2.233955e-001,,,,,,,-5.506624e-006,,,,,,,,,,,,,,,,,,,,,
1615627252.213,,1.000000e+003,2.100209e+002,2.100099e+002,4,0,1.432680e+000,-6.256294e-003,,,,,,,-1.542156e-007,,,,,,,,,,,,,,,,,,,,,
1615627252.213,,1.000000e+003,2.100099e+002,2.100099e+002,5,0,8.222107e-001,1.493881e-001,1.476485e-001,7.439200e-002,5.549321e-002,1.446214e-001,7.136481e-002,5.246602e-002,3.682367e-006,3.639487e-006,,,,,,,,,,,,,,,,,,,,
1615627549.992,,1.000000e+003,2.151477e+002,2.150899e+002,1,0,5.066838e-001,1.908933e-001,,,,,,,4.705456e-006,,,,,,,,,,,,,,,,,,,,,
1615627549.992,,1.000000e+003,2.150899e+002,2.150495e+002,2,0,8.195117e-001,1.872311e-001,,,,,,,4.615183e-006,,,,,,,,,,,,,,,,,,,,,
1615627549.992,,1.000000e+003,2.150437e+002,2.150263e+002,3,0,1.528734e+000,-8.392590e-002,,,,,,,-2.068746e-006,,,,,,,,,,,,,,,,,,,,,
1615627549.992,,1.000000e+003,2.150437e+002,2.150263e+002,3,0,2.326751e+000,-2.177496e-001,,,,,,,-5.367454e-006,,,,,,,,,,,,,,,,,,,,,
1615627549.992,,1.000000e+003,2.150263e+002,2.150090e+002,4,0,2.993487e+000,3.860591e-002,,,,,,,9.516230e-007,,,,,,,,,,,,,,,,,,,,,
1615627549.992,,1.000000e+003,2.150090e+002,2.150032e+002,5,0,3.449265e+000,1.579333e-001,1.480758e-001,9.508886e-002,5.298870e-002,1.515335e-001,9.854659e-002,5.644643e-002,3.893003e-006,3.650019e-006,,,,,,,,,,,,,,,,,,,,
1615627846.101,,1.000000e+003,2.201543e+002,2.200878e+002,1,0,3.351816e+000,1.126133e-001,,,,,,,2.775880e-006,,,,,,,,,,,,,,,,,,,,,
1615627846.101,,1.000000e+003,2.200878e+002,2.200514e+002,2,0,2.729998e+000,-2.761925e-002,,,,,,,-6.808053e-007,,,,,,,,,,,,,,,,,,,,,
1615627846.101,,1.000000e+003,2.200514e+002,2.200273e+002,3,0,1.934484e+000,-2.343822e-001,,,,,,,-5.777442e-006,,,,,,,,,,,,,,,,,,,,,
1615627846.101,,1.000000e+003,2.200273e+002,2.200091e+002,4,0,1.211334e+000,-9.155553e-003,,,,,,,-2.256813e-007,,,,,,,,,,,,,,,,,,,,,
1615627846.101,,1.000000e+003,2.200091e+002,2.200091e+002,5,0,6.640771e-001,2.188177e-001,1.669668e-001,1.037215e-001,8.559256e-002,1.641555e-001,1.009102e-001,8.278128e-002,5.393784e-006,4.115675e-006,,,,,,,,,,,,,,,,,,,,
1615628142.560,,1.000000e+003,2.251515e+002,2.250882e+002,1,0,5.401093e-001,1.913511e-001,,,,,,,4.716740e-006,,,,,,,,,,,,,,,,,,,,,
1615628142.560,,1.000000e+003,2.250882e+002,2.250565e+002,2,0,1.031666e+000,1.542711e-001,,,,,,,3.802730e-006,,,,,,,,,,,,,,,,,,,,,
1615628142.560,,1.000000e+003,2.250565e+002,2.250249e+002,3,0,1.797039e+000,-1.220740e-001,,,,,,,-3.009084e-006,,,,,,,,,,,,,,,,,,,,,
1615628142.560,,1.000000e+003,2.250565e+002,2.250249e+002,3,0,2.568471e+000,-9.140294e-002,,,,,,,-2.253052e-006,,,,,,,,,,,,,,,,,,,,,
1615628142.560,,1.000000e+003,2.250249e+002,2.250186e+002,4,0,3.178949e+000,8.514664e-002,,,,,,,2.098836e-006,,,,,,,,,,,,,,,,,,,,,
1615628142.560,,1.000000e+003,2.250186e+002,2.250059e+002,5,0,3.494559e+000,1.762444e-001,1.688589e-001,9.906055e-002,5.863550e-002,1.740970e-001,1.042986e-001,6.387354e-002,4.344366e-006,4.162316e-006,,,,,,,,,,,,,,,,,,,,
1615628440.809,,1.000000e+003,2.301480e+002,2.300819e+002,1,0,3.181665e+000,8.178961e-002,,,,,,,2.016086e-006,,,,,,,,,,,,,,,,,,,,,
1615628440.809,,1.000000e+003,2.300819e+002,2.300488e+002,2,0,2.472449e+000,-1.751762e-001,,,,,,,-4.318036e-006,,,,,,,,,,,,,,,,,,,,,
1615628440.809,,1.000000e+003,2.300488e+002,2.300158e+002,3,0,1.674489e+000,-1.159703e-001,,,,,,,-2.858630e-006,,,,,,,,,,,,,,,,,,,,,
1615628440.809,,1.000000e+003,2.300158e+002,2.300026e+002,4,0,1.007756e+000,3.006073e-002,,,,,,,7.409870e-007,,,,,,,,,,,,,,,,,,,,,
1615628440.809,,1.000000e+003,2.300026e+002,2.300092e+002,5,0,5.519660e-001,1.586962e-001,1.594897e-001,1.144995e-001,9.783486e-002,1.577637e-001,1.127735e-001,9.610885e-002,3.911810e-006,3.931369e-006,,,,,,,,,,,,,,,,,,,,
1615628734.348,,1.000000e+003,2.351702e+002,2.351080e+002,1,0,6.494347e-001,1.980651e-001,,,,,,,4.882239e-006,,,,,,,,,,,,,,,,,,,,,
1615628734.348,,1.000000e+003,2.351080e+002,2.350528e+002,2,0,1.271183e+000,9.308145e-003,,,,,,,2.294427e-007,,,,,,,,,,,,,,,,,,,,,
1615628734.348,,1.000000e+003,2.350528e+002,2.350252e+002,3,0,2.066780e+000,-1.828059e-001,,,,,,,-4.506104e-006,,,,,,,,,,,,,,,,,,,,,
1615628734.348,,1.000000e+003,2.350528e+002,2.350252e+002,3,0,2.789944e+000,-4.074221e-002,,,,,,,-1.004282e-006,,,,,,,,,,,,,,,,,,,,,
1615628734.348,,1.000000e+003,2.350252e+002,2.350114e+002,4,0,3.337234e+000,9.628590e-002,,,,,,,2.373415e-006,,,,,,,,,,,,,,,,,,,,,
1615628734.348,,1.000000e+003,2.350114e+002,2.349976e+002,5,0,3.461145e+000,1.606800e-001,1.398053e-001,9.220116e-002,4.958753e-002,1.466721e-001,9.906797e-002,5.645434e-002,3.960708e-006,3.446154e-006,,,,,,,,,,,,,,,,,,,,
1615629032.648,,1.000000e+003,2.401467e+002,2.400962e+002,1,0,2.969341e+000,2.655110e-002,,,,,,,6.544759e-007,,,,,,,,,,,,,,,,,,,,,
1615629032.648,,1.000000e+003,2.400962e+002,2.400458e+002,2,0,2.204077e+000,-2.620014e-001,,,,,,,-6.458247e-006,,,,,,,,,,,,,,,,,,,,,
1615629032.648,,1.000000e+003,2.400458e+002,2.400242e+002,3,0,1.432650e+000,-1.101718e-001,,,,,,,-2.715699e-006,,,,,,,,,,,,,,,,,,,,,
1615629032.648,,1.000000e+003,2.400242e+002,2.400098e+002,4,0,8.221905e-001,1.364177e-001,,,,,,,3.362652e-006,,,,,,,,,,,,,,,,,,,,,
1615629032.648,,1.000000e+003,2.400098e+002,2.400025e+002,5,0,5.066618e-001,1.455733e-001,1.536607e-001,1.165934e-001,1.007679e-001,1.523187e-001,1.152514e-001,9.942594e-002,3.588333e-006,3.787685e-006,,,,,,,,,,,,,,,,,,,,
1615629333.866,,1.000000e+003,2.451465e+002,2.450864e+002,1,0,8.196843e-001,1.008637e-001,,,,,,,2.486256e-006,,,,,,,,,,,,,,,,,,,,,
1615629333.866,,1.000000e+003,2.450864e+002,2.450413e+002,2,0,1.528936e+000,-1.255837e-001,,,,,,,-3.095596e-006,,,,,,,,,,,,,,,,,,,,,
1615629333.866,,1.000000e+003,2.450864e+002,2.450413e+002,2,0,2.326940e+000,-2.749718e-001,,,,,,,-6.777962e-006,,,,,,,,,,,,,,,,,,,,,
1615629333.866,,1.000000e+003,2.450413e+002,2.450113e+002,3,0,2.993540e+000,2.212592e-002,,,,,,,5.453966e-007,,,,,,,,,,,,,,,,,,,,,
1615629333.866,,1.000000e+003,2.450187e+002,2.449962e+002,4,0,3.449314e+000,1.055940e-001,,,,,,,2.602858e-006,,,,,,,,,,,,,,,,,,,,,
1615629333.866,,1.000000e+003,2.449962e+002,2.450037e+002,5,0,3.351802e+000,6.897183e-002,7.855465e-002,7.439531e-002,2.971759e-002,8.261396e-002,7.845462e-002,3.377691e-002,1.700133e-006,1.936346e-006,,,,,,,,,,,,,,,,,,,,
1615629635.075,,1.000000e+003,2.501351e+002,2.500803e+002,1,0,2.729953e+000,-1.133763e-001,,,,,,,-2.794687e-006,,,,,,,,,,,,,,,,,,,,,
1615629635.075,,1.000000e+003,2.500803e+002,2.500490e+002,2,0,1.934403e+000,-3.425703e-001,,,,,,,-8.444243e-006,,,,,,,,,,,,,,,,,,,,,
1615629635.075,,1.000000e+003,2.500490e+002,2.500177e+002,3,0,1.211219e+000,1.861629e-002,,,,,,,4.588854e-007,,,,,,,,,,,,,,,,,,,,,
1615629635.075,,1.000000e+003,2.500177e+002,2.500099e+002,4,0,6.640558e-001,8.621480e-002,,,,,,,2.125166e-006,,,,,,,,,,,,,,,,,,,,,
1615629635.075,,1.000000e+003,2.500099e+002,2.500020e+002,5,0,5.400884e-001,1.527451e-001,1.213721e-001,1.153880e-001,1.007554e-001,1.205910e-001,1.146069e-001,9.997431e-002,3.765117e-006,2.991782e-006,,,,,,,,,,,,,,,,,,,,
1615629937.094,,1.000000e+003,2.551382e+002,2.550893e+002,1,0,1.031747e+000,6.622516e-002,,,,,,,1.632428e-006,,,,,,,,,,,,,,,,,,,,,
1615629937.094,,1.000000e+003,2.550893e+002,2.550404e+002,2,0,1.797004e+000,-1.948607e-001,,,,,,,-4.803251e-006,,,,,,,,,,,,,,,,,,,,,
1615629937.094,,1.000000e+003,2.550893e+002,2.550404e+002,2,0,2.568461e+000,-1.803644e-001,,,,,,,-4.445922e-006,,,,,,,,,,,,,,,,,,,,,
1615629937.094,,1.000000e+003,2.550404e+002,2.550079e+002,3,0,3.178910e+000,-3.677480e-002,,,,,,,-9.064867e-007,,,,,,,,,,,,,,,,,,,,,
1615629937.094,,1.000000e+003,2.550079e+002,2.550079e+002,4,0,3.494559e+000,7.873775e-002,,,,,,,1.940859e-006,,,,,,,,,,,,,,,,,,,,,
1615629937.094,,1.000000e+003,2.550079e+002,2.550079e+002,5,0,3.181794e+000,3.433332e-002,2.160710e-002,3.502239e-002,-7.879803e-003,2.256768e-002,3.598297e-002,-6.919226e-003,8.463050e-007,5.326079e-007,,,,,,,,,,,,,,,,,,,,
1615630238.543,,1.000000e+003,2.601532e+002,2.600768e+002,1,0,2.472482e+000,-2.232429e-001,,,,,,,-5.502863e-006,,,,,,,,,,,,,,,,,,,,,
1615630238.543,,1.000000e+003,2.600768e+002,2.600345e+002,2,0,1.674546e+000,-2.230903e-001,,,,,,,-5.499102e-006,,,,,,,,,,,,,,,,,,,,,
1615630238.543,,1.000000e+003,2.600345e+002,2.600260e+002,3,0,1.007828e+000,-3.051851e-004,,,,,,,-7.522711e-009,,,,,,,,,,,,,,,,,,,,,
1615630238.543,,1.000000e+003,2.600260e+002,2.600090e+002,4,0,5.520051e-001,1.278726e-001,,,,,,,3.152016e-006,,,,,,,,,,,,,,,,,,,,,
1615630238.543,,1.000000e+003,2.600090e+002,2.600090e+002,5,0,6.493593e-001,7.934812e-003,8.435316e-002,1.082532e-001,9.401017e-002,8.245123e-002,1.063512e-001,9.210824e-002,1.955905e-007,2.079277e-006,,,,,,,,,,,,,,,,,,,,
1615630539.512,,1.000000e+003,2.651443e+002,2.650825e+002,1,0,1.271289e+000,-8.438368e-002,,,,,,,-2.080030e-006,,,,,,,,,,,,,,,,,,,,,
1615630539.512,,1.000000e+003,2.650825e+002,2.650385e+002,2,0,2.066735e+000,-3.270058e-001,,,,,,,-8.060585e-006,,,,,,,,,,,,,,,,,,,,,
1615630539.512,,1.000000e+003,2.650825e+002,2.650385e+002,2,0,2.789920e+000,-2.069155e-001,,,,,,,-5.100398e-006,,,,,,,,,,,,,,,,,,,,,
1615630539.512,,1.000000e+003,2.650385e+002,2.650208e+002,3,0,3.337174e+000,-4.394665e-002,,,,,,,-1.083270e-006,,,,,,,,,,,,,,,,,,,,,
1615630539.512,,1.000000e+003,2.650208e+002,2.649943e+002,4,0,3.461161e+000,1.129185e-002,,,,,,,2.783403e-007,,,,,,,,,,,,,,,,,,,,,
1615630539.512,,1.000000e+003,2.649943e+002,2.650032e+002,5,0,2.969523e+000,-1.771599e-001,-1.306192e-001,-3.132091e-002,-8.305240e-002,-1.293807e-001,-3.008240e-002,-8.181389e-002,-4.366934e-006,-3.219720e-006,,,,,,,,,,,,,,,,,,,,
1615630841.111,,1.000000e+003,2.701332e+002,2.700781e+002,1,0,2.203999e+000,-3.959777e-001,,,,,,,-9.760717e-006,,,,,,,,,,,,,,,,,,,,,
1615630841.111,,1.000000e+003,2.700781e+002,2.700322e+002,2,0,1.432677e+000,-1.292459e-001,,,,,,,-3.185868e-006,,,,,,,,,,,,,,,,,,,,,
1615630841.111,,1.000000e+003,2.700322e+002,2.700138e+002,3,0,8.222396e-001,5.005036e-002,,,,,,,1.233725e-006,,,,,,,,,,,,,,,,,,,,,
1615630841.111,,1.000000e+003,2.700138e+002,2.700046e+002,4,0,5.066439e-001,4.242073e-002,,,,,,,1.045657e-006,,,,,,,,,,,,,,,,,,,,,
1615630841.111,,1.000000e+003,2.700046e+002,2.700046e+002,5,0,8.195879e-001,1.770074e-002,3.082369e-002,8.304555e-002,7.033895e-002,2.862750e-002,8.084936e-002,6.814276e-002,4.363172e-007,7.597938e-007,,,,,,,,,,,,,,,,,,,,
1615631142.280,,1.000000e+003,2.751358e+002,2.750689e+002,1,0,1.528864e+000,-2.473525e-001,,,,,,,-6.097157e-006,,,,,,,,,,,,,,,,,,,,,
1615631142.280,,1.000000e+003,2.751358e+002,2.750689e+002,1,0,2.326854e+000,-4.359569e-001,,,,,,,-1.074619e-005,,,,,,,,,,,,,,,,,,,,,
1615631142.280,,1.000000e+003,2.750689e+002,2.750403e+002,2,0,2.993507e+000,-2.449110e-001,,,,,,,-6.036976e-006,,,,,,,,,,,,,,,,,,,,,
1615631142.280,,1.000000e+003,2.750403e+002,2.750212e+002,3,0,3.449298e+000,-8.835109e-002,,,,,,,-2.177825e-006,,,,,,,,,,,,,,,,,,,,,
1615631142.280,,1.000000e+003,2.750212e+002,2.749926e+002,4,0,3.351850e+000,-4.959258e-002,,,,,,,-1.222441e-006,,,,,,,,,,,,,,,,,,,,,
1615631142.280,,1.000000e+003,2.749926e+002,2.750021e+002,5,0,2.729968e+000,-1.849422e-001,-2.547990e-001,-1.134072e-001,-1.645319e-001,-2.545158e-001,-1.131239e-001,-1.642486e-001,-4.558763e-006,-6.280711e-006,,,,,,,,,,,,,,,,,,,,
1615631444.820,,1.000000e+003,2.801115e+002,2.800817e+002,1,0,1.934307e+000,-4.025391e-001,,,,,,,-9.922456e-006,,,,,,,,,,,,,,,,,,,,,
1615631444.820,,1.000000e+003,2.800817e+002,2.800421e+002,2,0,1.211214e+000,-1.576281e-001,,,,,,,-3.885480e-006,,,,,,,,,,,,,,,,,,,,,
1615631444.820,,1.000000e+003,2.800421e+002,2.800222e+002,3,0,6.640388e-001,1.052889e-002,,,,,,,2.595335e-007,,,,,,,,,,,,,,,,,,,,,
1615631444.820,,1.000000e+003,2.800222e+002,2.800024e+002,4,0,5.400814e-001,2.380444e-002,,,,,,,5.867715e-007,,,,,,,,,,,,,,,,,,,,,
1615631444.820,,1.000000e+003,2.800024e+002,2.800024e+002,5,0,1.031790e+000,-1.081881e-001,-7.364117e-002,3.313863e-002,2.172698e-002,-7.560814e-002,3.117166e-002,1.976001e-002,-2.666801e-006,-1.815230e-006,,,,,,,,,,,,,,,,,,,,
1615631747.608,,1.000000e+003,2.851276e+002,2.850658e+002,1,0,1.797240e+000,-3.166296e-001,,,,,,,-7.804812e-006,,,,,,,,,,,,,,,,,,,,,
1615631747.608,,1.000000e+003,2.851276e+002,2.850658e+002,1,0,2.568655e+000,-3.526414e-001,,,,,,,-8.692493e-006,,,,,,,,,,,,,,,,,,,,,
1615631747.608,,1.000000e+003,2.850658e+002,2.850349e+002,2,0,3.179050e+000,-1.353496e-001,,,,,,,-3.336322e-006,,,,,,,,,,,,,,,,,,,,,
1615631747.608,,1.000000e+003,2.850349e+002,2.850143e+002,3,0,3.494571e+000,-1.361126e-001,,,,,,,-3.355129e-006,,,,,,,,,,,,,,,,,,,,,
1615631747.608,,1.000000e+003,2.850143e+002,2.850040e+002,4,0,3.181690e+000,-1.428266e-001,,,,,,,-3.520629e-006,,,,,,,,,,,,,,,,,,,,,
1615631747.608,,1.000000e+003,2.850040e+002,2.850040e+002,5,0,2.472404e+000,-4.066591e-001,-3.752556e-001,-2.051710e-001,-2.590249e-001,-3.746177e-001,-2.045332e-001,-2.583870e-001,-1.002401e-005,-9.249925e-006,,,,,,,,,,,,,,,,,,,,
1615632050.498,,1.000000e+003,2.901237e+002,2.900810e+002,1,0,1.674319e+000,-4.261910e-001,,,,,,,-1.050547e-005,,,,,,,,,,,,,,,,,,,,,
1615632050.498,,1.000000e+003,2.900810e+002,2.900276e+002,2,0,1.007636e+000,-1.330607e-001,,,,,,,-3.279902e-006,,,,,,,,,,,,,,,,,,,,,
1615632050.498,,1.000000e+003,2.900276e+002,2.900062e+002,3,0,5.518924e-001,-1.239051e-001,,,,,,,-3.054221e-006,,,,,,,,,,,,,,,,,,,,,
1615632050.498,,1.000000e+003,2.900062e+002,2.900062e+002,4,0,6.494478e-001,-2.990814e-002,,,,,,,-7.372257e-007,,,,,,,,,,,,,,,,,,,,,
1615632050.498,,1.000000e+003,2.900062e+002,2.900062e+002,5,0,1.271372e+000,-1.919614e-001,-2.110965e-001,-3.795242e-002,-4.798946e-002,-2.113046e-001,-3.816047e-002,-4.819751e-002,-4.731785e-006,-5.203459e-006,,,,,,,,,,,,,,,,,,,,
1615632354.577,,1.000000e+003,2.951198e+002,2.950645e+002,1,0,2.067155e+000,-5.833613e-001,,,,,,,-1.437966e-005,,,,,,,,,,,,,,,,,,,,,
1615632354.577,,1.000000e+003,2.951198e+002,2.950645e+002,1,0,2.790235e+000,-5.159154e-001,,,,,,,-1.271714e-005,,,,,,,,,,,,,,,,,,,,,
1615632354.577,,1.000000e+003,2.950645e+002,2.950423e+002,2,0,3.337316e+000,-2.607807e-001,,,,,,,-6.428157e-006,,,,,,,,,,,,,,,,,,,,,
1615632354.577,,1.000000e+003,2.950423e+002,2.950091e+002,3,0,3.461100e+000,-3.096103e-001,,,,,,,-7.631790e-006,,,,,,,,,,,,,,,,,,,,,
1615632354.577,,1.000000e+003,2.950091e+002,2.949980e+002,4,0,2.969387e+000,-3.537095e-001,,,,,,,-8.718822e-006,,,,,,,,,,,,,,,,,,,,,
1615632354.577,,1.000000e+003,2.949980e+002,2.949980e+002,5,0,2.203932e+000,-4.809717e-001,-5.766472e-001,-2.663923e-001,-3.283068e-001,-5.742508e-001,-2.639959e-001,-3.259104e-001,-1.185579e-005,-1.421416e-005,,,,,,,,,,,,,,,,,,,,
1615632659.717,,1.000000e+003,3.001215e+002,3.000641e+002,1,0,1.432820e+000,-3.856014e-001,,,,,,,-9.504945e-006,,,,,,,,,,,,,,,,,,,,,
1615632659.717,,1.000000e+003,3.000641e+002,3.000296e+002,2,0,8.223703e-001,-1.876888e-001,,,,,,,-4.626467e-006,,,,,,,,,,,,,,,,,,,,,
1615632659.717,,1.000000e+003,3.000296e+002,3.000067e+002,3,0,5.066770e-001,-2.000488e-001,,,,,,,-4.931137e-006,,,,,,,,,,,,,,,,,,,,,
1615632659.717,,1.000000e+003,3.000067e+002,2.999952e+002,4,0,8.194455e-001,-2.284310e-001,,,,,,,-5.630749e-006,,,,,,,,,,,,,,,,,,,,,
1615632659.717,,1.000000e+003,2.999952e+002,2.999952e+002,5,0,1.528613e+000,-4.295480e-001,-4.055910e-001,-1.237620e-001,-1.313387e-001,-4.039141e-001,-1.220851e-001,-1.296618e-001,-1.058822e-005,-9.997683e-006,,,,,,,,,,,,,,,,,,,,
1615632659.717,,1.000000e+003,2.999952e+002,2.999952e+002,5,0,2.326633e+000,-6.643879e-001,-6.339915e-001,-2.423011e-001,-3.597392e-001,-6.389971e-001,-2.473066e-001,-3.647448e-001,-1.637694e-005,-1.562768e-005,,,,,,,,,,,,,,,,,,,,
1615632659.717,,1.000000e+003,2.999952e+002,2.999952e+002,5,0,2.198511e+000,-6.799524e-001,-6.493728e-001,-2.557882e-001,-3.751205e-001,-6.589561e-001,-2.653715e-001,-3.847038e-001,-1.676060e-005,-1.600682e-005,,,,,,,,,,,,,,,,,,,,