File: SiC 1/Hyst at 300K/SiC1_hyst_300K.rso.dat.csv
[Header]
TITLE,MPMS RSO Measurement
BYAPP,MPMS Measurement,1.1,Summary
FILEOPENTIME, 1615554242.321000 3/12/2021, 2:04:02 PM

INFO, APPNAME, MPMS MultiVu Application, Revision 1.61,  Build 082

INFO, NAME,
INFO, WEIGHT, 1.000
INFO, AREA, 1.000
INFO, LENGTH, 1.000
INFO, SHAPE, 0
INFO, COMMENT,
INFO, SEQUENCE FILE: H5T_Lin_NoO.seq


INFO, BACKGROUND DATA FILE:, None


STARTUPAXIS,X,4,LINEAR,AUTO,0.000000,0.000000
STARTUPAXIS,Y1,5,LINEAR,AUTO,0.000000,0.000000


STARTUPGROUP,Longitudinal
FIELDGROUP,Longitudinal,1,2,3,4,5,6,7,8,9,10,11,19,20,21,22,23,35
FIELDGROUP,Transverse,1,2,3,4,12,13,14,15,16,17,18,24,25,26,27,28,35

PLOT_APPEARANCE,ALL,HORZ_GRID_ON,VERT_GRID_ON,MARKERS_AND_LINES

[Data]
Time,Comment,Field (Oe),Temperature (K),Long Moment (emu),Long Scan Std Dev,Long Offset (cm),Long Offset Std Dev,Long Algorithm,Long Reg Fit,Long Reg Factor,Trans Moment (emu),Trans Scan Std Dev,Trans Offset (cm),Trans Offset Std Dev,Trans Algorithm,Trans Reg Fit,Trans Reg Factor,Long Moment [w/o ABS] (emu),Long Scan Std Dev [w/o ABS],Long Offset [w/o ABS] (cm),Long Offset Std Dev [w/o ABS],Long Reg Fit [w/o ABS],Trans Moment [w/o ABS] (emu),Trans Scan Std Dev [w/o ABS],Trans Offset [w/o ABS] (cm),Trans Offset Std Dev [w/o ABS],Trans Reg Fit [w/o ABS],RSO Position (deg),Amplitude (cm),Frequency,Cycles to Average,Scans per Measurement,Delta Temp (K),Error,EC Comp. Running,Using ABS,
1615554242.321,,0.000000e+000,2.999998e+002,2.910431e-007,5.391180e-009,0.000000e+000,0.000000e+000,2,9.010220e-001,1.825000e+000,,,,,,,,,,,,,,,,,,0,3.000000e+000,1.000000e+000,10,5,1.150513e-002,0,,0,
1615554428.600,,2.000000e+002,2.999975e+002,-4.961953e-007,5.305733e-009,0.000000e+000,0.000000e+000,2,9.235664e-001,1.825000e+000,,,,,,,,,,,,,,,,,,0,3.000000e+000,1.000000e+000,10,5,1.150513e-002,0,,0,
1615554614.769,,4.000000e+002,2.999975e+002,-1.309837e-006,5.268657e-009,0.000000e+000,0.000000e+000,2,9.659560e-001,1.825000e+000,,,,,,,,,,,,,,,,,,0,3.000000e+000,1.000000e+000,10,5,1.150513e-002,0,,0,
1615554802.398,,6.000000e+002,3.000021e+002,-2.187638e-006,5.800981e-009,0.000000e+000,0.000000e+000,2,9.771286e-001,1.825000e+000,,,,,,,,,,,,,,,,,,0,3.000000e+000,1.000000e+000,10,5,1.150513e-002,0,,0,
1615555009.937,,8.000000e+002,2.999964e+002,-3.102821e-006,5.467575e-009,0.000000e+000,0.000000e+000,2,9.832084e-001,1.825000e+000,,,,,,,,,,,,,,,,,,0,3.000000e+000,1.000000e+000,10,5,1.150513e-002,0,,0,
1615555195.767,,1.000000e+003,3.000010e+002,-4.045508e-006,6.882271e-009,0.000000e+000,0.000000e+000,2,9.826027e-001,1.825000e+000,,,,,,,,,,,,,,,,,,0,3.000000e+000,1.000000e+000,10,5,1.150513e-002,0,,0,
1615555433.286,,1.500000e+003,2.999964e+002,-6.463181e-006,1.661604e-009,0.000000e+000,0.000000e+000,2,9.853880e-001,1.825000e+000,,,,,,,,,,,,,,,,,,0,3.000000e+000,1.000000e+000,10,5,1.150513e-002,0,,0,
1615555653.425,,2.000000e+003,2.999975e+002,-8.931375e-006,1.873974e-008,0.000000e+000,0.000000e+000,2,9.868659e-001,1.825000e+000,,,,,,,,,,,,,,,,,,0,3.000000e+000,1.000000e+000,10,5,1.150513e-002,0,,0,
1615555907.504,,2.500000e+003,2.999987e+002,-1.143812e-005,2.351725e-008,0.000000e+000,0.000000e+000,2,9.851983e-001,1.825000e+000,,,,,,,,,,,,,,,,,,0,3.000000e+000,1.000000e+000,10,5,1.150513e-002,0,,0,
1615556104.623,,3.000000e+003,3.000021e+002,-1.396077e-005,1.413555e-008,0.000000e+000,0.000000e+000,2,9.841596e-001,1.825000e+000,,,,,,,,,,,,,,,,,,0,3.000000e+000,1.000000e+000,10,5,3.439331e-002,0,,0,
1615556300.302,,3.500000e+003,3.000033e+002,-1.649816e-005,1.718300e-008,0.000000e+000,0.000000e+000,2,9.839880e-001,1.825000e+000,,,,,,,,,,,,,,,,,,0,3.000000e+000,1.000000e+000,10,5,1.150513e-002,0,,0,
1615556489.492,,4.000000e+003,2.999975e+002,-1.905477e-005,3.201976e-008,0.000000e+000,0.000000e+000,2,9.834075e-001,1.825000e+000,,,,,,,,,,,,,,,,,,0,3.000000e+000,1.000000e+000,10,5,2.301025e-002,0,,0,
1615556681.356,,5.000000e+003,3.000010e+002,-2.417328e-005,2.806383e-008,0.000000e+000,0.000000e+000,2,9.839134e-001,1.825000e+000,,,,,,,,,,,,,,,,,,0,3.000000e+000,1.000000e+000,10,5,1.150513e-002,0,,0,
1615556880.087,,6.000000e+003,3.000033e+002,-2.930086e-005,2.632652e-008,0.000000e+000,0.000000e+000,2,9.834487e-001,1.825000e+000,,,,,,,,,,,,,,,,,,0,3.000000e+000,1.000000e+000,10,5,1.150513e-002,0,,0,
1615557080.187,,7.000000e+003,2.999987e+002,-3.476618e-005,7.663274e-007,0.000000e+000,0.000000e+000,2,9.258550e-001,1.825000e+000,,,,,,,,,,,,,,,,,,0,3.000000e+000,1.000000e+000,10,5,1.150513e-002,0,,0,
1615557259.821,,8.000000e+003,3.000021e+002,-3.958952e-005,5.977309e-008,0.000000e+000,0.000000e+000,2,9.859563e-001,1.825000e+000,,,,,,,,,,,,,,,,,,0,3.000000e+000,1.000000e+000,10,5,1.150513e-002,0,,0,
1615557446.596,,9.000000e+003,3.000056e+002,-4.594362e-005,2.412597e-006,0.000000e+000,0.000000e+000,2,9.554437e-001,1.825000e+000,,,,,,,,,,,,,,,,,,0,3.000000e+000,1.000000e+000,10,5,2.288818e-002,0,,0,
1615557633.138,,1.000000e+004,2.999987e+002,-4.999269e-005,2.619322e-008,0.000000e+000,0.000000e+000,2,9.868270e-001,1.825000e+000,,,,,,,,,,,,,,,,,,0,3.000000e+000,1.000000e+000,10,5,1.150513e-002,0,,0,
1615557824.845,,1.200000e+004,2.999998e+002,-6.137026e-005,2.368822e-006,0.000000e+000,0.000000e+000,2,9.629544e-001,1.825000e+000,,,,,,,,,,,,,,,,,,0,3.000000e+000,1.000000e+000,10,5,1.150513e-002,0,,0,
1615558018.237,,1.400000e+004,2.999987e+002,-7.061650e-005,4.950498e-008,0.000000e+000,0.000000e+000,2,9.862398e-001,1.825000e+000,,,,,,,,,,,,,,,,,,0,3.000000e+000,1.000000e+000,10,5,2.301025e-002,0,,0,
1615558204.105,,1.600000e+004,2.999987e+002,-8.094863e-005,2.251589e-008,0.000000e+000,0.000000e+000,2,9.867267e-001,1.825000e+000,,,,,,,,,,,,,,,,,,0,3.000000e+000,1.000000e+000,10,5,2.301025e-002,0,,0,
1615558391.573,,1.800000e+004,3.000044e+002,-9.132488e-005,5.579547e-008,0.000000e+000,0.000000e+000,2,9.865503e-001,1.825000e+000,,,,,,,,,,,,,,,,,,0,3.000000e+000,1.000000e+000,10,5,2.288818e-002,0,,0,
1615558584.475,,2.000000e+004,2.999964e+002,-1.015863e-004,4.797021e-008,0.000000e+000,0.000000e+000,2,9.866362e-001,1.825000e+000,,,,,,,,,,,,,,,,,,0,3.000000e+000,1.000000e+000,10,5,1.150513e-002,0,,0,
1615558790.654,,2.500000e+004,2.999964e+002,-1.274742e-004,4.787882e-008,0.000000e+000,0.000000e+000,2,9.869404e-001,1.825000e+000,,,,,,,,,,,,,,,,,,0,3.000000e+000,1.000000e+000,10,5,1.150513e-002,0,,0,
1615558997.854,,3.000000e+004,2.999998e+002,-1.532971e-004,2.355853e-008,0.000000e+000,0.000000e+000,2,9.867271e-001,1.825000e+000,,,,,,,,,,,,,,,,,,0,3.000000e+000,1.000000e+000,10,5,2.288818e-002,0,,0,
1615559212.613,,3.500000e+004,2.999998e+002,-1.792022e-004,8.332707e-008,0.000000e+000,0.000000e+000,2,9.867187e-001,1.825000e+000,,,,,,,,,,,,,,,,,,0,3.000000e+000,1.000000e+000,10,5,1.150513e-002,0,,0,
1615559423.573,,4.000000e+004,3.000033e+002,-2.050231e-004,6.284989e-008,0.000000e+000,0.000000e+000,2,9.869037e-001,1.825000e+000,,,,,,,,,,,,,,,,,,0,3.000000e+000,1.000000e+000,10,5,1.150513e-002,0,,0,
1615559634.672,,4.500000e+004,3.000021e+002,-2.309242e-004,9.964531e-008,0.000000e+000,0.000000e+000,2,9.871930e-001,1.825000e+000,,,,,,,,,,,,,,,,,,0,3.000000e+000,1.000000e+000,10,5,1.150513e-002,0,,0,
1615559865.691,,5.000000e+004,3.000033e+002,-2.568305e-004,6.653021e-008,0.000000e+000,0.000000e+000,2,9.872066e-001,1.825000e+000,,,,,,,,,,,,,,,,,,0,3.000000e+000,1.000000e+000,10,5,1.150513e-002,0,,0,
1615560069.701,,4.500000e+004,2.999987e+002,-2.308853e-004,1.011433e-007,0.000000e+000,0.000000e+000,2,9.871486e-001,1.825000e+000,,,,,,,,,,,,,,,,,,0,3.000000e+000,1.000000e+000,10,5,2.301025e-002,0,,0,
1615560279.610,,4.000000e+004,3.000021e+002,-2.049607e-004,7.095952e-008,0.000000e+000,0.000000e+000,2,9.870105e-001,1.825000e+000,,,,,,,,,,,,,,,,,,0,3.000000e+000,1.000000e+000,10,5,1.150513e-002,0,,0,
1615560488.869,,3.500000e+004,2.999987e+002,-1.790584e-004,1.080126e-007,0.000000e+000,0.000000e+000,2,9.872669e-001,1.825000e+000,,,,,,,,,,,,,,,,,,0,3.000000e+000,1.000000e+000,10,5,1.150513e-002,0,,0,
1615560695.979,,3.000000e+004,2.999987e+002,-1.532205e-004,9.225145e-008,0.000000e+000,0.000000e+000,2,9.870077e-001,1.825000e+000,,,,,,,,,,,,,,,,,,0,3.000000e+000,1.000000e+000,10,5,2.301025e-002,0,,0,
1615560904.838,,2.500000e+004,3.000021e+002,-1.273613e-004,8.204343e-008,0.000000e+000,0.000000e+000,2,9.874596e-001,1.825000e+000,,,,,,,,,,,,,,,,,,0,3.000000e+000,1.000000e+000,10,5,1.150513e-002,0,,0,
1615561116.167,,2.000000e+004,3.000010e+002,-1.014600e-004,4.793370e-008,0.000000e+000,0.000000e+000,2,9.878727e-001,1.825000e+000,,,,,,,,,,,,,,,,,,0,3.000000e+000,1.000000e+000,10,5,1.150513e-002,0,,0,
1615561309.496,,1.800000e+004,3.000044e+002,-9.116204e-005,2.962961e-008,0.000000e+000,0.000000e+000,2,9.872112e-001,1.825000e+000,,,,,,,,,,,,,,,,,,0,3.000000e+000,1.000000e+000,10,5,1.150513e-002,0,,0,
1615561507.905,,1.600000e+004,2.999987e+002,-8.082652e-005,1.999029e-008,0.000000e+000,0.000000e+000,2,9.884305e-001,1.825000e+000,,,,,,,,,,,,,,,,,,0,3.000000e+000,1.000000e+000,10,5,3.439331e-002,0,,0,
1615561699.385,,1.400000e+004,3.000010e+002,-7.052011e-005,3.929204e-008,0.000000e+000,0.000000e+000,2,9.882499e-001,1.825000e+000,,,,,,,,,,,,,,,,,,0,3.000000e+000,1.000000e+000,10,5,1.150513e-002,0,,0,
1615561891.744,,1.200000e+004,3.000009e+002,-6.020891e-005,2.125261e-008,0.000000e+000,0.000000e+000,2,9.889700e-001,1.825000e+000,,,,,,,,,,,,,,,,,,0,3.000000e+000,1.000000e+000,10,5,1.150513e-002,0,,0,
1615562081.953,,1.000000e+004,2.999987e+002,-4.991452e-005,3.860364e-008,0.000000e+000,0.000000e+000,2,9.895692e-001,1.825000e+000,,,,,,,,,,,,,,,,,,0,3.000000e+000,1.000000e+000,10,5,1.150513e-002,0,,0,
1615562268.693,,9.000000e+003,3.000010e+002,-4.476428e-005,1.372978e-008,0.000000e+000,0.000000e+000,2,9.893510e-001,1.825000e+000,,,,,,,,,,,,,,,,,,0,3.000000e+000,1.000000e+000,10,5,1.150513e-002,0,,0,
1615562463.472,,8.000000e+003,2.999987e+002,-3.961477e-005,1.269832e-008,0.000000e+000,0.000000e+000,2,9.900459e-001,1.825000e+000,,,,,,,,,,,,,,,,,,0,3.000000e+000,1.000000e+000,10,5,1.150513e-002,0,,0,
1615562662.432,,7.000000e+003,2.999964e+002,-3.448650e-005,5.784966e-009,0.000000e+000,0.000000e+000,2,9.900460e-001,1.825000e+000,,,,,,,,,,,,,,,,,,0,3.000000e+000,1.000000e+000,10,5,1.150513e-002,0,,0,
1615562854.601,,6.000000e+003,3.000021e+002,-2.935508e-005,2.795125e-008,0.000000e+000,0.000000e+000,2,9.903043e-001,1.825000e+000,,,,,,,,,,,,,,,,,,0,3.000000e+000,1.000000e+000,10,5,1.150513e-002,0,,0,
1615563053.660,,5.000000e+003,2.999975e+002,-2.429303e-005,1.436148e-007,0.000000e+000,0.000000e+000,2,9.872487e-001,1.825000e+000,,,,,,,,,,,,,,,,,,0,3.000000e+000,1.000000e+000,10,5,1.150513e-002,0,,0,
1615563273.080,,4.000000e+003,3.000021e+002,-1.910095e-005,1.565842e-008,0.000000e+000,0.000000e+000,2,9.892335e-001,1.825000e+000,,,,,,,,,,,,,,,,,,0,3.000000e+000,1.000000e+000,10,5,2.288818e-002,0,,0,
1615563460.479,,3.500000e+003,2.999987e+002,-1.654517e-005,2.294442e-008,0.000000e+000,0.000000e+000,2,9.888465e-001,1.825000e+000,,,,,,,,,,,,,,,,,,0,3.000000e+000,1.000000e+000,10,5,1.150513e-002,0,,0,
1615563647.908,,3.000000e+003,3.000033e+002,-1.398151e-005,2.074890e-008,0.000000e+000,0.000000e+000,2,9.865892e-001,1.825000e+000,,,,,,,,,,,,,,,,,,0,3.000000e+000,1.000000e+000,10,5,1.150513e-002,0,,0,
1615563841.228,,2.500000e+003,3.000010e+002,-1.141807e-005,1.079690e-008,0.000000e+000,0.000000e+000,2,9.862081e-001,1.825000e+000,,,,,,,,,,,,,,,,,,0,3.000000e+000,1.000000e+000,10,5,2.301025e-002,0,,0,
1615564035.497,,2.000000e+003,2.999952e+002,-8.918511e-006,2.024106e-008,0.000000e+000,0.000000e+000,2,9.797840e-001,1.825000e+000,,,,,,,,,,,,,,,,,,0,3.000000e+000,1.000000e+000,10,5,2.301025e-002,0,,0,
1615564254.097,,1.500000e+003,3.000010e+002,-6.403338e-006,2.701278e-008,0.000000e+000,0.000000e+000,2,9.756823e-001,1.825000e+000,,,,,,,,,,,,,,,,,,0,3.000000e+000,1.000000e+000,10,5,1.150513e-002,0,,0,
1615564550.546,,1.000000e+003,3.000032e+002,-3.963670e-006,3.040883e-008,0.000000e+000,0.000000e+000,2,9.727728e-001,1.825000e+000,,,,,,,,,,,,,,,,,,0,3.000000e+000,1.000000e+000,10,5,1.150513e-002,0,,0,
1615564758.806,,8.000000e+002,3.000044e+002,-2.981132e-006,4.371741e-008,0.000000e+000,0.000000e+000,2,9.543196e-001,1.825000e+000,,,,,,,,,,,,,,,,,,0,3.000000e+000,1.000000e+000,10,5,1.150513e-002,0,,0,
1615564975.265,,6.000000e+002,3.000009e+002,-2.096743e-006,2.064042e-008,0.000000e+000,0.000000e+000,2,9.491349e-001,1.825000e+000,,,,,,,,,,,,,,,,,,0,3.000000e+000,1.000000e+000,10,5,1.150513e-002,0,,0,
1615565210.014,,4.000000e+002,3.000056e+002,-1.183266e-006,1.744733e-008,0.000000e+000,0.000000e+000,2,9.192409e-001,1.825000e+000,,,,,,,,,,,,,,,,,,0,3.000000e+000,1.000000e+000,10,5,1.150513e-002,0,,0,
1615565422.244,,2.000000e+002,3.000032e+002,-3.759337e-007,1.713174e-008,0.000000e+000,0.000000e+000,2,6.772493e-001,1.825000e+000,,,,,,,,,,,,,,,,,,0,3.000000e+000,1.000000e+000,10,5,2.288818e-002,0,,0,
1615565650.643,,0.000000e+000,2.999998e+002,2.958878e-007,4.354050e-008,0.000000e+000,0.000000e+000,2,6.411169e-001,1.825000e+000,,,,,,,,,,,,,,,,,,0,3.000000e+000,1.000000e+000,10,5,1.150513e-002,0,,0,
1615565899.813,,-2.000000e+002,3.000010e+002,8.689724e-007,5.212627e-008,0.000000e+000,0.000000e+000,2,9.166764e-001,1.825000e+000,,,,,,,,,,,,,,,,,,0,3.000000e+000,1.000000e+000,10,5,1.150513e-002,0,,0,
1615566109.583,,-4.000000e+002,3.000033e+002,1.545229e-006,4.384022e-008,0.000000e+000,0.000000e+000,2,9.338747e-001,1.825000e+000,,,,,,,,,,,,,,,,,,0,3.000000e+000,1.000000e+000,10,5,1.150513e-002,0,,0,
1615566349.492,,-6.000000e+002,2.999998e+002,2.325401e-006,2.179219e-008,0.000000e+000,0.000000e+000,2,9.547932e-001,1.825000e+000,,,,,,,,,,,,,,,,,,0,3.000000e+000,1.000000e+000,10,5,1.150513e-002,0,,0,
1615566562.641,,-8.000000e+002,3.000009e+002,3.240254e-006,3.071074e-008,0.000000e+000,0.000000e+000,2,9.727242e-001,1.825000e+000,,,,,,,,,,,,,,,,,,0,3.000000e+000,1.000000e+000,10,5,2.288818e-002,0,,0,
1615566749.690,,-1.000000e+003,2.999952e+002,4.191905e-006,3.087746e-008,0.000000e+000,0.000000e+000,2,9.670265e-001,1.825000e+000,,,,,,,,,,,,,,,,,,0,3.000000e+000,1.000000e+000,10,5,0.000000e+000,0,,0,
1615566945.490,,-1.500000e+003,2.999964e+002,6.600050e-006,9.290583e-009,0.000000e+000,0.000000e+000,2,9.837043e-001,1.825000e+000,,,,,,,,,,,,,,,,,,0,3.000000e+000,1.000000e+000,10,5,1.150513e-002,0,,0,
1615567140.879,,-2.000000e+003,2.999998e+002,9.091716e-006,1.793149e-008,0.000000e+000,0.000000e+000,2,9.858820e-001,1.825000e+000,,,,,,,,,,,,,,,,,,0,3.000000e+000,1.000000e+000,10,5,1.150513e-002,0,,0,
1615567336.848,,-2.500000e+003,2.999975e+002,1.161126e-005,1.789927e-008,0.000000e+000,0.000000e+000,2,9.875093e-001,1.825000e+000,,,,,,,,,,,,,,,,,,0,3.000000e+000,1.000000e+000,10,5,1.150513e-002,0,,0,
1615567532.618,,-3.000000e+003,2.999975e+002,1.414023e-005,1.414737e-008,0.000000e+000,0.000000e+000,2,9.887097e-001,1.825000e+000,,,,,,,,,,,,,,,,,,0,3.000000e+000,1.000000e+000,10,5,1.150513e-002,0,,0,
1615567729.937,,-3.500000e+003,3.000010e+002,1.670375e-005,2.117738e-008,0.000000e+000,0.000000e+000,2,9.877334e-001,1.825000e+000,,,,,,,,,,,,,,,,,,0,3.000000e+000,1.000000e+000,10,5,3.439331e-002,0,,0,
1615567919.596,,-4.000000e+003,3.000010e+002,1.926757e-005,2.150130e-008,0.000000e+000,0.000000e+000,2,9.871891e-001,1.825000e+000,,,,,,,,,,,,,,,,,,0,3.000000e+000,1.000000e+000,10,5,2.301025e-002,0,,0,
1615568111.746,,-5.000000e+003,2.999929e+002,2.439931e-005,3.072116e-008,0.000000e+000,0.000000e+000,2,9.892056e-001,1.825000e+000,,,,,,,,,,,,,,,,,,0,3.000000e+000,1.000000e+000,10,5,1.150513e-002,0,,0,
1615568323.396,,-6.000000e+003,3.000010e+002,2.949275e-005,1.924710e-008,0.000000e+000,0.000000e+000,2,9.903017e-001,1.825000e+000,,,,,,,,,,,,,,,,,,0,3.000000e+000,1.000000e+000,10,5,1.150513e-002,0,,0,
1615568515.355,,-7.000000e+003,2.999964e+002,3.460341e-005,1.569091e-008,0.000000e+000,0.000000e+000,2,9.906281e-001,1.825000e+000,,,,,,,,,,,,,,,,,,0,3.000000e+000,1.000000e+000,10,5,2.301025e-002,0,,0,
1615568702.115,,-8.000000e+003,3.000010e+002,3.973861e-005,2.236415e-008,0.000000e+000,0.000000e+000,2,9.903024e-001,1.825000e+000,,,,,,,,,,,,,,,,,,0,3.000000e+000,1.000000e+000,10,5,1.150513e-002,0,,0,
1615568888.964,,-9.000000e+003,3.000021e+002,4.489195e-005,1.256157e-008,0.000000e+000,0.000000e+000,2,9.904784e-001,1.825000e+000,,,,,,,,,,,,,,,,,,0,3.000000e+000,1.000000e+000,10,5,1.150513e-002,0,,0,
1615569076.373,,-1.000000e+004,3.000044e+002,5.002903e-005,1.966970e-008,0.000000e+000,0.000000e+000,2,9.896154e-001,1.825000e+000,,,,,,,,,,,,,,,,,,0,3.000000e+000,1.000000e+000,10,5,2.288818e-002,0,,0,
1615569267.193,,-1.200000e+004,2.999975e+002,6.033394e-005,2.574042e-008,0.000000e+000,0.000000e+000,2,9.896483e-001,1.825000e+000,,,,,,,,,,,,,,,,,,0,3.000000e+000,1.000000e+000,10,5,2.301025e-002,0,,0,
1615569458.832,,-1.400000e+004,2.999975e+002,7.064905e-005,3.209187e-008,0.000000e+000,0.000000e+000,2,9.895815e-001,1.825000e+000,,,,,,,,,,,,,,,,,,0,3.000000e+000,1.000000e+000,10,5,2.301025e-002,0,,0,
1615569644.072,,-1.600000e+004,3.000033e+002,8.093896e-005,2.967549e-008,0.000000e+000,0.000000e+000,2,9.890752e-001,1.825000e+000,,,,,,,,,,,,,,,,,,0,3.000000e+000,1.000000e+000,10,5,1.150513e-002,0,,0,
1615569837.781,,-1.800000e+004,2.999987e+002,9.125941e-005,3.551772e-008,0.000000e+000,0.000000e+000,2,9.891587e-001,1.825000e+000,,,,,,,,,,,,,,,,,,0,3.000000e+000,1.000000e+000,10,5,1.150513e-002,0,,0,
1615570031.600,,-2.000000e+004,2.999964e+002,1.016042e-004,4.002309e-008,0.000000e+000,0.000000e+000,2,9.890300e-001,1.825000e+000,,,,,,,,,,,,,,,,,,0,3.000000e+000,1.000000e+000,10,5,1.150513e-002,0,,0,
1615570258.610,,-2.500000e+004,2.999987e+002,1.274668e-004,6.316960e-008,0.000000e+000,0.000000e+000,2,9.888871e-001,1.825000e+000,,,,,,,,,,,,,,,,,,0,3.000000e+000,1.000000e+000,10,5,3.439331e-002,0,,0,
1615570466.340,,-3.000000e+004,3.000021e+002,1.533130e-004,5.326709e-008,0.000000e+000,0.000000e+000,2,9.881731e-001,1.825000e+000,,,,,,,,,,,,,,,,,,0,3.000000e+000,1.000000e+000,10,5,1.150513e-002,0,,0,
1615570669.730,,-3.500000e+004,2.999987e+002,1.791947e-004,6.274320e-008,0.000000e+000,0.000000e+000,2,9.886643e-001,1.825000e+000,,,,,,,,,,,,,,,,,,0,3.000000e+000,1.000000e+000,10,5,1.150513e-002,0,,0,
1615570880.589,,-4.000000e+004,2.999987e+002,2.050634e-004,5.236917e-008,0.000000e+000,0.000000e+000,2,9.882175e-001,1.825000e+000,,,,,,,,,,,,,,,,,,0,3.000000e+000,1.000000e+000,10,5,2.301025e-002,0,,0,
1615571086.009,,-4.500000e+004,2.999975e+002,2.309330e-004,3.919488e-008,0.000000e+000,0.000000e+000,2,9.881684e-001,1.825000e+000,,,,,,,,,,,,,,,,,,0,3.000000e+000,1.000000e+000,10,5,2.301025e-002,0,,0,
1615571286.318,,-5.000000e+004,2.999987e+002,2.568624e-004,3.166625e-008,0.000000e+000,0.000000e+000,2,9.881245e-001,1.825000e+000,,,,,,,,,,,,,,,,,,0,3.000000e+000,1.000000e+000,10,5,2.301025e-002,0,,0,
1615571520.478,,-4.500000e+004,2.999975e+002,2.309530e-004,5.613543e-008,0.000000e+000,0.000000e+000,2,9.879526e-001,1.825000e+000,,,,,,,,,,,,,,,,,,0,3.000000e+000,1.000000e+000,10,5,1.150513e-002,0,,0,
1615571737.128,,-4.000000e+004,2.999987e+002,2.050109e-004,3.095687e-008,0.000000e+000,0.000000e+000,2,9.877383e-001,1.825000e+000,,,,,,,,,,,,,,,,,,0,3.000000e+000,1.000000e+000,10,5,2.301025e-002,0,,0,
1615571947.957,,-3.500000e+004,2.999975e+002,1.790615e-004,7.674033e-008,0.000000e+000,0.000000e+000,2,9.880025e-001,1.825000e+000,,,,,,,,,,,,,,,,,,0,3.000000e+000,1.000000e+000,10,5,1.150513e-002,0,,0,
1615572149.197,,-3.000000e+004,2.999975e+002,1.532074e-004,6.444695e-008,0.000000e+000,0.000000e+000,2,9.879979e-001,1.825000e+000,,,,,,,,,,,,,,,,,,0,3.000000e+000,1.000000e+000,10,5,2.301025e-002,0,,0,
1615572356.606,,-2.500000e+004,3.000021e+002,1.273446e-004,5.314998e-008,0.000000e+000,0.000000e+000,2,9.882296e-001,1.825000e+000,,,,,,,,,,,,,,,,,,0,3.000000e+000,1.000000e+000,10,5,2.288818e-002,0,,0,
1615572561.975,,-2.000000e+004,2.999998e+002,1.014810e-004,2.004913e-008,0.000000e+000,0.000000e+000,2,9.886450e-001,1.825000e+000,,,,,,,,,,,,,,,,,,0,3.000000e+000,1.000000e+000,10,5,2.301025e-002,0,,0,
1615572750.105,,-1.800000e+004,3.000010e+002,9.120802e-005,3.528992e-008,0.000000e+000,0.000000e+000,2,9.890814e-001,1.825000e+000,,,,,,,,,,,,,,,,,,0,3.000000e+000,1.000000e+000,10,5,1.150513e-002,0,,0,
1615572943.434,,-1.600000e+004,2.999918e+002,8.085401e-005,2.847579e-008,0.000000e+000,0.000000e+000,2,9.892334e-001,1.825000e+000,,,,,,,,,,,,,,,,,,0,3.000000e+000,1.000000e+000,10,5,2.301025e-002,0,,0,
1615573136.004,,-1.400000e+004,3.000044e+002,7.051769e-005,2.891698e-008,0.000000e+000,0.000000e+000,2,9.896201e-001,1.825000e+000,,,,,,,,,,,,,,,,,,0,3.000000e+000,1.000000e+000,10,5,1.150513e-002,0,,0,
1615573327.012,,-1.200000e+004,3.000010e+002,6.020090e-005,2.285362e-008,0.000000e+000,0.000000e+000,2,9.894622e-001,1.825000e+000,,,,,,,,,,,,,,,,,,0,3.000000e+000,1.000000e+000,10,5,1.150513e-002,0,,0,
1615573517.920,,-1.000000e+004,3.000044e+002,4.992233e-005,2.277385e-008,0.000000e+000,0.000000e+000,2,9.899474e-001,1.825000e+000,,,,,,,,,,,,,,,,,,0,3.000000e+000,1.000000e+000,10,5,1.150513e-002,0,,0,
1615573698.398,,-9.000000e+003,2.999987e+002,4.478342e-005,2.512572e-008,0.000000e+000,0.000000e+000,2,9.903227e-001,1.825000e+000,,,,,,,,,,,,,,,,,,0,3.000000e+000,1.000000e+000,10,5,2.301025e-002,0,,0,
1615573899.497,,-8.000000e+003,2.999963e+002,3.962941e-005,1.443474e-008,0.000000e+000,0.000000e+000,2,9.901739e-001,1.825000e+000,,,,,,,,,,,,,,,,,,0,3.000000e+000,1.000000e+000,10,5,3.439331e-002,0,,0,
1615574098.995,,-7.000000e+003,3.000010e+002,3.448582e-005,2.309708e-008,0.000000e+000,0.000000e+000,2,9.909533e-001,1.825000e+000,,,,,,,,,,,,,,,,,,0,3.000000e+000,1.000000e+000,10,5,1.150513e-002,0,,0,
1615574292.753,,-6.000000e+003,3.000056e+002,2.936809e-005,1.201543e-008,0.000000e+000,0.000000e+000,2,9.908223e-001,1.825000e+000,,,,,,,,,,,,,,,,,,0,3.000000e+000,1.000000e+000,10,5,1.150513e-002,0,,0,
1615574484.701,,-5.000000e+003,3.000044e+002,2.423010e-005,2.027601e-008,0.000000e+000,0.000000e+000,2,9.898913e-001,1.825000e+000,,,,,,,,,,,,,,,,,,0,3.000000e+000,1.000000e+000,10,5,2.288818e-002,0,,0,
1615574682.480,,-4.000000e+003,2.999975e+002,1.909321e-005,2.921408e-008,0.000000e+000,0.000000e+000,2,9.900193e-001,1.825000e+000,,,,,,,,,,,,,,,,,,0,3.000000e+000,1.000000e+000,10,5,1.150513e-002,0,,0,
1615574890.878,,-3.500000e+003,2.999952e+002,1.654254e-005,2.766451e-008,0.000000e+000,0.000000e+000,2,9.888743e-001,1.825000e+000,,,,,,,,,,,,,,,,,,0,3.000000e+000,1.000000e+000,10,5,2.301025e-002,0,,0,
1615575144.996,,-3.000000e+003,3.000033e+002,1.401100e-005,2.310808e-008,0.000000e+000,0.000000e+000,2,9.887335e-001,1.825000e+000,,,,,,,,,,,,,,,,,,0,3.000000e+000,1.000000e+000,10,5,1.150513e-002,0,,0,
1615575376.254,,-2.500000e+003,2.999987e+002,1.144542e-005,4.611119e-008,0.000000e+000,0.000000e+000,2,9.873445e-001,1.825000e+000,,,,,,,,,,,,,,,,,,0,3.000000e+000,1.000000e+000,10,5,1.150513e-002,0,,0,
1615575569.223,,-2.000000e+003,3.000056e+002,8.898742e-006,1.506015e-008,0.000000e+000,0.000000e+000,2,9.816067e-001,1.825000e+000,,,,,,,,,,,,,,,,,,0,3.000000e+000,1.000000e+000,10,5,1.150513e-002,0,,0,
1615575788.351,,-1.500000e+003,3.000021e+002,6.416271e-006,3.828369e-008,0.000000e+000,0.000000e+000,2,9.797874e-001,1.825000e+000,,,,,,,,,,,,,,,,,,0,3.000000e+000,1.000000e+000,10,5,2.288818e-002,0,,0,
1615576007.249,,-1.000000e+003,3.000021e+002,3.955171e-006,3.645409e-008,0.000000e+000,0.000000e+000,2,9.644622e-001,1.825000e+000,,,,,,,,,,,,,,,,,,0,3.000000e+000,1.000000e+000,10,5,2.288818e-002,0,,0,
1615576195.277,,-8.000000e+002,2.999975e+002,3.024810e-006,4.672625e-008,0.000000e+000,0.000000e+000,2,9.586551e-001,1.825000e+000,,,,,,,,,,,,,,,,,,0,3.000000e+000,1.000000e+000,10,5,1.150513e-002,0,,0,
1615576382.515,,-6.000000e+002,2.999987e+002,2.064336e-006,3.231217e-008,0.000000e+000,0.000000e+000,2,9.042159e-001,1.825000e+000,,,,,,,,,,,,,,,,,,0,3.000000e+000,1.000000e+000,10,5,1.150513e-002,0,,0,
1615576569.554,,-4.000000e+002,3.000021e+002,1.167655e-006,3.729087e-008,0.000000e+000,0.000000e+000,2,9.018902e-001,1.825000e+000,,,,,,,,,,,,,,,,,,0,3.000000e+000,1.000000e+000,10,5,1.150513e-002,0,,0,
1615576762.892,,-2.000000e+002,3.000021e+002,3.646698e-007,2.220395e-008,0.000000e+000,0.000000e+000,2,7.474011e-001,1.825000e+000,,,,,,,,,,,,,,,,,,0,3.000000e+000,1.000000e+000,10,5,1.150513e-002,0,,0,
1615576954.821,,0.000000e+000,2.999987e+002,-3.457061e-007,3.551954e-008,0.000000e+000,0.000000e+000,2,7.158371e-001,1.825000e+000,,,,,,,,,,,,,,,,,,0,3.000000e+000,1.000000e+000,10,5,1.150513e-002,0,,0,
1615577147.910,,2.000000e+002,3.000044e+002,-8.670320e-007,3.938343e-008,0.000000e+000,0.000000e+000,2,8.845905e-001,1.825000e+000,,,,,,,,,,,,,,,,,,0,3.000000e+000,1.000000e+000,10,5,1.150513e-002,0,,0,
1615577335.288,,4.000000e+002,3.000044e+002,-1.555095e-006,3.218141e-008,0.000000e+000,0.000000e+000,2,9.259559e-001,1.825000e+000,,,,,,,,,,,,,,,,,,0,3.000000e+000,1.000000e+000,10,5,2.288818e-002,0,,0,
1615577522.507,,6.000000e+002,2.999987e+002,-2.356461e-006,3.383155e-008,0.000000e+000,0.000000e+000,2,9.539076e-001,1.825000e+000,,,,,,,,,,,,,,,,,,0,3.000000e+000,1.000000e+000,10,5,1.150513e-002,0,,0,
1615577708.886,,8.000000e+002,3.000056e+002,-3.227988e-006,5.101654e-008,0.000000e+000,0.000000e+000,2,9.550951e-001,1.825000e+000,,,,,,,,,,,,,,,,,,0,3.000000e+000,1.000000e+000,10,5,3.439331e-002,0,,0,
1615577896.615,,1.000000e+003,2.999998e+002,-4.191839e-006,3.281590e-008,0.000000e+000,0.000000e+000,2,9.704217e-001,1.825000e+000,,,,,,,,,,,,,,,,,,0,3.000000e+000,1.000000e+000,10,5,1.150513e-002,0,,0,
1615578092.873,,1.500000e+003,2.999975e+002,-6.590358e-006,8.854641e-009,0.000000e+000,0.000000e+000,2,9.838284e-001,1.825000e+000,,,,,,,,,,,,,,,,,,0,3.000000e+000,1.000000e+000,10,5,1.150513e-002,0,,0,
1615578288.382,,2.000000e+003,2.999998e+002,-9.067830e-006,7.985557e-009,0.000000e+000,0.000000e+000,2,9.862994e-001,1.825000e+000,,,,,,,,,,,,,,,,,,0,3.000000e+000,1.000000e+000,10,5,1.150513e-002,0,,0,
1615578484.781,,2.500000e+003,3.000044e+002,-1.157860e-005,1.086441e-008,0.000000e+000,0.000000e+000,2,9.877689e-001,1.825000e+000,,,,,,,,,,,,,,,,,,0,3.000000e+000,1.000000e+000,10,5,3.439331e-002,0,,0,
1615578681.800,,3.000000e+003,3.000033e+002,-1.415072e-005,3.519107e-008,0.000000e+000,0.000000e+000,2,9.872556e-001,1.825000e+000,,,,,,,,,,,,,,,,,,0,3.000000e+000,1.000000e+000,10,5,1.150513e-002,0,,0,
1615578878.279,,3.500000e+003,2.999998e+002,-1.666021e-005,2.876809e-008,0.000000e+000,0.000000e+000,2,9.867684e-001,1.825000e+000,,,,,,,,,,,,,,,,,,0,3.000000e+000,1.000000e+000,10,5,2.301025e-002,0,,0,
1615579074.517,,4.000000e+003,2.999998e+002,-1.918231e-005,5.317164e-008,0.000000e+000,0.000000e+000,2,9.895775e-001,1.825000e+000,,,,,,,,,,,,,,,,,,0,3.000000e+000,1.000000e+000,10,5,1.150513e-002,0,,0,
1615579280.656,,5.000000e+003,2.999987e+002,-2.435865e-005,2.075490e-008,0.000000e+000,0.000000e+000,2,9.896770e-001,1.825000e+000,,,,,,,,,,,,,,,,,,0,3.000000e+000,1.000000e+000,10,5,1.150513e-002,0,,0,
1615579479.065,,6.000000e+003,2.999975e+002,-2.949118e-005,1.869723e-008,0.000000e+000,0.000000e+000,2,9.906452e-001,1.825000e+000,,,,,,,,,,,,,,,,,,0,3.000000e+000,1.000000e+000,10,5,1.150513e-002,0,,0,
1615579679.014,,7.000000e+003,2.999987e+002,-3.461050e-005,1.352246e-008,0.000000e+000,0.000000e+000,2,9.903046e-001,1.825000e+000,,,,,,,,,,,,,,,,,,0,3.000000e+000,1.000000e+000,10,5,1.150513e-002,0,,0,
1615579865.312,,8.000000e+003,2.999941e+002,-3.970994e-005,3.925548e-008,0.000000e+000,0.000000e+000,2,9.906304e-001,1.825000e+000,,,,,,,,,,,,,,,,,,0,3.000000e+000,1.000000e+000,10,5,2.301025e-002,0,,0,
1615580051.361,,9.000000e+003,2.999987e+002,-4.485670e-005,1.350808e-008,0.000000e+000,0.000000e+000,2,9.906058e-001,1.825000e+000,,,,,,,,,,,,,,,,,,0,3.000000e+000,1.000000e+000,10,5,2.301025e-002,0,,0,
1615580237.590,,1.000000e+004,2.999975e+002,-5.001431e-005,1.427447e-008,0.000000e+000,0.000000e+000,2,9.903613e-001,1.825000e+000,,,,,,,,,,,,,,,,,,0,3.000000e+000,1.000000e+000,10,5,2.301025e-002,0,,0,
1615580428.449,,1.200000e+004,2.999975e+002,-6.029440e-005,3.780688e-008,0.000000e+000,0.000000e+000,2,9.900121e-001,1.825000e+000,,,,,,,,,,,,,,,,,,0,3.000000e+000,1.000000e+000,10,5,2.288818e-002,0,,0,
1615580620.678,,1.400000e+004,2.999964e+002,-7.062303e-005,3.046730e-008,0.000000e+000,0.000000e+000,2,9.894099e-001,1.825000e+000,,,,,,,,,,,,,,,,,,0,3.000000e+000,1.000000e+000,10,5,2.301025e-002,0,,0,
1615580826.277,,1.600000e+004,3.000033e+002,-8.093455e-005,4.233593e-008,0.000000e+000,0.000000e+000,2,9.891120e-001,1.825000e+000,,,,,,,,,,,,,,,,,,0,3.000000e+000,1.000000e+000,10,5,1.150513e-002,0,,0,
1615581018.966,,1.800000e+004,3.000021e+002,-9.127081e-005,1.839285e-008,0.000000e+000,0.000000e+000,2,9.889346e-001,1.825000e+000,,,,,,,,,,,,,,,,,,0,3.000000e+000,1.000000e+000,10,5,1.150513e-002,0,,0,
1615581212.685,,2.000000e+004,2.999975e+002,-1.015675e-004,2.029781e-008,0.000000e+000,0.000000e+000,2,9.888247e-001,1.825000e+000,,,,,,,,,,,,,,,,,,0,3.000000e+000,1.000000e+000,10,5,1.150513e-002,0,,0,
1615581412.814,,2.500000e+004,2.999952e+002,-1.273868e-004,2.023001e-008,0.000000e+000,0.000000e+000,2,9.887254e-001,1.825000e+000,,,,,,,,,,,,,,,,,,0,3.000000e+000,1.000000e+000,10,5,0.000000e+000,0,,0,
1615581621.503,,3.000000e+004,3.000021e+002,-1.532298e-004,2.744030e-008,0.000000e+000,0.000000e+000,2,9.889313e-001,1.825000e+000,,,,,,,,,,,,,,,,,,0,3.000000e+000,1.000000e+000,10,5,1.150513e-002,0,,0,
1615581831.292,,3.500000e+004,3.000021e+002,-1.791399e-004,4.675248e-008,0.000000e+000,0.000000e+000,2,9.887949e-001,1.825000e+000,,,,,,,,,,,,,,,,,,0,3.000000e+000,1.000000e+000,10,5,1.150513e-002,0,,0,
1615582041.741,,4.000000e+004,2.999987e+002,-2.050328e-004,6.465298e-008,0.000000e+000,0.000000e+000,2,9.883292e-001,1.825000e+000,,,,,,,,,,,,,,,,,,0,3.000000e+000,1.000000e+000,10,5,1.150513e-002,0,,0,
1615582248.170,,4.500000e+004,3.000021e+002,-2.309841e-004,7.908265e-008,0.000000e+000,0.000000e+000,2,9.884905e-001,1.825000e+000,,,,,,,,,,,,,,,,,,0,3.000000e+000,1.000000e+000,10,5,1.150513e-002,0,,0,
1615582455.019,,5.000000e+004,2.999952e+002,-2.568284e-004,2.527343e-008,0.000000e+000,0.000000e+000,2,9.885119e-001,1.825000e+000,,,,,,,,,,,,,,,,,,0,3.000000e+000,1.000000e+000,10,5,2.301025e-002,0,,0,