File: Pd_callibration/callibration_data_300K_hyst.rso.dat.csv
[Header]
TITLE,MPMS RSO Measurement
BYAPP,MPMS Measurement,1.1,Summary
FILEOPENTIME, 1615978445.440000 3/17/2021, 11:54:05 AM

INFO, APPNAME, MPMS MultiVu Application, Revision 1.61,  Build 082

INFO, NAME,
INFO, WEIGHT, 1.000
INFO, AREA, 1.000
INFO, LENGTH, 1.000
INFO, SHAPE, 0
INFO, COMMENT,
INFO, SEQUENCE FILE: H5T_Lin_NoO.seq


INFO, BACKGROUND DATA FILE:, None


STARTUPAXIS,X,4,LINEAR,AUTO,0.000000,0.000000
STARTUPAXIS,Y1,5,LINEAR,AUTO,0.000000,0.000000


STARTUPGROUP,Longitudinal
FIELDGROUP,Longitudinal,1,2,3,4,5,6,7,8,9,10,11,19,20,21,22,23,35
FIELDGROUP,Transverse,1,2,3,4,12,13,14,15,16,17,18,24,25,26,27,28,35

PLOT_APPEARANCE,ALL,HORZ_GRID_ON,VERT_GRID_ON,MARKERS_AND_LINES

[Data]
Time,Comment,Field (Oe),Temperature (K),Long Moment (emu),Long Scan Std Dev,Long Offset (cm),Long Offset Std Dev,Long Algorithm,Long Reg Fit,Long Reg Factor,Trans Moment (emu),Trans Scan Std Dev,Trans Offset (cm),Trans Offset Std Dev,Trans Algorithm,Trans Reg Fit,Trans Reg Factor,Long Moment [w/o ABS] (emu),Long Scan Std Dev [w/o ABS],Long Offset [w/o ABS] (cm),Long Offset Std Dev [w/o ABS],Long Reg Fit [w/o ABS],Trans Moment [w/o ABS] (emu),Trans Scan Std Dev [w/o ABS],Trans Offset [w/o ABS] (cm),Trans Offset Std Dev [w/o ABS],Trans Reg Fit [w/o ABS],RSO Position (deg),Amplitude (cm),Frequency,Cycles to Average,Scans per Measurement,Delta Temp (K),Error,EC Comp. Running,Using ABS,
1615978445.440,,0.000000e+000,2.999998e+002,-2.481191e-005,4.147755e-009,0.000000e+000,0.000000e+000,2,9.834281e-001,1.825000e+000,,,,,,,,,,,,,,,,,,0,3.000000e+000,1.000000e+000,10,5,1.150513e-002,0,,0,
1615978651.210,,2.000000e+002,2.999998e+002,2.590808e-004,5.355955e-009,0.000000e+000,0.000000e+000,2,9.869476e-001,1.825000e+000,,,,,,,,,,,,,,,,,,0,3.000000e+000,1.000000e+000,10,5,2.288818e-002,0,,0,
1615978855.579,,4.000000e+002,2.999998e+002,5.427219e-004,4.460276e-008,0.000000e+000,0.000000e+000,2,9.870608e-001,1.825000e+000,,,,,,,,,,,,,,,,,,0,3.000000e+000,1.000000e+000,10,5,2.301025e-002,0,,0,
1615979040.248,,6.000000e+002,2.999987e+002,8.259173e-004,5.308322e-008,0.000000e+000,0.000000e+000,2,9.870143e-001,1.825000e+000,,,,,,,,,,,,,,,,,,0,3.000000e+000,1.000000e+000,10,5,1.150513e-002,0,,0,
1615979224.427,,8.000000e+002,2.999986e+002,1.107521e-003,2.032499e-006,0.000000e+000,0.000000e+000,2,9.841353e-001,1.825000e+000,,,,,,,,,,,,,,,,,,0,3.000000e+000,1.000000e+000,10,5,3.439331e-002,0,,0,
1615979410.056,,1.000000e+003,3.000067e+002,1.391672e-003,5.596581e-008,0.000000e+000,0.000000e+000,2,9.868565e-001,1.825000e+000,,,,,,,,,,,,,,,,,,0,3.000000e+000,1.000000e+000,10,5,2.288818e-002,0,,0,
1615979618.451,,1.500000e+003,3.000078e+002,2.098202e-003,3.531555e-007,0.000000e+000,0.000000e+000,2,9.868577e-001,1.825000e+000,,,,,,,,,,,,,,,,,,0,3.000000e+000,1.000000e+000,10,5,2.288818e-002,0,,0,
1615979812.478,,2.000000e+003,3.000021e+002,2.803265e-003,1.865056e-007,0.000000e+000,0.000000e+000,2,9.869239e-001,1.825000e+000,,,,,,,,,,,,,,,,,,0,3.000000e+000,1.000000e+000,10,5,2.301025e-002,0,,0,
1615980006.965,,2.500000e+003,2.999987e+002,3.507017e-003,1.513511e-006,0.000000e+000,0.000000e+000,2,9.869884e-001,1.825000e+000,,,,,,,,,,,,,,,,,,0,3.000000e+000,1.000000e+000,10,5,1.150513e-002,0,,0,
1615980208.901,,3.000000e+003,2.999987e+002,4.212216e-003,1.073378e-006,0.000000e+000,0.000000e+000,2,9.871096e-001,1.825000e+000,,,,,,,,,,,,,,,,,,0,3.000000e+000,1.000000e+000,10,5,1.150513e-002,0,,0,
1615980402.642,,3.500000e+003,2.999998e+002,4.915386e-003,8.109212e-007,0.000000e+000,0.000000e+000,2,9.872062e-001,1.825000e+000,,,,,,,,,,,,,,,,,,0,3.000000e+000,1.000000e+000,10,5,1.150513e-002,0,,0,
1615980590.210,,4.000000e+003,3.000078e+002,5.617510e-003,1.678684e-006,0.000000e+000,0.000000e+000,2,9.873045e-001,1.825000e+000,,,,,,,,,,,,,,,,,,0,3.000000e+000,1.000000e+000,10,5,2.288818e-002,0,,0,
1615980786.384,,5.000000e+003,3.000010e+002,7.021835e-003,1.035141e-007,0.000000e+000,0.000000e+000,2,9.875530e-001,1.825000e+000,,,,,,,,,,,,,,,,,,0,3.000000e+000,1.000000e+000,10,5,1.150513e-002,0,,0,
1615981004.628,,6.000000e+003,3.000044e+002,8.427809e-003,1.367355e-006,0.000000e+000,0.000000e+000,2,9.876730e-001,1.825000e+000,,,,,,,,,,,,,,,,,,0,3.000000e+000,1.000000e+000,10,5,1.150513e-002,0,,0,
1615981201.439,,7.000000e+003,2.999998e+002,9.832748e-003,3.364985e-007,0.000000e+000,0.000000e+000,2,9.878353e-001,1.825000e+000,,,,,,,,,,,,,,,,,,0,3.000000e+000,1.000000e+000,10,5,2.288818e-002,0,,0,
1615981392.499,,8.000000e+003,3.000010e+002,1.123319e-002,2.401905e-007,0.000000e+000,0.000000e+000,2,9.879519e-001,1.825000e+000,,,,,,,,,,,,,,,,,,0,3.000000e+000,1.000000e+000,10,5,1.150513e-002,0,,0,
1615981571.038,,9.000000e+003,3.000067e+002,1.263661e-002,4.982076e-007,0.000000e+000,0.000000e+000,2,9.881002e-001,1.825000e+000,,,,,,,,,,,,,,,,,,0,3.000000e+000,1.000000e+000,10,5,0.000000e+000,0,,0,
1615981755.627,,1.000000e+004,3.000044e+002,1.404256e-002,5.662820e-007,0.000000e+000,0.000000e+000,2,9.882378e-001,1.825000e+000,,,,,,,,,,,,,,,,,,0,3.000000e+000,1.000000e+000,10,5,2.288818e-002,0,,0,
1615981945.846,,1.200000e+004,3.000010e+002,1.685701e-002,6.040709e-007,0.000000e+000,0.000000e+000,2,9.883574e-001,1.825000e+000,,,,,,,,,,,,,,,,,,0,3.000000e+000,1.000000e+000,10,5,2.301025e-002,0,,0,
1615982135.596,,1.400000e+004,2.999987e+002,1.967044e-002,9.325953e-007,0.000000e+000,0.000000e+000,2,9.885123e-001,1.825000e+000,,,,,,,,,,,,,,,,,,0,3.000000e+000,1.000000e+000,10,5,2.301025e-002,0,,0,
1615982334.595,,1.600000e+004,3.000009e+002,2.248587e-002,4.856443e-007,0.000000e+000,0.000000e+000,2,9.886698e-001,1.825000e+000,,,,,,,,,,,,,,,,,,0,3.000000e+000,1.000000e+000,10,5,1.150513e-002,0,,0,
1615982531.934,,1.800000e+004,3.000033e+002,2.530472e-002,1.185259e-006,0.000000e+000,0.000000e+000,2,9.888221e-001,1.825000e+000,,,,,,,,,,,,,,,,,,0,3.000000e+000,1.000000e+000,10,5,1.150513e-002,0,,0,
1615982728.653,,2.000000e+004,3.000067e+002,2.812324e-002,1.461074e-006,0.000000e+000,0.000000e+000,2,9.890105e-001,1.825000e+000,,,,,,,,,,,,,,,,,,0,3.000000e+000,1.000000e+000,10,5,2.288818e-002,0,,0,
1615982926.723,,2.500000e+004,3.000021e+002,3.516951e-002,1.412718e-006,0.000000e+000,0.000000e+000,2,9.891598e-001,1.825000e+000,,,,,,,,,,,,,,,,,,0,3.000000e+000,1.000000e+000,10,5,1.150513e-002,0,,0,
1615983147.912,,3.000000e+004,2.999975e+002,4.221924e-002,1.045604e-006,0.000000e+000,0.000000e+000,2,9.892675e-001,1.825000e+000,,,,,,,,,,,,,,,,,,0,3.000000e+000,1.000000e+000,10,5,2.301025e-002,0,,0,
1615983355.291,,3.500000e+004,2.999998e+002,4.927951e-002,2.063179e-006,0.000000e+000,0.000000e+000,2,9.894425e-001,1.825000e+000,,,,,,,,,,,,,,,,,,0,3.000000e+000,1.000000e+000,10,5,1.150513e-002,0,,0,
1615983557.320,,4.000000e+004,2.999987e+002,5.633316e-002,1.257167e-006,0.000000e+000,0.000000e+000,2,9.895799e-001,1.825000e+000,,,,,,,,,,,,,,,,,,0,3.000000e+000,1.000000e+000,10,5,1.150513e-002,0,,0,
1615983760.289,,4.500000e+004,3.000021e+002,6.339475e-002,1.381289e-006,0.000000e+000,0.000000e+000,2,9.897094e-001,1.825000e+000,,,,,,,,,,,,,,,,,,0,3.000000e+000,1.000000e+000,10,5,2.288818e-002,0,,0,
1615983965.109,,5.000000e+004,2.999998e+002,7.046228e-002,1.410971e-006,0.000000e+000,0.000000e+000,2,9.898472e-001,1.825000e+000,,,,,,,,,,,,,,,,,,0,3.000000e+000,1.000000e+000,10,5,1.150513e-002,0,,0,
1615984173.028,,4.500000e+004,2.999987e+002,6.339012e-002,6.187684e-007,0.000000e+000,0.000000e+000,2,9.898412e-001,1.825000e+000,,,,,,,,,,,,,,,,,,0,3.000000e+000,1.000000e+000,10,5,2.301025e-002,0,,0,
1615984380.567,,4.000000e+004,2.999987e+002,5.632304e-002,1.091281e-006,0.000000e+000,0.000000e+000,2,9.898253e-001,1.825000e+000,,,,,,,,,,,,,,,,,,0,3.000000e+000,1.000000e+000,10,5,1.150513e-002,0,,0,
1615984587.916,,3.500000e+004,3.000010e+002,4.925971e-002,2.535677e-006,0.000000e+000,0.000000e+000,2,9.898178e-001,1.825000e+000,,,,,,,,,,,,,,,,,,0,3.000000e+000,1.000000e+000,10,5,1.150513e-002,0,,0,
1615984786.905,,3.000000e+004,3.000021e+002,4.220433e-002,4.878104e-007,0.000000e+000,0.000000e+000,2,9.898109e-001,1.825000e+000,,,,,,,,,,,,,,,,,,0,3.000000e+000,1.000000e+000,10,5,1.150513e-002,0,,0,
1615984991.915,,2.500000e+004,3.000056e+002,3.514862e-002,9.673228e-007,0.000000e+000,0.000000e+000,2,9.898371e-001,1.825000e+000,,,,,,,,,,,,,,,,,,0,3.000000e+000,1.000000e+000,10,5,1.150513e-002,0,,0,
1615985187.914,,2.000000e+004,2.999998e+002,2.810565e-002,5.646158e-007,0.000000e+000,0.000000e+000,2,9.898822e-001,1.825000e+000,,,,,,,,,,,,,,,,,,0,3.000000e+000,1.000000e+000,10,5,1.150513e-002,0,,0,
1615985378.353,,1.800000e+004,2.999964e+002,2.528902e-002,3.207727e-007,0.000000e+000,0.000000e+000,2,9.899234e-001,1.825000e+000,,,,,,,,,,,,,,,,,,0,3.000000e+000,1.000000e+000,10,5,1.150513e-002,0,,0,
1615985574.122,,1.600000e+004,2.999964e+002,2.247082e-002,5.817942e-007,0.000000e+000,0.000000e+000,2,9.899805e-001,1.825000e+000,,,,,,,,,,,,,,,,,,0,3.000000e+000,1.000000e+000,10,5,2.301025e-002,0,,0,
1615985763.202,,1.400000e+004,2.999987e+002,1.965788e-002,3.952748e-007,0.000000e+000,0.000000e+000,2,9.900382e-001,1.825000e+000,,,,,,,,,,,,,,,,,,0,3.000000e+000,1.000000e+000,10,5,1.150513e-002,0,,0,
1615985952.861,,1.200000e+004,3.000010e+002,1.684472e-002,7.607560e-007,0.000000e+000,0.000000e+000,2,9.900975e-001,1.825000e+000,,,,,,,,,,,,,,,,,,0,3.000000e+000,1.000000e+000,10,5,1.150513e-002,0,,0,
1615986141.560,,1.000000e+004,2.999975e+002,1.403234e-002,5.565059e-007,0.000000e+000,0.000000e+000,2,9.901272e-001,1.825000e+000,,,,,,,,,,,,,,,,,,0,3.000000e+000,1.000000e+000,10,5,1.150513e-002,0,,0,
1615986326.379,,9.000000e+003,2.999964e+002,1.262750e-002,2.852589e-007,0.000000e+000,0.000000e+000,2,9.902248e-001,1.825000e+000,,,,,,,,,,,,,,,,,,0,3.000000e+000,1.000000e+000,10,5,1.150513e-002,0,,0,
1615986517.289,,8.000000e+003,2.999975e+002,1.122076e-002,6.337618e-007,0.000000e+000,0.000000e+000,2,9.902579e-001,1.825000e+000,,,,,,,,,,,,,,,,,,0,3.000000e+000,1.000000e+000,10,5,1.150513e-002,0,,0,
1615986723.528,,7.000000e+003,2.999941e+002,9.820879e-003,3.542495e-007,0.000000e+000,0.000000e+000,2,9.903376e-001,1.825000e+000,,,,,,,,,,,,,,,,,,0,3.000000e+000,1.000000e+000,10,5,2.301025e-002,0,,0,
1615986919.787,,6.000000e+003,2.999952e+002,8.414919e-003,5.171042e-007,0.000000e+000,0.000000e+000,2,9.903976e-001,1.825000e+000,,,,,,,,,,,,,,,,,,0,3.000000e+000,1.000000e+000,10,5,2.301025e-002,0,,0,
1615987116.936,,5.000000e+003,2.999998e+002,7.009812e-003,2.993131e-007,0.000000e+000,0.000000e+000,2,9.904789e-001,1.825000e+000,,,,,,,,,,,,,,,,,,0,3.000000e+000,1.000000e+000,10,5,1.150513e-002,0,,0,
1615987306.166,,4.000000e+003,2.999975e+002,5.604628e-003,2.953980e-007,0.000000e+000,0.000000e+000,2,9.905126e-001,1.825000e+000,,,,,,,,,,,,,,,,,,0,3.000000e+000,1.000000e+000,10,5,1.150513e-002,0,,0,
1615987491.315,,3.500000e+003,2.999964e+002,4.902180e-003,3.654137e-007,0.000000e+000,0.000000e+000,2,9.905538e-001,1.825000e+000,,,,,,,,,,,,,,,,,,0,3.000000e+000,1.000000e+000,10,5,2.301025e-002,0,,0,
1615987683.264,,3.000000e+003,2.999952e+002,4.198932e-003,4.108131e-007,0.000000e+000,0.000000e+000,2,9.905856e-001,1.825000e+000,,,,,,,,,,,,,,,,,,0,3.000000e+000,1.000000e+000,10,5,2.301025e-002,0,,0,
1615987875.014,,2.500000e+003,3.000032e+002,3.495924e-003,3.962116e-007,0.000000e+000,0.000000e+000,2,9.906425e-001,1.825000e+000,,,,,,,,,,,,,,,,,,0,3.000000e+000,1.000000e+000,10,5,2.288818e-002,0,,0,
1615988065.513,,2.000000e+003,2.999987e+002,2.792874e-003,3.352140e-007,0.000000e+000,0.000000e+000,2,9.906359e-001,1.825000e+000,,,,,,,,,,,,,,,,,,0,3.000000e+000,1.000000e+000,10,5,1.150513e-002,0,,0,
1615988271.282,,1.500000e+003,3.000010e+002,2.089831e-003,3.209669e-007,0.000000e+000,0.000000e+000,2,9.906335e-001,1.825000e+000,,,,,,,,,,,,,,,,,,0,3.000000e+000,1.000000e+000,10,5,2.301025e-002,0,,0,
1615988462.441,,1.000000e+003,2.999975e+002,1.385078e-003,4.732114e-006,0.000000e+000,0.000000e+000,2,9.854968e-001,1.825000e+000,,,,,,,,,,,,,,,,,,0,3.000000e+000,1.000000e+000,10,5,2.301025e-002,0,,0,
1615988647.281,,8.000000e+002,2.999964e+002,1.104423e-003,3.346197e-007,0.000000e+000,0.000000e+000,2,9.906413e-001,1.825000e+000,,,,,,,,,,,,,,,,,,0,3.000000e+000,1.000000e+000,10,5,1.150513e-002,0,,0,
1615988846.310,,6.000000e+002,2.999952e+002,8.217142e-004,2.076522e-006,0.000000e+000,0.000000e+000,2,9.893363e-001,1.825000e+000,,,,,,,,,,,,,,,,,,0,3.000000e+000,1.000000e+000,10,5,2.301025e-002,0,,0,
1615989030.519,,4.000000e+002,2.999998e+002,5.399422e-004,2.551147e-006,0.000000e+000,0.000000e+000,2,9.862528e-001,1.825000e+000,,,,,,,,,,,,,,,,,,0,3.000000e+000,1.000000e+000,10,5,1.150513e-002,0,,0,
1615989229.519,,2.000000e+002,2.999964e+002,2.587950e-004,1.020742e-006,0.000000e+000,0.000000e+000,2,9.844989e-001,1.825000e+000,,,,,,,,,,,,,,,,,,0,3.000000e+000,1.000000e+000,10,5,3.439331e-002,0,,0,
1615989435.148,,0.000000e+000,2.999987e+002,-2.434770e-005,3.155935e-007,0.000000e+000,0.000000e+000,2,9.838325e-001,1.825000e+000,,,,,,,,,,,,,,,,,,0,3.000000e+000,1.000000e+000,10,5,2.288818e-002,0,,0,
1615989646.967,,-2.000000e+002,2.999998e+002,-3.068261e-004,2.172206e-007,0.000000e+000,0.000000e+000,2,9.908753e-001,1.825000e+000,,,,,,,,,,,,,,,,,,0,3.000000e+000,1.000000e+000,10,5,1.150513e-002,0,,0,
1615989857.307,,-4.000000e+002,3.000010e+002,-5.890990e-004,2.294125e-007,0.000000e+000,0.000000e+000,2,9.908994e-001,1.825000e+000,,,,,,,,,,,,,,,,,,0,3.000000e+000,1.000000e+000,10,5,2.301025e-002,0,,0,
1615990041.796,,-6.000000e+002,2.999987e+002,-8.716360e-004,1.574929e-006,0.000000e+000,0.000000e+000,2,9.888465e-001,1.825000e+000,,,,,,,,,,,,,,,,,,0,3.000000e+000,1.000000e+000,10,5,2.301025e-002,0,,0,
1615990226.115,,-8.000000e+002,2.999987e+002,-1.152503e-003,2.525418e-007,0.000000e+000,0.000000e+000,2,9.908410e-001,1.825000e+000,,,,,,,,,,,,,,,,,,0,3.000000e+000,1.000000e+000,10,5,1.150513e-002,0,,0,
1615990411.775,,-1.000000e+003,3.000021e+002,-1.432925e-003,2.027887e-006,0.000000e+000,0.000000e+000,2,9.905929e-001,1.825000e+000,,,,,,,,,,,,,,,,,,0,3.000000e+000,1.000000e+000,10,5,1.150513e-002,0,,0,
1615990620.144,,-1.500000e+003,3.000021e+002,-2.135589e-003,1.990200e-007,0.000000e+000,0.000000e+000,2,9.907719e-001,1.825000e+000,,,,,,,,,,,,,,,,,,0,3.000000e+000,1.000000e+000,10,5,1.150513e-002,0,,0,
1615990813.083,,-2.000000e+003,3.000044e+002,-2.836306e-003,1.942000e-007,0.000000e+000,0.000000e+000,2,9.907568e-001,1.825000e+000,,,,,,,,,,,,,,,,,,0,3.000000e+000,1.000000e+000,10,5,1.150513e-002,0,,0,
1615991007.083,,-2.500000e+003,2.999952e+002,-3.537273e-003,2.417366e-007,0.000000e+000,0.000000e+000,2,9.907457e-001,1.825000e+000,,,,,,,,,,,,,,,,,,0,3.000000e+000,1.000000e+000,10,5,2.301025e-002,0,,0,
1615991215.872,,-3.000000e+003,3.000021e+002,-4.239109e-003,2.629200e-007,0.000000e+000,0.000000e+000,2,9.907627e-001,1.825000e+000,,,,,,,,,,,,,,,,,,0,3.000000e+000,1.000000e+000,10,5,1.150513e-002,0,,0,
1615991409.531,,-3.500000e+003,2.999998e+002,-4.939623e-003,1.926073e-006,0.000000e+000,0.000000e+000,2,9.907335e-001,1.825000e+000,,,,,,,,,,,,,,,,,,0,3.000000e+000,1.000000e+000,10,5,1.150513e-002,0,,0,
1615991603.291,,-4.000000e+003,2.999975e+002,-5.641582e-003,2.509060e-007,0.000000e+000,0.000000e+000,2,9.907626e-001,1.825000e+000,,,,,,,,,,,,,,,,,,0,3.000000e+000,1.000000e+000,10,5,1.150513e-002,0,,0,
1615991794.230,,-5.000000e+003,3.000044e+002,-7.044855e-003,2.035575e-007,0.000000e+000,0.000000e+000,2,9.907187e-001,1.825000e+000,,,,,,,,,,,,,,,,,,0,3.000000e+000,1.000000e+000,10,5,2.288818e-002,0,,0,
1615992005.899,,-6.000000e+003,3.000021e+002,-8.450158e-003,1.726762e-007,0.000000e+000,0.000000e+000,2,9.907027e-001,1.825000e+000,,,,,,,,,,,,,,,,,,0,3.000000e+000,1.000000e+000,10,5,1.150513e-002,0,,0,
1615992196.789,,-7.000000e+003,3.000021e+002,-9.854420e-003,4.130434e-007,0.000000e+000,0.000000e+000,2,9.906873e-001,1.825000e+000,,,,,,,,,,,,,,,,,,0,3.000000e+000,1.000000e+000,10,5,1.150513e-002,0,,0,
1615992381.618,,-8.000000e+003,3.000010e+002,-1.125267e-002,1.927832e-007,0.000000e+000,0.000000e+000,2,9.906639e-001,1.825000e+000,,,,,,,,,,,,,,,,,,0,3.000000e+000,1.000000e+000,10,5,1.150513e-002,0,,0,
1615992560.017,,-9.000000e+003,2.999987e+002,-1.265748e-002,2.000485e-007,0.000000e+000,0.000000e+000,2,9.906426e-001,1.825000e+000,,,,,,,,,,,,,,,,,,0,3.000000e+000,1.000000e+000,10,5,1.150513e-002,0,,0,
1615992752.207,,-1.000000e+004,2.999975e+002,-1.406409e-002,2.704991e-007,0.000000e+000,0.000000e+000,2,9.906401e-001,1.825000e+000,,,,,,,,,,,,,,,,,,0,3.000000e+000,1.000000e+000,10,5,1.150513e-002,0,,0,
1615992941.936,,-1.200000e+004,2.999964e+002,-1.687344e-002,3.072108e-007,0.000000e+000,0.000000e+000,2,9.906099e-001,1.825000e+000,,,,,,,,,,,,,,,,,,0,3.000000e+000,1.000000e+000,10,5,2.301025e-002,0,,0,
1615993131.826,,-1.400000e+004,2.999998e+002,-1.968736e-002,2.837953e-007,0.000000e+000,0.000000e+000,2,9.905744e-001,1.825000e+000,,,,,,,,,,,,,,,,,,0,3.000000e+000,1.000000e+000,10,5,1.150513e-002,0,,0,
1615993330.185,,-1.600000e+004,2.999964e+002,-2.250426e-002,2.585590e-007,0.000000e+000,0.000000e+000,2,9.905477e-001,1.825000e+000,,,,,,,,,,,,,,,,,,0,3.000000e+000,1.000000e+000,10,5,2.301025e-002,0,,0,
1615993520.924,,-1.800000e+004,2.999929e+002,-2.532126e-002,3.865583e-007,0.000000e+000,0.000000e+000,2,9.905304e-001,1.825000e+000,,,,,,,,,,,,,,,,,,0,3.000000e+000,1.000000e+000,10,5,2.301025e-002,0,,0,
1615993705.954,,-2.000000e+004,2.999975e+002,-2.813510e-002,4.182053e-007,0.000000e+000,0.000000e+000,2,9.905124e-001,1.825000e+000,,,,,,,,,,,,,,,,,,0,3.000000e+000,1.000000e+000,10,5,2.301025e-002,0,,0,
1615993904.963,,-2.500000e+004,2.999987e+002,-3.518298e-002,2.467003e-007,0.000000e+000,0.000000e+000,2,9.904767e-001,1.825000e+000,,,,,,,,,,,,,,,,,,0,3.000000e+000,1.000000e+000,10,5,2.301025e-002,0,,0,
1615994119.772,,-3.000000e+004,3.000033e+002,-4.223220e-002,7.032762e-007,0.000000e+000,0.000000e+000,2,9.904336e-001,1.825000e+000,,,,,,,,,,,,,,,,,,0,3.000000e+000,1.000000e+000,10,5,2.288818e-002,0,,0,
1615994320.301,,-3.500000e+004,3.000033e+002,-4.928989e-002,4.306176e-007,0.000000e+000,0.000000e+000,2,9.904391e-001,1.825000e+000,,,,,,,,,,,,,,,,,,0,3.000000e+000,1.000000e+000,10,5,2.288818e-002,0,,0,
1615994522.631,,-4.000000e+004,2.999964e+002,-5.634657e-002,3.569822e-007,0.000000e+000,0.000000e+000,2,9.904302e-001,1.825000e+000,,,,,,,,,,,,,,,,,,0,3.000000e+000,1.000000e+000,10,5,2.301025e-002,0,,0,
1615994725.681,,-4.500000e+004,2.999975e+002,-6.341005e-002,1.217999e-006,0.000000e+000,0.000000e+000,2,9.904647e-001,1.825000e+000,,,,,,,,,,,,,,,,,,0,3.000000e+000,1.000000e+000,10,5,2.301025e-002,0,,0,
1615994923.670,,-5.000000e+004,2.999998e+002,-7.046858e-002,2.782595e-006,0.000000e+000,0.000000e+000,2,9.904368e-001,1.825000e+000,,,,,,,,,,,,,,,,,,0,3.000000e+000,1.000000e+000,10,5,2.301025e-002,0,,0,
1615995138.529,,-4.500000e+004,2.999952e+002,-6.339411e-002,1.385498e-006,0.000000e+000,0.000000e+000,2,9.903949e-001,1.825000e+000,,,,,,,,,,,,,,,,,,0,3.000000e+000,1.000000e+000,10,5,2.301025e-002,0,,0,
1615995353.259,,-4.000000e+004,3.000044e+002,-5.632483e-002,1.052071e-006,0.000000e+000,0.000000e+000,2,9.903410e-001,1.825000e+000,,,,,,,,,,,,,,,,,,0,3.000000e+000,1.000000e+000,10,5,2.288818e-002,0,,0,
1615995553.808,,-3.500000e+004,2.999964e+002,-4.926616e-002,1.181761e-006,0.000000e+000,0.000000e+000,2,9.903311e-001,1.825000e+000,,,,,,,,,,,,,,,,,,0,3.000000e+000,1.000000e+000,10,5,2.301025e-002,0,,0,
1615995765.326,,-3.000000e+004,2.999975e+002,-4.220672e-002,1.267038e-006,0.000000e+000,0.000000e+000,2,9.903066e-001,1.825000e+000,,,,,,,,,,,,,,,,,,0,3.000000e+000,1.000000e+000,10,5,1.150513e-002,0,,0,
1615995975.745,,-2.500000e+004,2.999964e+002,-3.515163e-002,1.585515e-006,0.000000e+000,0.000000e+000,2,9.903261e-001,1.825000e+000,,,,,,,,,,,,,,,,,,0,3.000000e+000,1.000000e+000,10,5,2.301025e-002,0,,0,
1615996180.084,,-2.000000e+004,2.999987e+002,-2.810671e-002,7.588628e-007,0.000000e+000,0.000000e+000,2,9.903652e-001,1.825000e+000,,,,,,,,,,,,,,,,,,0,3.000000e+000,1.000000e+000,10,5,1.150513e-002,0,,0,
1615996364.174,,-1.800000e+004,2.999941e+002,-2.529217e-002,3.944566e-007,0.000000e+000,0.000000e+000,2,9.903992e-001,1.825000e+000,,,,,,,,,,,,,,,,,,0,3.000000e+000,1.000000e+000,10,5,2.301025e-002,0,,0,
1615996554.053,,-1.600000e+004,3.000032e+002,-2.247506e-002,5.232939e-007,0.000000e+000,0.000000e+000,2,9.903975e-001,1.825000e+000,,,,,,,,,,,,,,,,,,0,3.000000e+000,1.000000e+000,10,5,2.288818e-002,0,,0,
1615996743.692,,-1.400000e+004,2.999987e+002,-1.965981e-002,5.313046e-007,0.000000e+000,0.000000e+000,2,9.904262e-001,1.825000e+000,,,,,,,,,,,,,,,,,,0,3.000000e+000,1.000000e+000,10,5,1.150513e-002,0,,0,
1615996926.092,,-1.200000e+004,2.999952e+002,-1.684642e-002,3.056313e-007,0.000000e+000,0.000000e+000,2,9.904700e-001,1.825000e+000,,,,,,,,,,,,,,,,,,0,3.000000e+000,1.000000e+000,10,5,0.000000e+000,0,,0,
1615997114.691,,-1.000000e+004,2.999975e+002,-1.403406e-002,3.452425e-007,0.000000e+000,0.000000e+000,2,9.905037e-001,1.825000e+000,,,,,,,,,,,,,,,,,,0,3.000000e+000,1.000000e+000,10,5,1.150513e-002,0,,0,
1615997299.021,,-9.000000e+003,3.000056e+002,-1.262834e-002,2.926413e-007,0.000000e+000,0.000000e+000,2,9.905186e-001,1.825000e+000,,,,,,,,,,,,,,,,,,0,3.000000e+000,1.000000e+000,10,5,1.150513e-002,0,,0,
1615997496.680,,-8.000000e+003,3.000010e+002,-1.122156e-002,4.391993e-007,0.000000e+000,0.000000e+000,2,9.905936e-001,1.825000e+000,,,,,,,,,,,,,,,,,,0,3.000000e+000,1.000000e+000,10,5,1.150513e-002,0,,0,
1615997702.599,,-7.000000e+003,2.999975e+002,-9.820565e-003,2.630566e-007,0.000000e+000,0.000000e+000,2,9.906201e-001,1.825000e+000,,,,,,,,,,,,,,,,,,0,3.000000e+000,1.000000e+000,10,5,1.150513e-002,0,,0,
1615997892.349,,-6.000000e+003,3.000010e+002,-8.415148e-003,3.236148e-007,0.000000e+000,0.000000e+000,2,9.906797e-001,1.825000e+000,,,,,,,,,,,,,,,,,,0,3.000000e+000,1.000000e+000,10,5,1.150513e-002,0,,0,
1615998088.438,,-5.000000e+003,3.000021e+002,-7.009344e-003,2.326239e-007,0.000000e+000,0.000000e+000,2,9.906887e-001,1.825000e+000,,,,,,,,,,,,,,,,,,0,3.000000e+000,1.000000e+000,10,5,2.288818e-002,0,,0,
1615998277.597,,-4.000000e+003,2.999987e+002,-5.604722e-003,3.604503e-007,0.000000e+000,0.000000e+000,2,9.907476e-001,1.825000e+000,,,,,,,,,,,,,,,,,,0,3.000000e+000,1.000000e+000,10,5,2.301025e-002,0,,0,
1615998462.427,,-3.500000e+003,2.999929e+002,-4.902154e-003,3.602637e-007,0.000000e+000,0.000000e+000,2,9.907652e-001,1.825000e+000,,,,,,,,,,,,,,,,,,0,3.000000e+000,1.000000e+000,10,5,1.150513e-002,0,,0,
1615998654.776,,-3.000000e+003,2.999987e+002,-4.198886e-003,2.276070e-007,0.000000e+000,0.000000e+000,2,9.907914e-001,1.825000e+000,,,,,,,,,,,,,,,,,,0,3.000000e+000,1.000000e+000,10,5,1.150513e-002,0,,0,
1615998846.985,,-2.500000e+003,2.999987e+002,-3.495891e-003,3.901243e-007,0.000000e+000,0.000000e+000,2,9.908273e-001,1.825000e+000,,,,,,,,,,,,,,,,,,0,3.000000e+000,1.000000e+000,10,5,1.150513e-002,0,,0,
1615999044.915,,-2.000000e+003,3.000009e+002,-2.792645e-003,2.464288e-007,0.000000e+000,0.000000e+000,2,9.908365e-001,1.825000e+000,,,,,,,,,,,,,,,,,,0,3.000000e+000,1.000000e+000,10,5,2.288818e-002,0,,0,
1615999257.193,,-1.500000e+003,3.000010e+002,-2.089435e-003,2.677267e-007,0.000000e+000,0.000000e+000,2,9.908429e-001,1.825000e+000,,,,,,,,,,,,,,,,,,0,3.000000e+000,1.000000e+000,10,5,1.150513e-002,0,,0,
1615999448.291,,-1.000000e+003,2.999975e+002,-1.385890e-003,3.215598e-007,0.000000e+000,0.000000e+000,2,9.908531e-001,1.825000e+000,,,,,,,,,,,,,,,,,,0,3.000000e+000,1.000000e+000,10,5,1.150513e-002,0,,0,
1615999632.430,,-8.000000e+002,2.999975e+002,-1.104368e-003,3.466384e-007,0.000000e+000,0.000000e+000,2,9.908257e-001,1.825000e+000,,,,,,,,,,,,,,,,,,0,3.000000e+000,1.000000e+000,10,5,1.150513e-002,0,,0,
1615999831.338,,-6.000000e+002,2.999998e+002,-8.226519e-004,2.577794e-007,0.000000e+000,0.000000e+000,2,9.908317e-001,1.825000e+000,,,,,,,,,,,,,,,,,,0,3.000000e+000,1.000000e+000,10,5,2.301025e-002,0,,0,
1616000016.856,,-4.000000e+002,2.999952e+002,-5.405745e-004,3.241493e-007,0.000000e+000,0.000000e+000,2,9.907883e-001,1.825000e+000,,,,,,,,,,,,,,,,,,0,3.000000e+000,1.000000e+000,10,5,0.000000e+000,0,,0,
1616000208.034,,-2.000000e+002,3.000044e+002,-2.580930e-004,2.775552e-007,0.000000e+000,0.000000e+000,2,9.905080e-001,1.825000e+000,,,,,,,,,,,,,,,,,,0,3.000000e+000,1.000000e+000,10,5,2.288818e-002,0,,0,
1616000416.422,,0.000000e+000,3.000009e+002,2.417987e-005,2.399748e-007,0.000000e+000,0.000000e+000,2,9.851708e-001,1.825000e+000,,,,,,,,,,,,,,,,,,0,3.000000e+000,1.000000e+000,10,5,1.150513e-002,0,,0,
1616000620.020,,2.000000e+002,3.000021e+002,3.063755e-004,2.278003e-007,0.000000e+000,0.000000e+000,2,9.911659e-001,1.825000e+000,,,,,,,,,,,,,,,,,,0,3.000000e+000,1.000000e+000,10,5,2.288818e-002,0,,0,
1616000811.219,,4.000000e+002,3.000033e+002,5.900690e-004,1.789975e-006,0.000000e+000,0.000000e+000,2,9.889954e-001,1.825000e+000,,,,,,,,,,,,,,,,,,0,3.000000e+000,1.000000e+000,10,5,1.150513e-002,0,,0,
1616001010.447,,6.000000e+002,2.999964e+002,8.707663e-004,3.167398e-007,0.000000e+000,0.000000e+000,2,9.910119e-001,1.825000e+000,,,,,,,,,,,,,,,,,,0,3.000000e+000,1.000000e+000,10,5,2.301025e-002,0,,0,
1616001194.895,,8.000000e+002,2.999964e+002,1.152412e-003,2.649309e-007,0.000000e+000,0.000000e+000,2,9.910177e-001,1.825000e+000,,,,,,,,,,,,,,,,,,0,3.000000e+000,1.000000e+000,10,5,1.150513e-002,0,,0,
1616001386.054,,1.000000e+003,2.999998e+002,1.433767e-003,2.378511e-007,0.000000e+000,0.000000e+000,2,9.910045e-001,1.825000e+000,,,,,,,,,,,,,,,,,,0,3.000000e+000,1.000000e+000,10,5,1.150513e-002,0,,0,
1616001594.592,,1.500000e+003,3.000010e+002,2.135315e-003,2.064414e-007,0.000000e+000,0.000000e+000,2,9.909821e-001,1.825000e+000,,,,,,,,,,,,,,,,,,0,3.000000e+000,1.000000e+000,10,5,1.150513e-002,0,,0,
1616001789.240,,2.000000e+003,2.999952e+002,2.836461e-003,2.787140e-007,0.000000e+000,0.000000e+000,2,9.909597e-001,1.825000e+000,,,,,,,,,,,,,,,,,,0,3.000000e+000,1.000000e+000,10,5,0.000000e+000,0,,0,
1616001983.038,,2.500000e+003,2.999998e+002,3.537363e-003,2.327769e-007,0.000000e+000,0.000000e+000,2,9.909512e-001,1.825000e+000,,,,,,,,,,,,,,,,,,0,3.000000e+000,1.000000e+000,10,5,1.150513e-002,0,,0,
1616002191.216,,3.000000e+003,3.000056e+002,4.238903e-003,1.838062e-007,0.000000e+000,0.000000e+000,2,9.909270e-001,1.825000e+000,,,,,,,,,,,,,,,,,,0,3.000000e+000,1.000000e+000,10,5,1.150513e-002,0,,0,
1616002384.834,,3.500000e+003,3.000010e+002,4.940601e-003,1.827557e-007,0.000000e+000,0.000000e+000,2,9.909236e-001,1.825000e+000,,,,,,,,,,,,,,,,,,0,3.000000e+000,1.000000e+000,10,5,2.301025e-002,0,,0,
1616002579.702,,4.000000e+003,2.999987e+002,5.641862e-003,2.023208e-007,0.000000e+000,0.000000e+000,2,9.909133e-001,1.825000e+000,,,,,,,,,,,,,,,,,,0,3.000000e+000,1.000000e+000,10,5,2.301025e-002,0,,0,
1616002770.191,,5.000000e+003,2.999975e+002,7.045050e-003,2.792742e-007,0.000000e+000,0.000000e+000,2,9.909039e-001,1.825000e+000,,,,,,,,,,,,,,,,,,0,3.000000e+000,1.000000e+000,10,5,2.301025e-002,0,,0,
1616002981.849,,6.000000e+003,2.999998e+002,8.449529e-003,2.145708e-007,0.000000e+000,0.000000e+000,2,9.908724e-001,1.825000e+000,,,,,,,,,,,,,,,,,,0,3.000000e+000,1.000000e+000,10,5,1.150513e-002,0,,0,
1616003178.358,,7.000000e+003,3.000010e+002,9.854162e-003,3.035937e-007,0.000000e+000,0.000000e+000,2,9.908618e-001,1.825000e+000,,,,,,,,,,,,,,,,,,0,3.000000e+000,1.000000e+000,10,5,1.150513e-002,0,,0,
1616003356.777,,8.000000e+003,3.000033e+002,1.125181e-002,3.245429e-007,0.000000e+000,0.000000e+000,2,9.908385e-001,1.825000e+000,,,,,,,,,,,,,,,,,,0,3.000000e+000,1.000000e+000,10,5,1.150513e-002,0,,0,
1616003541.995,,9.000000e+003,3.000021e+002,1.265851e-002,9.940205e-008,0.000000e+000,0.000000e+000,2,9.908194e-001,1.825000e+000,,,,,,,,,,,,,,,,,,0,3.000000e+000,1.000000e+000,10,5,1.150513e-002,0,,0,
1616003727.084,,1.000000e+004,2.999998e+002,1.406193e-002,2.675401e-007,0.000000e+000,0.000000e+000,2,9.908037e-001,1.825000e+000,,,,,,,,,,,,,,,,,,0,3.000000e+000,1.000000e+000,10,5,1.150513e-002,0,,0,
1616003916.473,,1.200000e+004,3.000044e+002,1.687326e-002,3.505375e-007,0.000000e+000,0.000000e+000,2,9.907696e-001,1.825000e+000,,,,,,,,,,,,,,,,,,0,3.000000e+000,1.000000e+000,10,5,2.288818e-002,0,,0,
1616004106.982,,1.400000e+004,3.000033e+002,1.968795e-002,4.096433e-007,0.000000e+000,0.000000e+000,2,9.907680e-001,1.825000e+000,,,,,,,,,,,,,,,,,,0,3.000000e+000,1.000000e+000,10,5,1.150513e-002,0,,0,
1616004310.910,,1.600000e+004,2.999952e+002,2.250389e-002,3.960640e-007,0.000000e+000,0.000000e+000,2,9.907219e-001,1.825000e+000,,,,,,,,,,,,,,,,,,0,3.000000e+000,1.000000e+000,10,5,2.301025e-002,0,,0,
1616004501.579,,1.800000e+004,2.999987e+002,2.531859e-002,3.569141e-007,0.000000e+000,0.000000e+000,2,9.906904e-001,1.825000e+000,,,,,,,,,,,,,,,,,,0,3.000000e+000,1.000000e+000,10,5,2.288818e-002,0,,0,
1616004686.418,,2.000000e+004,2.999998e+002,2.813372e-002,4.604568e-007,0.000000e+000,0.000000e+000,2,9.906597e-001,1.825000e+000,,,,,,,,,,,,,,,,,,0,3.000000e+000,1.000000e+000,10,5,1.150513e-002,0,,0,
1616004891.697,,2.500000e+004,3.000033e+002,3.518347e-002,9.090968e-007,0.000000e+000,0.000000e+000,2,9.906361e-001,1.825000e+000,,,,,,,,,,,,,,,,,,0,3.000000e+000,1.000000e+000,10,5,1.150513e-002,0,,0,
1616005106.435,,3.000000e+004,3.000021e+002,4.222697e-002,2.041917e-006,0.000000e+000,0.000000e+000,2,9.906414e-001,1.825000e+000,,,,,,,,,,,,,,,,,,0,3.000000e+000,1.000000e+000,10,5,2.288818e-002,0,,0,
1616005313.724,,3.500000e+004,2.999975e+002,4.928667e-002,8.298978e-007,0.000000e+000,0.000000e+000,2,9.906763e-001,1.825000e+000,,,,,,,,,,,,,,,,,,0,3.000000e+000,1.000000e+000,10,5,1.150513e-002,0,,0,
1616005522.212,,4.000000e+004,3.000021e+002,5.635240e-002,1.008004e-006,0.000000e+000,0.000000e+000,2,9.906672e-001,1.825000e+000,,,,,,,,,,,,,,,,,,0,3.000000e+000,1.000000e+000,10,5,1.150513e-002,0,,0,
1616005725.391,,4.500000e+004,2.999998e+002,6.341752e-002,1.401774e-006,0.000000e+000,0.000000e+000,2,9.906486e-001,1.825000e+000,,,,,,,,,,,,,,,,,,0,3.000000e+000,1.000000e+000,10,5,1.150513e-002,0,,0,
1616005923.010,,5.000000e+004,2.999975e+002,7.047836e-002,1.581499e-006,0.000000e+000,0.000000e+000,2,9.906456e-001,1.825000e+000,,,,,,,,,,,,,,,,,,0,3.000000e+000,1.000000e+000,10,5,1.150513e-002,0,,0,