File: Pd_callibration/callibration_data_30K_hyst.rso.dat.csv
[Header]
TITLE,MPMS RSO Measurement
BYAPP,MPMS Measurement,1.1,Summary
FILEOPENTIME, 1616061590.267000 3/18/2021, 10:59:50 AM

INFO, APPNAME, MPMS MultiVu Application, Revision 1.61,  Build 082

INFO, NAME,
INFO, WEIGHT, 1.000
INFO, AREA, 1.000
INFO, LENGTH, 1.000
INFO, SHAPE, 0
INFO, COMMENT,
INFO, SEQUENCE FILE: H5T_Lin_NoO.seq


INFO, BACKGROUND DATA FILE:, None


STARTUPAXIS,X,4,LINEAR,AUTO,0.000000,0.000000
STARTUPAXIS,Y1,5,LINEAR,AUTO,0.000000,0.000000


STARTUPGROUP,Longitudinal
FIELDGROUP,Longitudinal,1,2,3,4,5,6,7,8,9,10,11,19,20,21,22,23,35
FIELDGROUP,Transverse,1,2,3,4,12,13,14,15,16,17,18,24,25,26,27,28,35

PLOT_APPEARANCE,ALL,HORZ_GRID_ON,VERT_GRID_ON,MARKERS_AND_LINES

[Data]
Time,Comment,Field (Oe),Temperature (K),Long Moment (emu),Long Scan Std Dev,Long Offset (cm),Long Offset Std Dev,Long Algorithm,Long Reg Fit,Long Reg Factor,Trans Moment (emu),Trans Scan Std Dev,Trans Offset (cm),Trans Offset Std Dev,Trans Algorithm,Trans Reg Fit,Trans Reg Factor,Long Moment [w/o ABS] (emu),Long Scan Std Dev [w/o ABS],Long Offset [w/o ABS] (cm),Long Offset Std Dev [w/o ABS],Long Reg Fit [w/o ABS],Trans Moment [w/o ABS] (emu),Trans Scan Std Dev [w/o ABS],Trans Offset [w/o ABS] (cm),Trans Offset Std Dev [w/o ABS],Trans Reg Fit [w/o ABS],RSO Position (deg),Amplitude (cm),Frequency,Cycles to Average,Scans per Measurement,Delta Temp (K),Error,EC Comp. Running,Using ABS,
1616061590.267,,0.000000e+000,3.000055e+001,-5.203926e-006,3.432574e-009,0.000000e+000,0.000000e+000,2,8.381626e-001,1.825000e+000,,,,,,,,,,,,,,,,,,0,3.000000e+000,1.000000e+000,10,5,2.889633e-003,0,,0,
1616061801.976,,2.000000e+002,3.000055e+001,3.779841e-004,1.126116e-008,0.000000e+000,0.000000e+000,2,8.523441e-001,1.825000e+000,,,,,,,,,,,,,,,,,,0,3.000000e+000,1.000000e+000,10,5,4.339218e-003,0,,0,
1616061994.155,,4.000000e+002,3.000056e+001,7.595117e-004,1.980827e-008,0.000000e+000,0.000000e+000,2,8.521187e-001,1.825000e+000,,,,,,,,,,,,,,,,,,0,3.000000e+000,1.000000e+000,10,5,1.449585e-003,0,,0,
1616062197.843,,6.000000e+002,3.000027e+001,1.140593e-003,5.911689e-008,0.000000e+000,0.000000e+000,2,8.520117e-001,1.825000e+000,,,,,,,,,,,,,,,,,,0,3.000000e+000,1.000000e+000,10,5,1.449585e-003,0,,0,
1616062383.096,,8.000000e+002,3.000012e+001,1.521091e-003,6.441889e-008,0.000000e+000,0.000000e+000,2,8.518004e-001,1.825000e+000,,,,,,,,,,,,,,,,,,0,3.000000e+000,1.000000e+000,10,5,2.899170e-003,0,,0,
1616062568.547,,1.000000e+003,3.000084e+001,1.900145e-003,2.784173e-006,0.000000e+000,0.000000e+000,2,8.514410e-001,1.825000e+000,,,,,,,,,,,,,,,,,,0,3.000000e+000,1.000000e+000,10,5,4.339218e-003,0,,0,
1616062762.125,,1.500000e+003,3.000027e+001,2.848992e-003,1.347779e-007,0.000000e+000,0.000000e+000,2,8.516514e-001,1.825000e+000,,,,,,,,,,,,,,,,,,0,3.000000e+000,1.000000e+000,10,5,1.449585e-003,0,,0,
1616062955.584,,2.000000e+003,3.000041e+001,3.795452e-003,2.438826e-007,0.000000e+000,0.000000e+000,2,8.515983e-001,1.825000e+000,,,,,,,,,,,,,,,,,,0,3.000000e+000,1.000000e+000,10,5,4.339218e-003,0,,0,
1616063164.193,,2.500000e+003,3.000027e+001,4.740591e-003,2.122948e-007,0.000000e+000,0.000000e+000,2,8.515546e-001,1.825000e+000,,,,,,,,,,,,,,,,,,0,3.000000e+000,1.000000e+000,10,5,4.339218e-003,0,,0,
1616063364.503,,3.000000e+003,3.000027e+001,5.685448e-003,3.452902e-007,0.000000e+000,0.000000e+000,2,8.515356e-001,1.825000e+000,,,,,,,,,,,,,,,,,,0,3.000000e+000,1.000000e+000,10,5,1.449585e-003,0,,0,
1616063558.192,,3.500000e+003,2.999983e+001,6.630772e-003,2.076232e-006,0.000000e+000,0.000000e+000,2,8.516144e-001,1.825000e+000,,,,,,,,,,,,,,,,,,0,3.000000e+000,1.000000e+000,10,5,2.899170e-003,0,,0,
1616063752.491,,4.000000e+003,3.000070e+001,7.574168e-003,3.055856e-007,0.000000e+000,0.000000e+000,2,8.514561e-001,1.825000e+000,,,,,,,,,,,,,,,,,,0,3.000000e+000,1.000000e+000,10,5,1.449585e-003,0,,0,
1616063957.491,,5.000000e+003,3.000041e+001,9.464547e-003,6.855866e-007,0.000000e+000,0.000000e+000,2,8.514019e-001,1.825000e+000,,,,,,,,,,,,,,,,,,0,3.000000e+000,1.000000e+000,10,5,2.889633e-003,0,,0,
1616064160.090,,6.000000e+003,3.000084e+001,1.135487e-002,2.701606e-006,0.000000e+000,0.000000e+000,2,8.513275e-001,1.825000e+000,,,,,,,,,,,,,,,,,,0,3.000000e+000,1.000000e+000,10,5,4.339218e-003,0,,0,
1616064358.130,,7.000000e+003,2.999983e+001,1.324698e-002,2.172997e-007,0.000000e+000,0.000000e+000,2,8.513592e-001,1.825000e+000,,,,,,,,,,,,,,,,,,0,3.000000e+000,1.000000e+000,10,5,1.449585e-003,0,,0,
1616064536.259,,8.000000e+003,3.000027e+001,1.512930e-002,5.551973e-007,0.000000e+000,0.000000e+000,2,8.513597e-001,1.825000e+000,,,,,,,,,,,,,,,,,,0,3.000000e+000,1.000000e+000,10,5,1.449585e-003,0,,0,
1616064721.398,,9.000000e+003,3.000113e+001,1.702276e-002,1.302960e-006,0.000000e+000,0.000000e+000,2,8.512444e-001,1.825000e+000,,,,,,,,,,,,,,,,,,0,3.000000e+000,1.000000e+000,10,5,2.889633e-003,0,,0,
1616064900.566,,1.000000e+004,3.000056e+001,1.891038e-002,9.185155e-007,0.000000e+000,0.000000e+000,2,8.509414e-001,1.825000e+000,,,,,,,,,,,,,,,,,,0,3.000000e+000,1.000000e+000,10,5,1.449585e-003,0,,0,
1616065111.684,,1.200000e+004,3.000056e+001,2.270217e-002,2.619766e-007,0.000000e+000,0.000000e+000,2,8.512573e-001,1.825000e+000,,,,,,,,,,,,,,,,,,0,3.000000e+000,1.000000e+000,10,5,1.449585e-003,0,,0,
1616065301.792,,1.400000e+004,3.000027e+001,2.648813e-002,3.238687e-007,0.000000e+000,0.000000e+000,2,8.513077e-001,1.825000e+000,,,,,,,,,,,,,,,,,,0,3.000000e+000,1.000000e+000,10,5,1.449585e-003,0,,0,
1616065485.791,,1.600000e+004,3.000012e+001,3.027343e-002,7.622128e-007,0.000000e+000,0.000000e+000,2,8.513277e-001,1.825000e+000,,,,,,,,,,,,,,,,,,0,3.000000e+000,1.000000e+000,10,5,1.449585e-003,0,,0,
1616065670.529,,1.800000e+004,3.000056e+001,3.406431e-002,7.899965e-007,0.000000e+000,0.000000e+000,2,8.513395e-001,1.825000e+000,,,,,,,,,,,,,,,,,,0,3.000000e+000,1.000000e+000,10,5,1.449585e-003,0,,0,
1616065862.637,,2.000000e+004,3.000012e+001,3.785232e-002,1.199597e-006,0.000000e+000,0.000000e+000,2,8.512177e-001,1.825000e+000,,,,,,,,,,,,,,,,,,0,3.000000e+000,1.000000e+000,10,5,1.449585e-003,0,,0,
1616066081.865,,2.500000e+004,3.000084e+001,4.731406e-002,1.889004e-006,0.000000e+000,0.000000e+000,2,8.511740e-001,1.825000e+000,,,,,,,,,,,,,,,,,,0,3.000000e+000,1.000000e+000,10,5,2.889633e-003,0,,0,
1616066288.472,,3.000000e+004,3.000012e+001,5.678398e-002,1.779677e-006,0.000000e+000,0.000000e+000,2,8.512493e-001,1.825000e+000,,,,,,,,,,,,,,,,,,0,3.000000e+000,1.000000e+000,10,5,1.449585e-003,0,,0,
1616066497.290,,3.500000e+004,3.000084e+001,6.625167e-002,7.741774e-006,0.000000e+000,0.000000e+000,2,8.513776e-001,1.825000e+000,,,,,,,,,,,,,,,,,,0,3.000000e+000,1.000000e+000,10,5,1.449585e-003,0,,0,
1616066705.738,,4.000000e+004,3.000070e+001,7.572124e-002,2.024420e-006,0.000000e+000,0.000000e+000,2,8.514639e-001,1.825000e+000,,,,,,,,,,,,,,,,,,0,3.000000e+000,1.000000e+000,10,5,4.339218e-003,0,,0,
1616066930.036,,4.500000e+004,3.000055e+001,8.517731e-002,2.428578e-006,0.000000e+000,0.000000e+000,2,8.516078e-001,1.825000e+000,,,,,,,,,,,,,,,,,,0,3.000000e+000,1.000000e+000,10,5,2.889633e-003,0,,0,
1616067134.504,,5.000000e+004,3.000127e+001,9.461637e-002,3.255755e-006,0.000000e+000,0.000000e+000,2,8.516839e-001,1.825000e+000,,,,,,,,,,,,,,,,,,0,3.000000e+000,1.000000e+000,10,5,4.339218e-003,0,,0,
1616067342.852,,4.500000e+004,3.000099e+001,8.514987e-002,4.150539e-006,0.000000e+000,0.000000e+000,2,8.514665e-001,1.825000e+000,,,,,,,,,,,,,,,,,,0,3.000000e+000,1.000000e+000,10,5,2.889633e-003,0,,0,
1616067550.650,,4.000000e+004,3.000026e+001,7.568282e-002,3.627004e-006,0.000000e+000,0.000000e+000,2,8.512858e-001,1.825000e+000,,,,,,,,,,,,,,,,,,0,3.000000e+000,1.000000e+000,10,5,4.339218e-003,0,,0,
1616067758.368,,3.500000e+004,3.000041e+001,6.621821e-002,1.865322e-006,0.000000e+000,0.000000e+000,2,8.511254e-001,1.825000e+000,,,,,,,,,,,,,,,,,,0,3.000000e+000,1.000000e+000,10,5,2.889633e-003,0,,0,
1616067963.645,,3.000000e+004,3.000084e+001,5.675397e-002,2.178570e-006,0.000000e+000,0.000000e+000,2,8.511055e-001,1.825000e+000,,,,,,,,,,,,,,,,,,0,3.000000e+000,1.000000e+000,10,5,2.889633e-003,0,,0,
1616068174.553,,2.500000e+004,3.000084e+001,4.728567e-002,7.712048e-007,0.000000e+000,0.000000e+000,2,8.511227e-001,1.825000e+000,,,,,,,,,,,,,,,,,,0,3.000000e+000,1.000000e+000,10,5,2.889633e-003,0,,0,
1616068384.632,,2.000000e+004,3.000157e+001,3.781769e-002,5.192238e-007,0.000000e+000,0.000000e+000,2,8.511952e-001,1.825000e+000,,,,,,,,,,,,,,,,,,0,3.000000e+000,1.000000e+000,10,5,2.889633e-003,0,,0,
1616068575.611,,1.800000e+004,2.999998e+001,3.403337e-002,1.151527e-006,0.000000e+000,0.000000e+000,2,8.512303e-001,1.825000e+000,,,,,,,,,,,,,,,,,,0,3.000000e+000,1.000000e+000,10,5,4.339218e-003,0,,0,
1616068766.330,,1.600000e+004,3.000113e+001,3.024669e-002,1.696238e-006,0.000000e+000,0.000000e+000,2,8.512852e-001,1.825000e+000,,,,,,,,,,,,,,,,,,0,3.000000e+000,1.000000e+000,10,5,2.889633e-003,0,,0,
1616068956.769,,1.400000e+004,3.000056e+001,2.645903e-002,9.389237e-007,0.000000e+000,0.000000e+000,2,8.514205e-001,1.825000e+000,,,,,,,,,,,,,,,,,,0,3.000000e+000,1.000000e+000,10,5,4.339218e-003,0,,0,
1616069161.187,,1.200000e+004,3.000041e+001,2.267193e-002,1.376363e-006,0.000000e+000,0.000000e+000,2,8.514362e-001,1.825000e+000,,,,,,,,,,,,,,,,,,0,3.000000e+000,1.000000e+000,10,5,2.889633e-003,0,,0,
1616069345.316,,1.000000e+004,3.000027e+001,1.888665e-002,9.249989e-007,0.000000e+000,0.000000e+000,2,8.514292e-001,1.825000e+000,,,,,,,,,,,,,,,,,,0,3.000000e+000,1.000000e+000,10,5,2.899170e-003,0,,0,
1616069530.285,,9.000000e+003,3.000084e+001,1.699415e-002,4.592006e-007,0.000000e+000,0.000000e+000,2,8.514883e-001,1.825000e+000,,,,,,,,,,,,,,,,,,0,3.000000e+000,1.000000e+000,10,5,2.889633e-003,0,,0,
1616069708.234,,8.000000e+003,3.000012e+001,1.510203e-002,5.104187e-007,0.000000e+000,0.000000e+000,2,8.512716e-001,1.825000e+000,,,,,,,,,,,,,,,,,,0,3.000000e+000,1.000000e+000,10,5,1.449585e-003,0,,0,
1616069904.903,,7.000000e+003,3.000070e+001,1.321778e-002,2.959093e-006,0.000000e+000,0.000000e+000,2,8.513669e-001,1.825000e+000,,,,,,,,,,,,,,,,,,0,3.000000e+000,1.000000e+000,10,5,2.889633e-003,0,,0,
1616070095.711,,6.000000e+003,3.000084e+001,1.132822e-002,1.162901e-006,0.000000e+000,0.000000e+000,2,8.515025e-001,1.825000e+000,,,,,,,,,,,,,,,,,,0,3.000000e+000,1.000000e+000,10,5,4.339218e-003,0,,0,
1616070308.260,,5.000000e+003,3.000070e+001,9.434291e-003,3.254243e-007,0.000000e+000,0.000000e+000,2,8.513070e-001,1.825000e+000,,,,,,,,,,,,,,,,,,0,3.000000e+000,1.000000e+000,10,5,2.889633e-003,0,,0,
1616070510.859,,4.000000e+003,3.000099e+001,7.542301e-003,1.390297e-006,0.000000e+000,0.000000e+000,2,8.512844e-001,1.825000e+000,,,,,,,,,,,,,,,,,,0,3.000000e+000,1.000000e+000,10,5,2.889633e-003,0,,0,
1616070697.527,,3.500000e+003,3.000070e+001,6.597790e-003,6.794566e-007,0.000000e+000,0.000000e+000,2,8.515904e-001,1.825000e+000,,,,,,,,,,,,,,,,,,0,3.000000e+000,1.000000e+000,10,5,5.790710e-003,0,,0,
1616070883.187,,3.000000e+003,3.000027e+001,5.650171e-003,2.038492e-006,0.000000e+000,0.000000e+000,2,8.513661e-001,1.825000e+000,,,,,,,,,,,,,,,,,,0,3.000000e+000,1.000000e+000,10,5,2.899170e-003,0,,0,
1616071075.425,,2.500000e+003,3.000012e+001,4.704957e-003,3.100844e-007,0.000000e+000,0.000000e+000,2,8.515613e-001,1.825000e+000,,,,,,,,,,,,,,,,,,0,3.000000e+000,1.000000e+000,10,5,1.449585e-003,0,,0,
1616071267.994,,2.000000e+003,3.000099e+001,3.758105e-003,6.903495e-007,0.000000e+000,0.000000e+000,2,8.515413e-001,1.825000e+000,,,,,,,,,,,,,,,,,,0,3.000000e+000,1.000000e+000,10,5,4.339218e-003,0,,0,
1616071460.033,,1.500000e+003,3.000070e+001,2.812703e-003,1.541285e-006,0.000000e+000,0.000000e+000,2,8.519288e-001,1.825000e+000,,,,,,,,,,,,,,,,,,0,3.000000e+000,1.000000e+000,10,5,4.339218e-003,0,,0,
1616071665.521,,1.000000e+003,3.000099e+001,1.865064e-003,2.408374e-007,0.000000e+000,0.000000e+000,2,8.525215e-001,1.825000e+000,,,,,,,,,,,,,,,,,,0,3.000000e+000,1.000000e+000,10,5,0.000000e+000,0,,0,
1616071851.540,,8.000000e+002,3.000099e+001,1.486101e-003,6.790247e-007,0.000000e+000,0.000000e+000,2,8.528040e-001,1.825000e+000,,,,,,,,,,,,,,,,,,0,3.000000e+000,1.000000e+000,10,5,2.889633e-003,0,,0,
1616072037.539,,6.000000e+002,3.000113e+001,1.106713e-003,1.070229e-006,0.000000e+000,0.000000e+000,2,8.515725e-001,1.825000e+000,,,,,,,,,,,,,,,,,,0,3.000000e+000,1.000000e+000,10,5,2.889633e-003,0,,0,
1616072222.248,,4.000000e+002,3.000070e+001,7.276890e-004,4.441764e-007,0.000000e+000,0.000000e+000,2,8.531928e-001,1.825000e+000,,,,,,,,,,,,,,,,,,0,3.000000e+000,1.000000e+000,10,5,2.889633e-003,0,,0,
1616072422.597,,2.000000e+002,3.000041e+001,3.482245e-004,3.952524e-007,0.000000e+000,0.000000e+000,2,8.537339e-001,1.825000e+000,,,,,,,,,,,,,,,,,,0,3.000000e+000,1.000000e+000,10,5,2.889633e-003,0,,0,
1616072666.855,,0.000000e+000,3.000041e+001,-3.221213e-005,6.628663e-007,0.000000e+000,0.000000e+000,2,8.336825e-001,1.825000e+000,,,,,,,,,,,,,,,,,,0,3.000000e+000,1.000000e+000,10,5,2.889633e-003,0,,0,
1616072872.364,,-2.000000e+002,3.000041e+001,-4.126207e-004,3.745900e-007,0.000000e+000,0.000000e+000,2,8.510790e-001,1.825000e+000,,,,,,,,,,,,,,,,,,0,3.000000e+000,1.000000e+000,10,5,1.449585e-003,0,,0,
1616073078.783,,-4.000000e+002,2.999998e+001,-7.928357e-004,4.035040e-007,0.000000e+000,0.000000e+000,2,8.516269e-001,1.825000e+000,,,,,,,,,,,,,,,,,,0,3.000000e+000,1.000000e+000,10,5,1.449585e-003,0,,0,
1616073263.632,,-6.000000e+002,3.000113e+001,-1.171987e-003,4.522230e-007,0.000000e+000,0.000000e+000,2,8.519275e-001,1.825000e+000,,,,,,,,,,,,,,,,,,0,3.000000e+000,1.000000e+000,10,5,2.889633e-003,0,,0,
1616073448.452,,-8.000000e+002,3.000041e+001,-1.550834e-003,4.818916e-007,0.000000e+000,0.000000e+000,2,8.520488e-001,1.825000e+000,,,,,,,,,,,,,,,,,,0,3.000000e+000,1.000000e+000,10,5,2.889633e-003,0,,0,
1616073634.921,,-1.000000e+003,2.999998e+001,-1.929696e-003,1.441905e-006,0.000000e+000,0.000000e+000,2,8.520426e-001,1.825000e+000,,,,,,,,,,,,,,,,,,0,3.000000e+000,1.000000e+000,10,5,4.339218e-003,0,,0,
1616073854.567,,-1.500000e+003,3.000026e+001,-2.874881e-003,3.265316e-007,0.000000e+000,0.000000e+000,2,8.522204e-001,1.825000e+000,,,,,,,,,,,,,,,,,,0,3.000000e+000,1.000000e+000,10,5,4.339218e-003,0,,0,
1616074048.668,,-2.000000e+003,3.000099e+001,-3.818000e-003,7.013885e-007,0.000000e+000,0.000000e+000,2,8.522372e-001,1.825000e+000,,,,,,,,,,,,,,,,,,0,3.000000e+000,1.000000e+000,10,5,2.889633e-003,0,,0,
1616074236.374,,-2.500000e+003,3.000113e+001,-4.761189e-003,5.253920e-007,0.000000e+000,0.000000e+000,2,8.523072e-001,1.825000e+000,,,,,,,,,,,,,,,,,,0,3.000000e+000,1.000000e+000,10,5,2.889633e-003,0,,0,
1616074431.344,,-3.000000e+003,3.000056e+001,-5.705644e-003,1.231626e-006,0.000000e+000,0.000000e+000,2,8.524049e-001,1.825000e+000,,,,,,,,,,,,,,,,,,0,3.000000e+000,1.000000e+000,10,5,1.449585e-003,0,,0,
1616074625.206,,-3.500000e+003,3.000113e+001,-6.648369e-003,1.995970e-006,0.000000e+000,0.000000e+000,2,8.523206e-001,1.825000e+000,,,,,,,,,,,,,,,,,,0,3.000000e+000,1.000000e+000,10,5,4.339218e-003,0,,0,
1616074820.789,,-4.000000e+003,3.000041e+001,-7.593603e-003,2.722964e-007,0.000000e+000,0.000000e+000,2,8.522124e-001,1.825000e+000,,,,,,,,,,,,,,,,,,0,3.000000e+000,1.000000e+000,10,5,4.339218e-003,0,,0,
1616075026.402,,-5.000000e+003,3.000084e+001,-9.486572e-003,1.206277e-006,0.000000e+000,0.000000e+000,2,8.523830e-001,1.825000e+000,,,,,,,,,,,,,,,,,,0,3.000000e+000,1.000000e+000,10,5,4.339218e-003,0,,0,
1616075223.453,,-6.000000e+003,3.000012e+001,-1.137622e-002,1.867859e-007,0.000000e+000,0.000000e+000,2,8.523630e-001,1.825000e+000,,,,,,,,,,,,,,,,,,0,3.000000e+000,1.000000e+000,10,5,2.899170e-003,0,,0,
1616075420.994,,-7.000000e+003,3.000113e+001,-1.327069e-002,2.098216e-006,0.000000e+000,0.000000e+000,2,8.523217e-001,1.825000e+000,,,,,,,,,,,,,,,,,,0,3.000000e+000,1.000000e+000,10,5,1.440048e-003,0,,0,
1616075604.943,,-8.000000e+003,3.000056e+001,-1.515385e-002,1.354640e-006,0.000000e+000,0.000000e+000,2,8.523992e-001,1.825000e+000,,,,,,,,,,,,,,,,,,0,3.000000e+000,1.000000e+000,10,5,1.449585e-003,0,,0,
1616075784.107,,-9.000000e+003,3.000084e+001,-1.704429e-002,2.369747e-006,0.000000e+000,0.000000e+000,2,8.523046e-001,1.825000e+000,,,,,,,,,,,,,,,,,,0,3.000000e+000,1.000000e+000,10,5,1.449585e-003,0,,0,
1616075969.665,,-1.000000e+004,3.000084e+001,-1.893859e-002,5.554096e-007,0.000000e+000,0.000000e+000,2,8.524520e-001,1.825000e+000,,,,,,,,,,,,,,,,,,0,3.000000e+000,1.000000e+000,10,5,2.889633e-003,0,,0,
1616076174.742,,-1.200000e+004,3.000041e+001,-2.272811e-002,6.915633e-007,0.000000e+000,0.000000e+000,2,8.523801e-001,1.825000e+000,,,,,,,,,,,,,,,,,,0,3.000000e+000,1.000000e+000,10,5,2.889633e-003,0,,0,
1616076366.352,,-1.400000e+004,3.000041e+001,-2.651961e-002,1.802761e-006,0.000000e+000,0.000000e+000,2,8.523980e-001,1.825000e+000,,,,,,,,,,,,,,,,,,0,3.000000e+000,1.000000e+000,10,5,1.449585e-003,0,,0,
1616076551.087,,-1.600000e+004,2.999998e+001,-3.030716e-002,8.237099e-007,0.000000e+000,0.000000e+000,2,8.524448e-001,1.825000e+000,,,,,,,,,,,,,,,,,,0,3.000000e+000,1.000000e+000,10,5,2.899170e-003,0,,0,
1616076743.358,,-1.800000e+004,3.000084e+001,-3.409773e-002,8.529898e-007,0.000000e+000,0.000000e+000,2,8.525245e-001,1.825000e+000,,,,,,,,,,,,,,,,,,0,3.000000e+000,1.000000e+000,10,5,2.889633e-003,0,,0,
1616076942.216,,-2.000000e+004,3.000157e+001,-3.789053e-002,5.415410e-006,0.000000e+000,0.000000e+000,2,8.523772e-001,1.825000e+000,,,,,,,,,,,,,,,,,,0,3.000000e+000,1.000000e+000,10,5,1.440048e-003,0,,0,
1616077162.240,,-2.500000e+004,3.000070e+001,-4.735822e-002,1.878772e-006,0.000000e+000,0.000000e+000,2,8.525161e-001,1.825000e+000,,,,,,,,,,,,,,,,,,0,3.000000e+000,1.000000e+000,10,5,1.449585e-003,0,,0,
1616077369.079,,-3.000000e+004,3.000113e+001,-5.683879e-002,6.401920e-007,0.000000e+000,0.000000e+000,2,8.528304e-001,1.825000e+000,,,,,,,,,,,,,,,,,,0,3.000000e+000,1.000000e+000,10,5,2.889633e-003,0,,0,
1616077569.795,,-3.500000e+004,3.000070e+001,-6.631401e-002,2.393684e-006,0.000000e+000,0.000000e+000,2,8.528099e-001,1.825000e+000,,,,,,,,,,,,,,,,,,0,3.000000e+000,1.000000e+000,10,5,4.339218e-003,0,,0,
1616077772.265,,-4.000000e+004,3.000070e+001,-7.577455e-002,4.237776e-006,0.000000e+000,0.000000e+000,2,8.527441e-001,1.825000e+000,,,,,,,,,,,,,,,,,,0,3.000000e+000,1.000000e+000,10,5,4.339218e-003,0,,0,
1616077990.084,,-4.500000e+004,3.000099e+001,-8.525456e-002,6.799417e-006,0.000000e+000,0.000000e+000,2,8.522550e-001,1.825000e+000,,,,,,,,,,,,,,,,,,0,3.000000e+000,1.000000e+000,10,5,2.889633e-003,0,,0,
1616078195.575,,-5.000000e+004,3.000128e+001,-9.471613e-002,6.113401e-006,0.000000e+000,0.000000e+000,2,8.528743e-001,1.825000e+000,,,,,,,,,,,,,,,,,,0,3.000000e+000,1.000000e+000,10,5,2.889633e-003,0,,0,
1616078403.458,,-4.500000e+004,3.000113e+001,-8.523009e-002,2.544496e-006,0.000000e+000,0.000000e+000,2,8.526207e-001,1.825000e+000,,,,,,,,,,,,,,,,,,0,3.000000e+000,1.000000e+000,10,5,2.889633e-003,0,,0,
1616078610.933,,-4.000000e+004,3.000055e+001,-7.575276e-002,8.203086e-007,0.000000e+000,0.000000e+000,2,8.524489e-001,1.825000e+000,,,,,,,,,,,,,,,,,,0,3.000000e+000,1.000000e+000,10,5,4.339218e-003,0,,0,
1616078817.352,,-3.500000e+004,3.000142e+001,-6.627853e-002,3.339184e-006,0.000000e+000,0.000000e+000,2,8.523687e-001,1.825000e+000,,,,,,,,,,,,,,,,,,0,3.000000e+000,1.000000e+000,10,5,4.339218e-003,0,,0,
1616079029.625,,-3.000000e+004,3.000041e+001,-5.680590e-002,1.421033e-006,0.000000e+000,0.000000e+000,2,8.523234e-001,1.825000e+000,,,,,,,,,,,,,,,,,,0,3.000000e+000,1.000000e+000,10,5,2.899170e-003,0,,0,
1616079233.987,,-2.500000e+004,3.000041e+001,-4.733242e-002,3.793980e-006,0.000000e+000,0.000000e+000,2,8.523856e-001,1.825000e+000,,,,,,,,,,,,,,,,,,0,3.000000e+000,1.000000e+000,10,5,4.339218e-003,0,,0,
1616079437.498,,-2.000000e+004,3.000084e+001,-3.785662e-002,3.887341e-006,0.000000e+000,0.000000e+000,2,8.523260e-001,1.825000e+000,,,,,,,,,,,,,,,,,,0,3.000000e+000,1.000000e+000,10,5,2.889633e-003,0,,0,
1616079628.102,,-1.800000e+004,3.000099e+001,-3.406475e-002,1.602896e-006,0.000000e+000,0.000000e+000,2,8.520510e-001,1.825000e+000,,,,,,,,,,,,,,,,,,0,3.000000e+000,1.000000e+000,10,5,2.889633e-003,0,,0,
1616079821.011,,-1.600000e+004,3.000041e+001,-3.027081e-002,4.387726e-006,0.000000e+000,0.000000e+000,2,8.520302e-001,1.825000e+000,,,,,,,,,,,,,,,,,,0,3.000000e+000,1.000000e+000,10,5,2.889633e-003,0,,0,
1616080010.891,,-1.400000e+004,3.000041e+001,-2.647645e-002,1.017631e-006,0.000000e+000,0.000000e+000,2,8.520821e-001,1.825000e+000,,,,,,,,,,,,,,,,,,0,3.000000e+000,1.000000e+000,10,5,2.899170e-003,0,,0,
1616080213.630,,-1.200000e+004,3.000055e+001,-2.268494e-002,4.396869e-007,0.000000e+000,0.000000e+000,2,8.521017e-001,1.825000e+000,,,,,,,,,,,,,,,,,,0,3.000000e+000,1.000000e+000,10,5,2.889633e-003,0,,0,
1616080403.240,,-1.000000e+004,3.000055e+001,-1.889428e-002,2.532358e-007,0.000000e+000,0.000000e+000,2,8.521571e-001,1.825000e+000,,,,,,,,,,,,,,,,,,0,3.000000e+000,1.000000e+000,10,5,2.889633e-003,0,,0,
1616080594.419,,-9.000000e+003,3.000041e+001,-1.699917e-002,6.360926e-007,0.000000e+000,0.000000e+000,2,8.522059e-001,1.825000e+000,,,,,,,,,,,,,,,,,,0,3.000000e+000,1.000000e+000,10,5,1.449585e-003,0,,0,
1616080780.188,,-8.000000e+003,3.000027e+001,-1.510748e-002,4.712580e-007,0.000000e+000,0.000000e+000,2,8.521751e-001,1.825000e+000,,,,,,,,,,,,,,,,,,0,3.000000e+000,1.000000e+000,10,5,2.889633e-003,0,,0,
1616080984.327,,-7.000000e+003,3.000084e+001,-1.321865e-002,5.587654e-007,0.000000e+000,0.000000e+000,2,8.522048e-001,1.825000e+000,,,,,,,,,,,,,,,,,,0,3.000000e+000,1.000000e+000,10,5,2.889633e-003,0,,0,
1616081181.227,,-6.000000e+003,3.000084e+001,-1.132626e-002,5.289668e-007,0.000000e+000,0.000000e+000,2,8.521920e-001,1.825000e+000,,,,,,,,,,,,,,,,,,0,3.000000e+000,1.000000e+000,10,5,2.889633e-003,0,,0,
1616081392.806,,-5.000000e+003,2.999998e+001,-9.434249e-003,2.749055e-007,0.000000e+000,0.000000e+000,2,8.521737e-001,1.825000e+000,,,,,,,,,,,,,,,,,,0,3.000000e+000,1.000000e+000,10,5,1.449585e-003,0,,0,
1616081588.965,,-4.000000e+003,3.000113e+001,-7.542200e-003,1.210463e-006,0.000000e+000,0.000000e+000,2,8.522208e-001,1.825000e+000,,,,,,,,,,,,,,,,,,0,3.000000e+000,1.000000e+000,10,5,2.889633e-003,0,,0,
1616081780.764,,-3.500000e+003,3.000070e+001,-6.595880e-003,2.690387e-007,0.000000e+000,0.000000e+000,2,8.522082e-001,1.825000e+000,,,,,,,,,,,,,,,,,,0,3.000000e+000,1.000000e+000,10,5,1.449585e-003,0,,0,
1616081972.714,,-3.000000e+003,2.999998e+001,-5.649646e-003,4.553163e-007,0.000000e+000,0.000000e+000,2,8.521472e-001,1.825000e+000,,,,,,,,,,,,,,,,,,0,3.000000e+000,1.000000e+000,10,5,4.339218e-003,0,,0,
1616082166.053,,-2.500000e+003,3.000056e+001,-4.702324e-003,3.456874e-007,0.000000e+000,0.000000e+000,2,8.518705e-001,1.825000e+000,,,,,,,,,,,,,,,,,,0,3.000000e+000,1.000000e+000,10,5,2.889633e-003,0,,0,
1616082357.972,,-2.000000e+003,3.000012e+001,-3.756653e-003,5.484874e-007,0.000000e+000,0.000000e+000,2,8.518560e-001,1.825000e+000,,,,,,,,,,,,,,,,,,0,3.000000e+000,1.000000e+000,10,5,2.899170e-003,0,,0,
1616082549.922,,-1.500000e+003,3.000128e+001,-2.810428e-003,3.710991e-007,0.000000e+000,0.000000e+000,2,8.519819e-001,1.825000e+000,,,,,,,,,,,,,,,,,,0,3.000000e+000,1.000000e+000,10,5,1.440048e-003,0,,0,
1616082755.741,,-1.000000e+003,3.000128e+001,-1.864155e-003,3.974935e-007,0.000000e+000,0.000000e+000,2,8.521545e-001,1.825000e+000,,,,,,,,,,,,,,,,,,0,3.000000e+000,1.000000e+000,10,5,2.889633e-003,0,,0,
1616082940.540,,-8.000000e+002,3.000027e+001,-1.485442e-003,4.877610e-007,0.000000e+000,0.000000e+000,2,8.523825e-001,1.825000e+000,,,,,,,,,,,,,,,,,,0,3.000000e+000,1.000000e+000,10,5,2.899170e-003,0,,0,
1616083125.659,,-6.000000e+002,3.000012e+001,-1.106565e-003,4.856371e-007,0.000000e+000,0.000000e+000,2,8.525357e-001,1.825000e+000,,,,,,,,,,,,,,,,,,0,3.000000e+000,1.000000e+000,10,5,2.899170e-003,0,,0,
1616083311.129,,-4.000000e+002,3.000070e+001,-7.274076e-004,4.900128e-007,0.000000e+000,0.000000e+000,2,8.528270e-001,1.825000e+000,,,,,,,,,,,,,,,,,,0,3.000000e+000,1.000000e+000,10,5,2.889633e-003,0,,0,
1616083510.668,,-2.000000e+002,3.000041e+001,-3.479509e-004,5.627492e-007,0.000000e+000,0.000000e+000,2,8.534968e-001,1.825000e+000,,,,,,,,,,,,,,,,,,0,3.000000e+000,1.000000e+000,10,5,2.889633e-003,0,,0,
1616083733.767,,0.000000e+000,3.000128e+001,3.269945e-005,4.462941e-007,0.000000e+000,0.000000e+000,2,8.352022e-001,1.825000e+000,,,,,,,,,,,,,,,,,,0,3.000000e+000,1.000000e+000,10,5,2.889633e-003,0,,0,
1616083938.016,,2.000000e+002,3.000012e+001,4.124951e-004,3.603124e-007,0.000000e+000,0.000000e+000,2,8.509285e-001,1.825000e+000,,,,,,,,,,,,,,,,,,0,3.000000e+000,1.000000e+000,10,5,1.449585e-003,0,,0,
1616084130.076,,4.000000e+002,3.000027e+001,7.929028e-004,3.608152e-007,0.000000e+000,0.000000e+000,2,8.515483e-001,1.825000e+000,,,,,,,,,,,,,,,,,,0,3.000000e+000,1.000000e+000,10,5,1.449585e-003,0,,0,
1616084333.155,,6.000000e+002,3.000056e+001,1.171469e-003,3.406585e-007,0.000000e+000,0.000000e+000,2,8.517243e-001,1.825000e+000,,,,,,,,,,,,,,,,,,0,3.000000e+000,1.000000e+000,10,5,1.449585e-003,0,,0,
1616084518.394,,8.000000e+002,3.000070e+001,1.550440e-003,3.996603e-007,0.000000e+000,0.000000e+000,2,8.518701e-001,1.825000e+000,,,,,,,,,,,,,,,,,,0,3.000000e+000,1.000000e+000,10,5,2.889633e-003,0,,0,
1616084710.114,,1.000000e+003,3.000084e+001,1.928910e-003,4.502130e-007,0.000000e+000,0.000000e+000,2,8.517956e-001,1.825000e+000,,,,,,,,,,,,,,,,,,0,3.000000e+000,1.000000e+000,10,5,2.889633e-003,0,,0,
1616084905.084,,1.500000e+003,3.000027e+001,2.872764e-003,4.780644e-007,0.000000e+000,0.000000e+000,2,8.519136e-001,1.825000e+000,,,,,,,,,,,,,,,,,,0,3.000000e+000,1.000000e+000,10,5,1.449585e-003,0,,0,
1616085099.183,,2.000000e+003,3.000070e+001,3.816082e-003,4.212257e-007,0.000000e+000,0.000000e+000,2,8.519024e-001,1.825000e+000,,,,,,,,,,,,,,,,,,0,3.000000e+000,1.000000e+000,10,5,2.889633e-003,0,,0,
1616085308.023,,2.500000e+003,3.000099e+001,4.759749e-003,3.994637e-007,0.000000e+000,0.000000e+000,2,8.519585e-001,1.825000e+000,,,,,,,,,,,,,,,,,,0,3.000000e+000,1.000000e+000,10,5,2.889633e-003,0,,0,
1616085501.942,,3.000000e+003,3.000012e+001,5.703501e-003,4.917526e-007,0.000000e+000,0.000000e+000,2,8.519511e-001,1.825000e+000,,,,,,,,,,,,,,,,,,0,3.000000e+000,1.000000e+000,10,5,2.899170e-003,0,,0,
1616085696.241,,3.500000e+003,2.999997e+001,6.647730e-003,3.863599e-007,0.000000e+000,0.000000e+000,2,8.520320e-001,1.825000e+000,,,,,,,,,,,,,,,,,,0,3.000000e+000,1.000000e+000,10,5,4.339218e-003,0,,0,
1616085891.210,,4.000000e+003,3.000070e+001,7.592240e-003,4.580785e-007,0.000000e+000,0.000000e+000,2,8.520683e-001,1.825000e+000,,,,,,,,,,,,,,,,,,0,3.000000e+000,1.000000e+000,10,5,2.889633e-003,0,,0,
1616086096.810,,5.000000e+003,2.999998e+001,9.481980e-003,4.013706e-007,0.000000e+000,0.000000e+000,2,8.521051e-001,1.825000e+000,,,,,,,,,,,,,,,,,,0,3.000000e+000,1.000000e+000,10,5,1.449585e-003,0,,0,
1616086286.940,,6.000000e+003,2.999997e+001,1.137289e-002,5.138673e-007,0.000000e+000,0.000000e+000,2,8.521011e-001,1.825000e+000,,,,,,,,,,,,,,,,,,0,3.000000e+000,1.000000e+000,10,5,4.339218e-003,0,,0,
1616086484.759,,7.000000e+003,3.000027e+001,1.326437e-002,4.594784e-007,0.000000e+000,0.000000e+000,2,8.521265e-001,1.825000e+000,,,,,,,,,,,,,,,,,,0,3.000000e+000,1.000000e+000,10,5,2.889633e-003,0,,0,
1616086669.538,,8.000000e+003,3.000084e+001,1.514714e-002,5.134306e-007,0.000000e+000,0.000000e+000,2,8.520663e-001,1.825000e+000,,,,,,,,,,,,,,,,,,0,3.000000e+000,1.000000e+000,10,5,1.449585e-003,0,,0,
1616086848.768,,9.000000e+003,3.000156e+001,1.703800e-002,5.311781e-007,0.000000e+000,0.000000e+000,2,8.520709e-001,1.825000e+000,,,,,,,,,,,,,,,,,,0,3.000000e+000,1.000000e+000,10,5,4.339218e-003,0,,0,
1616087033.867,,1.000000e+004,3.000056e+001,1.893079e-002,1.202963e-006,0.000000e+000,0.000000e+000,2,8.520520e-001,1.825000e+000,,,,,,,,,,,,,,,,,,0,3.000000e+000,1.000000e+000,10,5,4.339218e-003,0,,0,
1616087238.896,,1.200000e+004,2.999969e+001,2.271720e-002,5.158804e-007,0.000000e+000,0.000000e+000,2,8.520001e-001,1.825000e+000,,,,,,,,,,,,,,,,,,0,3.000000e+000,1.000000e+000,10,5,1.449585e-003,0,,0,
1616087428.825,,1.400000e+004,3.000056e+001,2.650584e-002,9.590448e-007,0.000000e+000,0.000000e+000,2,8.520207e-001,1.825000e+000,,,,,,,,,,,,,,,,,,0,3.000000e+000,1.000000e+000,10,5,1.449585e-003,0,,0,
1616087619.325,,1.600000e+004,3.000012e+001,3.029235e-002,4.698917e-007,0.000000e+000,0.000000e+000,2,8.520531e-001,1.825000e+000,,,,,,,,,,,,,,,,,,0,3.000000e+000,1.000000e+000,10,5,2.899170e-003,0,,0,
1616087810.694,,1.800000e+004,3.000084e+001,3.408363e-002,1.067926e-006,0.000000e+000,0.000000e+000,2,8.520703e-001,1.825000e+000,,,,,,,,,,,,,,,,,,0,3.000000e+000,1.000000e+000,10,5,1.449585e-003,0,,0,
1616087995.634,,2.000000e+004,3.000099e+001,3.787143e-002,8.669288e-007,0.000000e+000,0.000000e+000,2,8.520656e-001,1.825000e+000,,,,,,,,,,,,,,,,,,0,3.000000e+000,1.000000e+000,10,5,4.339218e-003,0,,0,
1616088215.954,,2.500000e+004,3.000099e+001,4.734048e-002,2.497686e-006,0.000000e+000,0.000000e+000,2,8.520778e-001,1.825000e+000,,,,,,,,,,,,,,,,,,0,3.000000e+000,1.000000e+000,10,5,2.889633e-003,0,,0,
1616088423.373,,3.000000e+004,3.000070e+001,5.681363e-002,2.067136e-006,0.000000e+000,0.000000e+000,2,8.521503e-001,1.825000e+000,,,,,,,,,,,,,,,,,,0,3.000000e+000,1.000000e+000,10,5,2.889633e-003,0,,0,
1616088631.942,,3.500000e+004,3.000185e+001,6.628373e-002,1.064853e-006,0.000000e+000,0.000000e+000,2,8.522488e-001,1.825000e+000,,,,,,,,,,,,,,,,,,0,3.000000e+000,1.000000e+000,10,5,1.440048e-003,0,,0,
1616088833.842,,4.000000e+004,3.000084e+001,7.574619e-002,8.709056e-007,0.000000e+000,0.000000e+000,2,8.522401e-001,1.825000e+000,,,,,,,,,,,,,,,,,,0,3.000000e+000,1.000000e+000,10,5,2.889633e-003,0,,0,
1616089059.691,,4.500000e+004,3.000128e+001,8.521190e-002,3.553851e-006,0.000000e+000,0.000000e+000,2,8.523026e-001,1.825000e+000,,,,,,,,,,,,,,,,,,0,3.000000e+000,1.000000e+000,10,5,2.889633e-003,0,,0,
1616089263.970,,5.000000e+004,3.000128e+001,9.465388e-002,4.171342e-006,0.000000e+000,0.000000e+000,2,8.523344e-001,1.825000e+000,,,,,,,,,,,,,,,,,,0,3.000000e+000,1.000000e+000,10,5,2.889633e-003,0,,0,