File: Pd_callibration/callibration_data_tempDepend.rso.raw
[Header]
TITLE,MPMS RSO Measurement
BYAPP,MPMS Measurement,2.1,Raw with ABS
FILEOPENTIME, 1616090444.307000 3/18/2021, 7:00:44 PM

INFO, APPNAME, MPMS MultiVu Application, Revision 1.61,  Build 082

INFO, NAME,
INFO, WEIGHT, 1.000
INFO, AREA, 1.000
INFO, LENGTH, 1.000
INFO, SHAPE, 0
INFO, COMMENT,
INFO, SEQUENCE FILE: callibration_sequence.seq


INFO, BACKGROUND DATA FILE:, None


STARTUPAXIS,X,8,LINEAR,AUTO,0.000000,0.000000
STARTUPAXIS,Y1,9,LINEAR,AUTO,0.000000,0.000000


STARTUPGROUP,Longitudinal
FIELDGROUP,Longitudinal,1,2,3,4,5,6,7,8,9,10,11,12,13,14,15,16,17,18,19,20,21,22
FIELDGROUP,Transverse,1,2,3,4,5,6,7,8,23,24,25,26,27,28,29,30,31,32,33,34,35,36

PLOT_APPEARANCE,ALL,HORZ_GRID_ON,VERT_GRID_ON,MARKERS_ONLY

[Data]
Time,Comment,Field (Oe),Start Temperature (K),End Temperature (K),Scan,Rejected,Position (cm),Long Voltage,Long Average Voltage,Long Detrended Voltage,Long Demeaned Voltage,Long Reg Fit,Long Detrended Fit,Long Demeaned Fit,Long Scaled Response,Long Avg. Scaled Response,Long Background Response,Long Response [w/ABS],Long Detrended Resp. [w/ABS],Long Fit [w/ABS],Long Detrended Fit [w/ABS],Trans Voltage,Trans Average Voltage,Trans Detrended Voltage,Trans Demeaned Voltage,Trans Reg Fit,Trans Detrended Fit,Trans Demeaned Fit,Trans Scaled Response,Trans Avg. Scaled Response,Trans Background Response,Trans Response [w/ABS],Trans Detrended Resp. [w/ABS],Trans Adjusted Fit,Trans Detrended Fit [w/ABS],
1616090444.307,,1.000000e+003,5.004365e+000,5.001330e+000,1,0,2.066866e+000,-5.661184e-002,,,,,,,-2.790926e-004,,,,,,,,,,,,,,,,,,,,,
1616090444.307,,1.000000e+003,5.004365e+000,5.001330e+000,1,0,2.681794e+000,-6.183050e-001,,,,,,,-3.048202e-003,,,,,,,,,,,,,,,,,,,,,
1616090444.307,,1.000000e+003,5.001330e+000,5.000494e+000,2,0,3.178782e+000,-9.344767e-001,,,,,,,-4.606908e-003,,,,,,,,,,,,,,,,,,,,,
1616090444.307,,1.000000e+003,5.000494e+000,5.000494e+000,3,0,3.481357e+000,-1.019776e+000,,,,,,,-5.027428e-003,,,,,,,,,,,,,,,,,,,,,
1616090444.307,,1.000000e+003,5.000494e+000,5.001225e+000,4,0,3.351689e+000,-1.005280e+000,,,,,,,-4.955962e-003,,,,,,,,,,,,,,,,,,,,,
1616090444.307,,1.000000e+003,5.001016e+000,5.000075e+000,5,0,2.852321e+000,-7.138280e-001,-7.262490e-001,-2.384838e-002,-2.646160e-002,-7.166417e-001,-1.424106e-002,-1.685429e-002,-3.519124e-003,-3.580359e-003,,,,,,,,,,,,,,,,,,,,
1616090713.376,,1.000000e+003,9.998867e+000,1.000502e+001,1,0,2.203866e+000,-9.048738e-002,,,,,,,-4.460968e-004,,,,,,,,,,,,,,,,,,,,,
1616090713.376,,1.000000e+003,1.000502e+001,1.000172e+001,2,0,1.550463e+000,-1.182592e-001,,,,,,,-5.830101e-004,,,,,,,,,,,,,,,,,,,,,
1616090713.376,,1.000000e+003,1.000078e+001,1.000315e+001,3,0,1.007600e+000,-6.013672e-001,,,,,,,-2.964700e-003,,,,,,,,,,,,,,,,,,,,,
1616090713.376,,1.000000e+003,1.000315e+001,1.000126e+001,4,0,6.006152e-001,-8.951079e-001,,,,,,,-4.412822e-003,,,,,,,,,,,,,,,,,,,,,
1616090713.376,,1.000000e+003,1.000126e+001,1.000222e+001,5,0,5.398172e-001,-9.208961e-001,-9.132664e-001,-2.320921e-001,-2.328981e-001,-9.159386e-001,-2.347643e-001,-2.355703e-001,-4.539956e-003,-4.502343e-003,,,,,,,,,,,,,,,,,,,,
1616090978.036,,1.000000e+003,1.500146e+001,1.500302e+001,1,0,9.214582e-001,-6.447035e-001,,,,,,,-3.178345e-003,,,,,,,,,,,,,,,,,,,,,
1616090978.036,,1.000000e+003,1.500302e+001,1.500224e+001,2,0,1.528581e+000,-1.249733e-001,,,,,,,-6.161100e-004,,,,,,,,,,,,,,,,,,,,,
1616090978.036,,1.000000e+003,1.500302e+001,1.500224e+001,2,0,2.198830e+000,-1.179540e-001,,,,,,,-5.815055e-004,,,,,,,,,,,,,,,,,,,,,
1616090978.036,,1.000000e+003,1.500224e+001,1.500146e+001,3,0,2.789996e+000,-6.288339e-001,,,,,,,-3.100109e-003,,,,,,,,,,,,,,,,,,,,,
1616090978.036,,1.000000e+003,1.500146e+001,1.499911e+001,4,0,3.262362e+000,-9.155553e-001,,,,,,,-4.513626e-003,,,,,,,,,,,,,,,,,,,,,
1616090978.036,,1.000000e+003,1.499911e+001,1.499755e+001,5,0,3.494571e+000,-9.498886e-001,-9.575182e-001,-2.970455e-001,-2.997493e-001,-9.593178e-001,-2.988451e-001,-3.015488e-001,-4.682887e-003,-4.720501e-003,,,,,,,,,,,,,,,,,,,,
1616091242.175,,1.000000e+003,1.999960e+001,1.999960e+001,1,0,3.272771e+000,-9.263893e-001,,,,,,,-4.567038e-003,,,,,,,,,,,,,,,,,,,,,
1616091242.175,,1.000000e+003,1.999960e+001,1.999279e+001,2,0,2.729597e+000,-5.871761e-001,,,,,,,-2.894739e-003,,,,,,,,,,,,,,,,,,,,,
1616091242.175,,1.000000e+003,1.999279e+001,1.999347e+001,3,0,2.067913e+000,-4.959258e-002,,,,,,,-2.444881e-004,,,,,,,,,,,,,,,,,,,,,
1616091242.175,,1.000000e+003,1.999347e+001,1.999824e+001,4,0,1.431749e+000,-1.823481e-001,,,,,,,-8.989639e-004,,,,,,,,,,,,,,,,,,,,,
1616091242.175,,1.000000e+003,1.999824e+001,2.000165e+001,5,0,9.118364e-001,-6.302072e-001,-6.358837e-001,2.127200e-002,2.014226e-002,-6.435891e-001,1.356661e-002,1.243687e-002,-3.106880e-003,-3.134864e-003,,,,,,,,,,,,,,,,,,,,
1616091507.275,,1.000000e+003,2.499935e+001,2.500245e+001,1,0,5.516207e-001,-8.882412e-001,,,,,,,-4.378970e-003,,,,,,,,,,,,,,,,,,,,,
1616091507.275,,1.000000e+003,2.500245e+001,2.500348e+001,2,0,5.861486e-001,-8.674887e-001,,,,,,,-4.276661e-003,,,,,,,,,,,,,,,,,,,,,
1616091507.275,,1.000000e+003,2.500348e+001,2.500245e+001,3,0,1.031941e+000,-5.543687e-001,,,,,,,-2.733001e-003,,,,,,,,,,,,,,,,,,,,,
1616091507.275,,1.000000e+003,2.500245e+001,2.500245e+001,4,0,1.662284e+000,-4.348888e-002,,,,,,,-2.143973e-004,,,,,,,,,,,,,,,,,,,,,
1616091507.275,,1.000000e+003,2.500245e+001,2.500245e+001,4,0,2.327246e+000,-2.241585e-001,,,,,,,-1.105086e-003,,,,,,,,,,,,,,,,,,,,,
1616091507.275,,1.000000e+003,2.500245e+001,2.500039e+001,5,0,2.894094e+000,-7.037568e-001,-7.079989e-001,-4.428156e-002,-4.731441e-002,-7.077498e-001,-4.403247e-002,-4.706532e-002,-3.469474e-003,-3.490387e-003,,,,,,,,,,,,,,,,,,,,
1616091776.015,,1.000000e+003,3.000243e+001,3.000099e+001,1,0,3.337209e+000,-9.515672e-001,,,,,,,-4.691163e-003,,,,,,,,,,,,,,,,,,,,,
1616091776.015,,1.000000e+003,3.000099e+001,3.000099e+001,2,0,3.487762e+000,-9.669789e-001,,,,,,,-4.767142e-003,,,,,,,,,,,,,,,,,,,,,
1616091776.015,,1.000000e+003,2.999954e+001,2.999954e+001,3,0,3.181381e+000,-8.958709e-001,,,,,,,-4.416584e-003,,,,,,,,,,,,,,,,,,,,,
1616091776.015,,1.000000e+003,2.999954e+001,3.000099e+001,4,0,2.602884e+000,-4.916532e-001,,,,,,,-2.423818e-003,,,,,,,,,,,,,,,,,,,,,
1616091776.015,,1.000000e+003,3.000099e+001,3.000099e+001,5,0,1.933969e+000,-5.645924e-003,-8.545183e-003,6.627249e-001,6.609185e-001,-3.561440e-003,6.677087e-001,6.659023e-001,-2.783403e-005,-4.212718e-005,,,,,,,,,,,,,,,,,,,,
1616092059.454,,1.000000e+003,3.500000e+001,3.500077e+001,1,0,1.319018e+000,-2.526932e-001,,,,,,,-1.245761e-003,,,,,,,,,,,,,,,,,,,,,
1616092059.454,,1.000000e+003,3.500000e+001,3.500154e+001,2,0,8.220652e-001,-6.672872e-001,,,,,,,-3.289681e-003,,,,,,,,,,,,,,,,,,,,,
1616092059.454,,1.000000e+003,3.500154e+001,3.500154e+001,3,0,5.195827e-001,-8.517717e-001,,,,,,,-4.199177e-003,,,,,,,,,,,,,,,,,,,,,
1616092059.454,,1.000000e+003,3.500154e+001,3.500154e+001,4,0,6.492469e-001,-7.837154e-001,,,,,,,-3.863664e-003,,,,,,,,,,,,,,,,,,,,,
1616092059.454,,1.000000e+003,3.500154e+001,3.500077e+001,5,0,1.148592e+000,-4.058962e-001,-4.073305e-001,2.064359e-001,2.060597e-001,-4.069796e-001,2.067869e-001,2.064106e-001,-2.001041e-003,-2.008112e-003,,,,,,,,,,,,,,,,,,,,
1616092354.673,,1.000000e+003,4.000087e+001,4.000087e+001,1,0,1.797050e+000,4.440443e-002,,,,,,,2.189109e-004,,,,,,,,,,,,,,,,,,,,,
1616092354.673,,1.000000e+003,4.000087e+001,4.000087e+001,1,0,2.450502e+000,-2.940458e-001,,,,,,,-1.449626e-003,,,,,,,,,,,,,,,,,,,,,
1616092354.673,,1.000000e+003,4.000087e+001,4.000185e+001,2,0,2.993313e+000,-7.446517e-001,,,,,,,-3.671083e-003,,,,,,,,,,,,,,,,,,,,,
1616092354.673,,1.000000e+003,4.000185e+001,4.000087e+001,3,0,3.400272e+000,-9.166234e-001,,,,,,,-4.518893e-003,,,,,,,,,,,,,,,,,,,,,
1616092354.673,,1.000000e+003,4.000087e+001,3.999987e+001,4,0,3.461104e+000,-9.212012e-001,,,,,,,-4.541460e-003,,,,,,,,,,,,,,,,,,,,,
1616092354.673,,1.000000e+003,3.999987e+001,4.000087e+001,5,0,3.079569e+000,-7.976012e-001,-7.985168e-001,-1.725529e-001,-1.744236e-001,-7.932519e-001,-1.672880e-001,-1.691588e-001,-3.932121e-003,-3.936634e-003,,,,,,,,,,,,,,,,,,,,
1616092652.733,,1.000000e+003,4.500230e+001,4.500230e+001,1,0,2.472281e+000,-3.173925e-001,,,,,,,-1.564724e-003,,,,,,,,,,,,,,,,,,,,,
1616092652.733,,1.000000e+003,4.500230e+001,4.499985e+001,2,0,1.802151e+000,6.302072e-002,,,,,,,3.106880e-004,,,,,,,,,,,,,,,,,,,,,
1616092652.733,,1.000000e+003,4.499985e+001,4.500107e+001,3,0,1.210948e+000,-3.427229e-001,,,,,,,-1.689601e-003,,,,,,,,,,,,,,,,,,,,,
1616092652.733,,1.000000e+003,4.499985e+001,4.500230e+001,4,0,7.385941e-001,-7.225257e-001,,,,,,,-3.562004e-003,,,,,,,,,,,,,,,,,,,,,
1616092652.733,,1.000000e+003,4.500230e+001,4.499862e+001,5,0,5.063270e-001,-8.575701e-001,-8.578753e-001,-2.433297e-001,-2.440184e-001,-8.587743e-001,-2.442287e-001,-2.449175e-001,-4.227764e-003,-4.229268e-003,,,,,,,,,,,,,,,,,,,,
1616092932.122,,1.000000e+003,5.001512e+001,5.001065e+001,1,0,7.280278e-001,-7.457198e-001,,,,,,,-3.676349e-003,,,,,,,,,,,,,,,,,,,,,
1616092932.122,,1.000000e+003,5.001065e+001,5.000616e+001,2,0,1.271040e+000,-3.105258e-001,,,,,,,-1.530872e-003,,,,,,,,,,,,,,,,,,,,,
1616092932.122,,1.000000e+003,5.000616e+001,5.000468e+001,3,0,1.932429e+000,5.569628e-002,,,,,,,2.745790e-004,,,,,,,,,,,,,,,,,,,,,
1616092932.122,,1.000000e+003,5.000616e+001,5.000468e+001,3,0,2.568697e+000,-3.941466e-001,,,,,,,-1.943116e-003,,,,,,,,,,,,,,,,,,,,,
1616092932.122,,1.000000e+003,5.000468e+001,5.000468e+001,4,0,3.088560e+000,-7.983642e-001,,,,,,,-3.935882e-003,,,,,,,,,,,,,,,,,,,,,
1616092932.122,,1.000000e+003,5.000468e+001,5.000318e+001,5,0,3.449242e+000,-9.224219e-001,-9.226050e-001,-2.976296e-001,-2.997864e-001,-9.230139e-001,-2.980385e-001,-3.001953e-001,-4.547479e-003,-4.548382e-003,,,,,,,,,,,,,,,,,,,,
1616093206.831,,1.000000e+003,5.502256e+001,5.501544e+001,1,0,3.415127e+000,-9.358500e-001,,,,,,,-4.613678e-003,,,,,,,,,,,,,,,,,,,,,
1616093206.831,,1.000000e+003,5.501544e+001,5.501188e+001,2,0,2.969292e+000,-7.417524e-001,,,,,,,-3.656790e-003,,,,,,,,,,,,,,,,,,,,,
1616093206.831,,1.000000e+003,5.501188e+001,5.500653e+001,3,0,2.339059e+000,-2.188177e-001,,,,,,,-1.078757e-003,,,,,,,,,,,,,,,,,,,,,
1616093206.831,,1.000000e+003,5.500653e+001,5.500475e+001,4,0,1.673998e+000,4.882962e-003,,,,,,,2.407267e-005,,,,,,,,,,,,,,,,,,,,,
1616093206.831,,1.000000e+003,5.500475e+001,5.499942e+001,5,0,1.107209e+000,-4.655599e-001,-4.656514e-001,1.733439e-001,1.722293e-001,-4.687236e-001,1.702718e-001,1.691572e-001,-2.295179e-003,-2.295631e-003,,,,,,,,,,,,,,,,,,,,
1616093484.050,,1.000000e+003,6.003188e+001,6.002140e+001,1,0,6.638457e-001,-7.892087e-001,,,,,,,-3.890746e-003,,,,,,,,,,,,,,,,,,,,,
1616093484.050,,1.000000e+003,6.002140e+001,6.001511e+001,2,0,5.130286e-001,-8.725241e-001,,,,,,,-4.301486e-003,,,,,,,,,,,,,,,,,,,,,
1616093484.050,,1.000000e+003,6.001511e+001,6.000882e+001,3,0,8.194106e-001,-6.927701e-001,,,,,,,-3.415311e-003,,,,,,,,,,,,,,,,,,,,,
1616093484.050,,1.000000e+003,6.000882e+001,6.000672e+001,4,0,1.397807e+000,-1.995911e-001,,,,,,,-9.839706e-004,,,,,,,,,,,,,,,,,,,,,
1616093484.050,,1.000000e+003,6.000672e+001,6.000463e+001,5,0,2.066769e+000,1.144444e-002,1.147496e-002,6.390591e-001,6.390591e-001,1.006512e-002,6.376492e-001,6.376492e-001,5.642033e-005,5.657079e-005,,,,,,,,,,,,,,,,,,,,
1616093484.050,,1.000000e+003,6.000672e+001,6.000463e+001,5,0,2.681714e+000,-4.948576e-001,-4.949187e-001,1.349228e-001,1.326654e-001,-4.975259e-001,1.323156e-001,1.300582e-001,-2.439615e-003,-2.439916e-003,,,,,,,,,,,,,,,,,,,,
1616093764.979,,1.000000e+003,6.504213e+001,6.502753e+001,1,0,3.178772e+000,-8.549761e-001,,,,,,,-4.214975e-003,,,,,,,,,,,,,,,,,,,,,
1616093764.979,,1.000000e+003,6.502753e+001,6.502264e+001,2,0,3.481305e+000,-9.352397e-001,,,,,,,-4.610669e-003,,,,,,,,,,,,,,,,,,,,,
1616093764.979,,1.000000e+003,6.502264e+001,6.501535e+001,3,0,3.351693e+000,-9.195226e-001,,,,,,,-4.533186e-003,,,,,,,,,,,,,,,,,,,,,
1616093764.979,,1.000000e+003,6.501535e+001,6.501047e+001,4,0,2.852442e+000,-6.489761e-001,,,,,,,-3.199409e-003,,,,,,,,,,,,,,,,,,,,,
1616093764.979,,1.000000e+003,6.501047e+001,6.499831e+001,5,0,2.204032e+000,-9.628589e-002,-9.616382e-002,5.376826e-001,5.364733e-001,-8.328371e-002,5.505627e-001,5.493534e-001,-4.746831e-004,-4.740813e-004,,,,,,,,,,,,,,,,,,,,
1616094047.779,,1.000000e+003,7.004613e+001,7.003493e+001,1,0,1.550562e+000,-6.607257e-002,,,,,,,-3.257334e-004,,,,,,,,,,,,,,,,,,,,,
1616094047.779,,1.000000e+003,7.003493e+001,7.002095e+001,2,0,1.007667e+000,-5.481125e-001,,,,,,,-2.702158e-003,,,,,,,,,,,,,,,,,,,,,
1616094047.779,,1.000000e+003,7.002095e+001,7.001814e+001,3,0,6.007170e-001,-8.383434e-001,,,,,,,-4.132977e-003,,,,,,,,,,,,,,,,,,,,,
1616094047.779,,1.000000e+003,7.001814e+001,7.000697e+001,4,0,5.398038e-001,-8.665730e-001,,,,,,,-4.272148e-003,,,,,,,,,,,,,,,,,,,,,
1616094047.779,,1.000000e+003,7.000697e+001,7.000697e+001,5,0,9.212751e-001,-6.199836e-001,-6.199530e-001,1.277667e-002,1.250124e-002,-6.202270e-001,1.250267e-002,1.222724e-002,-3.056478e-003,-3.056327e-003,,,,,,,,,,,,,,,,,,,,
1616094333.328,,1.000000e+003,7.506044e+001,7.504135e+001,1,0,1.528517e+000,-1.080355e-001,,,,,,,-5.326080e-004,,,,,,,,,,,,,,,,,,,,,
1616094333.328,,1.000000e+003,7.506044e+001,7.504135e+001,1,0,2.198725e+000,-8.041628e-002,,,,,,,-3.964469e-004,,,,,,,,,,,,,,,,,,,,,
1616094333.328,,1.000000e+003,7.504135e+001,7.502861e+001,2,0,2.789849e+000,-6.012146e-001,,,,,,,-2.963948e-003,,,,,,,,,,,,,,,,,,,,,
1616094333.328,,1.000000e+003,7.502861e+001,7.502544e+001,3,0,3.262283e+000,-9.012116e-001,,,,,,,-4.442913e-003,,,,,,,,,,,,,,,,,,,,,
1616094333.328,,1.000000e+003,7.502544e+001,7.501590e+001,4,0,3.494581e+000,-9.456161e-001,,,,,,,-4.661824e-003,,,,,,,,,,,,,,,,,,,,,
1616094333.328,,1.000000e+003,7.501590e+001,7.501271e+001,5,0,3.273044e+000,-9.082309e-001,-9.082308e-001,-2.645038e-001,-2.657539e-001,-9.048467e-001,-2.611196e-001,-2.623697e-001,-4.477518e-003,-4.477518e-003,,,,,,,,,,,,,,,,,,,,
1616094617.278,,1.000000e+003,8.005376e+001,8.004660e+001,1,0,2.729977e+000,-5.552843e-001,,,,,,,-2.737514e-003,,,,,,,,,,,,,,,,,,,,,
1616094617.278,,1.000000e+003,8.004660e+001,8.003943e+001,2,0,2.068670e+000,-1.220740e-002,,,,,,,-6.018169e-005,,,,,,,,,,,,,,,,,,,,,
1616094617.278,,1.000000e+003,8.003943e+001,8.002508e+001,3,0,1.432395e+000,-1.713614e-001,,,,,,,-8.448004e-004,,,,,,,,,,,,,,,,,,,,,
1616094617.278,,1.000000e+003,8.002508e+001,8.001791e+001,4,0,9.124678e-001,-6.323435e-001,,,,,,,-3.117411e-003,,,,,,,,,,,,,,,,,,,,,
1616094617.278,,1.000000e+003,8.001791e+001,8.001433e+001,5,0,5.517504e-001,-8.769494e-001,-8.768883e-001,-2.342503e-001,-2.347471e-001,-8.749720e-001,-2.323340e-001,-2.328308e-001,-4.323302e-003,-4.323001e-003,,,,,,,,,,,,,,,,,,,,
1616094901.847,,1.000000e+003,8.507246e+001,8.505642e+001,1,0,5.857469e-001,-8.597064e-001,,,,,,,-4.238295e-003,,,,,,,,,,,,,,,,,,,,,
1616094901.847,,1.000000e+003,8.505642e+001,8.504037e+001,2,0,1.031461e+000,-5.467391e-001,,,,,,,-2.695387e-003,,,,,,,,,,,,,,,,,,,,,
1616094901.847,,1.000000e+003,8.503637e+001,8.502435e+001,3,0,1.661739e+000,-2.059999e-002,,,,,,,-1.015566e-004,,,,,,,,,,,,,,,,,,,,,
1616094901.847,,1.000000e+003,8.503637e+001,8.502435e+001,3,0,2.326784e+000,-1.820429e-001,,,,,,,-8.974594e-004,,,,,,,,,,,,,,,,,,,,,
1616094901.847,,1.000000e+003,8.502435e+001,8.502034e+001,4,0,2.893550e+000,-6.769005e-001,,,,,,,-3.337075e-003,,,,,,,,,,,,,,,,,,,,,
1616094901.847,,1.000000e+003,8.502034e+001,8.502034e+001,5,0,3.336924e+000,-9.228797e-001,-9.231239e-001,-2.792726e-001,-2.806035e-001,-9.235840e-001,-2.797327e-001,-2.810636e-001,-4.549736e-003,-4.550939e-003,,,,,,,,,,,,,,,,,,,,
1616095188.046,,1.000000e+003,9.008069e+001,9.005397e+001,1,0,3.487876e+000,-9.457687e-001,,,,,,,-4.662576e-003,,,,,,,,,,,,,,,,,,,,,
1616095188.046,,1.000000e+003,9.005397e+001,9.003615e+001,2,0,3.181609e+000,-8.662679e-001,,,,,,,-4.270643e-003,,,,,,,,,,,,,,,,,,,,,
1616095188.046,,1.000000e+003,9.003615e+001,9.002280e+001,3,0,2.603183e+000,-4.481643e-001,,,,,,,-2.209420e-003,,,,,,,,,,,,,,,,,,,,,
1616095188.046,,1.000000e+003,9.002280e+001,9.001834e+001,4,0,1.934269e+000,3.753776e-002,,,,,,,1.850587e-004,,,,,,,,,,,,,,,,,,,,,
1616095188.046,,1.000000e+003,9.001834e+001,9.000944e+001,5,0,1.319291e+000,-2.871792e-001,-2.875454e-001,3.570527e-001,3.564469e-001,-2.942070e-001,3.503910e-001,3.497852e-001,-1.415774e-003,-1.417580e-003,,,,,,,,,,,,,,,,,,,,
1616095473.125,,1.000000e+003,9.509148e+001,9.505704e+001,1,0,8.222092e-001,-7.112339e-001,,,,,,,-3.506335e-003,,,,,,,,,,,,,,,,,,,,,
1616095473.125,,1.000000e+003,9.505704e+001,9.504722e+001,2,0,5.196251e-001,-8.940398e-001,,,,,,,-4.407556e-003,,,,,,,,,,,,,,,,,,,,,
1616095473.125,,1.000000e+003,9.504722e+001,9.502755e+001,3,0,6.491465e-001,-8.285775e-001,,,,,,,-4.084832e-003,,,,,,,,,,,,,,,,,,,,,
1616095473.125,,1.000000e+003,9.502755e+001,9.502263e+001,4,0,1.148425e+000,-4.507584e-001,,,,,,,-2.222209e-003,,,,,,,,,,,,,,,,,,,,,
1616095473.125,,1.000000e+003,9.502263e+001,9.501772e+001,5,0,1.796813e+000,3.021332e-002,2.951140e-002,6.745718e-001,6.745312e-001,3.194756e-002,6.770079e-001,6.769674e-001,1.489497e-004,1.454892e-004,,,,,,,,,,,,,,,,,,,,
1616095473.125,,1.000000e+003,9.502263e+001,9.501772e+001,5,0,2.450271e+000,-2.932829e-001,-2.939543e-001,3.523017e-001,3.510655e-001,-2.999502e-001,3.463058e-001,3.450696e-001,-1.445865e-003,-1.449175e-003,,,,,,,,,,,,,,,,,,,,
1616095754.135,,1.000000e+003,1.000985e+002,1.000714e+002,1,0,2.993178e+000,-7.452620e-001,,,,,,,-3.674092e-003,,,,,,,,,,,,,,,,,,,,,
1616095754.135,,1.000000e+003,1.000714e+002,1.000606e+002,2,0,3.400154e+000,-9.288308e-001,,,,,,,-4.579074e-003,,,,,,,,,,,,,,,,,,,,,
1616095754.135,,1.000000e+003,1.000606e+002,1.000309e+002,3,0,3.461174e+000,-9.355448e-001,,,,,,,-4.612174e-003,,,,,,,,,,,,,,,,,,,,,
1616095754.135,,1.000000e+003,1.000309e+002,1.000336e+002,4,0,3.079745e+000,-8.005005e-001,,,,,,,-3.946414e-003,,,,,,,,,,,,,,,,,,,,,
1616095754.135,,1.000000e+003,1.000336e+002,1.000174e+002,5,0,2.472587e+000,-3.219703e-001,-3.227332e-001,3.153680e-001,3.147413e-001,-3.115598e-001,3.265415e-001,3.259147e-001,-1.587292e-003,-1.591053e-003,,,,,,,,,,,,,,,,,,,,
1616096033.364,,1.000000e+003,1.051115e+002,1.050908e+002,1,0,1.802229e+000,4.333628e-002,,,,,,,2.136450e-004,,,,,,,,,,,,,,,,,,,,,
1616096033.364,,1.000000e+003,1.050908e+002,1.050463e+002,2,0,1.211008e+000,-3.770562e-001,,,,,,,-1.858862e-003,,,,,,,,,,,,,,,,,,,,,
1616096033.364,,1.000000e+003,1.050611e+002,1.050315e+002,3,0,7.387339e-001,-7.513657e-001,,,,,,,-3.704183e-003,,,,,,,,,,,,,,,,,,,,,
1616096033.364,,1.000000e+003,1.050315e+002,1.050197e+002,4,0,5.063586e-001,-8.809168e-001,,,,,,,-4.342861e-003,,,,,,,,,,,,,,,,,,,,,
1616096033.364,,1.000000e+003,1.050197e+002,1.050256e+002,5,0,7.278408e-001,-7.631153e-001,-7.639393e-001,-1.333655e-001,-1.335309e-001,-7.662985e-001,-1.357247e-001,-1.358901e-001,-3.762108e-003,-3.766170e-003,,,,,,,,,,,,,,,,,,,,
1616096312.443,,1.000000e+003,1.101217e+002,1.100732e+002,1,0,1.270890e+000,-3.869747e-001,,,,,,,-1.907759e-003,,,,,,,,,,,,,,,,,,,,,
1616096312.443,,1.000000e+003,1.100732e+002,1.100441e+002,2,0,1.932258e+000,-2.746666e-003,,,,,,,-1.354088e-005,,,,,,,,,,,,,,,,,,,,,
1616096312.443,,1.000000e+003,1.100732e+002,1.100441e+002,2,0,2.568552e+000,-4.330576e-001,,,,,,,-2.134945e-003,,,,,,,,,,,,,,,,,,,,,
1616096312.443,,1.000000e+003,1.100538e+002,1.100538e+002,3,0,3.088459e+000,-8.378857e-001,,,,,,,-4.130721e-003,,,,,,,,,,,,,,,,,,,,,
1616096312.443,,1.000000e+003,1.100538e+002,1.100408e+002,4,0,3.449166e+000,-9.715568e-001,,,,,,,-4.789710e-003,,,,,,,,,,,,,,,,,,,,,
1616096312.443,,1.000000e+003,1.100408e+002,1.100344e+002,5,0,3.415224e+000,-9.672842e-001,-9.683218e-001,-2.900202e-001,-2.905944e-001,-9.673755e-001,-2.890739e-001,-2.896481e-001,-4.768646e-003,-4.773762e-003,,,,,,,,,,,,,,,,,,,,
1616096587.902,,1.000000e+003,1.151295e+002,1.151014e+002,1,0,2.969409e+000,-7.173375e-001,,,,,,,-3.536426e-003,,,,,,,,,,,,,,,,,,,,,
1616096587.902,,1.000000e+003,1.150944e+002,1.150803e+002,2,0,2.339247e+000,-2.008118e-001,,,,,,,-9.899888e-004,,,,,,,,,,,,,,,,,,,,,
1616096587.902,,1.000000e+003,1.150803e+002,1.150592e+002,3,0,1.674149e+000,-8.850368e-003,,,,,,,-4.363172e-005,,,,,,,,,,,,,,,,,,,,,
1616096587.902,,1.000000e+003,1.150592e+002,1.150346e+002,4,0,1.107353e+000,-4.771569e-001,,,,,,,-2.352352e-003,,,,,,,,,,,,,,,,,,,,,
1616096587.902,,1.000000e+003,1.150346e+002,1.149995e+002,5,0,6.640009e-001,-7.974486e-001,-7.985778e-001,-1.681822e-001,-1.683853e-001,-8.056242e-001,-1.752286e-001,-1.754316e-001,-3.931369e-003,-3.936936e-003,,,,,,,,,,,,,,,,,,,,
1616096861.251,,1.000000e+003,1.201381e+002,1.201114e+002,1,0,5.130539e-001,-8.618428e-001,,,,,,,-4.248827e-003,,,,,,,,,,,,,,,,,,,,,
1616096861.251,,1.000000e+003,1.201114e+002,1.200734e+002,2,0,8.193208e-001,-6.933805e-001,,,,,,,-3.418320e-003,,,,,,,,,,,,,,,,,,,,,
1616096861.251,,1.000000e+003,1.200734e+002,1.200468e+002,3,0,1.397707e+000,-2.171392e-001,,,,,,,-1.070482e-003,,,,,,,,,,,,,,,,,,,,,
1616096861.251,,1.000000e+003,1.200468e+002,1.200240e+002,4,0,2.066601e+000,1.770074e-002,,,,,,,8.726345e-005,,,,,,,,,,,,,,,,,,,,,
1616096861.251,,1.000000e+003,1.200468e+002,1.200240e+002,4,0,2.681584e+000,-4.667806e-001,,,,,,,-2.301197e-003,,,,,,,,,,,,,,,,,,,,,
1616096861.251,,1.000000e+003,1.200240e+002,1.200126e+002,5,0,3.178605e+000,-8.185064e-001,-8.197882e-001,-2.041872e-001,-2.045572e-001,-8.210036e-001,-2.054026e-001,-2.057726e-001,-4.035182e-003,-4.041501e-003,,,,,,,,,,,,,,,,,,,,
1616097137.980,,1.000000e+003,1.251297e+002,1.251092e+002,1,0,3.481274e+000,-9.070101e-001,,,,,,,-4.471499e-003,,,,,,,,,,,,,,,,,,,,,
1616097137.980,,1.000000e+003,1.251092e+002,1.250764e+002,2,0,3.351802e+000,-8.865627e-001,,,,,,,-4.370695e-003,,,,,,,,,,,,,,,,,,,,,
1616097137.980,,1.000000e+003,1.250764e+002,1.250354e+002,3,0,2.852529e+000,-6.135746e-001,,,,,,,-3.024882e-003,,,,,,,,,,,,,,,,,,,,,
1616097137.980,,1.000000e+003,1.250354e+002,1.250436e+002,4,0,2.204150e+000,-8.056886e-002,,,,,,,-3.971991e-004,,,,,,,,,,,,,,,,,,,,,
1616097137.980,,1.000000e+003,1.250436e+002,1.250231e+002,5,0,1.550691e+000,-8.346812e-002,-8.490250e-002,5.306515e-001,5.305530e-001,-9.561673e-002,5.199372e-001,5.198387e-001,-4.114923e-004,-4.185636e-004,,,,,,,,,,,,,,,,,,,,
1616097415.299,,1.000000e+003,1.301440e+002,1.300955e+002,1,0,1.007712e+000,-5.493332e-001,,,,,,,-2.708176e-003,,,,,,,,,,,,,,,,,,,,,
1616097415.299,,1.000000e+003,1.300955e+002,1.300779e+002,2,0,6.007852e-001,-8.189642e-001,,,,,,,-4.037439e-003,,,,,,,,,,,,,,,,,,,,,
1616097415.299,,1.000000e+003,1.300779e+002,1.300382e+002,3,0,5.397233e-001,-8.436842e-001,,,,,,,-4.159307e-003,,,,,,,,,,,,,,,,,,,,,
1616097415.299,,1.000000e+003,1.300382e+002,1.300206e+002,4,0,9.210942e-001,-6.149480e-001,,,,,,,-3.031652e-003,,,,,,,,,,,,,,,,,,,,,
1616097415.299,,1.000000e+003,1.300206e+002,1.300338e+002,5,0,1.528254e+000,-1.156652e-001,-1.173742e-001,4.942735e-001,4.942722e-001,-1.139281e-001,4.977196e-001,4.977183e-001,-5.702215e-004,-5.786470e-004,,,,,,,,,,,,,,,,,,,,
1616097415.299,,1.000000e+003,1.300206e+002,1.300338e+002,5,0,2.198510e+000,-5.783258e-002,-5.948057e-002,5.521866e-001,5.521658e-001,-6.478796e-002,5.468792e-001,5.468584e-001,-2.851108e-004,-2.932353e-004,,,,,,,,,,,,,,,,,,,,
1616097695.857,,1.000000e+003,1.351535e+002,1.351062e+002,1,0,2.789854e+000,-5.452132e-001,,,,,,,-2.687865e-003,,,,,,,,,,,,,,,,,,,,,
1616097695.857,,1.000000e+003,1.351062e+002,1.350683e+002,2,0,3.262158e+000,-8.378857e-001,,,,,,,-4.130721e-003,,,,,,,,,,,,,,,,,,,,,
1616097695.857,,1.000000e+003,1.350683e+002,1.350494e+002,3,0,3.494590e+000,-9.092990e-001,,,,,,,-4.482783e-003,,,,,,,,,,,,,,,,,,,,,
1616097695.857,,1.000000e+003,1.350494e+002,1.350258e+002,4,0,3.273175e+000,-8.435316e-001,,,,,,,-4.158555e-003,,,,,,,,,,,,,,,,,,,,,
1616097695.857,,1.000000e+003,1.350258e+002,1.350305e+002,5,0,2.730121e+000,-4.992828e-001,-5.040742e-001,1.007556e-001,9.969234e-002,-4.969199e-001,1.079099e-001,1.068467e-001,-2.461431e-003,-2.485052e-003,,,,,,,,,,,,,,,,,,,,
1616097981.924,,1.000000e+003,1.401413e+002,1.400907e+002,1,0,2.068675e+000,-7.629627e-004,,,,,,,-3.761355e-006,,,,,,,,,,,,,,,,,,,,,
1616097981.924,,1.000000e+003,1.400907e+002,1.400502e+002,2,0,1.432408e+000,-1.808222e-001,,,,,,,-8.914412e-004,,,,,,,,,,,,,,,,,,,,,
1616097981.924,,1.000000e+003,1.400502e+002,1.400452e+002,3,0,9.124480e-001,-6.112857e-001,,,,,,,-3.013598e-003,,,,,,,,,,,,,,,,,,,,,
1616097981.924,,1.000000e+003,1.400452e+002,1.400199e+002,4,0,5.517720e-001,-8.323923e-001,,,,,,,-4.103639e-003,,,,,,,,,,,,,,,,,,,,,
1616097981.924,,1.000000e+003,1.400199e+002,1.400249e+002,5,0,5.856807e-001,-8.157598e-001,-8.176519e-001,-2.136003e-001,-2.135088e-001,-8.174145e-001,-2.133629e-001,-2.132714e-001,-4.021641e-003,-4.030969e-003,,,,,,,,,,,,,,,,,,,,
1616098258.342,,1.000000e+003,1.451766e+002,1.451117e+002,1,0,1.031486e+000,-5.856502e-001,,,,,,,-2.887216e-003,,,,,,,,,,,,,,,,,,,,,
1616098258.342,,1.000000e+003,1.451117e+002,1.450739e+002,2,0,1.661614e+000,-8.865627e-002,,,,,,,-4.370695e-004,,,,,,,,,,,,,,,,,,,,,
1616098258.342,,1.000000e+003,1.451117e+002,1.450739e+002,2,0,2.326684e+000,-2.067629e-001,,,,,,,-1.019327e-003,,,,,,,,,,,,,,,,,,,,,
1616098258.342,,1.000000e+003,1.450739e+002,1.450415e+002,3,0,2.893543e+000,-6.706442e-001,,,,,,,-3.306231e-003,,,,,,,,,,,,,,,,,,,,,
1616098258.342,,1.000000e+003,1.450415e+002,1.450307e+002,4,0,3.336850e+000,-9.096042e-001,,,,,,,-4.484288e-003,,,,,,,,,,,,,,,,,,,,,
1616098258.342,,1.000000e+003,1.450307e+002,1.450145e+002,5,0,3.487920e+000,-9.341716e-001,-9.362163e-001,-2.806049e-001,-2.800974e-001,-9.370284e-001,-2.814170e-001,-2.809095e-001,-4.605404e-003,-4.615484e-003,,,,,,,,,,,,,,,,,,,,
1616098543.769,,1.000000e+003,1.501454e+002,1.500993e+002,1,0,3.181599e+000,-7.951598e-001,,,,,,,-3.920085e-003,,,,,,,,,,,,,,,,,,,,,
1616098543.769,,1.000000e+003,1.500993e+002,1.500648e+002,2,0,2.603185e+000,-3.975036e-001,,,,,,,-1.959666e-003,,,,,,,,,,,,,,,,,,,,,
1616098543.769,,1.000000e+003,1.500648e+002,1.500360e+002,3,0,1.934333e+000,3.814814e-002,,,,,,,1.880678e-004,,,,,,,,,,,,,,,,,,,,,
1616098543.769,,1.000000e+003,1.500360e+002,1.500245e+002,4,0,1.319328e+000,-2.862636e-001,,,,,,,-1.411261e-003,,,,,,,,,,,,,,,,,,,,,
1616098543.769,,1.000000e+003,1.500245e+002,1.500130e+002,5,0,8.223246e-001,-6.717124e-001,-6.738792e-001,-7.505749e-002,-7.472682e-002,-6.772013e-001,-7.837962e-002,-7.804894e-002,-3.311497e-003,-3.322180e-003,,,,,,,,,,,,,,,,,,,,
1616098829.946,,1.000000e+003,1.551393e+002,1.550841e+002,1,0,5.196365e-001,-8.198797e-001,,,,,,,-4.041953e-003,,,,,,,,,,,,,,,,,,,,,
1616098829.946,,1.000000e+003,1.550841e+002,1.550473e+002,2,0,6.490782e-001,-7.623523e-001,,,,,,,-3.758346e-003,,,,,,,,,,,,,,,,,,,,,
1616098829.946,,1.000000e+003,1.550473e+002,1.550412e+002,3,0,1.148348e+000,-4.199347e-001,,,,,,,-2.070250e-003,,,,,,,,,,,,,,,,,,,,,
1616098829.946,,1.000000e+003,1.550412e+002,1.550290e+002,4,0,1.796676e+000,3.753776e-002,,,,,,,1.850587e-004,,,,,,,,,,,,,,,,,,,,,
1616098829.946,,1.000000e+003,1.550412e+002,1.550290e+002,4,0,2.450165e+000,-2.336192e-001,,,,,,,-1.151727e-003,,,,,,,,,,,,,,,,,,,,,
1616098829.946,,1.000000e+003,1.550290e+002,1.550106e+002,5,0,2.993129e+000,-7.361065e-001,-6.790369e-001,-8.448790e-002,-8.341801e-002,-6.747710e-001,-8.022206e-002,-7.915217e-002,-3.628956e-003,-3.347606e-003,,,,,,,,,,,,,,,,,,,,
1616099118.864,,1.000000e+003,1.601382e+002,1.600796e+002,1,0,3.400156e+000,-8.482620e-001,,,,,,,-4.181875e-003,,,,,,,,,,,,,,,,,,,,,
1616099118.864,,1.000000e+003,1.600796e+002,1.600535e+002,2,0,3.461182e+000,-8.558916e-001,,,,,,,-4.219489e-003,,,,,,,,,,,,,,,,,,,,,
1616099118.864,,1.000000e+003,1.600471e+002,1.600276e+002,3,0,3.079774e+000,-7.185583e-001,,,,,,,-3.542445e-003,,,,,,,,,,,,,,,,,,,,,
1616099118.864,,1.000000e+003,1.600276e+002,1.600210e+002,4,0,2.472611e+000,-2.720725e-001,,,,,,,-1.341299e-003,,,,,,,,,,,,,,,,,,,,,
1616099118.864,,1.000000e+003,1.600210e+002,1.600015e+002,5,0,1.802352e+000,3.692739e-002,3.439436e-002,6.177960e-001,6.185079e-001,3.128172e-002,6.146834e-001,6.153952e-001,1.820496e-004,1.695619e-004,,,,,,,,,,,,,,,,,,,,
1616099408.841,,1.000000e+003,1.651391e+002,1.650977e+002,1,0,1.211112e+000,-4.266488e-001,,,,,,,-2.103350e-003,,,,,,,,,,,,,,,,,,,,,
1616099408.841,,1.000000e+003,1.650907e+002,1.650493e+002,2,0,7.387713e-001,-7.623523e-001,,,,,,,-3.758346e-003,,,,,,,,,,,,,,,,,,,,,
1616099408.841,,1.000000e+003,1.650493e+002,1.650355e+002,3,0,5.063226e-001,-8.729819e-001,,,,,,,-4.303743e-003,,,,,,,,,,,,,,,,,,,,,
1616099408.841,,1.000000e+003,1.650355e+002,1.650217e+002,4,0,7.277333e-001,-7.710501e-001,,,,,,,-3.801226e-003,,,,,,,,,,,,,,,,,,,,,
1616099408.841,,1.000000e+003,1.650217e+002,1.650148e+002,5,0,1.270772e+000,-3.840755e-001,-3.867000e-001,2.500274e-001,2.501872e-001,-3.831258e-001,2.536016e-001,2.537614e-001,-1.893466e-003,-1.906405e-003,,,,,,,,,,,,,,,,,,,,
1616099698.018,,1.000000e+003,1.701540e+002,1.700881e+002,1,0,1.932183e+000,4.440443e-002,,,,,,,2.189109e-004,,,,,,,,,,,,,,,,,,,,,
1616099698.018,,1.000000e+003,1.701540e+002,1.700881e+002,1,0,2.568492e+000,-3.279214e-001,,,,,,,-1.616631e-003,,,,,,,,,,,,,,,,,,,,,
1616099698.018,,1.000000e+003,1.700881e+002,1.700588e+002,2,0,3.088345e+000,-7.014679e-001,,,,,,,-3.458190e-003,,,,,,,,,,,,,,,,,,,,,
1616099698.018,,1.000000e+003,1.700515e+002,1.700296e+002,3,0,3.449128e+000,-8.343760e-001,,,,,,,-4.113419e-003,,,,,,,,,,,,,,,,,,,,,
1616099698.018,,1.000000e+003,1.700296e+002,1.700150e+002,4,0,3.415320e+000,-8.284249e-001,,,,,,,-4.084080e-003,,,,,,,,,,,,,,,,,,,,,
1616099698.018,,1.000000e+003,1.700150e+002,1.700076e+002,5,0,2.969563e+000,-6.299020e-001,-6.325266e-001,-6.343972e-002,-6.222779e-002,-6.276554e-001,-5.856847e-002,-5.735654e-002,-3.105375e-003,-3.118314e-003,,,,,,,,,,,,,,,,,,,,
1616099989.646,,1.000000e+003,1.751387e+002,1.750922e+002,1,0,2.339283e+000,-1.644948e-001,,,,,,,-8.109483e-004,,,,,,,,,,,,,,,,,,,,,
1616099989.646,,1.000000e+003,1.750922e+002,1.750613e+002,2,0,1.674250e+000,-2.197333e-002,,,,,,,-1.083270e-004,,,,,,,,,,,,,,,,,,,,,
1616099989.646,,1.000000e+003,1.750613e+002,1.750381e+002,3,0,1.107452e+000,-4.525895e-001,,,,,,,-2.231236e-003,,,,,,,,,,,,,,,,,,,,,
1616099989.646,,1.000000e+003,1.750381e+002,1.750149e+002,4,0,6.640718e-001,-7.354961e-001,,,,,,,-3.625947e-003,,,,,,,,,,,,,,,,,,,,,
1616099989.646,,1.000000e+003,1.750149e+002,1.750149e+002,5,0,5.129939e-001,-7.998902e-001,-8.027894e-001,-2.309027e-001,-2.303929e-001,-8.046748e-001,-2.327881e-001,-2.322783e-001,-3.943405e-003,-3.957698e-003,,,,,,,,,,,,,,,,,,,,
1616100281.413,,1.000000e+003,1.801440e+002,1.800868e+002,1,0,8.192534e-001,-6.410413e-001,,,,,,,-3.160291e-003,,,,,,,,,,,,,,,,,,,,,
1616100281.413,,1.000000e+003,1.800868e+002,1.800460e+002,2,0,1.397641e+000,-2.140873e-001,,,,,,,-1.055436e-003,,,,,,,,,,,,,,,,,,,,,
1616100281.413,,1.000000e+003,1.800460e+002,1.800215e+002,3,0,2.066468e+000,-4.501480e-002,,,,,,,-2.219200e-004,,,,,,,,,,,,,,,,,,,,,
1616100281.413,,1.000000e+003,1.800460e+002,1.800215e+002,3,0,2.681468e+000,-4.719687e-001,,,,,,,-2.326774e-003,,,,,,,,,,,,,,,,,,,,,
1616100281.413,,1.000000e+003,1.800215e+002,1.800133e+002,4,0,3.178504e+000,-7.965331e-001,,,,,,,-3.926855e-003,,,,,,,,,,,,,,,,,,,,,
1616100281.413,,1.000000e+003,1.800133e+002,1.800133e+002,5,0,3.481266e+000,-8.856471e-001,-8.588519e-001,-2.630947e-001,-2.612470e-001,-8.582568e-001,-2.624996e-001,-2.606519e-001,-4.366181e-003,-4.234083e-003,,,,,,,,,,,,,,,,,,,,
1616100571.920,,1.000000e+003,1.851500e+002,1.850982e+002,1,0,3.351810e+000,-7.997376e-001,,,,,,,-3.942653e-003,,,,,,,,,,,,,,,,,,,,,
1616100571.920,,1.000000e+003,1.850982e+002,1.850551e+002,2,0,2.852686e+000,-5.409406e-001,,,,,,,-2.666801e-003,,,,,,,,,,,,,,,,,,,,,
1616100571.920,,1.000000e+003,1.850551e+002,1.850379e+002,3,0,2.204369e+000,-6.134220e-002,,,,,,,-3.024130e-004,,,,,,,,,,,,,,,,,,,,,
1616100571.920,,1.000000e+003,1.850379e+002,1.850207e+002,4,0,1.550889e+000,-9.826960e-002,,,,,,,-4.844626e-004,,,,,,,,,,,,,,,,,,,,,
1616100571.920,,1.000000e+003,1.850121e+002,1.850035e+002,5,0,1.007888e+000,-5.160680e-001,-5.193335e-001,4.077366e-002,4.177809e-002,-5.198697e-001,4.023740e-002,4.124182e-002,-2.544181e-003,-2.560279e-003,,,,,,,,,,,,,,,,,,,,
1616100863.738,,1.000000e+003,1.901497e+002,1.900862e+002,1,0,6.007939e-001,-7.478561e-001,,,,,,,-3.686881e-003,,,,,,,,,,,,,,,,,,,,,
1616100863.738,,1.000000e+003,1.900862e+002,1.900499e+002,2,0,5.396941e-001,-7.672353e-001,,,,,,,-3.782419e-003,,,,,,,,,,,,,,,,,,,,,
1616100863.738,,1.000000e+003,1.900499e+002,1.900318e+002,3,0,9.210606e-001,-5.694754e-001,,,,,,,-2.807476e-003,,,,,,,,,,,,,,,,,,,,,
1616100863.738,,1.000000e+003,1.900318e+002,1.900136e+002,4,0,1.528145e+000,-1.214637e-001,,,,,,,-5.988078e-004,,,,,,,,,,,,,,,,,,,,,
1616100863.738,,1.000000e+003,1.900318e+002,1.900136e+002,4,0,2.198399e+000,-3.387555e-002,,,,,,,-1.670042e-004,,,,,,,,,,,,,,,,,,,,,
1616100863.738,,1.000000e+003,1.900136e+002,1.900046e+002,5,0,2.789713e+000,-4.739524e-001,-4.772485e-001,6.931110e-002,7.198462e-002,-4.750363e-001,7.152324e-002,7.419676e-002,-2.336554e-003,-2.352803e-003,,,,,,,,,,,,,,,,,,,,
1616101156.575,,1.000000e+003,1.951502e+002,1.950929e+002,1,0,3.262003e+000,-7.467879e-001,,,,,,,-3.681615e-003,,,,,,,,,,,,,,,,,,,,,
1616101156.575,,1.000000e+003,1.950929e+002,1.950452e+002,2,0,3.494572e+000,-7.991272e-001,,,,,,,-3.939644e-003,,,,,,,,,,,,,,,,,,,,,
1616101156.575,,1.000000e+003,1.950452e+002,1.950262e+002,3,0,3.273293e+000,-7.507553e-001,,,,,,,-3.701174e-003,,,,,,,,,,,,,,,,,,,,,
1616101156.575,,1.000000e+003,1.950262e+002,1.950070e+002,4,0,2.730342e+000,-4.310740e-001,,,,,,,-2.125166e-003,,,,,,,,,,,,,,,,,,,,,
1616101156.575,,1.000000e+003,1.950070e+002,1.950070e+002,5,0,2.068954e+000,1.770074e-002,1.416059e-002,5.567188e-001,5.583727e-001,2.103717e-002,5.635954e-001,5.652493e-001,8.726345e-005,6.981076e-005,,,,,,,,,,,,,,,,,,,,
1616101451.633,,1.000000e+003,2.001509e+002,2.000908e+002,1,0,1.432494e+000,-1.882992e-001,,,,,,,-9.283025e-004,,,,,,,,,,,,,,,,,,,,,
1616101451.633,,1.000000e+003,2.000908e+002,2.000507e+002,2,0,9.125392e-001,-5.693228e-001,,,,,,,-2.806723e-003,,,,,,,,,,,,,,,,,,,,,
1616101451.633,,1.000000e+003,2.000407e+002,2.000307e+002,3,0,5.518548e-001,-7.573168e-001,,,,,,,-3.733521e-003,,,,,,,,,,,,,,,,,,,,,
1616101451.633,,1.000000e+003,2.000307e+002,2.000006e+002,4,0,5.855767e-001,-7.429731e-001,,,,,,,-3.662808e-003,,,,,,,,,,,,,,,,,,,,,
1616101451.633,,1.000000e+003,2.000006e+002,2.000006e+002,5,0,1.031274e+000,-4.925687e-001,-4.960479e-001,4.801179e-002,4.845130e-002,-4.937981e-001,5.026154e-002,5.070105e-002,-2.428331e-003,-2.445483e-003,,,,,,,,,,,,,,,,,,,,
1616101745.031,,1.000000e+003,2.051535e+002,2.050904e+002,1,0,1.661531e+000,-4.562517e-002,,,,,,,-2.249291e-004,,,,,,,,,,,,,,,,,,,,,
1616101745.031,,1.000000e+003,2.051535e+002,2.050904e+002,1,0,2.326613e+000,-1.147496e-001,,,,,,,-5.657079e-004,,,,,,,,,,,,,,,,,,,,,
1616101745.031,,1.000000e+003,2.050904e+002,2.050484e+002,2,0,2.893370e+000,-5.287331e-001,,,,,,,-2.606619e-003,,,,,,,,,,,,,,,,,,,,,
1616101745.031,,1.000000e+003,2.050484e+002,2.050273e+002,3,0,3.336815e+000,-7.522812e-001,,,,,,,-3.708696e-003,,,,,,,,,,,,,,,,,,,,,
1616101745.031,,1.000000e+003,2.050273e+002,2.050168e+002,4,0,3.487816e+000,-7.794427e-001,,,,,,,-3.842601e-003,,,,,,,,,,,,,,,,,,,,,
1616101745.031,,1.000000e+003,2.050168e+002,2.049958e+002,5,0,3.181699e+000,-6.923124e-001,-6.958525e-001,-1.634266e-001,-1.609147e-001,-6.941152e-001,-1.616893e-001,-1.591774e-001,-3.413054e-003,-3.430507e-003,,,,,,,,,,,,,,,,,,,,
1616102040.280,,1.000000e+003,2.101643e+002,2.100981e+002,1,0,2.603006e+000,-3.196814e-001,,,,,,,-1.576008e-003,,,,,,,,,,,,,,,,,,,,,
1616102040.280,,1.000000e+003,2.100981e+002,2.100429e+002,2,0,1.934143e+000,-2.426222e-002,,,,,,,-1.196111e-004,,,,,,,,,,,,,,,,,,,,,
1616102040.280,,1.000000e+003,2.100429e+002,2.100209e+002,3,0,1.319153e+000,-3.370769e-001,,,,,,,-1.661767e-003,,,,,,,,,,,,,,,,,,,,,
1616102040.280,,1.000000e+003,2.100209e+002,2.100099e+002,4,0,8.220153e-001,-6.746117e-001,,,,,,,-3.325790e-003,,,,,,,,,,,,,,,,,,,,,
1616102040.280,,1.000000e+003,2.100099e+002,2.100099e+002,5,0,5.197475e-001,-8.093508e-001,-7.983642e-001,-2.198828e-001,-2.186509e-001,-7.984548e-001,-2.199734e-001,-2.187415e-001,-3.990046e-003,-3.935882e-003,,,,,,,,,,,,,,,,,,,,
1616102334.918,,1.000000e+003,2.151535e+002,2.150899e+002,1,0,6.493830e-001,-7.011628e-001,,,,,,,-3.456686e-003,,,,,,,,,,,,,,,,,,,,,
1616102334.918,,1.000000e+003,2.150899e+002,2.150552e+002,2,0,1.148521e+000,-4.043702e-001,,,,,,,-1.993518e-003,,,,,,,,,,,,,,,,,,,,,
1616102334.918,,1.000000e+003,2.150437e+002,2.150206e+002,3,0,1.796956e+000,1.617481e-002,,,,,,,7.974073e-005,,,,,,,,,,,,,,,,,,,,,
1616102334.918,,1.000000e+003,2.150437e+002,2.150206e+002,3,0,2.450384e+000,-1.933348e-001,,,,,,,-9.531275e-004,,,,,,,,,,,,,,,,,,,,,
1616102334.918,,1.000000e+003,2.150206e+002,2.150032e+002,4,0,2.993428e+000,-5.777154e-001,,,,,,,-2.848098e-003,,,,,,,,,,,,,,,,,,,,,
1616102334.918,,1.000000e+003,2.150032e+002,2.150090e+002,5,0,3.400235e+000,-7.495346e-001,-7.531663e-001,-2.316018e-001,-2.274131e-001,-7.523004e-001,-2.307360e-001,-2.265472e-001,-3.695155e-003,-3.713060e-003,,,,,,,,,,,,,,,,,,,,
1616102630.686,,1.000000e+003,2.201543e+002,2.200817e+002,1,0,3.460876e+000,-8.200323e-001,,,,,,,-4.042705e-003,,,,,,,,,,,,,,,,,,,,,
1616102630.686,,1.000000e+003,2.200817e+002,2.200454e+002,2,0,3.079542e+000,-6.843776e-001,,,,,,,-3.373936e-003,,,,,,,,,,,,,,,,,,,,,
1616102630.686,,1.000000e+003,2.200454e+002,2.200212e+002,3,0,2.472392e+000,-2.807703e-001,,,,,,,-1.384179e-003,,,,,,,,,,,,,,,,,,,,,
1616102630.686,,1.000000e+003,2.200212e+002,2.200091e+002,4,0,1.802128e+000,-3.509628e-002,,,,,,,-1.730223e-004,,,,,,,,,,,,,,,,,,,,,
1616102630.686,,1.000000e+003,2.200091e+002,2.200031e+002,5,0,1.210927e+000,-4.043702e-001,-4.084597e-001,1.706350e-001,1.730518e-001,-4.134613e-001,1.656334e-001,1.680503e-001,-1.993518e-003,-2.013679e-003,,,,,,,,,,,,,,,,,,,,
1616102928.044,,1.000000e+003,2.251451e+002,2.250945e+002,1,0,7.386869e-001,-6.817835e-001,,,,,,,-3.361147e-003,,,,,,,,,,,,,,,,,,,,,
1616102928.044,,1.000000e+003,2.250945e+002,2.250439e+002,2,0,5.065369e-001,-7.715079e-001,,,,,,,-3.803483e-003,,,,,,,,,,,,,,,,,,,,,
1616102928.044,,1.000000e+003,2.250439e+002,2.250186e+002,3,0,7.279539e-001,-6.877346e-001,,,,,,,-3.390486e-003,,,,,,,,,,,,,,,,,,,,,
1616102928.044,,1.000000e+003,2.250186e+002,2.250123e+002,4,0,1.270857e+000,-3.511154e-001,,,,,,,-1.730976e-003,,,,,,,,,,,,,,,,,,,,,
1616102928.044,,1.000000e+003,2.250123e+002,2.250059e+002,5,0,1.932308e+000,5.035554e-003,9.765923e-004,5.550316e-001,5.551256e-001,9.542124e-005,5.541504e-001,5.542445e-001,2.482495e-005,4.814535e-006,,,,,,,,,,,,,,,,,,,,
1616102928.044,,1.000000e+003,2.250123e+002,2.250059e+002,5,0,2.568552e+000,-3.064058e-001,-3.102817e-001,2.382250e-001,2.438673e-001,-3.144923e-001,2.340145e-001,2.396568e-001,-1.510560e-003,-1.529668e-003,,,,,,,,,,,,,,,,,,,,
1616103224.812,,1.000000e+003,2.301546e+002,2.300885e+002,1,0,3.088430e+000,-6.035035e-001,,,,,,,-2.975232e-003,,,,,,,,,,,,,,,,,,,,,
1616103224.812,,1.000000e+003,2.300885e+002,2.300423e+002,2,0,3.449096e+000,-7.336650e-001,,,,,,,-3.616919e-003,,,,,,,,,,,,,,,,,,,,,
1616103224.812,,1.000000e+003,2.300423e+002,2.300290e+002,3,0,3.415103e+000,-7.260354e-001,,,,,,,-3.579306e-003,,,,,,,,,,,,,,,,,,,,,
1616103224.812,,1.000000e+003,2.300290e+002,2.300092e+002,4,0,2.969527e+000,-5.348369e-001,,,,,,,-2.636710e-003,,,,,,,,,,,,,,,,,,,,,
1616103224.812,,1.000000e+003,2.300092e+002,2.300026e+002,5,0,2.339311e+000,-1.826533e-001,-1.278115e-001,3.872944e-001,3.902977e-001,-1.200596e-001,3.950463e-001,3.980497e-001,-9.004685e-004,-6.301022e-004,,,,,,,,,,,,,,,,,,,,
1616103516.191,,1.000000e+003,2.351840e+002,2.351219e+002,1,0,1.674290e+000,-9.659109e-002,,,,,,,-4.761876e-004,,,,,,,,,,,,,,,,,,,,,
1616103516.191,,1.000000e+003,2.351219e+002,2.350666e+002,2,0,1.107481e+000,-4.829554e-001,,,,,,,-2.380938e-003,,,,,,,,,,,,,,,,,,,,,
1616103516.191,,1.000000e+003,2.350666e+002,2.350321e+002,3,0,6.641215e-001,-7.251198e-001,,,,,,,-3.574792e-003,,,,,,,,,,,,,,,,,,,,,
1616103516.191,,1.000000e+003,2.350321e+002,2.350114e+002,4,0,5.129578e-001,-7.757805e-001,,,,,,,-3.824546e-003,,,,,,,,,,,,,,,,,,,,,
1616103516.191,,1.000000e+003,2.350114e+002,2.350045e+002,5,0,8.191425e-001,-6.534013e-001,-6.578875e-001,-9.201387e-002,-9.108949e-002,-6.569191e-001,-9.104548e-002,-9.012109e-002,-3.221225e-003,-3.243342e-003,,,,,,,,,,,,,,,,,,,,
1616103813.149,,1.000000e+003,2.401467e+002,2.400890e+002,1,0,1.397564e+000,-2.150029e-001,,,,,,,-1.059950e-003,,,,,,,,,,,,,,,,,,,,,
1616103813.149,,1.000000e+003,2.400890e+002,2.400458e+002,2,0,2.066335e+000,-3.921629e-002,,,,,,,-1.933337e-004,,,,,,,,,,,,,,,,,,,,,
1616103813.149,,1.000000e+003,2.400890e+002,2.400458e+002,2,0,2.681365e+000,-4.025392e-001,,,,,,,-1.984491e-003,,,,,,,,,,,,,,,,,,,,,
1616103813.149,,1.000000e+003,2.400458e+002,2.400170e+002,3,0,3.178400e+000,-6.976531e-001,,,,,,,-3.439383e-003,,,,,,,,,,,,,,,,,,,,,
1616103813.149,,1.000000e+003,2.400170e+002,2.400025e+002,4,0,3.481262e+000,-7.884457e-001,,,,,,,-3.886985e-003,,,,,,,,,,,,,,,,,,,,,
1616103813.149,,1.000000e+003,2.400025e+002,2.399953e+002,5,0,3.351942e+000,-7.603687e-001,-7.497787e-001,-2.049235e-001,-2.003819e-001,-7.492130e-001,-2.043578e-001,-1.998162e-001,-3.748567e-003,-3.696359e-003,,,,,,,,,,,,,,,,,,,,
1616104111.647,,1.000000e+003,2.451465e+002,2.450864e+002,1,0,2.852647e+000,-5.149999e-001,,,,,,,-2.538915e-003,,,,,,,,,,,,,,,,,,,,,
1616104111.647,,1.000000e+003,2.450864e+002,2.450488e+002,2,0,2.204472e+000,-9.353923e-002,,,,,,,-4.611422e-004,,,,,,,,,,,,,,,,,,,,,
1616104111.647,,1.000000e+003,2.450488e+002,2.450187e+002,3,0,1.550927e+000,-1.657155e-001,,,,,,,-8.169664e-004,,,,,,,,,,,,,,,,,,,,,
1616104111.647,,1.000000e+003,2.450187e+002,2.450037e+002,4,0,1.008006e+000,-5.346843e-001,,,,,,,-2.635958e-003,,,,,,,,,,,,,,,,,,,,,
1616104111.647,,1.000000e+003,2.450037e+002,2.450037e+002,5,0,6.008647e-001,-7.338176e-001,-7.382122e-001,-1.860051e-001,-1.839999e-001,-7.390758e-001,-1.868687e-001,-1.848635e-001,-3.617672e-003,-3.639337e-003,,,,,,,,,,,,,,,,,,,,
1616104410.105,,1.000000e+003,2.501508e+002,2.500803e+002,1,0,5.397148e-001,-7.542650e-001,,,,,,,-3.718476e-003,,,,,,,,,,,,,,,,,,,,,
1616104410.105,,1.000000e+003,2.500803e+002,2.500333e+002,2,0,9.209365e-001,-5.896176e-001,,,,,,,-2.906776e-003,,,,,,,,,,,,,,,,,,,,,
1616104410.105,,1.000000e+003,2.500333e+002,2.500177e+002,3,0,1.528039e+000,-1.953185e-001,,,,,,,-9.629070e-004,,,,,,,,,,,,,,,,,,,,,
1616104410.105,,1.000000e+003,2.500333e+002,2.500177e+002,3,0,2.198324e+000,-7.690664e-002,,,,,,,-3.791446e-004,,,,,,,,,,,,,,,,,,,,,
1616104410.105,,1.000000e+003,2.500177e+002,2.500099e+002,4,0,2.789548e+000,-4.591510e-001,,,,,,,-2.263584e-003,,,,,,,,,,,,,,,,,,,,,
1616104410.105,,1.000000e+003,2.500099e+002,2.500020e+002,5,0,3.261984e+000,-7.097079e-001,-7.142857e-001,-1.692609e-001,-1.634679e-001,-7.141983e-001,-1.691735e-001,-1.633804e-001,-3.498813e-003,-3.521381e-003,,,,,,,,,,,,,,,,,,,,
1616104708.874,,1.000000e+003,2.551382e+002,2.550811e+002,1,0,3.494564e+000,-7.002472e-001,,,,,,,-3.452172e-003,,,,,,,,,,,,,,,,,,,,,
1616104708.874,,1.000000e+003,2.550811e+002,2.550404e+002,2,0,3.273339e+000,-6.468398e-001,,,,,,,-3.188877e-003,,,,,,,,,,,,,,,,,,,,,
1616104708.874,,1.000000e+003,2.550404e+002,2.550160e+002,3,0,2.730451e+000,-3.520310e-001,,,,,,,-1.735489e-003,,,,,,,,,,,,,,,,,,,,,
1616104708.874,,1.000000e+003,2.550160e+002,2.550079e+002,4,0,2.068979e+000,-4.211554e-002,,,,,,,-2.076268e-004,,,,,,,,,,,,,,,,,,,,,
1616104708.874,,1.000000e+003,2.550079e+002,2.549997e+002,5,0,1.432659e+000,-2.465896e-001,-2.064577e-001,2.971278e-001,3.003344e-001,-2.139966e-001,2.895889e-001,2.927955e-001,-1.215670e-003,-1.017823e-003,,,,,,,,,,,,,,,,,,,,
1616105008.052,,1.000000e+003,2.601277e+002,2.600768e+002,1,0,9.126332e-001,-5.133213e-001,,,,,,,-2.530640e-003,,,,,,,,,,,,,,,,,,,,,
1616105008.052,,1.000000e+003,2.600768e+002,2.600514e+002,2,0,5.518709e-001,-7.419050e-001,,,,,,,-3.657542e-003,,,,,,,,,,,,,,,,,,,,,
1616105008.052,,1.000000e+003,2.600514e+002,2.600175e+002,3,0,5.855808e-001,-7.300028e-001,,,,,,,-3.598865e-003,,,,,,,,,,,,,,,,,,,,,
1616105008.052,,1.000000e+003,2.600175e+002,2.600090e+002,4,0,1.031140e+000,-5.194250e-001,,,,,,,-2.560731e-003,,,,,,,,,,,,,,,,,,,,,
1616105008.052,,1.000000e+003,2.600005e+002,2.600005e+002,5,0,1.661380e+000,-1.150548e-001,-1.050447e-001,4.232191e-001,4.235787e-001,-1.015843e-001,4.266795e-001,4.270392e-001,-5.672124e-004,-5.178634e-004,,,,,,,,,,,,,,,,,,,,
1616105008.052,,1.000000e+003,2.600005e+002,2.600005e+002,5,0,2.326475e+000,-1.362651e-001,-1.262856e-001,3.949053e-001,4.023378e-001,-1.305214e-001,3.906695e-001,3.981021e-001,-6.717781e-004,-6.225795e-004,,,,,,,,,,,,,,,,,,,,
1616105309.071,,1.000000e+003,2.651355e+002,2.650737e+002,1,0,2.893359e+000,-5.082858e-001,,,,,,,-2.505815e-003,,,,,,,,,,,,,,,,,,,,,
1616105309.071,,1.000000e+003,2.650737e+002,2.650296e+002,2,0,3.336716e+000,-7.173375e-001,,,,,,,-3.536426e-003,,,,,,,,,,,,,,,,,,,,,
1616105309.071,,1.000000e+003,2.650296e+002,2.650120e+002,3,0,3.487952e+000,-7.478561e-001,,,,,,,-3.686881e-003,,,,,,,,,,,,,,,,,,,,,
1616105309.071,,1.000000e+003,2.650120e+002,2.650208e+002,4,0,3.181897e+000,-6.569109e-001,,,,,,,-3.238527e-003,,,,,,,,,,,,,,,,,,,,,
1616105309.071,,1.000000e+003,2.650208e+002,2.649943e+002,5,0,2.603528e+000,-3.231910e-001,-3.279824e-001,2.037917e-001,2.084318e-001,-3.224466e-001,2.093275e-001,2.139676e-001,-1.593310e-003,-1.616932e-003,,,,,,,,,,,,,,,,,,,,
1616105608.849,,1.000000e+003,2.701332e+002,2.700873e+002,1,0,1.934516e+000,3.891110e-002,,,,,,,1.918291e-004,,,,,,,,,,,,,,,,,,,,,
1616105608.849,,1.000000e+003,2.700873e+002,2.700322e+002,2,0,1.319606e+000,-2.635273e-001,,,,,,,-1.299172e-003,,,,,,,,,,,,,,,,,,,,,
1616105608.849,,1.000000e+003,2.700322e+002,2.700138e+002,3,0,8.225448e-001,-5.545213e-001,,,,,,,-2.733753e-003,,,,,,,,,,,,,,,,,,,,,
1616105608.849,,1.000000e+003,2.700138e+002,2.700046e+002,4,0,5.196894e-001,-7.361065e-001,,,,,,,-3.628956e-003,,,,,,,,,,,,,,,,,,,,,
1616105608.849,,1.000000e+003,2.700046e+002,2.700046e+002,5,0,6.489635e-001,-6.985687e-001,-6.587115e-001,-1.665369e-001,-1.649620e-001,-6.595681e-001,-1.673935e-001,-1.658186e-001,-3.443897e-003,-3.247404e-003,,,,,,,,,,,,,,,,,,,,
1616105908.638,,1.000000e+003,2.751454e+002,2.750785e+002,1,0,1.148247e+000,-4.449599e-001,,,,,,,-2.193623e-003,,,,,,,,,,,,,,,,,,,,,
1616105908.638,,1.000000e+003,2.750785e+002,2.750403e+002,2,0,1.796427e+000,-6.027406e-002,,,,,,,-2.971471e-004,,,,,,,,,,,,,,,,,,,,,
1616105908.638,,1.000000e+003,2.750785e+002,2.750403e+002,2,0,2.449954e+000,-2.043214e-001,,,,,,,-1.007291e-003,,,,,,,,,,,,,,,,,,,,,
1616105908.638,,1.000000e+003,2.750403e+002,2.750117e+002,3,0,2.992923e+000,-5.471969e-001,,,,,,,-2.697644e-003,,,,,,,,,,,,,,,,,,,,,
1616105908.638,,1.000000e+003,2.750117e+002,2.750021e+002,4,0,3.400048e+000,-7.124546e-001,,,,,,,-3.512354e-003,,,,,,,,,,,,,,,,,,,,,
1616105908.638,,1.000000e+003,2.750021e+002,2.750021e+002,5,0,3.461232e+000,-7.223731e-001,-7.273476e-001,-2.089847e-001,-2.025020e-001,-7.262024e-001,-2.078395e-001,-2.013568e-001,-3.561251e-003,-3.585775e-003,,,,,,,,,,,,,,,,,,,,
1616106198.986,,1.000000e+003,2.801711e+002,2.801215e+002,1,0,3.079885e+000,-5.223243e-001,,,,,,,-2.575024e-003,,,,,,,,,,,,,,,,,,,,,
1616106198.986,,1.000000e+003,2.801016e+002,2.800520e+002,2,0,2.472894e+000,-1.580859e-001,,,,,,,-7.793528e-004,,,,,,,,,,,,,,,,,,,,,
1616106198.986,,1.000000e+003,2.800520e+002,2.800123e+002,3,0,1.802672e+000,-5.584887e-002,,,,,,,-2.753312e-004,,,,,,,,,,,,,,,,,,,,,
1616106198.986,,1.000000e+003,2.800123e+002,2.800024e+002,4,0,1.211404e+000,-3.973510e-001,,,,,,,-1.958914e-003,,,,,,,,,,,,,,,,,,,,,
1616106198.986,,1.000000e+003,2.800024e+002,2.800024e+002,5,0,7.389597e-001,-6.483657e-001,-6.236457e-001,-1.298423e-001,-1.267017e-001,-6.273149e-001,-1.335115e-001,-1.303709e-001,-3.196400e-003,-3.074532e-003,,,,,,,,,,,,,,,,,,,,
1616106500.595,,1.000000e+003,2.851276e+002,2.850761e+002,1,0,5.063843e-001,-6.498917e-001,,,,,,,-3.203923e-003,,,,,,,,,,,,,,,,,,,,,
1616106500.595,,1.000000e+003,2.850761e+002,2.850246e+002,2,0,7.275997e-001,-5.848872e-001,,,,,,,-2.883455e-003,,,,,,,,,,,,,,,,,,,,,
1616106500.595,,1.000000e+003,2.850246e+002,2.850040e+002,3,0,1.270522e+000,-3.711051e-001,,,,,,,-1.829523e-003,,,,,,,,,,,,,,,,,,,,,
1616106500.595,,1.000000e+003,2.850040e+002,2.850040e+002,4,0,1.931857e+000,-2.960295e-002,,,,,,,-1.459406e-004,,,,,,,,,,,,,,,,,,,,,
1616106500.595,,1.000000e+003,2.850040e+002,2.850040e+002,4,0,2.568237e+000,-2.713096e-001,,,,,,,-1.337538e-003,,,,,,,,,,,,,,,,,,,,,
1616106500.595,,1.000000e+003,2.850040e+002,2.849937e+002,5,0,3.088201e+000,-5.778680e-001,-5.534837e-001,-7.021757e-002,-6.144527e-002,-5.547228e-001,-7.145669e-002,-6.268439e-002,-2.848851e-003,-2.728638e-003,,,,,,,,,,,,,,,,,,,,
1616106802.683,,1.000000e+003,2.901345e+002,2.900703e+002,1,0,3.449046e+000,-7.019257e-001,,,,,,,-3.460447e-003,,,,,,,,,,,,,,,,,,,,,
1616106802.683,,1.000000e+003,2.900703e+002,2.900276e+002,2,0,3.415380e+000,-6.923124e-001,,,,,,,-3.413054e-003,,,,,,,,,,,,,,,,,,,,,
1616106802.683,,1.000000e+003,2.900276e+002,2.900062e+002,3,0,2.969788e+000,-5.050813e-001,,,,,,,-2.490017e-003,,,,,,,,,,,,,,,,,,,,,
1616106802.683,,1.000000e+003,2.900062e+002,2.900062e+002,4,0,2.339658e+000,-1.255837e-001,,,,,,,-6.191191e-004,,,,,,,,,,,,,,,,,,,,,
1616106802.683,,1.000000e+003,2.900062e+002,2.899955e+002,5,0,1.674512e+000,-9.323405e-002,-9.903257e-002,4.004013e-001,4.054977e-001,-1.041143e-001,3.953196e-001,4.004160e-001,-4.596376e-004,-4.882239e-004,,,,,,,,,,,,,,,,,,,,
1616107105.842,,1.000000e+003,2.951309e+002,2.950645e+002,1,0,1.107592e+000,-4.608295e-001,,,,,,,-2.271859e-003,,,,,,,,,,,,,,,,,,,,,
1616107105.842,,1.000000e+003,2.950645e+002,2.950201e+002,2,0,6.642317e-001,-6.620991e-001,,,,,,,-3.264104e-003,,,,,,,,,,,,,,,,,,,,,
1616107105.842,,1.000000e+003,2.950201e+002,2.949980e+002,3,0,5.129755e-001,-6.973479e-001,,,,,,,-3.437879e-003,,,,,,,,,,,,,,,,,,,,,
1616107105.842,,1.000000e+003,2.949980e+002,2.949980e+002,4,0,8.189858e-001,-6.027406e-001,,,,,,,-2.971471e-003,,,,,,,,,,,,,,,,,,,,,
1616107105.842,,1.000000e+003,2.949980e+002,2.949980e+002,5,0,1.397372e+000,-2.766503e-001,-2.823572e-001,2.210031e-001,2.219047e-001,-2.798414e-001,2.235189e-001,2.244206e-001,-1.363867e-003,-1.392002e-003,,,,,,,,,,,,,,,,,,,,
1616107408.390,,1.000000e+003,3.001215e+002,3.000526e+002,1,0,2.066334e+000,-2.929777e-002,,,,,,,-1.444361e-004,,,,,,,,,,,,,,,,,,,,,
1616107408.390,,1.000000e+003,3.001215e+002,3.000526e+002,1,0,2.681367e+000,-3.263955e-001,,,,,,,-1.609108e-003,,,,,,,,,,,,,,,,,,,,,
1616107408.390,,1.000000e+003,3.000526e+002,3.000296e+002,2,0,3.178377e+000,-5.961791e-001,,,,,,,-2.939123e-003,,,,,,,,,,,,,,,,,,,,,
1616107408.390,,1.000000e+003,3.000296e+002,3.000067e+002,3,0,3.481251e+000,-6.926175e-001,,,,,,,-3.414558e-003,,,,,,,,,,,,,,,,,,,,,
1616107408.390,,1.000000e+003,3.000067e+002,3.000067e+002,4,0,3.352013e+000,-6.584368e-001,,,,,,,-3.246050e-003,,,,,,,,,,,,,,,,,,,,,
1616107408.390,,1.000000e+003,3.000067e+002,2.999837e+002,5,0,2.852837e+000,-4.248177e-001,-4.306772e-001,6.384088e-002,7.129589e-002,-4.296367e-001,6.488140e-002,7.233641e-002,-2.094323e-003,-2.123210e-003,,,,,,,,,,,,,,,,,,,,
1616107408.390,,1.000000e+003,3.000067e+002,2.999837e+002,5,0,2.198225e+000,-4.654073e-002,-5.255288e-002,4.373775e-001,4.494202e-001,-5.207643e-002,4.378540e-001,4.498967e-001,-2.294427e-004,-2.590822e-004,,,,,,,,,,,,,,,,,,,,