File: Pd_callibration/callibration_data_tempDepend.rso.dat.csv
[Header]
TITLE,MPMS RSO Measurement
BYAPP,MPMS Measurement,1.1,Summary
FILEOPENTIME, 1616090444.307000 3/18/2021, 7:00:44 PM

INFO, APPNAME, MPMS MultiVu Application, Revision 1.61,  Build 082

INFO, NAME,
INFO, WEIGHT, 1.000
INFO, AREA, 1.000
INFO, LENGTH, 1.000
INFO, SHAPE, 0
INFO, COMMENT,
INFO, SEQUENCE FILE: callibration_sequence.seq


INFO, BACKGROUND DATA FILE:, None


STARTUPAXIS,X,4,LINEAR,AUTO,0.000000,0.000000
STARTUPAXIS,Y1,5,LINEAR,AUTO,0.000000,0.000000


STARTUPGROUP,Longitudinal
FIELDGROUP,Longitudinal,1,2,3,4,5,6,7,8,9,10,11,19,20,21,22,23,35
FIELDGROUP,Transverse,1,2,3,4,12,13,14,15,16,17,18,24,25,26,27,28,35

PLOT_APPEARANCE,ALL,HORZ_GRID_ON,VERT_GRID_ON,MARKERS_AND_LINES

[Data]
Time,Comment,Field (Oe),Temperature (K),Long Moment (emu),Long Scan Std Dev,Long Offset (cm),Long Offset Std Dev,Long Algorithm,Long Reg Fit,Long Reg Factor,Trans Moment (emu),Trans Scan Std Dev,Trans Offset (cm),Trans Offset Std Dev,Trans Algorithm,Trans Reg Fit,Trans Reg Factor,Long Moment [w/o ABS] (emu),Long Scan Std Dev [w/o ABS],Long Offset [w/o ABS] (cm),Long Offset Std Dev [w/o ABS],Long Reg Fit [w/o ABS],Trans Moment [w/o ABS] (emu),Trans Scan Std Dev [w/o ABS],Trans Offset [w/o ABS] (cm),Trans Offset Std Dev [w/o ABS],Trans Reg Fit [w/o ABS],RSO Position (deg),Amplitude (cm),Frequency,Cycles to Average,Scans per Measurement,Delta Temp (K),Error,EC Comp. Running,Using ABS,
1616090444.307,,1.000000e+003,5.001132e+000,2.221231e-003,1.048775e-007,-1.343109e-001,2.650847e-005,3,9.854366e-001,1.825000e+000,,,,,,,,,,,,,,,,,,0,3.000000e+000,1.000000e+000,10,5,4.290104e-003,0,,0,
1616090713.376,,1.000000e+003,1.000224e+001,2.049846e-003,3.318785e-007,-1.347905e-001,1.233555e-004,3,9.854234e-001,1.825000e+000,,,,,,,,,,,,,,,,,,0,3.000000e+000,1.000000e+000,10,5,6.153107e-003,0,,0,
1616090978.036,,1.000000e+003,1.500107e+001,1.994789e-003,3.481266e-008,-1.353206e-001,1.000992e-004,3,9.854012e-001,1.825000e+000,,,,,,,,,,,,,,,,,,0,3.000000e+000,1.000000e+000,10,5,5.470276e-003,0,,0,
1616091242.175,,1.000000e+003,1.999694e+001,1.974062e-003,3.778216e-007,-1.356884e-001,1.666999e-004,3,9.852628e-001,1.825000e+000,,,,,,,,,,,,,,,,,,0,3.000000e+000,1.000000e+000,10,5,8.859634e-003,0,,0,
1616091507.275,,1.000000e+003,2.500214e+001,1.967848e-003,1.794729e-007,-1.347231e-001,1.206969e-004,3,9.854302e-001,1.825000e+000,,,,,,,,,,,,,,,,,,0,3.000000e+000,1.000000e+000,10,5,4.131317e-003,0,,0,
1616091776.015,,1.000000e+003,3.000070e+001,1.969241e-003,9.316383e-008,-1.339183e-001,1.270235e-004,3,9.854196e-001,1.825000e+000,,,,,,,,,,,,,,,,,,0,3.000000e+000,1.000000e+000,10,5,2.889633e-003,0,,0,
1616092059.454,,1.000000e+003,3.500108e+001,1.975260e-003,6.701267e-008,-1.329952e-001,4.264106e-005,3,9.854819e-001,1.825000e+000,,,,,,,,,,,,,,,,,,0,3.000000e+000,1.000000e+000,10,5,1.541138e-003,0,,0,
1616092354.673,,1.000000e+003,4.000086e+001,1.983731e-003,1.272686e-007,-1.322114e-001,3.549924e-005,3,9.854544e-001,1.825000e+000,,,,,,,,,,,,,,,,,,0,3.000000e+000,1.000000e+000,10,5,1.979828e-003,0,,0,
1616092652.733,,1.000000e+003,4.500108e+001,1.992717e-003,1.727566e-007,-1.313485e-001,1.671877e-004,3,9.854576e-001,1.825000e+000,,,,,,,,,,,,,,,,,,0,3.000000e+000,1.000000e+000,10,5,3.681183e-003,0,,0,
1616092932.122,,1.000000e+003,5.000707e+001,2.001604e-003,2.522373e-007,-1.301179e-001,8.129278e-005,3,9.855831e-001,1.825000e+000,,,,,,,,,,,,,,,,,,0,3.000000e+000,1.000000e+000,10,5,1.194000e-002,0,,0,
1616093206.831,,1.000000e+003,5.500992e+001,2.009224e-003,1.371713e-007,-1.285265e-001,7.376224e-005,3,9.855568e-001,1.825000e+000,,,,,,,,,,,,,,,,,,0,3.000000e+000,1.000000e+000,10,5,2.313995e-002,0,,0,
1616093484.050,,1.000000e+003,6.001406e+001,2.015443e-003,1.779749e-007,-1.271878e-001,8.454485e-005,3,9.856589e-001,1.825000e+000,,,,,,,,,,,,,,,,,,0,3.000000e+000,1.000000e+000,10,5,2.724838e-002,0,,0,
1616093764.979,,1.000000e+003,6.501924e+001,2.019679e-003,1.239725e-007,-1.259693e-001,3.572694e-005,3,9.856647e-001,1.825000e+000,,,,,,,,,,,,,,,,,,0,3.000000e+000,1.000000e+000,10,5,4.382324e-002,0,,0,
1616094047.779,,1.000000e+003,7.002151e+001,2.022802e-003,9.120099e-008,-1.244904e-001,4.041219e-005,3,9.857445e-001,1.825000e+000,,,,,,,,,,,,,,,,,,0,3.000000e+000,1.000000e+000,10,5,3.915405e-002,0,,0,
1616094333.328,,1.000000e+003,7.502958e+001,2.023692e-003,7.504185e-008,-1.229463e-001,6.807836e-005,3,9.858282e-001,1.825000e+000,,,,,,,,,,,,,,,,,,0,3.000000e+000,1.000000e+000,10,5,4.772949e-002,0,,0,
1616094617.278,,1.000000e+003,8.003261e+001,2.022630e-003,8.963473e-008,-1.213796e-001,9.071898e-005,3,9.859042e-001,1.825000e+000,,,,,,,,,,,,,,,,,,0,3.000000e+000,1.000000e+000,10,5,3.942871e-002,0,,0,
1616094901.847,,1.000000e+003,8.503717e+001,2.019793e-003,1.170371e-007,-1.194989e-001,2.233724e-004,3,9.859865e-001,1.825000e+000,,,,,,,,,,,,,,,,,,0,3.000000e+000,1.000000e+000,10,5,5.211639e-002,0,,0,
1616095188.046,,1.000000e+003,9.003526e+001,2.015371e-003,4.970812e-008,-1.177143e-001,7.627608e-005,3,9.860690e-001,1.825000e+000,,,,,,,,,,,,,,,,,,0,3.000000e+000,1.000000e+000,10,5,7.125092e-002,0,,0,
1616095473.125,,1.000000e+003,9.504180e+001,2.009220e-003,8.898152e-008,-1.160763e-001,7.408289e-005,3,9.861439e-001,1.825000e+000,,,,,,,,,,,,,,,,,,0,3.000000e+000,1.000000e+000,10,5,7.375336e-002,0,,0,
1616095754.135,,1.000000e+003,1.000509e+002,2.001581e-003,7.599531e-008,-1.143382e-001,5.411847e-005,3,9.862216e-001,1.825000e+000,,,,,,,,,,,,,,,,,,0,3.000000e+000,1.000000e+000,10,5,8.110046e-002,0,,0,
1616096033.364,,1.000000e+003,1.050529e+002,1.992553e-003,1.442202e-007,-1.124661e-001,1.497540e-004,3,9.862998e-001,1.825000e+000,,,,,,,,,,,,,,,,,,0,3.000000e+000,1.000000e+000,10,5,9.180450e-002,0,,0,
1616096312.443,,1.000000e+003,1.100590e+002,1.982306e-003,1.404343e-007,-1.105675e-001,1.485026e-004,3,9.863749e-001,1.825000e+000,,,,,,,,,,,,,,,,,,0,3.000000e+000,1.000000e+000,10,5,8.729553e-002,0,,0,
1616096587.902,,1.000000e+003,1.150673e+002,1.971145e-003,1.476366e-007,-1.086997e-001,7.317860e-005,3,9.864535e-001,1.825000e+000,,,,,,,,,,,,,,,,,,0,3.000000e+000,1.000000e+000,10,5,1.300049e-001,0,,0,
1616096861.251,,1.000000e+003,1.200662e+002,1.959078e-003,1.909570e-007,-1.070060e-001,4.166154e-005,3,9.865372e-001,1.825000e+000,,,,,,,,,,,,,,,,,,0,3.000000e+000,1.000000e+000,10,5,1.254959e-001,0,,0,
1616097137.980,,1.000000e+003,1.250682e+002,1.946087e-003,1.663436e-007,-1.050515e-001,1.086318e-004,3,9.866237e-001,1.825000e+000,,,,,,,,,,,,,,,,,,0,3.000000e+000,1.000000e+000,10,5,1.065979e-001,0,,0,
1616097415.299,,1.000000e+003,1.300642e+002,1.932240e-003,1.597921e-007,-1.030467e-001,5.431645e-005,3,9.867274e-001,1.825000e+000,,,,,,,,,,,,,,,,,,0,3.000000e+000,1.000000e+000,10,5,1.233978e-001,0,,0,
1616097695.857,,1.000000e+003,1.350683e+002,1.918151e-003,5.512833e-007,-1.010499e-001,2.736335e-004,3,9.867569e-001,1.825000e+000,,,,,,,,,,,,,,,,,,0,3.000000e+000,1.000000e+000,10,5,1.277008e-001,0,,0,
1616097981.924,,1.000000e+003,1.400578e+002,1.903070e-003,2.203789e-007,-9.924961e-002,3.117787e-005,3,9.869185e-001,1.825000e+000,,,,,,,,,,,,,,,,,,0,3.000000e+000,1.000000e+000,10,5,1.213989e-001,0,,0,
1616098258.342,,1.000000e+003,1.450707e+002,1.887431e-003,1.676139e-007,-9.724478e-002,2.786364e-005,3,9.870387e-001,1.825000e+000,,,,,,,,,,,,,,,,,,0,3.000000e+000,1.000000e+000,10,5,1.621094e-001,0,,0,
1616098543.769,,1.000000e+003,1.500608e+002,1.871665e-003,1.823666e-007,-9.523082e-002,2.409158e-005,3,9.871442e-001,1.825000e+000,,,,,,,,,,,,,,,,,,0,3.000000e+000,1.000000e+000,10,5,1.324005e-001,0,,0,
1616098829.946,,1.000000e+003,1.550553e+002,1.855366e-003,1.970907e-007,-9.316149e-002,5.969412e-005,3,9.872519e-001,1.825000e+000,,,,,,,,,,,,,,,,,,0,3.000000e+000,1.000000e+000,10,5,1.286926e-001,0,,0,
1616099118.864,,1.000000e+003,1.600497e+002,1.838843e-003,2.136538e-007,-9.098241e-002,2.905741e-005,3,9.873717e-001,1.825000e+000,,,,,,,,,,,,,,,,,,0,3.000000e+000,1.000000e+000,10,5,1.367035e-001,0,,0,
1616099408.841,,1.000000e+003,1.650555e+002,1.821966e-003,2.007656e-007,-8.876812e-002,4.064505e-005,3,9.875064e-001,1.825000e+000,,,,,,,,,,,,,,,,,,0,3.000000e+000,1.000000e+000,10,5,1.242981e-001,0,,0,
1616099698.018,,1.000000e+003,1.700537e+002,1.805038e-003,2.185698e-007,-8.662415e-002,2.359817e-005,3,9.876038e-001,1.825000e+000,,,,,,,,,,,,,,,,,,0,3.000000e+000,1.000000e+000,10,5,1.464081e-001,0,,0,
1616099989.646,,1.000000e+003,1.750567e+002,1.787985e-003,2.784567e-007,-8.444638e-002,3.786458e-005,3,9.877077e-001,1.825000e+000,,,,,,,,,,,,,,,,,,0,3.000000e+000,1.000000e+000,10,5,1.238098e-001,0,,0,
1616100281.413,,1.000000e+003,1.800493e+002,1.770971e-003,2.121902e-007,-8.228417e-002,3.445462e-005,3,9.878303e-001,1.825000e+000,,,,,,,,,,,,,,,,,,0,3.000000e+000,1.000000e+000,10,5,1.306915e-001,0,,0,
1616100571.920,,1.000000e+003,1.850569e+002,1.753871e-003,2.764528e-007,-7.999604e-002,1.401555e-005,3,9.879675e-001,1.825000e+000,,,,,,,,,,,,,,,,,,0,3.000000e+000,1.000000e+000,10,5,1.464996e-001,0,,0,
1616100863.738,,1.000000e+003,1.900517e+002,1.736757e-003,2.232541e-007,-7.767693e-002,3.310974e-005,3,9.880800e-001,1.825000e+000,,,,,,,,,,,,,,,,,,0,3.000000e+000,1.000000e+000,10,5,1.451111e-001,0,,0,
1616101156.575,,1.000000e+003,1.950500e+002,1.719674e-003,3.153489e-007,-7.524566e-002,2.860568e-005,3,9.882277e-001,1.825000e+000,,,,,,,,,,,,,,,,,,0,3.000000e+000,1.000000e+000,10,5,1.432037e-001,0,,0,
1616101451.633,,1.000000e+003,2.000487e+002,1.702547e-003,3.298734e-007,-7.286646e-002,3.895631e-005,3,9.883435e-001,1.825000e+000,,,,,,,,,,,,,,,,,,0,3.000000e+000,1.000000e+000,10,5,1.502991e-001,0,,0,
1616101745.031,,1.000000e+003,2.050515e+002,1.685507e-003,3.500053e-007,-7.042772e-002,1.263875e-004,3,9.884616e-001,1.825000e+000,,,,,,,,,,,,,,,,,,0,3.000000e+000,1.000000e+000,10,5,1.576996e-001,0,,0,
1616102040.280,,1.000000e+003,2.100518e+002,1.668474e-003,3.313629e-007,-6.807946e-002,4.535818e-005,3,9.883366e-001,1.825000e+000,,,,,,,,,,,,,,,,,,0,3.000000e+000,1.000000e+000,10,5,1.544037e-001,0,,0,
1616102334.918,,1.000000e+003,2.150489e+002,1.651807e-003,4.827813e-007,-6.538679e-002,7.296056e-005,3,9.883845e-001,1.825000e+000,,,,,,,,,,,,,,,,,,0,3.000000e+000,1.000000e+000,10,5,1.502991e-001,0,,0,
1616102630.686,,1.000000e+003,2.200472e+002,1.635452e-003,6.094631e-007,-6.286601e-002,9.099764e-005,3,9.884620e-001,1.825000e+000,,,,,,,,,,,,,,,,,,0,3.000000e+000,1.000000e+000,10,5,1.511993e-001,0,,0,
1616102928.044,,1.000000e+003,2.250490e+002,1.618757e-003,2.945768e-007,-5.987498e-002,1.244361e-004,3,9.886825e-001,1.825000e+000,,,,,,,,,,,,,,,,,,0,3.000000e+000,1.000000e+000,10,5,1.391907e-001,0,,0,
1616103224.812,,1.000000e+003,2.300495e+002,1.602141e-003,2.855973e-007,-5.655508e-002,2.073463e-004,3,9.893152e-001,1.825000e+000,,,,,,,,,,,,,,,,,,0,3.000000e+000,1.000000e+000,10,5,1.520081e-001,0,,0,
1616103516.191,,1.000000e+003,2.350653e+002,1.585497e-003,2.822398e-007,-5.350406e-002,5.105238e-005,3,9.894522e-001,1.825000e+000,,,,,,,,,,,,,,,,,,0,3.000000e+000,1.000000e+000,10,5,1.795044e-001,0,,0,
1616103813.149,,1.000000e+003,2.400451e+002,1.569351e-003,3.889688e-007,-5.074498e-002,3.443750e-005,3,9.893903e-001,1.825000e+000,,,,,,,,,,,,,,,,,,0,3.000000e+000,1.000000e+000,10,5,1.513977e-001,0,,0,
1616104111.647,,1.000000e+003,2.450465e+002,1.553349e-003,3.335350e-007,-4.765783e-002,3.361428e-005,3,9.897142e-001,1.825000e+000,,,,,,,,,,,,,,,,,,0,3.000000e+000,1.000000e+000,10,5,1.428070e-001,0,,0,
1616104410.105,,1.000000e+003,2.500435e+002,1.537397e-003,3.811446e-007,-4.443569e-002,2.771441e-005,3,9.898028e-001,1.825000e+000,,,,,,,,,,,,,,,,,,0,3.000000e+000,1.000000e+000,10,5,1.488037e-001,0,,0,
1616104708.874,,1.000000e+003,2.550429e+002,1.521822e-003,3.213550e-007,-4.115012e-002,1.666817e-005,3,9.899501e-001,1.825000e+000,,,,,,,,,,,,,,,,,,0,3.000000e+000,1.000000e+000,10,5,1.385040e-001,0,,0,
1616105008.052,,1.000000e+003,2.600429e+002,1.506248e-003,3.225235e-007,-3.774959e-002,2.835673e-005,3,9.901140e-001,1.825000e+000,,,,,,,,,,,,,,,,,,0,3.000000e+000,1.000000e+000,10,5,1.271973e-001,0,,0,
1616105309.071,,1.000000e+003,2.650402e+002,1.490645e-003,2.657424e-007,-3.416152e-002,2.894849e-005,3,9.902765e-001,1.825000e+000,,,,,,,,,,,,,,,,,,0,3.000000e+000,1.000000e+000,10,5,1.412048e-001,0,,0,
1616105608.849,,1.000000e+003,2.700414e+002,1.475655e-003,2.147492e-007,-3.035004e-002,4.157555e-005,3,9.904079e-001,1.825000e+000,,,,,,,,,,,,,,,,,,0,3.000000e+000,1.000000e+000,10,5,1.286011e-001,0,,0,
1616105908.638,,1.000000e+003,2.750413e+002,1.461044e-003,3.594584e-007,-2.629201e-002,1.271252e-005,3,9.905859e-001,1.825000e+000,,,,,,,,,,,,,,,,,,0,3.000000e+000,1.000000e+000,10,5,1.432800e-001,0,,0,
1616106198.986,,1.000000e+003,2.800530e+002,1.446457e-003,3.079386e-007,-2.186963e-002,2.354053e-005,3,9.907639e-001,1.825000e+000,,,,,,,,,,,,,,,,,,0,3.000000e+000,1.000000e+000,10,5,1.687012e-001,0,,0,
1616106500.595,,1.000000e+003,2.850339e+002,1.432256e-003,2.770201e-007,-1.711532e-002,1.636178e-005,3,9.908947e-001,1.825000e+000,,,,,,,,,,,,,,,,,,0,3.000000e+000,1.000000e+000,10,5,1.338806e-001,0,,0,
1616106802.683,,1.000000e+003,2.900351e+002,1.418105e-003,3.437096e-007,-1.211921e-002,2.585349e-005,3,9.910401e-001,1.825000e+000,,,,,,,,,,,,,,,,,,0,3.000000e+000,1.000000e+000,10,5,1.389771e-001,0,,0,
1616107105.842,,1.000000e+003,2.950290e+002,1.404132e-003,2.917528e-007,-6.873866e-003,2.555274e-005,3,9.911686e-001,1.825000e+000,,,,,,,,,,,,,,,,,,0,3.000000e+000,1.000000e+000,10,5,1.329041e-001,0,,0,
1616107408.390,,1.000000e+003,3.000297e+002,1.390305e-003,3.547379e-007,-1.301988e-003,3.180202e-005,3,9.912111e-001,1.825000e+000,,,,,,,,,,,,,,,,,,0,3.000000e+000,1.000000e+000,10,5,1.377869e-001,0,,0,